Workbook
Name CAPEX_TOTAL: '[2]Assumptions - Pretpostavke'!$E$46
Name CONTINGENCY_PCT: '[2]Assumptions - Pretpostavke'!$E$72
Name MACHINE_PARK_TOTAL: '[2]Assumptions - Pretpostavke'!$E$35

Sheet Executive Summary
A1: ARS METAL INDUSTRIES – Nova fabrika Podgorica
A2: Executive Summary – CAPEX & Ključni parametri
A3: Ukupni CAPEX (sa contingency) | B3: =CAPEX_TOTAL*(1+CONTINGENCY_PCT) | D3: Datum ažuriranja | E3: =TODAY()
A4: Verzija | B4: 4.0 – Bank Ready
A6: KPI | B6: Vrijednost | C6: Jedinica | D6: % od ukupnog CAPEX | E6: Low | F6: High | G6: Komentar
A7: Ukupni CAPEX | B7: =B3 | C7: € | D7: 100%
A8: Machine Park | B8: =MACHINE_PARK_TOTAL | C8: € | D8: =B8/B7
A9: Hala & građevina | B9: =BUILD_COST*10000 | C9: € | D9: =B9/B7
A10: Contingency | B10: =CONTINGENCY_AMOUNT | C10: € | D10: =B10/B7
A11: Soft Costs | B11: =SOFT_COSTS_AMOUNT | C11: € | D11: =B11/B7
A12: Working Capital | B12: =WC_TOTAL_EST | C12: €
A14: Kategorija | B14: Iznos (€) | C14: % ukupno
A15: Građevina & hala | B15: =BUILD_COST*10000 | C15: =B15/$B$7
A16: Machine Park | B16: =MACHINE_PARK_TOTAL | C16: =B16/$B$7
A17: Soft Costs | B17: =SOFT_COSTS_AMOUNT | C17: =B17/$B$7
A18: Contingency | B18: =CONTINGENCY_AMOUNT | C18: =B18/$B$7
A19: Ukupno | B19: =SUM(B15:B18) | C19: 100%
A27: Godina/Faza | B27: % CAPEX-a | C27: Iznos (€) | D27: Ključne aktivnosti
A28: 2026 | B28: 0.25 | C28: =B28*$B$7 | D28: Zemljište, dozvole, projektovanje, početak građevine
A29: 2027 | B29: 0.55 | C29: =B29*$B$7 | D29: Glavna građevina, većina mašina, MEP
A30: 2028 | B30: 0.2 | C30: =B30*$B$7 | D30: Završetak, instalacija, commissioning
A37: Rizik | B37: Vjerovatnoća | C37: Utjecaj (€) | D37: Mitigacija
A38: Deprecijacija TRY (+20%) | B38: Srednja | C38: =FX_STRESS_20 | D38: 80% hedžovano forward ugovorom
A39: Kašnjenje dozvola | B39: Visoka | C39: 400000 | D39: Već započeta procedura
A40: Viši građevinski troškovi | B40: Srednja | C40: 500000 | D40: Contingency 15% na civil
A41: Veći WC potreban | B41: Srednja | C41: 400000 | D41: Revolving kredit linija

Sheet Depreciation Schedule
A1: PLAN AMORTIZACIJE – DEPRECIATION SCHEDULE
A2: Početak amortizacije: Q3 2028 (mid-year 50%)
A3: Poreske stope (PDPL CG 2026):
A4: I grupa (hala): 2.5% straight-line
A5: II grupa (opšta oprema): 10% degresivno
A6: III grupa (laseri, robot): 15% degresivno
A7: IV grupa (viljuškari, kranovi, generator): 20% degresivno
A8: Računovodstvena amortizacija: straight-line (5–10 godina oprema)
A12: Red | B12: Mašina / Linija | C12: Osnovica (€) | D12: Poreska grupa | E12: Stopa % | F12: 2028 | G12: 2029 | H12: 2030 | I12: 2031 | J12: 2032 | K12: 2033 | L12: 2034 | M12: 2035 | N12: 2036 | O12: 2037 | P12: 2038
A13: 1 | B13: UNI-MAK linija | C13: 900000 | D13: II | E13: 0.1 | F13: =C13*E13*0.5 | G13: =(C13-SUM(F13:F13))*E13 | H13: =(C13-SUM(F13:G13))*E13 | I13: =(C13-SUM(F13:H13))*E13 | J13: =(C13-SUM(F13:I13))*E13 | K13: =(C13-SUM(F13:J13))*E13 | L13: =(C13-SUM(F13:K13))*E13 | M13: =(C13-SUM(F13:L13))*E13 | N13: =(C13-SUM(F13:M13))*E13 | O13: =(C13-SUM(F13:N13))*E13
A14: 2 | B14: SLS MECANO robot | C14: 80000 | D14: III | E14: 0.15 | F14: =C14*E14*0.5 | G14: =(C14-SUM(F14:F14))*E14 | H14: =(C14-SUM(F14:G14))*E14 | I14: =(C14-SUM(F14:H14))*E14 | J14: =(C14-SUM(F14:I14))*E14 | K14: =(C14-SUM(F14:J14))*E14 | L14: =(C14-SUM(F14:K14))*E14 | M14: =(C14-SUM(F14:L14))*E14 | N14: =(C14-SUM(F14:M14))*E14 | O14: =(C14-SUM(F14:N14))*E14
A15: 3 | B15: Abkant + Punta + Giyotin | C15: 342490 | D15: II | E15: 0.1 | F15: =C15*E15*0.5 | G15: =(C15-SUM(F15:F15))*E15 | H15: =(C15-SUM(F15:G15))*E15 | I15: =(C15-SUM(F15:H15))*E15 | J15: =(C15-SUM(F15:I15))*E15 | K15: =(C15-SUM(F15:J15))*E15 | L15: =(C15-SUM(F15:K15))*E15 | M15: =(C15-SUM(F15:L15))*E15 | N15: =(C15-SUM(F15:M15))*E15 | O15: =(C15-SUM(F15:N15))*E15
A16: 4 | B16: NKN Laseri | C16: 965000 | D16: III | E16: 0.15 | F16: =C16*E16*0.5 | G16: =(C16-SUM(F16:F16))*E16 | H16: =(C16-SUM(F16:G16))*E16 | I16: =(C16-SUM(F16:H16))*E16 | J16: =(C16-SUM(F16:I16))*E16 | K16: =(C16-SUM(F16:J16))*E16 | L16: =(C16-SUM(F16:K16))*E16 | M16: =(C16-SUM(F16:L16))*E16 | N16: =(C16-SUM(F16:M16))*E16 | O16: =(C16-SUM(F16:N16))*E16
A17: 5 | B17: Vinčevi | C17: 785000 | D17: IV | E17: 0.2 | F17: =C17*E17*0.5 | G17: =(C17-SUM(F17:F17))*E17 | H17: =(C17-SUM(F17:G17))*E17 | I17: =(C17-SUM(F17:H17))*E17 | J17: =(C17-SUM(F17:I17))*E17 | K17: =(C17-SUM(F17:J17))*E17 | L17: =(C17-SUM(F17:K17))*E17 | M17: =(C17-SUM(F17:L17))*E17 | N17: =(C17-SUM(F17:M17))*E17 | O17: =(C17-SUM(F17:N17))*E17
A18: 6 | B18: GENPOWER generator | C18: 72085 | D18: IV | E18: 0.2 | F18: =C18*E18*0.5 | G18: =(C18-SUM(F18:F18))*E18 | H18: =(C18-SUM(F18:G18))*E18 | I18: =(C18-SUM(F18:H18))*E18 | J18: =(C18-SUM(F18:I18))*E18 | K18: =(C18-SUM(F18:J18))*E18 | L18: =(C18-SUM(F18:K18))*E18 | M18: =(C18-SUM(F18:L18))*E18 | N18: =(C18-SUM(F18:M18))*E18 | O18: =(C18-SUM(F18:N18))*E18
A19: 7 | B19: ASTOR pano | C19: 53862 | D19: II | E19: 0.1 | F19: =C19*E19*0.5 | G19: =(C19-SUM(F19:F19))*E19 | H19: =(C19-SUM(F19:G19))*E19 | I19: =(C19-SUM(F19:H19))*E19 | J19: =(C19-SUM(F19:I19))*E19 | K19: =(C19-SUM(F19:J19))*E19 | L19: =(C19-SUM(F19:K19))*E19 | M19: =(C19-SUM(F19:L19))*E19 | N19: =(C19-SUM(F19:M19))*E19 | O19: =(C19-SUM(F19:N19))*E19
A20: 8 | B20: Ostale mašine | C20: 747350 | D20: II/III/IV | E20: 0.12 | F20: =C20*E20*0.5 | G20: =(C20-SUM(F20:F20))*E20 | H20: =(C20-SUM(F20:G20))*E20 | I20: =(C20-SUM(F20:H20))*E20 | J20: =(C20-SUM(F20:I20))*E20 | K20: =(C20-SUM(F20:J20))*E20 | L20: =(C20-SUM(F20:K20))*E20 | M20: =(C20-SUM(F20:L20))*E20 | N20: =(C20-SUM(F20:M20))*E20 | O20: =(C20-SUM(F20:N20))*E20
A21: 9 | B21: Građevina & hala | C21: 6500000 | D21: I | E21: 0.025 | F21: =C21*E21 | G21: =C21*E21 | H21: =C21*E21 | I21: =C21*E21 | J21: =C21*E21 | K21: =C21*E21 | L21: =C21*E21 | M21: =C21*E21 | N21: =C21*E21 | O21: =C21*E21
B23: Ukupno amortizacija po godinama | F23: =SUM(F13:F21) | G23: =SUM(G13:G21) | H23: =SUM(H13:H21) | I23: =SUM(I13:I21) | J23: =SUM(J13:J21) | K23: =SUM(K13:K21) | L23: =SUM(L13:L21) | M23: =SUM(M13:M21) | ... O23: =SUM(O13:O21)
A55: Napomena: Poreska amortizacija smanjuje oporezivu dobit (PDPL). Razlika između poreske i računovodstvene stvara odložene poreze (IAS 12).

Sheet Funding Sources & Uses
A1: ARS METAL INDUSTRIES – FUNDING SOURCES & USES
A2: Ukupni potrebni iznos (CAPEX + WC + finansijski troškovi) | B2: 15887500
A5: IZVORI SREDSTAVA (Sources) | B5: Iznos (€) | C5: % ukupno | E5: NAMENE SREDSTAVA (Uses) | F5: Iznos (€) | G5: % ukupno
A6: Sopstveni kapital / Equity | B6: 3500000 | C6: =B6/$B$2 | E6: CAPEX bez contingency | F6: 12500000 | G6: =F6/$B$2
A7: Grant / Bespovratna sredstva | B7: 1875000 | C7: =B7/$B$2 | E7: Contingency / Rezerva | F7: 1187500 | G7: =F7/$B$2
A8: Investicioni kredit | B8: 8000000 | C8: =B8/$B$2 | E8: Početni obrtni kapital (WC) | F8: 2200000 | G8: =F8/$B$2
A9: Odloženo plaćanje dobavljača | B9: 1200000 | C9: =B9/$B$2 | E9: Početni finansijski troškovi | F9: 200000 | G9: =F9/$B$2
A10: Revolving WC linija | B10: 1312500 | C10: =B10/$B$2 | E10: Rezerva za kamate tokom grace | F10: 100000 | G10: =F10/$B$2
A11: Ukupno IZVORI | B11: =SUM(B6:B10) | E11: Ukupno NAMENE | F11: =SUM(F6:F10)
A13: Balans (Sources – Uses) | B13: =B11-F11
A30: Balans → Sources = Uses (0 razlike → model konzistentan)
A31: Grant cilj 15% (Fond za inovacije / IPA III) – aplikacija u toku
A32: Kredit očekivana kamata 5,2–6,5%, grace 12–18 mjeseci
A33: Equity 22% – može se povećati na 25–30%
A34: WC linija: revolving kredit kod NLB/Addiko/IRF

Sheet ASSUMPTIONS   MASTER INPUT
A1: ARS Metal Industries DOO Version 1.0 Date: 25.02.2026 | C1: ASSUMPTIONS / MASTER INPUT
H2: VAT_RATE | I2: DEBT_INT_RATE | J2: 0.065
A3: Br | B3: KEY | C3: Opis | D3: Base vrijednost | E3: Jedinica | F3: Komentar / Izvor | G3: Status | H3: =XLOOKUP("VAT_STD",$B:$B,$D:$D)/100 | I3: TENOR_MONTHS | J3: 120
I4: GRACE_MONTHS | J4: 36
A5: 1. MACRO & TAX ASSUMPTIONS
A6: MT1 | B6: FX_EUR_TRY | C6: Kurs EUR/TRY (uvoz mašina iz Turske) | D6: 51.7 | E6: TRY | F6: ECB/TCMB 24–25.02.2026 | G6: Soft | H6: Najveći valutni rizik (~80 % Machine Park). Hedžuj 80 % u EUR!
A7: MT2 | B7: VAT_STD | C7: Standardna stopa PDV-a | D7: 21 | E7: % | F7: Zakon o PDV CG | G7: Hard | H7: Skriveni trošak na OPEX – jede EBITDA 2–3 % godišnje
A8: MT3 | B8: VAT_INV | C8: PDV na investicije > 0.5 mil € | D8: 0 | E8: % | F8: Član 25 Zakona o PDV | G8: Hard | H8: Najveći besplatni keš od države (~2.5–2.8 mil € uštede)
A9: MT4 | B9: CIT_RATE | C9: Porez na dobit (efektivna) | D9: 9–15 | E9: % | F9: Zakon o porezu na dobit CG | G9: Hard | H9: Progresivno + tax shield ~0.9–1.1 mil €/god
A10: MT5 | B10: WHT_DIV | C10: Porez po odbitku na dividendu | D10: 15 | E10: % | F10: Poreski propisi CG | G10: Hard | H10: Reinvestiraj profit prve 3–4 godine + DTU
A11: MT6 | B11: INF_CONSTRUCTION | C11: Inflacija građevinskih troškova | D11: 3.5 | E11: % | F11: CBCG / tržište 2026 | G11: Soft | H11: Contingency 9.5 % obavezan
A12: MT7 | B12: INF_OPEX | C12: Inflacija operativnih troškova | D12: 2.5 | E12: % | F12: CBCG / IMF / MONSTAT | G12: Soft | H12: Price pass-through klauzule obavezne
A13: MT8 | B13: DISCOUNT_RATE | C13: Socio-ekonomska diskontna stopa | D13: 8 | E13: % | F13: JASPERS / IPA III | G13: Hard | H13: Samo za grantove i socio-analizu
A14: MT9 | B14: WACC | C14: Weighted Average Cost of Capital | D14: 9.5 | E14: % | F14: Izračunato | G14: Hard | H14: Project IRR 16.5 % > WACC → NPV pozitivan
A15: MT10 | B15: MODEL_CCY | C15: Model valuta | D15: EUR | E15: text | F15: Sva izvještavanja u EUR | G15: Hard | H15: Eliminira valutni rizik
A16: 2. TIMELINE / KEY DATES
A17: TL1 | B17: FINANCIAL_CLOSE | C17: Financial Close | D17: 30.06.2026 | E17: Datum | F17: Nakon odobrenja kredita/granta | G17: Hard | H17: Početak drawdown-a
A18: TL2 | B18: CONSTRUCTION_START | C18: Početak radova | D18: 01.07.2026 | E18: Datum | F18: Odmah nakon dozvola | G18: Hard | H18: Kašnjenje 6 m → IRR -2–3 pp
A19: TL3 | B19: HALL_COMPLETION | C19: Mehanički završetak hale | D19: 30.06.2027 | E19: Datum | F19: 12 mjeseci od starta | G19: Hard | H19: Početak amortizacije zgrade
A20: TL4 | B20: EQUIPMENT_COMMISSIONING | C20: Commissioning mašina + solara | D20: 31.12.2028 | E20: Datum | F20: Nakon montaže | G20: Hard | H20: Najveći tax shield
A21: TL5 | B21: SOLAR_COD | C21: Solar COD | D21: 30.11.2028 | E21: Datum | F21: 1 mjesec prije commissioning | G21: Hard | H21: Ušteda struje 0.3–0.4 mil €/god
A22: TL6 | B22: ISO_CERTIFICATION_DATE | C22: ISO + EN/CE | D22: 31.05.2029 | E22: Datum | F22: Prije COD | G22: Hard | H22: Obavezno za 70 % off-take
A23: TL7 | B23: FIRST_TENDER_SUBMISSION | C23: Prvi tender | D23: 01.04.2029 | E23: Datum | F23: 3 mjeseca prije COD | G23: Soft | H23: Pipeline za revenue
A24: TL8 | B24: PROVISIONAL_ACCEPTANCE_CERT | C24: PAC | D24: 15.06.2029 | E24: Datum | F24: 15 dana prije COD | G24: Hard | H24: Revenue recognition
A25: TL9 | B25: COD | C25: Commercial Operations Date | D25: 01.07.2029 | E25: Datum | F25: Početak proizvodnje | G25: Hard | H25: NAJKRITIČNIJI DATUM – kašnjenje 6 m → IRR -4–6 pp
A26: TL10 | B26: GRACE_PERIOD_END | C26: Kraj grace perioda | D26: 30.06.2029 | E26: Datum | F26: 36 mjeseci od FC | G26: Hard | H26: Početak otplate glavnice
A27: TL11 | B27: FINAL_ACCEPTANCE_CERT | C27: FAC | D27: 31.12.2029 | E27: Datum | F27: 6 mjeseci nakon PAC | G27: Hard | H27: Kraj EPC odgovornosti
A28: 3. CAPEX & ASSET LIFE (Ukupno fixed assets 12.850.000 €)
A29: Br | B29: KEY | C29: Opis / Asset Class | D29: Base vrijednost | E29: Jedinica | F29: Useful Life | G29: Deprec. Rate | H29: Tax shield godišnje
A30: CA1 | B30: CAPEX_LAND_PREP | C30: Zemljište + priprema | D30: 380 | E30: € | F30: ∞ | G30: 0 | H30: 0
A31: CA2 | B31: CAPEX_BUILDING_HALL | C31: Hala 10.000 m² | D31: 7.505.000 | E31: € | F31: 40 god | G31: 0.025 | H31: ~188k €
A32: CA3 | B32: CAPEX_MACHINE_PARK | C32: Kompletan park mašina | D32: 3.945.787 | E32: € | F32: 12 god | G32: 0.12 | H32: ~470–590k €
A33: CA4 | B33: CAPEX_SOLAR_SYSTEM | C33: Rooftop solar 1.4 MWp | D33: 994 | E33: € | F33: 25 god | G33: 0.04 | H33: ~40k € + OPEX ušteda 250–300k €
A34: CA5 | B34: CAPEX_MEP_INFRA | C34: Elektro, HVAC, IT | D34: 1.505.000 | E34: € | F34: 18 god | G34: 0.055 | H34: ~83k €
A35: CA6 | B35: CAPEX_SOFT_COSTS | C35: Projektovanje, ERP, obuka | D35: 665 | E35: € | F35: 5 god | G35: 0.2 | H35: ~133k €
A36: CA7 | B36: CONTINGENCY_RESERVE | C36: Rezerva za rizike (9.5 %) | D36: 1.220.000 | E36: € | F36: – | G36: – | H36: Ako se ne potroši → +1–2 pp IRR
A37: CA8 | B37: TOTAL_CAPEX_FIXED | C37: Ukupno fixed assets | D37: 12.850.000 | E37: € | F37: – | G37: – | H37: ~0.9–1.1 mil €/god
A38: 4. CAPEX DRAW SCHEDULE + OPERATIONAL PARAMETERS (Motor)
A39: Br | B39: KEY | C39: Opis | D39: Base vrijednost | E39: Jedinica | F39: Komentar / Benchmark | G39: Status | H39: H – Finansijski uticaj / Rizik / Lekcija
A40: CA10 | B40: CAPEX_DRAW_PHASE1_PCT | C40: Faza 1 (2026–mid 2027) | D40: 55 | E40: % | F40: Hala + priprema + contingency | G40: Hard | H40: ~7.1 mil € outflow
...

Sheet CAPEX_MASTER (2)
A1: ARS METAL INDUSTRIES DOO – CAPEX MASTER
A2: Version 2.0 | Datum: 26.02.2026 | CFO: Onur
L3: ASSUMPTIONS
A4: TOTAL PROJECT COST (bez PDV) | B4: Kategorija | C4: Subtotal bez PDV (€) | D4: Subtotal sa PDV (€) | E4: % od ukupnog CAPEX | L4: PDV stopa | M4: 0.21
A5: 1. Land & Site | C5: =SUMIF($B$22:$B$1000,$A5,$I$22:$I$1000) | D5: =C5*(1+'ASSUMPTIONS MASTER INPUT'!$H$3) | E5: =IF($C$13=0,0,C5/$C$13)
A6: 2. Civil Works | C6: =SUMIF($B$22:$B$1000,$A6,$I$22:$I$1000) | D6: =C6*(1+'ASSUMPTIONS MASTER INPUT'!$H$3) | E6: =IF($C$13=0,0,C6/$C$13)
A7: 3. Machinery (ARS linija) | C7: =SUMIF($B$22:$B$1000,$A7,$I$22:$I$1000) | D7: =C7*(1+'ASSUMPTIONS MASTER INPUT'!$H$3) | E7: =IF($C$13=0,0,C7/$C$13)
A8: 4. Installation & Commissioning | C8: =SUMIF($B$22:$B$1000,$A8,$I$22:$I$1000) | D8: =C8*(1+'ASSUMPTIONS MASTER INPUT'!$H$3) | E8: =IF($C$13=0,0,C8/$C$13)
A9: 5. Engineering & Permits | C9: =SUMIF($B$22:$B$1000,$A9,$I$22:$I$1000) | D9: =C9*(1+'ASSUMPTIONS MASTER INPUT'!$H$3) | E9: =IF($C$13=0,0,C9/$C$13)
A10: 6. Contingency (7%) | C10: =SUM(C5:C9)*0.07 | D10: =C10*(1+'ASSUMPTIONS MASTER INPUT'!$H$3) | E10: =IF($C$13=0,0,C10/$C$13)
A11: TOTAL CAPEX (bez WC) | C11: =SUM(C5:C10) | D11: =SUM(D5:D10) | E11: 1
A12: 7. Working Capital (start-up) | C12: =SUMIF($B$22:$B$1000,$A12,$I$22:$I$1000) | D12: =C12*(1+'ASSUMPTIONS MASTER INPUT'!$H$3) | E12: =IF($C$13=0,0,C12/$C$13)
A13: GRAND TOTAL INVESTICIJA | C13: =C11+C12 | D13: =D11+D12 | E13: 1
A15: FUNDING STRUCTURE
A16: Equity (Hamzi + sopstveno) | B16: 0.4 | C16: =D13*0.4
A17: Bank Debt | B17: 0.55 | C17: =D13*0.55
A18: Grant (EU/IPA opcionalno) | B18: 0.05 | C18: =D13*0.05
A19: UKUPNO FINANSIRANJE | C19: =SUM(C16:C18)
A21: CAPEX ID | B21: Category | C21: Subcategory | D21: Description | E21: Supplier | F21: Unit | G21: Qty | H21: Unit Cost € | I21: Total bez PDV | J21: PDV 21% | K21: Total sa PDV | L21: Year | M21: Useful Life | N21: Funding Source | O21: Notes / Rizik
A22: 1.1 | B22: 1. Land & Site | C22: Acquisition | D22: Kupovina parcele (cca 15.000–18.000 m² bruto, uzeto 22.500 m²) | E22: - | F22: m² | G22: 22500 | H22: 55 | I22: =G22*H22 | J22: =I22*'ASSUMPTIONS MASTER INPUT'!$H$3 | K22: =I22+J22 | L22: 2026 | M22: 999 | N22: Equity | O22: Raspon 750k–1.1M €; ~45–65 €/m² po oglasima Tuzi 2026; proveri katastar
A23: 1.2 | B23: 1. Land & Site | C23: Acquisition | D23: Pravne i Notarske takse (prenos apsolutnih prava, upis u katastar) | E23: - | F23: % | G23: 0.02 | H23: =I22 | I23: =G23*H23 | J23: =I23*'ASSUMPTIONS MASTER INPUT'!$H$3 | K23: 2026 | L23: 999 | M23: Equity | N23: 1–3% vrednosti parcele; poreski i katastarski troškovi
A24: 1.3 | B24: 1. Land & Site | C24: Inženjering | D24: Geomehaničko ispitivanje (bušotine i ispitivanje nosivosti tla) | E24: - | F24: kom | G24: 1 | H24: 7500 | I24: =G24*H24 | J24: =I24*'ASSUMPTIONS MASTER INPUT'!$H$3 | K24: =I24+J24 | L24: 2026 | M24: 999 | N24: Equity | O24: 5–10k €; ključno za heavy duty podove i kraneve
A25: 1.4 | B25: 1. Land & Site | C25: Priprema | D25: Priprema i ravnanje terena (skidanje humusa, nasipanje tampona, drenaža) | E25: - | F25: m² | G25: 16500 | H25: 5 | I25: =G25*H25 | J25: =I25*'ASSUMPTIONS MASTER INPUT'!$H$3 | K25: =I25+J25 | L25: 2026 | M25: 40 | N25: Equity | O25: 60–100k € ukupno; zavisi od terena
A26: 1.5 | B26: 1. Land & Site | C26: Takse | D26: Komunalna naknada za opremanje (Opština Tuzi, zona I) | E26: - | F26: m² | G26: 10000 | H26: 48.81 | I26: =G26*H26 | J26: =I26*'ASSUMPTIONS MASTER INPUT'!$H$3 | K26: =I26+J26 | L26: 2026 | M26: 999 | N26: Equity | O26: Po Odluci Opštine Tuzi ~48.81 €/m²; proveri subvencije za industriju
A27: 1.6 | B27: 1. Land & Site | C27: Infrastruktura | D27: Energetski priključak – izgradnja trafostanice i priključak na mrežu (1MW+) | E27: - | F27: kom | G27: 1 | H27: 65000 | I27: =G27*H27 | J27: =I27*'ASSUMPTIONS MASTER INPUT'!$H$3 | K27: =I27+J27 | L27: 2026 | M27: 30 | N27: Debt | O27: 50–80k €; može biti više za 1MW+; CEDIS projekti pokazuju velika ulaganja
A28: 1.7 | B28: 1. Land & Site | C28: Infrastruktura | D28: Hidrotehnička instalacija (priključak na vodovod + separatori ulja/masti) | E28: - | F28: kom | G28: 1 | H28: 27500 | I28: =G28*H28 | J28: =I28*'ASSUMPTIONS MASTER INPUT'!$H$3 | K28: =I28+J28 | L28: 2026 | M28: 30 | N28: Debt | O28: 20–35k €; obavezno za fabriku (ulja od transformatora)
A29: 1.8 | B29: 1. Land & Site | C29: Sigurnost | D29: Ograda i obezbeđenje (industrijska ograda, kapije za šlepere, video nadzor) | E29: - | F29: m | G29: 800 | H29: 50 | I29: =G29*H29 | J29: =I29*'ASSUMPTIONS MASTER INPUT'!$H$3 | K29: =I29+J29 | L29: 2026 | M29: 20 | N29: Equity | O29: 30–50k €; dužina ograde ~800m za parcelu 22.5k m²
A30: 1.9 | B30: 1. Land & Site | C30: Logistika | D30: Pristupne saobraćajnice (asfalt za teški teretni saobraćaj) | E30: - | F30: m² | G30: 2000 | H30: 30 | I30: =G30*H30 | J30: =I30*'ASSUMPTIONS MASTER INPUT'!$H$3 | K30: =I30+J30 | L30: 2026 | M30: 15 | N30: Equity | O30: 40–70k €; širina 6–8m, debljina za šlepere
A31: 2.1 | B31: 2. Civil Works | C31: Noseća konstrukcija | D31: Čelična primarna konstrukcija (stubovi, grede, veze) | E31: - | F31: m² | G31: 10000 | H31: 200 | I31: =G31*H31 | J31: =I31*'ASSUMPTIONS MASTER INPUT'!$H$3 | K31: =I31+J31 | L31: 2026 | M31: 25 | N31: Debt | O31: 180–260 €/m²; za kraneve može više
A32: 2.2 | B32: 2. Civil Works | C32: Krov i fasada | D32: Sendvič paneli PIR (80–100 mm izolacija) | E32: - | F32: m² | G32: 12000 | H32: 50 | I32: =G32*H32 | J32: =I32*'ASSUMPTIONS MASTER INPUT'!$H$3 | K32: =I32+J32 | L32: 2026 | M32: 20 | N32: Debt | O32: PIR za bolji ESG i grant
A33: 2.3 | B33: 2. Civil Works | C33: Heavy Duty podovi | D33: Pojačani beton + armatura + zaptivke za ulja (nosivost za kraneve/tankove) | E33: - | F33: m² | G33: 10000 | H33: 120 | I33: =G33*H33 | J33: =I33*'ASSUMPTIONS MASTER INPUT'!$H$3 | K33: =I33+J33 | L33: 2026 | M33: 30 | N33: Debt | O33: Ne štedjeti – ključno za dinamičko opterećenje
A34: 2.4 | B34: 2. Civil Works | C34: Administrativni dio | D34: Kancelarije + svlačionice + kantina (viši standard) | E34: - | F34: m² | G34: 1000 | H34: 380 | I34: =G34*H34 | J34: =I34*'ASSUMPTIONS MASTER INPUT'!$H$3 | K34: =I34+J34 | L34: 2026 | M34: 25 | N34: Equity | O34: Energy Class A/B preporučeno za EU grantove
A35: 2.5 | B35: 2. Civil Works | C35: Vrata i prozori | D35: Industrijska sekcijska vrata + prozori | E35: - | F35: set | G35: 1 | H35: 90000 | I35: =G35*H35 | J35: =I35*'ASSUMPTIONS MASTER INPUT'!$H$3 | K35: =I35+J35 | L35: 2026 | M35: 15 | N35: Debt | O35: Door Height 8–10 m za visoke hale
... A41: 2.11 | B41: 2. Civil Works | C41: HVAC / Ventilacija | D41: Industrijska ventilacija (za zavarivanje + emisije) | E41: - | F41: lot | G41: 1 | H41: 140000 | I41: =G41*H41 | J41: =I41*'ASSUMPTIONS MASTER INPUT'!$H$3 | K41: =I41+J41 | L41: 2026 | M41: 15 | N41: Debt | O41: 80–200k €; specijalno za fabriku
A42: 2.12 | B42: 2. Civil Works | C42: Projektovanje i nadzor | D42: Inženjering, dozvole, stručni nadzor (soft costs) | E42: - | F42: % | G42: 0.06 | I42: =G42*H42 | J42: =I42*'ASSUMPTIONS MASTER INPUT'!$H$3 | K42: 2026 | L42: 5 | M42: Debt | N42: 5–8% od Civil Works; obavezno za EU
A43: 3.1 | B43: 3. Machinery (ARS linija) | C43: Cutting | D43: Fiber Laser (visoka snaga 6–12kW, large format) | E43: Turska/Kina | F43: kom | G43: 1 | H43: 300000 | I43: =G43*H43 | J43: =I43*'ASSUMPTIONS MASTER INPUT'!$H$3 | K43: =I43+J43 | L43: 2026 | M43: 7 | N43: Debt | O43: 250k–450k €; precizno sečenje limova
A44: 3.2 | B44: 3. Machinery | C44: Cutting | D44: CNC Plasma (large format za deblje ploče) | E44: - | F44: kom | G44: 1 | H44: 100000 | I44: =G44*H44 | J44: =I44*'ASSUMPTIONS MASTER INPUT'!$H$3 | K44: =I44+J44 | L44: 2026 | M44: 7 | N44: Debt | O44: 80k–130k €; grublja obrada
A45: 3.3 | B45: 3. Machinery | C45: Bending | D45: Press Brake (400t+ tonaža, CNC) | E45: - | F45: kom | G45: 1 | H45: 180000 | I45: =G45*H45 | J45: =I45*'ASSUMPTIONS MASTER INPUT'!$H$3 | K45: =I45+J45 | L45: 2026 | M45: 7 | N45: Debt | O45: 150k–220k €; savijanje stranica/ojacanja
A46: 3.4 | B46: 3. Machinery | C46: Forming | D46: Corrugated Wall Line (specijalizovana za rebraste zidove) | E46: Turska | F46: linija | G46: 1 | H46: 450000 | I46: =G46*H46 | J46: =I46*'ASSUMPTIONS MASTER INPUT'!$H$3 | K46: =I46+J46 | L46: 2026 | M46: 10 | N46: Debt | O46: 350k–550k €; srce ARS proizvodnje
A47: 3.5 | B47: 3. Machinery | C47: Welding | D47: Welding Robots (ćelija sa pozicionerom, multi-robot) | E47: EU/Turska | F47: ćelija | G47: 1 | H47: 280000 | I47: =G47*H47 | J47: =I47*'ASSUMPTIONS MASTER INPUT'!$H$3 | K47: =I47+J47 | L47: 2026 | M47: 7 | N47: Debt | O47: 200k–350k €; za uljno-nepropusnost
...

Sheet Machine Park Detail
A1: ARS Metal Industries DOO Version 1.0 Date: 25.02.2026
A3: Red. br. | B3: Proizvođač / Model | C3: Opis / Specifikacija | D3: Količina | E3: Jed. | F3: Cijena po jed. (€) | G3: Ukupno (€) | H3: Poreska grupa | I3: Stopa (%) | J3: Rač. vijek (god.) | K3: Napomena
A4: 1 | B4: UNI-MAK | C4: 1600mm DALGADUVAR ÜRETİM HATTI (kompletna linija) | D4: 1 | E4: kom | F4: 900000 | G4: =D4*F4 | H4: II | I4: 10 | J4: 10 | K4: Glavna linija
A5: 2 | B5: SLS MECANO | C5: ROBOT KAYNAK | D5: 1 | E5: kom | F5: 80000 | G5: =D5*F5 | H5: III | I5: 15 | J5: 7 | K5: Specijalna
A6: 3 | B6: - | C6: ABKANT BÜKÜM MAKİNASI | D6: 1 | E6: kom | F6: 85000 | G6: =D6*F6 | H6: II | I6: 10 | J6: 10 | K6: -
A7: 4 | B7: - | C7: PUNTA MAKİNASI | D7: 1 | E7: kom | F7: 96000 | G7: =D7*F7 | H7: II | I7: 10 | J7: 10 | K7: -
A8: 5 | B8: SAYMAK | C8: GİYOTİN MAKAS | D8: 1 | E8: kom | F8: 10740 | G8: =D8*F8 | H8: II | I8: 10 | J8: 10 | K8: -
A9: 6 | B9: MVD | C9: ABKANT PRES | D9: 1 | E9: kom | F9: 150750 | G9: =D9*F9 | H9: II | I9: 10 | J9: 10 | K9: -
A10: 7 | B10: NKN | C10: 8 kW LAZER KESİM | D10: 1 | E10: kom | F10: 290000 | G10: =D10*F10 | H10: III | I10: 15 | J10: 7 | K10: Specijalna
A11: 8 | B11: NKN | C11: 15 kW LAZER KESİM | D11: 1 | E11: kom | F11: 340000 | G11: =D11*F11 | H11: III | I11: 15 | J11: 7 | K11: Specijalna
A12: 9 | B12: NKN | C12: 4 kW BORU LAZER KESİM | D12: 1 | E12: kom | F12: 335000 | G12: =D12*F12 | H12: III | I12: 15 | J12: 7 | K12: Specijalna
A13: 10 | B13: ÖZFATİHLER VİNÇ | C13: 10 ton čift kiriş tavan vinç | D13: 10 | E13: adet | G13: 350000 | H13: IV | I13: 20 | J13: 10 | K13: Teška oprema
A14: 11 | B14: TORO VİNÇ | C14: 40 ton čift kiriş tavan vinç | D14: 3 | E14: adet | G14: 225000 | H14: IV | I14: 20 | J14: 10 | K14: Teška oprema
A15: 12 | B15: TORO VİNÇ | C15: 5 ton pergol vinç | D15: 15 | E15: adet | G15: 210000 | H15: IV | I15: 20 | J15: 10 | K15: Teška oprema
A16: 13 | B16: GENPOWER | C16: 1000 kW kabinski dizel generator | D16: 1 | E16: kom | F16: 72085 | G16: =D16*F16 | H16: IV | I16: 20 | J16: 10 | K16: Backup
A17: 14 | B17: ASTOR | C17: 1600 kW köşk pano | D17: 1 | E17: kom | F17: 53862 | G17: =D17*F17 | H17: II | I17: 10 | J17: 10 | K17: Elektro
A18: 15 | B18: BİNMAK | C18: Boru bükme makinesi | D18: 1 | E18: kom | F18: 14600 | G18: =D18*F18 | H18: II | I18: 10 | J18: 10 | K18: -
A19: 16 | B19: ADS | C19: Kazan basınç hava test ünitesi | D19: 1 | E19: kom | F19: 40000 | G19: =D19*F19 | H19: II | I19: 10 | J19: 10 | K19: Test
A20: 17 | B20: YILDIZ KARDEŞLER | C20: Otomatik kumlama hattı | D20: 1 | E20: kom | F20: 75000 | G20: =D20*F20 | H20: III | I20: 15 | J20: 8 | K20: Priprema
A21: 18 | B21: ENDÜSTRİYEL | C21: Taylor saplama kaynak makinesi | D21: 1 | E21: kom | F21: 6700 | G21: =D21*F21 | H21: II | I21: 10 | J21: 10 | K21: Zavarivanje
A22: 19 | B22: HİLALSAN | C22: Hidrolik kombine makas | D22: 1 | E22: kom | F22: 49500 | G22: =D22*F22 | H22: II | I22: 10 | J22: 10 | K22: -
A23: 20 | B23: LINDE | C23: Akülü forklift 8 ton | D23: 2 | E23: adet | G23: 304000 | H23: IV | I23: 20 | J23: 5 | K23: Logistika
A24: 21 | B24: LINDE | C24: Akülü forklift 2 ton | D24: 4 | E24: adet | G24: 120000 | H24: IV | I24: 20 | J24: 5 | K24: Logistika
A25: 22 | B25: İESMAK | C25: Yaş boya tesisi + kapak i konveyör hattı | D25: 1 | E25: kom | F25: 120000 | G25: =D25*F25 | H25: II | I25: 10 | J25: 10 | K25: Bojenje
A26: 23 | B26: TAMSAN | C26: Vidali hava kompresör (tank + kurutucu) | D26: 1 | E26: kom | F26: 17550 | G26: =D26*F26 | H26: II | I26: 10 | J26: 10 | K26: Pneumatika
A28: UKUPNO MAKINA PARKI | G28: =SUM(G4:G26)
A31: Grupa | B31: Iznos (€)
A32: II | B32: =SUMIF(H4:H26,"II",G4:G26)
A33: III | B33: =SUMIF(H4:H26,"III",G4:G26)
A34: IV | B34: =SUMIF(H4:H26,"IV",G4:G26)
A35: UKUPNO | B35: =SUM(B32:B34)

Sheet Timeline & Sensitivity
A1: ARS METAL INDUSTRIES DOO – CAPEX MASTER
A3: VREMENSKI PLAN PROJEKTA – TIMELINE & GANTT
A4: Ukupno trajanje: 30–36 mjeseci (od Q2 2026 do Q3/Q4 2028)
A6: Faza / Aktivnost | B6: 2026 Q2 | C6: 2026 Q3 | D6: 2026 Q4 | E6: 2027 Q1 | F6: 2027 Q2 | G6: 2027 Q3 | H6: 2027 Q4 | I6: 2028 Q1 | J6: 2028 Q2 | K6: 2028 Q3 | L6: 2028 Q4 | M6: % CAPEX | N6: Iznos (€) | O6: Komentar / Rizik
A7: Kupovina zemljišta & dozvole | B7: ████ | C7: ████ | M7: 0.05 | N7: 625000 | O7: Rizik kašnjenja dozvola
A8: Projektovanje & studije | B8: ████ | C8: ████ | D8: ████ | M8: 0.03 | N8: 375000 | O8: EIA Feb 2026
A9: Građevinski radovi | D9: ████ | E9: ████ | F9: ████ | G9: ████ | H9: ████ | I9: ████ | M9: 0.35 | N9: 4375000 | O9: Seizmički uplift
A10: Nabavka & isporuka mašina | D10: ████ | E10: ████ | F10: ████ | G10: ████ | H10: ████ | I10: ████ | M10: 0.3 | N10: 3750000 | O10: TRY rizik
A11: MEP instalacije | F11: ████ | G11: ████ | H11: ████ | I11: ████ | J11: ████ | M11: 0.12 | N11: 1500000 | O11: Kritična faza
A12: Soft costs | D12: ████ | E12: ████ | F12: ████ | G12: ████ | H12: ████ | I12: ████ | M12: 0.1 | N12: 1250000 | O12: ERP + sertifikati
A13: Commissioning | H13: ████ | I13: ████ | J13: ████ | M13: 0.05 | N13: 625000 | O13: Start Q3/Q4 2028
A17: SENZITIVNOST / SCENARIJI (Sensitivity Analysis)
A18: Scenarij | B18: Promjena | C18: Utjecaj na CAPEX (€) | D18: Utjecaj na WC (€) | E18: Ukupni potrebni iznos (€) | F18: Rizik / Mitigacija
A19: Base Case | B19: — | C19: 12500000 | D19: 2200000 | E19: 14700000 | F19: —
A20: TRY deprecijacija +20% | B20: FX_STRESS_20 | C20: 789157 | D20: 0 | E20: 789157 | F20: 80% hedžovano
A21: Građevinski troškovi +15% | B21: +15% civil | C21: 975000 | D21: 0 | E21: 975000 | F21: Contingency 15%
A22: Kašnjenje 6 mjeseci | B22: +6 mjeseci | C22: 450000 | D22: 400000 | E22: 850000 | F22: Plate + eskalacija
A23: WC potreban +20% | B23: +20% WC | C23: 0 | D23: 440000 | E23: 440000 | F23: Revolving linija
A24: Worst Case | B24: Kombinovano | C24: 2214157 | D24: 840000 | E24: 3054157 | F24: Equity buffer
A27: Svi scenariji su konzervativni. Worst Case pokriven equity-jem i contingency-jem od 9.5%.

Sheet WC Cash Flow
A1: ARS METAL INDUSTRIES DOO – CAPEX MASTER
A2: Version 2.0 | Datum: 26.02.2026 | CFO: Onur
A3: WORKING CAPITAL CASH FLOW – PRVA GODINA
A4: Početni WC: 2.200.000 € | Početak proizvodnje: septembar 2028
A5: Mjesečni pregled (u €)
A7: Stavka | B7: M1 (Sep 28) | C7: M2 (Okt) | D7: M3 (Nov) | E7: M4 (Dec) | F7: M5 (Jan 29) | G7: M6 (Feb) | H7: M7 (Mar) | I7: M8 (Apr) | J7: M9 (Maj) | K7: M10 (Jun) | L7: M11 (Jul) | M7: M12 (Avg) | N7: Ukupno 12 m
A8: Početni WC saldo | B8: 2200000 | C8: =N8 | D8: =N9 | E8: =N10 | F8: =N11 | G8: =N12 | H8: =N13 | I8: =N14 | J8: =N15 | K8: =N16 | L8: =N17 | M8: =N18
A10: Plate (55 ljudi) | B10: 58000 | C10: 70000 | D10: 90000 | E10: 110000 | F10: 130000 | G10: 130000 | H10: 130000 | I10: 130000 | J10: 130000 | K10: 130000 | L10: 130000 | M10: 130000 | N10: =SUM(B10:M10)
A11: Sirovina & materijal | B11: 120000 | C11: 200000 | D11: 350000 | E11: 500000 | F11: 650000 | G11: 700000 | H11: 700000 | I11: 700000 | J11: 700000 | K11: 700000 | L11: 700000 | M11: 700000 | N11: =SUM(B11:M11)
A12: Rezervni dijelovi & održavanje | B12: 20000 | C12: 25000 | D12: 30000 | E12: 35000 | F12: 40000 | G12: 40000 | H12: 40000 | I12: 40000 | J12: 40000 | K12: 40000 | L12: 40000 | M12: 40000 | N12: =SUM(B12:M12)
A13: Energija | B13: 40000 | C13: 55000 | D13: 70000 | E13: 85000 | F13: 100000 | G13: 100000 | H13: 100000 | I13: 100000 | J13: 100000 | K13: 100000 | L13: 100000 | M13: 100000 | N13: =SUM(B13:M13)
A14: Ostali operativni troškovi | B14: 30000 | C14: 40000 | D14: 50000 | E14: 60000 | F14: 70000 | G14: 70000 | H14: 70000 | I14: 70000 | J14: 70000 | K14: 70000 | L14: 70000 | M14: 70000 | N14: =SUM(B14:M14)
A15: Ukupni mjesečni odlivi | B15: =SUM(B10:B14) | C15: =SUM(C10:C14) | D15: =SUM(D10:D14) | E15: =SUM(E10:E14) | F15: =SUM(F10:F14) | G15: =SUM(G10:G14) | H15: =SUM(H10:H14) | I15: =SUM(I10:I14) | ... N15: =SUM(N10:N14)
A17: Prihodi od prodaje | B17: 0 | C17: 0 | D17: 0 | E17: 0 | F17: 200000 | G17: 500000 | H17: 800000 | I17: 1000000 | J17: 1200000 | K17: 1400000 | L17: 1600000 | M17: 1800000 | N17: =SUM(B17:M17)
A18: Naplata potraživanja (DSO 60 dana) | B18: 0 | C18: 0 | D18: 0 | E18: 0 | F18: 0 | G18: 0 | H18: 100000 | I18: 300000 | J18: 600000 | K18: 1000000 | L18: 1400000 | M18: 0 | N18: =SUM(B18:M18)
A19: Ukupni mjesečni prilivi | B19: =SUM(B17:B18) | C19: =SUM(C17:C18) | D19: =SUM(D17:D18) | E19: =SUM(E17:E18) | F19: =SUM(F17:F18) | G19: =SUM(G17:G18) | H19: =SUM(H17:H18) | I19: =SUM(I17:I18) | ... N19: =SUM(N17:N18)
A21: Neto cash flow mjesec | B21: =B19-B15 | C21: =C19-C15 | D21: =D19-D15 | E21: =E19-E15 | F21: =F19-F15 | G21: =G19-G15 | H21: =H19-H15 | I21: =I19-I15 | ... M21: =M19-M15 | N21: =SUM(B21:M21)
A23: Kumulativni WC saldo | B23: =B8+B21 | C23: =B23+C21 | D23: =C23+D21 | E23: =D23+E21 | F23: =E23+F21 | G23: =F23+G21 | H23: =G23+H21 | I23: =H23+I21 | J23: =I23+J21 | ... M23: =L23+M21 | N23: =M23
A37: Napomene:
A38: Početni WC saldo pokriva ~5.5 mjeseci operacija bez prihoda
A39: Prvi značajniji priliv očekuje se u 5. mjesecu
A40: Najveći odliv: sirovine + plate
A41: Ako DSO >60 dana → potreban dodatni WC 300–500k €
A42: Mitigacija: factoring + duži DPO

Sheet REVENUE_COGS
A1: ARS METAL INDUSTRIES – REVENUE & COGS PROJEKCIJA (v2.5)
A2: Datum: 26.02.2026
A4: Ključni inputi (veži na Assumptions)
A5: Parametar | B5: Vrijednost
A6: MAX_CAPACITY_TPY | B6: =XLOOKUP("BASE_PROD_CAPACITY",'ASSUMPTIONS MASTER INPUT'!$B:$B,'ASSUMPTIONS MASTER INPUT'!$D:$D)
A7: RAMP_UP_Y1 | B7: =XLOOKUP("RAMP_UP_Y1",'ASSUMPTIONS MASTER INPUT'!$B:$B,'ASSUMPTIONS MASTER INPUT'!$D:$D)
A8: RAMP_UP_Y2 | B8: =XLOOKUP("RAMP_UP_Y2",'ASSUMPTIONS MASTER INPUT'!$B:$B,'ASSUMPTIONS MASTER INPUT'!$D:$D)
A9: RAMP_UP_Y3 | B9: =XLOOKUP("RAMP_UP_Y3",'ASSUMPTIONS MASTER INPUT'!$B:$B,'ASSUMPTIONS MASTER INPUT'!$D:$D)
A10: BASE_SALES_PRICE_EUR_PER_T | B10: =XLOOKUP("BASE_SALES_PRICE",'ASSUMPTIONS MASTER INPUT'!$B:$B,'ASSUMPTIONS MASTER INPUT'!$D:$D)*1000
A11: SALES_PRICE_INFL | B11: =XLOOKUP("INF_REVENUE",'ASSUMPTIONS MASTER INPUT'!$B:$B,'ASSUMPTIONS MASTER INPUT'!$D:$D)
A12: TARGET_GROSS_MARGIN | B12: =XLOOKUP("TARGET_GROSS_MARGIN",'ASSUMPTIONS MASTER INPUT'!$B:$B,'ASSUMPTIONS MASTER INPUT'!$D:$D)
A13: COGS_INFL | B13: =XLOOKUP("STEEL_PRICE_ESC",'ASSUMPTIONS MASTER INPUT'!$B:$B,'ASSUMPTIONS MASTER INPUT'!$D:$D)
A16: Godina | B16: Prodaja (t) | C16: Cijena €/t | D16: Prihod (€) | E16: COGS €/t | F16: COGS (€) | G16: Bruto marža (€) | H16: Bruto marža %
A17: 2029 | B17: =$B$6*IF(2029=2029,$B$6,IF(2029=2030,$B$7,$B$8)) | C17: =$B$9*(1+$B$10)^0 | D17: =B17*C17 | E17: =C17*(1-$B$11)*(1+$B$12)^0 | F17: =B17*E17 | G17: =D17-F17 | H17: =IF(D17=0,0,G17/D17)
A18: 2030 | B18: =$B$6*IF(2030=2029,$B$6,IF(2030=2030,$B$7,$B$8)) | C18: =$B$9*(1+$B$10)^1 | D18: =B18*C18 | E18: =C18*(1-$B$11)*(1+$B$12)^1 | F18: =B18*E18 | G18: =D18-F18 | H18: =IF(D18=0,0,G18/D18)
A19: 2031 | B19: =$B$6*IF(2031=2029,$B$6,IF(2031=2030,$B$7,$B$8)) | C19: =$B$9*(1+$B$10)^2 | D19: =B19*C19 | E19: =C19*(1-$B$11)*(1+$B$12)^2 | F19: =B19*E19 | G19: =D19-F19 | H19: =IF(D19=0,0,G19/D19)
A20: 2032 | B20: =$B$6*IF(2032=2029,$B$6,IF(2032=2030,$B$7,$B$8)) | C20: =$B$9*(1+$B$10)^3 | D20: =B20*C20 | E20: =C20*(1-$B$11)*(1+$B$12)^3 | F20: =B20*E20 | G20: =D20-F20 | H20: =IF(D20=0,0,G20/D20)
A21: 2033 | B21: =$B$6*IF(2033=2029,$B$6,IF(2033=2030,$B$7,$B$8)) | C21: =$B$9*(1+$B$10)^4 | D21: =B21*C21 | E21: =C21*(1-$B$11)*(1+$B$12)^4 | F21: =B21*E21 | G21: =D21-F21 | H21: =IF(D21=0,0,G21/D21)
A22: 2034 | B22: =$B$6*IF(2034=2029,$B$6,IF(2034=2030,$B$7,$B$8)) | C22: =$B$9*(1+$B$10)^5 | D22: =B22*C22 | E22: =C22*(1-$B$11)*(1+$B$12)^5 | F22: =B22*E22 | G22: =D22-F22 | H22: =IF(D22=0,0,G22/D22)
A23: 2035 | B23: =$B$6*IF(2035=2029,$B$6,IF(2035=2030,$B$7,$B$8)) | C23: =$B$9*(1+$B$10)^6 | D23: =B23*C23 | E23: =C23*(1-$B$11)*(1+$B$12)^6 | F23: =B23*E23 | G23: =D23-F23 | H23: =IF(D23=0,0,G23/D23)
A24: 2036 | B24: =$B$6*IF(2036=2029,$B$6,IF(2036=2030,$B$7,$B$8)) | C24: =$B$9*(1+$B$10)^7 | D24: =B24*C24 | E24: =C24*(1-$B$11)*(1+$B$12)^7 | F24: =B24*E24 | G24: =D24-F24 | H24: =IF(D24=0,0,G24/D24)
A25: 2037 | B25: =$B$6*IF(2037=2029,$B$6,IF(2037=2030,$B$7,$B$8)) | C25: =$B$9*(1+$B$10)^8 | D25: =B25*C25 | E25: =C25*(1-$B$11)*(1+$B$12)^8 | F25: =B25*E25 | G25: =D25-F25 | H25: =IF(D25=0,0,G25/D25)
A26: 2038 | B26: =$B$6*IF(2038=2029,$B$6,IF(2038=2030,$B$7,$B$8)) | C26: =$B$9*(1+$B$10)^9 | D26: =B26*C26 | E26: =C26*(1-$B$11)*(1+$B$12)^9 | F26: =B26*E26 | G26: =D26-F26 | H26: =IF(D26=0,0,G26/D26)

Sheet OPEX_DETAIL
A1: ARS METAL INDUSTRIES – OPEX DETAIL (v2.5)
A2: Datum: 26.02.2026
A4: OPEX model: total OPEX = Revenue * FIXED_OPEX_PCT, uz inflaciju.
A6: FIXED_OPEX_PCT | B6: =XLOOKUP("FIXED_OPEX_PCT",'ASSUMPTIONS MASTER INPUT'!$B:$B,'ASSUMPTIONS MASTER INPUT'!$D:$D)
A7: INF_OPEX | B7: =XLOOKUP("INF_OPEX",'ASSUMPTIONS MASTER INPUT'!$B:$B,'ASSUMPTIONS MASTER INPUT'!$D:$D)
A10: Godina | B10: Total OPEX (€) | C10: Admin & HR (30%) | D10: Maintenance (20%) | E10: Utilities (15%) | F10: Insurance (5%) | G10: SG&A (30%)
A11: 2029 | B11: =REVENUE_COGS!D17*$B$6*(1+$B$7)^0 | C11: =B11*0.30 | D11: =B11*0.20 | E11: =B11*0.15 | F11: =B11*0.05 | G11: =B11*0.30
A12: 2030 | B12: =REVENUE_COGS!D18*$B$6*(1+$B$7)^1 | C12: =B12*0.30 | D12: =B12*0.20 | E12: =B12*0.15 | F12: =B12*0.05 | G12: =B12*0.30
A13: 2031 | B13: =REVENUE_COGS!D19*$B$6*(1+$B$7)^2 | C13: =B13*0.30 | D13: =B13*0.20 | E13: =B13*0.15 | F13: =B13*0.05 | G13: =B13*0.30
A14: 2032 | B14: =REVENUE_COGS!D20*$B$6*(1+$B$7)^3 | C14: =B14*0.30 | D14: =B14*0.20 | E14: =B14*0.15 | F14: =B14*0.05 | G14: =B14*0.30
A15: 2033 | B15: =REVENUE_COGS!D21*$B$6*(1+$B$7)^4 | C15: =B15*0.30 | D15: =B15*0.20 | E15: =B15*0.15 | F15: =B15*0.05 | G15: =B15*0.30
A16: 2034 | B16: =REVENUE_COGS!D22*$B$6*(1+$B$7)^5 | C16: =B16*0.30 | D16: =B16*0.20 | E16: =B16*0.15 | F16: =B16*0.05 | G16: =B16*0.30
A17: 2035 | B17: =REVENUE_COGS!D23*$B$6*(1+$B$7)^6 | C17: =B17*0.30 | D17: =B17*0.20 | E17: =B17*0.15 | F17: =B17*0.05 | G17: =B17*0.30
A18: 2036 | B18: =REVENUE_COGS!D24*$B$6*(1+$B$7)^7 | C18: =B18*0.30 | D18: =B18*0.20 | E18: =B18*0.15 | F18: =B18*0.05 | G18: =B18*0.30
A19: 2037 | B19: =REVENUE_COGS!D25*$B$6*(1+$B$7)^8 | C19: =B19*0.30 | D19: =B19*0.20 | E19: =B19*0.15 | F19: =B19*0.05 | G19: =B19*0.30
A20: 2038 | B20: =REVENUE_COGS!D26*$B$6*(1+$B$7)^9 | C20: =B20*0.30 | D20: =B20*0.20 | E20: =B20*0.15 | F20: =B20*0.05 | G20: =B20*0.30

Sheet CAPEX_CASHFLOW
A1: ARS METAL INDUSTRIES – CAPEX CASH FLOW (godišnji) (v2.5)
A2: Izvor: CAPEX_MASTER (2)
A4: Godina | B4: Land & Site | C4: Civil Works | D4: Machinery | E4: Installation | F4: Engineering | G4: Contingency | H4: Total CAPEX (bez WC) | I4: Cumulative
A5: 2026 | B5: =SUMIFS('CAPEX_MASTER (2)'!$I$22:$I$1000,'CAPEX_MASTER (2)'!$L$22:$L$1000,$A5,'CAPEX_MASTER (2)'!$B$22:$B$1000,"1. Land & Site") | C5: =SUMIFS('CAPEX_MASTER (2)'!$I$22:$I$1000,'CAPEX_MASTER (2)'!$L$22:$L$1000,$A5,'CAPEX_MASTER (2)'!$B$22:$B$1000,"2. Civil Works") | D5: =SUMIFS('CAPEX_MASTER (2)'!$I$22:$I$1000,'CAPEX_MASTER (2)'!$L$22:$L$1000,$A5,'CAPEX_MASTER (2)'!$B$22:$B$1000,"3. Machinery (ARS linija)") | E5: =SUMIFS('CAPEX_MASTER (2)'!$I$22:$I$1000,'CAPEX_MASTER (2)'!$L$22:$L$1000,$A5,'CAPEX_MASTER (2)'!$B$22:$B$1000,"4. Installation & Commissioning") | F5: =SUMIFS('CAPEX_MASTER (2)'!$I$22:$I$1000,'CAPEX_MASTER (2)'!$L$22:$L$1000,$A5,'CAPEX_MASTER (2)'!$B$22:$B$1000,"5. Engineering & Permits") | G5: =SUM(B5:F5)*0.085 | H5: =SUM(B5:G5) | I5: =H5+IF($A5=2026,0,I4)
A6: 2027 | B6: =SUMIFS('CAPEX_MASTER (2)'!$I$22:$I$1000,'CAPEX_MASTER (2)'!$L$22:$L$1000,$A6,'CAPEX_MASTER (2)'!$B$22:$B$1000,"1. Land & Site") | C6: =SUMIFS('CAPEX_MASTER (2)'!$I$22:$I$1000,'CAPEX_MASTER (2)'!$L$22:$L$1000,$A6,'CAPEX_MASTER (2)'!$B$22:$B$1000,"2. Civil Works") | D6: =SUMIFS('CAPEX_MASTER (2)'!$I$22:$I$1000,'CAPEX_MASTER (2)'!$L$22:$L$1000,$A6,'CAPEX_MASTER (2)'!$B$22:$B$1000,"3. Machinery (ARS linija)") | E6: =SUMIFS('CAPEX_MASTER (2)'!$I$22:$I$1000,'CAPEX_MASTER (2)'!$L$22:$L$1000,$A6,'CAPEX_MASTER (2)'!$B$22:$B$1000,"4. Installation & Commissioning") | F6: =SUMIFS('CAPEX_MASTER (2)'!$I$22:$I$1000,'CAPEX_MASTER (2)'!$L$22:$L$1000,$A6,'CAPEX_MASTER (2)'!$B$22:$B$1000,"5. Engineering & Permits") | G6: =SUM(B6:F6)*0.085 | H6: =SUM(B6:G6) | I6: =H6+IF($A6=2026,0,I5)
A7: 2028 | B7: =SUMIFS('CAPEX_MASTER (2)'!$I$22:$I$1000,'CAPEX_MASTER (2)'!$L$22:$L$1000,$A7,'CAPEX_MASTER (2)'!$B$22:$B$1000,"1. Land & Site") | C7: =SUMIFS('CAPEX_MASTER (2)'!$I$22:$I$1000,'CAPEX_MASTER (2)'!$L$22:$L$1000,$A7,'CAPEX_MASTER (2)'!$B$22:$B$1000,"2. Civil Works") | D7: =SUMIFS('CAPEX_MASTER (2)'!$I$22:$I$1000,'CAPEX_MASTER (2)'!$L$22:$L$1000,$A7,'CAPEX_MASTER (2)'!$B$22:$B$1000,"3. Machinery (ARS linija)") | E7: =SUMIFS('CAPEX_MASTER (2)'!$I$22:$I$1000,'CAPEX_MASTER (2)'!$L$22:$L$1000,$A7,'CAPEX_MASTER (2)'!$B$22:$B$1000,"4. Installation & Commissioning") | F7: =SUMIFS('CAPEX_MASTER (2)'!$I$22:$I$1000,'CAPEX_MASTER (2)'!$L$22:$L$1000,$A7,'CAPEX_MASTER (2)'!$B$22:$B$1000,"5. Engineering & Permits") | G7: =SUM(B7:F7)*0.085 | H7: =SUM(B7:G7) | I7: =H7+IF($A7=2026,0,I6)

Sheet DEBT_SCHEDULE
A1: ARS METAL INDUSTRIES – DEBT SCHEDULE & DSCR (v2.5)
A2: Datum: 26.02.2026
A4: Ukupan debt | B4: =CAPEX_MASTER (2)!C17
A5: Kamatna stopa | B5: ='ASSUMPTIONS MASTER INPUT'!$J$2
A6: Grace period (mjeseci) | B6: ='ASSUMPTIONS MASTER INPUT'!$J$4
A7: Tenor (mjeseci) | B7: ='ASSUMPTIONS MASTER INPUT'!$J$3
A8: Mjesečni anuitet (posle grace) | B8: =PMT($B$5/12,$B$7,-$B$4)
A11: Godina | B11: Početni saldo | C11: Drawdown | D11: Kamata | E11: Principal | F11: Otplata ukupno | G11: Krajnji saldo | H11: DSCR
A12: 2026 | B12: 0 | C12: =IF(A12<=2028, CAPEX_CASHFLOW!H5*0.55, 0) | D12: =(B12+B12+C12)/2*$B$5 | E12: =MAX(0,F12-D12) | F12: =IF(A12>=2029, -$B$8*12, 0) | G12: =B12+C12-E12 | H12: =IF(F12=0,0, INTEGRATED_P&L_BS_CF!F6/F12)
A13: 2027 | B13: =G12 | C13: =IF(A13<=2028, CAPEX_CASHFLOW!H6*0.55, 0) | D13: =(B13+B13+C13)/2*$B$5 | E13: =MAX(0,F13-D13) | F13: =IF(A13>=2029, -$B$8*12, 0) | G13: =B13+C13-E13 | H13: =IF(F13=0,0, INTEGRATED_P&L_BS_CF!F7/F13)
A14: 2028 | B14: =G13 | C14: =IF(A14<=2028, CAPEX_CASHFLOW!H7*0.55, 0) | D14: =(B14+B14+C14)/2*$B$5 | E14: =MAX(0,F14-D14) | F14: =IF(A14>=2029, -$B$8*12, 0) | G14: =B14+C14-E14 | H14: =IF(F14=0,0, INTEGRATED_P&L_BS_CF!F8/F14)
A15: 2029 | B15: =G14 | C15: =IF(A15<=2028, CAPEX_CASHFLOW!H8*0.55, 0) | D15: =(B15+B15+C15)/2*$B$5 | E15: =MAX(0,F15-D15) | F15: =IF(A15>=2029, -$B$8*12, 0) | G15: =B15+C15-E15 | H15: =IF(F15=0,0, INTEGRATED_P&L_BS_CF!F9/F15)
A16: 2030 | B16: =G15 | C16: =IF(A16<=2028, CAPEX_CASHFLOW!H9*0.55, 0) | D16: =(B16+B16+C16)/2*$B$5 | E16: =MAX(0,F16-D16) | F16: =IF(A16>=2029, -$B$8*12, 0) | G16: =B16+C16-E16 | H16: =IF(F16=0,0, INTEGRATED_P&L_BS_CF!F10/F16)
A17: 2031 | B17: =G16 | C17: =IF(A17<=2028, CAPEX_CASHFLOW!H10*0.55, 0) | D17: =(B17+B17+C17)/2*$B$5 | E17: =MAX(0,F17-D17) | F17: =IF(A17>=2029, -$B$8*12, 0) | G17: =B17+C17-E17 | H17: =IF(F17=0,0, INTEGRATED_P&L_BS_CF!F11/F17)
A18: 2032 | B18: =G17 | C18: =IF(A18<=2028, CAPEX_CASHFLOW!H11*0.55, 0) | D18: =(B18+B18+C18)/2*$B$5 | E18: =MAX(0,F18-D18) | F18: =IF(A18>=2029, -$B$8*12, 0) | G18: =B18+C18-E18 | H18: =IF(F18=0,0, INTEGRATED_P&L_BS_CF!F12/F18)
A19: 2033 | B19: =G18 | C19: =IF(A19<=2028, CAPEX_CASHFLOW!H12*0.55, 0) | D19: =(B19+B19+C19)/2*$B$5 | E19: =MAX(0,F19-D19) | F19: =IF(A19>=2029, -$B$8*12, 0) | G19: =B19+C19-E19 | H19: =IF(F19=0,0, INTEGRATED_P&L_BS_CF!F13/F19)
A20: 2034 | B20: =G19 | C20: =IF(A20<=2028, CAPEX_CASHFLOW!H13*0.55, 0) | D20: =(B20+B20+C20)/2*$B$5 | E20: =MAX(0,F20-D20) | F20: =IF(A20>=2029, -$B$8*12, 0) | G20: =B20+C20-E20 | H20: =IF(F20=0,0, INTEGRATED_P&L_BS_CF!F14/F20)
A21: 2035 | B21: =G20 | C21: =IF(A21<=2028, CAPEX_CASHFLOW!H14*0.55, 0) | D21: =(B21+B21+C21)/2*$B$5 | E21: =MAX(0,F21-D21) | F21: =IF(A21>=2029, -$B$8*12, 0) | G21: =B21+C21-E21 | H21: =IF(F21=0,0, INTEGRATED_P&L_BS_CF!F15/F21)
A22: 2036 | B22: =G21 | C22: =IF(A22<=2028, CAPEX_CASHFLOW!H15*0.55, 0) | D22: =(B22+B22+C22)/2*$B$5 | E22: =MAX(0,F22-D22) | F22: =IF(A22>=2029, -$B$8*12, 0) | G22: =B22+C22-E22 | H22: =IF(F22=0,0, INTEGRATED_P&L_BS_CF!F16/F22)
A23: 2037 | B23: =G22 | C23: =IF(A23<=2028, CAPEX_CASHFLOW!H16*0.55, 0) | D23: =(B23+B23+C23)/2*$B$5 | E23: =MAX(0,F23-D23) | F23: =IF(A23>=2029, -$B$8*12, 0) | G23: =B23+C23-E23 | H23: =IF(F23=0,0, INTEGRATED_P&L_BS_CF!F17/F23)
A24: 2038 | B24: =G23 | C24: =IF(A24<=2028, CAPEX_CASHFLOW!H17*0.55, 0) | D24: =(B24+B24+C24)/2*$B$5 | E24: =MAX(0,F24-D24) | F24: =IF(A24>=2029, -$B$8*12, 0) | G24: =B24+C24-E24 | H24: =IF(F24=0,0, INTEGRATED_P&L_BS_CF!F18/F24)

Sheet INTEGRATED_P&L_BS_CF
A1: ARS METAL INDUSTRIES – INTEGRATED P&L + BS + CF (v2.5)
A2: Datum: 26.02.2026
A4: Svi ključni inputi vuku iz Assumptions + CAPEX_MASTER. Provjeri CHECKS_&_CONTROLS za greške.
A5: Godina | B5: 2026 | C5: 2027 | D5: 2028 | E5: 2029 | F5: 2030 | G5: 2031 | H5: 2032 | I5: 2033 | J5: 2034 | K5: 2035 | L5: 2036 | M5: 2037 | N5: 2038
A6: Revenue | B6: =IF(B$5<2029,0,REVENUE_COGS!D14) | C6: =IF(C$5<2029,0,REVENUE_COGS!D15) | D6: =IF(D$5<2029,0,REVENUE_COGS!D16) | E6: =IF(E$5<2029,0,REVENUE_COGS!D17) | F6: =IF(F$5<2029,0,REVENUE_COGS!D18) | G6: =IF(G$5<2029,0,REVENUE_COGS!D19) | H6: =IF(H$5<2029,0,REVENUE_COGS!D20) | I6: =IF(I$5<2029,0,REVENUE_COGS!D21) | J6: =IF(J$5<2029,0,REVENUE_COGS!D22) | K6: =IF(K$5<2029,0,REVENUE_COGS!D23) | L6: =IF(L$5<2029,0,REVENUE_COGS!D24) | M6: =IF(M$5<2029,0,REVENUE_COGS!D25) | N6: =IF(N$5<2029,0,REVENUE_COGS!D26)
A7: COGS | B7: =IF(B$5<2029,0,REVENUE_COGS!F14) | C7: =IF(C$5<2029,0,REVENUE_COGS!F15) | D7: =IF(D$5<2029,0,REVENUE_COGS!F16) | E7: =IF(E$5<2029,0,REVENUE_COGS!F17) | F7: =IF(F$5<2029,0,REVENUE_COGS!F18) | G7: =IF(G$5<2029,0,REVENUE_COGS!F19) | H7: =IF(H$5<2029,0,REVENUE_COGS!F20) | I7: =IF(I$5<2029,0,REVENUE_COGS!F21) | J7: =IF(J$5<2029,0,REVENUE_COGS!F22) | K7: =IF(K$5<2029,0,REVENUE_COGS!F23) | L7: =IF(L$5<2029,0,REVENUE_COGS!F24) | M7: =IF(M$5<2029,0,REVENUE_COGS!F25) | N7: =IF(N$5<2029,0,REVENUE_COGS!F26)
A8: Gross Profit | B8: =B6-B7 | C8: =C6-C7 | D8: =D6-D7 | E8: =E6-E7 | F8: =F6-F7 | G8: =G6-G7 | H8: =H6-H7 | I8: =I6-I7 | ... N8: =N6-N7
A9: OPEX | B9: =IF(B$5<2029,0,OPEX_DETAIL!B8) | C9: =IF(C$5<2029,0,OPEX_DETAIL!B9) | D9: =IF(D$5<2029,0,OPEX_DETAIL!B10) | E9: =IF(E$5<2029,0,OPEX_DETAIL!B11) | F9: =IF(F$5<2029,0,OPEX_DETAIL!B12) | G9: =IF(G$5<2029,0,OPEX_DETAIL!B13) | H9: =IF(H$5<2029,0,OPEX_DETAIL!B14) | I9: =IF(I$5<2029,0,OPEX_DETAIL!B15) | J9: =IF(J$5<2029,0,OPEX_DETAIL!B16) | K9: =IF(K$5<2029,0,OPEX_DETAIL!B17) | L9: =IF(L$5<2029,0,OPEX_DETAIL!B18) | M9: =IF(M$5<2029,0,OPEX_DETAIL!B19) | N9: =IF(N$5<2029,0,OPEX_DETAIL!B20)
A10: EBITDA | B10: =B8-B9 | C10: =C8-C9 | D10: =D8-D9 | E10: =E8-E9 | F10: =F8-F9 | G10: =G8-G9 | H10: =H8-H9 | I10: =I8-I9 | ... N10: =N8-N9
A11: Depreciation | B11: =IFERROR(XLOOKUP(B$5,'Depreciation Schedule'!$F$12:$ZZ$12,'Depreciation Schedule'!$F$23:$ZZ$23),0) | C11: =IFERROR(XLOOKUP(C$5,'Depreciation Schedule'!$F$12:$ZZ$12,'Depreciation Schedule'!$F$23:$ZZ$23),0) | D11: =IFERROR(XLOOKUP(D$5,'Depreciation Schedule'!$F$12:$ZZ$12,'Depreciation Schedule'!$F$23:$ZZ$23),0) | E11: =IFERROR(XLOOKUP(E$5,'Depreciation Schedule'!$F$12:$ZZ$12,'Depreciation Schedule'!$F$23:$ZZ$23),0) | F11: =IFERROR(XLOOKUP(F$5,'Depreciation Schedule'!$F$12:$ZZ$12,'Depreciation Schedule'!$F$23:$ZZ$23),0) | G11: =IFERROR(XLOOKUP(G$5,'Depreciation Schedule'!$F$12:$ZZ$12,'Depreciation Schedule'!$F$23:$ZZ$23),0) | H11: =IFERROR(XLOOKUP(H$5,'Depreciation Schedule'!$F$12:$ZZ$12,'Depreciation Schedule'!$F$23:$ZZ$23),0) | I11: =IFERROR(XLOOKUP(I$5,'Depreciation Schedule'!$F$12:$ZZ$12,'Depreciation Schedule'!$F$23:$ZZ$23),0) | ... N11: =IFERROR(XLOOKUP(N$5,'Depreciation Schedule'!$F$12:$ZZ$12,'Depreciation Schedule'!$F$23:$ZZ$23),0)
A12: EBIT | B12: =B10-B11 | C12: =C10-C11 | D12: =D10-D11 | E12: =E10-E11 | F12: =F10-F11 | G12: =G10-G11 | H12: =H10-H11 | I12: =I10-I11 | ... N12: =N10-N11
A13: Interest | B13: =IFERROR(XLOOKUP(B$5,DEBT_SCHEDULE!$A$12:$A$200,DEBT_SCHEDULE!$D$12:$D$200),0) | C13: =IFERROR(XLOOKUP(C$5,DEBT_SCHEDULE!$A$12:$A$200,DEBT_SCHEDULE!$D$12:$D$200),0) | D13: =IFERROR(XLOOKUP(D$5,DEBT_SCHEDULE!$A$12:$A$200,DEBT_SCHEDULE!$D$12:$D$200),0) | E13: =IFERROR(XLOOKUP(E$5,DEBT_SCHEDULE!$A$12:$A$200,DEBT_SCHEDULE!$D$12:$D$200),0) | F13: =IFERROR(XLOOKUP(F$5,DEBT_SCHEDULE!$A$12:$A$200,DEBT_SCHEDULE!$D$12:$D$200),0) | G13: =IFERROR(XLOOKUP(G$5,DEBT_SCHEDULE!$A$12:$A$200,DEBT_SCHEDULE!$D$12:$D$200),0) | H13: =IFERROR(XLOOKUP(H$5,DEBT_SCHEDULE!$A$12:$A$200,DEBT_SCHEDULE!$D$12:$D$200),0) | I13: =IFERROR(XLOOKUP(I$5,DEBT_SCHEDULE!$A$12:$A$200,DEBT_SCHEDULE!$D$12:$D$200),0) | ... N13: =IFERROR(XLOOKUP(N$5,DEBT_SCHEDULE!$A$12:$A$200,DEBT_SCHEDULE!$D$12:$D$200),0)
A14: EBT | B14: =B12-B13 | C14: =C12-C13 | D14: =D12-D13 | E14: =E12-E13 | F14: =F12-F13 | G14: =G12-G13 | H14: =H12-H13 | I14: =I12-I13 | ... N14: =N12-N13
A15: Tax | B15: =MAX(0,B14*XLOOKUP("TAX_RATE",'ASSUMPTIONS MASTER INPUT'!$B:$B,'ASSUMPTIONS MASTER INPUT'!$D:$D)) | C15: =MAX(0,C14*XLOOKUP("TAX_RATE",'ASSUMPTIONS MASTER INPUT'!$B:$B,'ASSUMPTIONS MASTER INPUT'!$D:$D)) | D15: =MAX(0,D14*XLOOKUP("TAX_RATE",'ASSUMPTIONS MASTER INPUT'!$B:$B,'ASSUMPTIONS MASTER INPUT'!$D:$D)) | E15: =MAX(0,E14*XLOOKUP("TAX_RATE",'ASSUMPTIONS MASTER INPUT'!$B:$B,'ASSUMPTIONS MASTER INPUT'!$D:$D)) | F15: =MAX(0,F14*XLOOKUP("TAX_RATE",'ASSUMPTIONS MASTER INPUT'!$B:$B,'ASSUMPTIONS MASTER INPUT'!$D:$D)) | G15: =MAX(0,G14*XLOOKUP("TAX_RATE",'ASSUMPTIONS MASTER INPUT'!$B:$B,'ASSUMPTIONS MASTER INPUT'!$D:$D)) | H15: =MAX(0,H14*XLOOKUP("TAX_RATE",'ASSUMPTIONS MASTER INPUT'!$B:$B,'ASSUMPTIONS MASTER INPUT'!$D:$D)) | I15: =MAX(0,I14*XLOOKUP("TAX_RATE",'ASSUMPTIONS MASTER INPUT'!$B:$B,'ASSUMPTIONS MASTER INPUT'!$D:$D)) | ... N15: =MAX(0,N14*XLOOKUP("TAX_RATE",'ASSUMPTIONS MASTER INPUT'!$B:$B,'ASSUMPTIONS MASTER INPUT'!$D:$D))
A16: Net Profit | B16: =B14-B15 | C16: =C14-C15 | D16: =D14-D15 | E16: =E14-E15 | F16: =F14-F15 | G16: =G14-G15 | H16: =H14-H15 | I16: =I14-I15 | ... N16: =N14-N15
A18: Operating CF | B18: =B10-B15 | C18: =C10-C15 | D18: =D10-D15 | E18: =E10-E15 | F18: =F10-F15 | G18: =G10-G15 | H18: =H10-H15 | I18: =I10-I15 | ... N18: =N10-N15
A19: Investing CF | B19: =IF(B$5<2029,-CAPEX_CASHFLOW!H5,-(B11*0.02)) | C19: =IF(C$5<2029,-CAPEX_CASHFLOW!H6,-(C11*0.02)) | D19: =IF(D$5<2029,-CAPEX_CASHFLOW!H7,-(D11*0.02)) | E19: =IF(E$5<2029,-CAPEX_CASHFLOW!H8,-(E11*0.02)) | F19: =IF(F$5<2029,-CAPEX_CASHFLOW!H9,-(F11*0.02)) | G19: =IF(G$5<2029,-CAPEX_CASHFLOW!H10,-(G11*0.02)) | H19: =IF(H$5<2029,-CAPEX_CASHFLOW!H11,-(H11*0.02)) | I19: =IF(I$5<2029,-CAPEX_CASHFLOW!H12,-(I11*0.02)) | J19: =IF(J$5<2029,-CAPEX_CASHFLOW!H13,-(J11*0.02)) | K19: =IF(K$5<2029,-CAPEX_CASHFLOW!H14,-(K11*0.02)) | L19: =IF(L$5<2029,-CAPEX_CASHFLOW!H15,-(L11*0.02)) | M19: =IF(M$5<2029,-CAPEX_CASHFLOW!H16,-(M11*0.02)) | N19: =IF(N$5<2029,-CAPEX_CASHFLOW!H17,-(N11*0.02))
A20: Financing CF | B20: =IFERROR(XLOOKUP(B$5,DEBT_SCHEDULE!$A$12:$A$200,DEBT_SCHEDULE!$C$12:$C$200),0)-IFERROR(XLOOKUP(B$5,DEBT_SCHEDULE!$A$12:$A$200,DEBT_SCHEDULE!$F$12:$F$200),0) | C20: =IFERROR(XLOOKUP(C$5,DEBT_SCHEDULE!$A$12:$A$200,DEBT_SCHEDULE!$C$12:$C$200),0)-IFERROR(XLOOKUP(C$5,DEBT_SCHEDULE!$A$12:$A$200,DEBT_SCHEDULE!$F$12:$F$200),0) | D20: =IFERROR(XLOOKUP(D$5,DEBT_SCHEDULE!$A$12:$A$200,DEBT_SCHEDULE!$C$12:$C$200),0)-IFERROR(XLOOKUP(D$5,DEBT_SCHEDULE!$A$12:$A$200,DEBT_SCHEDULE!$F$12:$F$200),0) | E20: =IFERROR(XLOOKUP(E$5,DEBT_SCHEDULE!$A$12:$A$200,DEBT_SCHEDULE!$C$12:$C$200),0)-IFERROR(XLOOKUP(E$5,DEBT_SCHEDULE!$A$12:$A$200,DEBT_SCHEDULE!$F$12:$F$200),0) | F20: =IFERROR(XLOOKUP(F$5,DEBT_SCHEDULE!$A$12:$A$200,DEBT_SCHEDULE!$C$12:$C$200),0)-IFERROR(XLOOKUP(F$5,DEBT_SCHEDULE!$A$12:$A$200,DEBT_SCHEDULE!$F$12:$F$200),0) | G20: =IFERROR(XLOOKUP(G$5,DEBT_SCHEDULE!$A$12:$A$200,DEBT_SCHEDULE!$C$12:$C$200),0)-IFERROR(XLOOKUP(G$5,DEBT_SCHEDULE!$A$12:$A$200,DEBT_SCHEDULE!$F$12:$F$200),0) | H20: =IFERROR(XLOOKUP(H$5,DEBT_SCHEDULE!$A$12:$A$200,DEBT_SCHEDULE!$C$12:$C$200),0)-IFERROR(XLOOKUP(H$5,DEBT_SCHEDULE!$A$12:$A$200,DEBT_SCHEDULE!$F$12:$F$200),0) | I20: =IFERROR(XLOOKUP(I$5,DEBT_SCHEDULE!$A$12:$A$200,DEBT_SCHEDULE!$C$12:$C$200),0)-IFERROR(XLOOKUP(I$5,DEBT_SCHEDULE!$A$12:$A$200,DEBT_SCHEDULE!$F$12:$F$200),0) | ... N20: =IFERROR(XLOOKUP(N$5,DEBT_SCHEDULE!$A$12:$A$200,DEBT_SCHEDULE!$C$12:$C$200),0)-IFERROR(XLOOKUP(N$5,DEBT_SCHEDULE!$A$12:$A$200,DEBT_SCHEDULE!$F$12:$F$200),0)
A21: Net Cash Flow | B21: =SUM(B18:B20) | C21: =SUM(C18:C20) | D21: =SUM(D18:D20) | E21: =SUM(E18:E20) | F21: =SUM(F18:F20) | G21: =SUM(G18:G20) | H21: =SUM(H18:H20) | I21: =SUM(I18:I20) | ... N21: =SUM(N18:N20)
A22: Ending Cash | B22: =B21 | C22: =B22+C21 | D22: =C22+D21 | E22: =D22+E21 | F22: =E22+F21 | G22: =F22+G21 | H22: =G22+H21 | I22: =H22+I21 | J22: =I22+J21 | ... N22: =M22+N21

Sheet DASHBOARD
A1: ARS METAL INDUSTRIES – CFO DASHBOARD (Bank-Ready) (v2.5)
A2: Automatski KPI + grafici (iz INTEGRATED / CAPEX / DEBT).
A4: TOTAL CAPEX (bez PDV) | B4: ='CAPEX_MASTER (2)'!C11
A5: GRAND TOTAL INVESTICIJA (sa WC, bez PDV) | B5: ='CAPEX_MASTER (2)'!C13
A6: Equity (EUR) | B6: ='CAPEX_MASTER (2)'!C16
A7: Debt (EUR) | B7: ='CAPEX_MASTER (2)'!C17
A8: Grant (EUR) | B8: ='CAPEX_MASTER (2)'!C18
A9: Min DSCR | B9: =MIN(DEBT_SCHEDULE!H12:H200)
A10: Revenue @2031 | B10: =INTEGRATED_P&L_BS_CF!G6
A11: EBITDA Margin @2031 | B11: =IF(INTEGRATED_P&L_BS_CF!G6=0,0,INTEGRATED_P&L_BS_CF!G10/INTEGRATED_P&L_BS_CF!G6)

Sheet CHECKS_&_CONTROLS
A1: CHECKS & CONTROLS – Model QA (v2.5)
A2: Crveno = kritično (banke će odbiti). Žuto = upozorenje.
A4: Kontrola | B4: Formula | C4: Status
A5: VAT rate defined | B5: ='ASSUMPTIONS MASTER INPUT'!$H$3 | C5: =IF(B5>0, "OK","FAIL")
A6: Sources = Uses (Debt+Equity+Grant vs Grand Total) | B6: =SUM('CAPEX_MASTER (2)'!C16:C18)-'CAPEX_MASTER (2)'!C13 | C6: =IF(ABS(B6)<1, "OK","FAIL")
A7: CAPEX subtotal sum | B7: ='CAPEX_MASTER (2)'!C11-SUM('CAPEX_MASTER (2)'!C5:C10) | C7: =IF(ABS(B7)<1, "OK","FAIL")
A8: Min DSCR >= 1.30 | B8: =MIN(DEBT_SCHEDULE!H12:H200) | C8: =IF(B8>=1.3,"OK","FAIL")
A9: Count of '#NAME?' strings | B9: 1 | C9: =IF(B9=0,"OK","FAIL")
