Workbook

Sheet Master_Lista
A1: Employee_ID | B1: Ime Radnika
A2: EMP001 | B2: Branko Vasic
A3: EMP002 | B3: Filip Antic
A4: EMP003 | B4: Luka Filipovic
A5: EMP004 | B5: Tomas Obradovic
A6: EMP005 | B6: Jelena Nikolic
A7: EMP006 | B7: Goran Zivkovic
A8: EMP007 | B8: Filip Kostic
A9: EMP008 | B9: Lidija Tomic
A10: EMP009 | B10: Petar Lazic
A11: EMP010 | B11: Branko Babic
A12: EMP011 | B12: Uros Djordjevic
... A151: EMP150 | B151: Filip Lazic

Sheet Pozicije
A1: Pozicija | B1: Satnica (€ / h)
A2: Elektromonter | B2: 8.5
A3: Vodeći monter | B3: 11
A4: Inženjer na gradilištu | B4: 18
A5: Projekt menadžer | B5: 28
A6: Bravar | B6: 9
A7: Zavarivač | B7: 10
A8: CNC operater | B8: 12
A9: Kontrola kvaliteta | B9: 14
A10: Mašinski inženjer | B10: 20
A11: Elektro inženjer | B11: 22
A12: Operater prese | B12: 9.5
A13: Slikar | B13: 8
... A19: Finansijski analitičar | B19: 16

Sheet Sheet11_Zarade
A1: Employee_ID | B1: Ime Radnika | C1: Pozicija | D1: Satnica (€ / h) | E1: Bruto Plata (€ / mj.) | F1: Napomena | G1: Employee Contrib | H1: Taxable | I1: PIT | J1: Surtax | K1: Neto Plata | L1: Employer Contrib | M1: Total Cost
A2: EMP001 | B2: =INDEX(Master_Lista!$B$2:$B$151,MATCH(A2,Master_Lista!$A$2:$A$151,0)) -> Branko Vasic | C2: Elektromonter | D2: =IFERROR(INDEX(Pozicije!$B$2:$B$19,MATCH(C2,Pozicije!$A$2:$A$19,0)),0) -> 8.5 | E2: =ROUND(D2*176*0.98,2) -> 1466.08 | G2: =E2*10.5% -> 153.9384 | H2: =E2-G2 -> 1312.1416 | I2: =IF(H2<=700,0,IF(H2<=1000,9%*(H2-700),9%*300+15%*(H2-1000))) -> 73.82124 | J2: =I2*15% -> 11.073186 | K2: =H2-I2-J2 -> 1227.2472 | L2: =E2*0.5% -> 7.3304 | M2: =E2+L2 -> 1473.4104
A3: EMP002 | B3: =INDEX(Master_Lista!$B$2:$B$151,MATCH(A3,Master_Lista!$A$2:$A$151,0)) -> Filip Antic | C3: Vodeći monter | D3: =IFERROR(INDEX(Pozicije!$B$2:$B$19,MATCH(C3,Pozicije!$A$2:$A$19,0)),0) -> 11 | E3: =ROUND(D3*176*1,2) -> 1936 | G3: =E3*10.5% -> 203.28 | H3: =E3-G3 -> 1732.72 | I3: =IF(H3<=700,0,IF(H3<=1000,9%*(H3-700),9%*300+15%*(H3-1000))) -> 136.908 | J3: =I3*15% -> 20.5362 | K3: =H3-I3-J3 -> 1575.2758 | L3: =E3*0.5% -> 9.68 | M3: =E3+L3 -> 1945.68
A4: EMP003 | B4: =INDEX(Master_Lista!$B$2:$B$151,MATCH(A4,Master_Lista!$A$2:$A$151,0)) -> Luka Filipovic | C4: Inženjer na gradilištu | D4: =IFERROR(INDEX(Pozicije!$B$2:$B$19,MATCH(C4,Pozicije!$A$2:$A$19,0)),0) -> 18 | E4: =ROUND(D4*176*1.02,2) -> 3231.36 | G4: =E4*10.5% -> 339.2928 | H4: =E4-G4 -> 2892.0672 | I4: =IF(H4<=700,0,IF(H4<=1000,9%*(H4-700),9%*300+15%*(H4-1000))) -> 310.81008 | J4: =I4*15% -> 46.621512 | K4: =H4-I4-J4 -> 2534.6356 | L4: =E4*0.5% -> 16.1568 | M4: =E4+L4 -> 3247.5168
A5: EMP004 | B5: =INDEX(Master_Lista!$B$2:$B$151,MATCH(A5,Master_Lista!$A$2:$A$151,0)) -> Tomas Obradovic | C5: Projekt menadžer | D5: =IFERROR(INDEX(Pozicije!$B$2:$B$19,MATCH(C5,Pozicije!$A$2:$A$19,0)),0) -> 28 | E5: =ROUND(D5*176*1.04,2) -> 5125.12 | G5: =E5*10.5% -> 538.1376 | H5: =E5-G5 -> 4586.9824 | I5: =IF(H5<=700,0,IF(H5<=1000,9%*(H5-700),9%*300+15%*(H5-1000))) -> 565.04736 | J5: =I5*15% -> 84.757104 | K5: =H5-I5-J5 -> 3937.1779 | L5: =E5*0.5% -> 25.6256 | M5: =E5+L5 -> 5150.7456
A6: EMP005 | B6: =INDEX(Master_Lista!$B$2:$B$151,MATCH(A6,Master_Lista!$A$2:$A$151,0)) -> Jelena Nikolic | C6: Bravar | D6: =IFERROR(INDEX(Pozicije!$B$2:$B$19,MATCH(C6,Pozicije!$A$2:$A$19,0)),0) -> 9 | E6: =ROUND(D6*176*1.06,2) -> 1679.04 | G6: =E6*10.5% -> 176.2992 | H6: =E6-G6 -> 1502.7408 | I6: =IF(H6<=700,0,IF(H6<=1000,9%*(H6-700),9%*300+15%*(H6-1000))) -> 102.41112 | J6: =I6*15% -> 15.361668 | K6: =H6-I6-J6 -> 1384.968 | L6: =E6*0.5% -> 8.3952 | M6: =E6+L6 -> 1687.4352
A7: EMP006 | B7: =INDEX(Master_Lista!$B$2:$B$151,MATCH(A7,Master_Lista!$A$2:$A$151,0)) -> Goran Zivkovic | C7: Zavarivač | D7: =IFERROR(INDEX(Pozicije!$B$2:$B$19,MATCH(C7,Pozicije!$A$2:$A$19,0)),0) -> 10 | E7: =ROUND(D7*176*0.98,2) -> 1724.8 | G7: =E7*10.5% -> 181.104 | H7: =E7-G7 -> 1543.696 | I7: =IF(H7<=700,0,IF(H7<=1000,9%*(H7-700),9%*300+15%*(H7-1000))) -> 108.5544 | J7: =I7*15% -> 16.28316 | K7: =H7-I7-J7 -> 1418.8584 | L7: =E7*0.5% -> 8.624 | M7: =E7+L7 -> 1733.424
A8: EMP007 | B8: =INDEX(Master_Lista!$B$2:$B$151,MATCH(A8,Master_Lista!$A$2:$A$151,0)) -> Filip Kostic | C8: CNC operater | D8: =IFERROR(INDEX(Pozicije!$B$2:$B$19,MATCH(C8,Pozicije!$A$2:$A$19,0)),0) -> 12 | E8: =ROUND(D8*176*1,2) -> 2112 | G8: =E8*10.5% -> 221.76 | H8: =E8-G8 -> 1890.24 | I8: =IF(H8<=700,0,IF(H8<=1000,9%*(H8-700),9%*300+15%*(H8-1000))) -> 160.536 | J8: =I8*15% -> 24.0804 | K8: =H8-I8-J8 -> 1705.6236 | L8: =E8*0.5% -> 10.56 | M8: =E8+L8 -> 2122.56
A9: EMP008 | B9: =INDEX(Master_Lista!$B$2:$B$151,MATCH(A9,Master_Lista!$A$2:$A$151,0)) -> Lidija Tomic | C9: Kontrola kvaliteta | D9: =IFERROR(INDEX(Pozicije!$B$2:$B$19,MATCH(C9,Pozicije!$A$2:$A$19,0)),0) -> 14 | E9: =ROUND(D9*176*1.02,2) -> 2513.28 | G9: =E9*10.5% -> 263.8944 | H9: =E9-G9 -> 2249.3856 | I9: =IF(H9<=700,0,IF(H9<=1000,9%*(H9-700),9%*300+15%*(H9-1000))) -> 214.40784 | J9: =I9*15% -> 32.161176 | K9: =H9-I9-J9 -> 2002.8166 | L9: =E9*0.5% -> 12.5664 | M9: =E9+L9 -> 2525.8464
A10: EMP009 | B10: =INDEX(Master_Lista!$B$2:$B$151,MATCH(A10,Master_Lista!$A$2:$A$151,0)) -> Petar Lazic | C10: Mašinski inženjer | D10: =IFERROR(INDEX(Pozicije!$B$2:$B$19,MATCH(C10,Pozicije!$A$2:$A$19,0)),0) -> 20 | E10: =ROUND(D10*176*1.04,2) -> 3660.8 | G10: =E10*10.5% -> 384.384 | H10: =E10-G10 -> 3276.416 | I10: =IF(H10<=700,0,IF(H10<=1000,9%*(H10-700),9%*300+15%*(H10-1000))) -> 368.4624 | J10: =I10*15% -> 55.26936 | K10: =H10-I10-J10 -> 2852.6842 | L10: =E10*0.5% -> 18.304 | M10: =E10+L10 -> 3679.104
A11: EMP010 | B11: =INDEX(Master_Lista!$B$2:$B$151,MATCH(A11,Master_Lista!$A$2:$A$151,0)) -> Branko Babic | C11: Elektro inženjer | D11: =IFERROR(INDEX(Pozicije!$B$2:$B$19,MATCH(C11,Pozicije!$A$2:$A$19,0)),0) -> 22 | E11: =ROUND(D11*176*1.06,2) -> 4104.32 | G11: =E11*10.5% -> 430.9536 | H11: =E11-G11 -> 3673.3664 | I11: =IF(H11<=700,0,IF(H11<=1000,9%*(H11-700),9%*300+15%*(H11-1000))) -> 428.00496 | J11: =I11*15% -> 64.200744 | K11: =H11-I11-J11 -> 3181.1607 | L11: =E11*0.5% -> 20.5216 | M11: =E11+L11 -> 4124.8416
A12: EMP011 | B12: =INDEX(Master_Lista!$B$2:$B$151,MATCH(A12,Master_Lista!$A$2:$A$151,0)) -> Uros Djordjevic | C12: Operater prese | D12: =IFERROR(INDEX(Pozicije!$B$2:$B$19,MATCH(C12,Pozicije!$A$2:$A$19,0)),0) -> 9.5 | E12: =ROUND(D12*176*0.98,2) -> 1638.56 | G12: =E12*10.5% -> 172.0488 | H12: =E12-G12 -> 1466.5112 | I12: =IF(H12<=700,0,IF(H12<=1000,9%*(H12-700),9%*300+15%*(H12-1000))) -> 96.97668 | J12: =I12*15% -> 14.546502 | K12: =H12-I12-J12 -> 1354.988 | L12: =E12*0.5% -> 8.1928 | M12: =E12+L12 -> 1646.7528
A13: EMP012 | B13: =INDEX(Master_Lista!$B$2:$B$151,MATCH(A13,Master_Lista!$A$2:$A$151,0)) -> Branko Babic | C13: Slikar | D13: =IFERROR(INDEX(Pozicije!$B$2:$B$19,MATCH(C13,Pozicije!$A$2:$A$19,0)),0) -> 8 | E13: =ROUND(D13*176*1,2) -> 1408 | G13: =E13*10.5% -> 147.84 | H13: =E13-G13 -> 1260.16 | I13: =IF(H13<=700,0,IF(H13<=1000,9%*(H13-700),9%*300+15%*(H13-1000))) -> 66.024 | J13: =I13*15% -> 9.9036 | K13: =H13-I13-J13 -> 1184.2324 | L13: =E13*0.5% -> 7.04 | M13: =E13+L13 -> 1415.04
A14: EMP013 | B14: =INDEX(Master_Lista!$B$2:$B$151,MATCH(A14,Master_Lista!$A$2:$A$151,0)) -> Cedomir Vasic | C14: Magacioner | D14: =IFERROR(INDEX(Pozicije!$B$2:$B$19,MATCH(C14,Pozicije!$A$2:$A$19,0)),0) -> 7.5 | E14: =ROUND(D14*176*1.02,2) -> 1346.4 | G14: =E14*10.5% -> 141.372 | H14: =E14-G14 -> 1205.028 | I14: =IF(H14<=700,0,IF(H14<=1000,9%*(H14-700),9%*300+15%*(H14-1000))) -> 57.7542 | J14: =I14*15% -> 8.66313 | K14: =H14-I14-J14 -> 1138.6107 | L14: =E14*0.5% -> 6.732 | M14: =E14+L14 -> 1353.132
A15: EMP014 | B15: =INDEX(Master_Lista!$B$2:$B$151,MATCH(A15,Master_Lista!$A$2:$A$151,0)) -> Nikola Jankovic | C15: Tehničar održavanja | D15: =IFERROR(INDEX(Pozicije!$B$2:$B$19,MATCH(C15,Pozicije!$A$2:$A$19,0)),0) -> 10.5 | E15: =ROUND(D15*176*1.04,2) -> 1921.92 | G15: =E15*10.5% -> 201.8016 | H15: =E15-G15 -> 1720.1184 | I15: =IF(H15<=700,0,IF(H15<=1000,9%*(H15-700),9%*300+15%*(H15-1000))) -> 135.01776 | J15: =I15*15% -> 20.252664 | K15: =H15-I15-J15 -> 1564.848 | L15: =E15*0.5% -> 9.6096 | M15: =E15+L15 -> 1931.5296
A16: EMP015 | B16: =INDEX(Master_Lista!$B$2:$B$151,MATCH(A16,Master_Lista!$A$2:$A$151,0)) -> Petar Antic | C16: Menadžer kvaliteta | D16: =IFERROR(INDEX(Pozicije!$B$2:$B$19,MATCH(C16,Pozicije!$A$2:$A$19,0)),0) -> 25 | E16: =ROUND(D16*176*1.06,2) -> 4664 | G16: =E16*10.5% -> 489.72 | H16: =E16-G16 -> 4174.28 | I16: =IF(H16<=700,0,IF(H16<=1000,9%*(H16-700),9%*300+15%*(H16-1000))) -> 503.142 | J16: =I16*15% -> 75.4713 | K16: =H16-I16-J16 -> 3595.6667 | L16: =E16*0.5% -> 23.32 | M16: =E16+L16 -> 4687.32
A17: EMP016 | B17: =INDEX(Master_Lista!$B$2:$B$151,MATCH(A17,Master_Lista!$A$2:$A$151,0)) -> Stefan Cvetkovic | C17: Logističar | D17: =IFERROR(INDEX(Pozicije!$B$2:$B$19,MATCH(C17,Pozicije!$A$2:$A$19,0)),0) -> 15 | E17: =ROUND(D17*176*0.98,2) -> 2587.2 | G17: =E17*10.5% -> 271.656 | H17: =E17-G17 -> 2315.544 | I17: =IF(H17<=700,0,IF(H17<=1000,9%*(H17-700),9%*300+15%*(H17-1000))) -> 224.3316 | J17: =I17*15% -> 33.64974 | K17: =H17-I17-J17 -> 2057.5627 | L17: =E17*0.5% -> 12.936 | M17: =E17+L17 -> 2600.136
A18: EMP017 | B18: =INDEX(Master_Lista!$B$2:$B$151,MATCH(A18,Master_Lista!$A$2:$A$151,0)) -> Cedomir Markovic | C18: Administrator | D18: =IFERROR(INDEX(Pozicije!$B$2:$B$19,MATCH(C18,Pozicije!$A$2:$A$19,0)),0) -> 12.5 | E18: =ROUND(D18*176*1,2) -> 2200 | G18: =E18*10.5% -> 231 | H18: =E18-G18 -> 1969 | I18: =IF(H18<=700,0,IF(H18<=1000,9%*(H18-700),9%*300+15%*(H18-1000))) -> 172.35 | J18: =I18*15% -> 25.8525 | K18: =H18-I18-J18 -> 1770.7975 | L18: =E18*0.5% -> 11 | M18: =E18+L18 -> 2211
A19: EMP018 | B19: =INDEX(Master_Lista!$B$2:$B$151,MATCH(A19,Master_Lista!$A$2:$A$151,0)) -> Sanja Grujic | C19: Finansijski analitičar | D19: =IFERROR(INDEX(Pozicije!$B$2:$B$19,MATCH(C19,Pozicije!$A$2:$A$19,0)),0) -> 16 | E19: =ROUND(D19*176*1.02,2) -> 2872.32 | G19: =E19*10.5% -> 301.5936 | H19: =E19-G19 -> 2570.7264 | I19: =IF(H19<=700,0,IF(H19<=1000,9%*(H19-700),9%*300+15%*(H19-1000))) -> 262.60896 | J19: =I19*15% -> 39.391344 | K19: =H19-I19-J19 -> 2268.7261 | L19: =E19*0.5% -> 14.3616 | M19: =E19+L19 -> 2886.6816
A20: EMP019 | B20: =INDEX(Master_Lista!$B$2:$B$151,MATCH(A20,Master_Lista!$A$2:$A$151,0)) -> Jovan Tomic | C20: Elektromonter | D20: =IFERROR(INDEX(Pozicije!$B$2:$B$19,MATCH(C20,Pozicije!$A$2:$A$19,0)),0) -> 8.5 | E20: =ROUND(D20*176*1.04,2) -> 1555.84 | G20: =E20*10.5% -> 163.3632 | H20: =E20-G20 -> 1392.4768 | I20: =IF(H20<=700,0,IF(H20<=1000,9%*(H20-700),9%*300+15%*(H20-1000))) -> 85.87152 | J20: =I20*15% -> 12.880728 | K20: =H20-I20-J20 -> 1293.7246 | L20: =E20*0.5% -> 7.7792 | M20: =E20+L20 -> 1563.6192
A21: EMP020 | B21: =INDEX(Master_Lista!$B$2:$B$151,MATCH(A21,Master_Lista!$A$2:$A$151,0)) -> Luka Kostic | C21: Vodeći monter | D21: =IFERROR(INDEX(Pozicije!$B$2:$B$19,MATCH(C21,Pozicije!$A$2:$A$19,0)),0) -> 11 | E21: =ROUND(D21*176*1.06,2) -> 2052.16 | G21: =E21*10.5% -> 215.4768 | H21: =E21-G21 -> 1836.6832 | I21: =IF(H21<=700,0,IF(H21<=1000,9%*(H21-700),9%*300+15%*(H21-1000))) -> 152.50248 | J21: =I21*15% -> 22.875372 | K21: =H21-I21-J21 -> 1661.3053 | L21: =E21*0.5% -> 10.2608 | M21: =E21+L21 -> 2062.4208
A22: EMP021 | B22: =INDEX(Master_Lista!$B$2:$B$151,MATCH(A22,Master_Lista!$A$2:$A$151,0)) -> Lidija Obradovic | C22: Inženjer na gradilištu | D22: =IFERROR(INDEX(Pozicije!$B$2:$B$19,MATCH(C22,Pozicije!$A$2:$A$19,0)),0) -> 18 | E22: =ROUND(D22*176*0.98,2) -> 3104.64 | G22: =E22*10.5% -> 325.9872 | H22: =E22-G22 -> 2778.6528 | I22: =IF(H22<=700,0,IF(H22<=1000,9%*(H22-700),9%*300+15%*(H22-1000))) -> 293.79792 | J22: =I22*15% -> 44.069688 | K22: =H22-I22-J22 -> 2440.7852 | L22: =E22*0.5% -> 15.5232 | M22: =E22+L22 -> 3120.1632
A23: EMP022 | B23: =INDEX(Master_Lista!$B$2:$B$151,MATCH(A23,Master_Lista!$A$2:$A$151,0)) -> Aleksandar Lazic | C23: Projekt menadžer | D23: =IFERROR(INDEX(Pozicije!$B$2:$B$19,MATCH(C23,Pozicije!$A$2:$A$19,0)),0) -> 28 | E23: =ROUND(D23*176*1,2) -> 4928 | G23: =E23*10.5% -> 517.44 | H23: =E23-G23 -> 4410.56 | I23: =IF(H23<=700,0,IF(H23<=1000,9%*(H23-700),9%*300+15%*(H23-1000))) -> 538.584 | J23: =I23*15% -> 80.7876 | K23: =H23-I23-J23 -> 3791.1884 | L23: =E23*0.5% -> 24.64 | M23: =E23+L23 -> 4952.64
A24: EMP023 | B24: =INDEX(Master_Lista!$B$2:$B$151,MATCH(A24,Master_Lista!$A$2:$A$151,0)) -> Petra Lazic | C24: Bravar | D24: =IFERROR(INDEX(Pozicije!$B$2:$B$19,MATCH(C24,Pozicije!$A$2:$A$19,0)),0) -> 9 | E24: =ROUND(D24*176*1.02,2) -> 1615.68 | G24: =E24*10.5% -> 169.6464 | H24: =E24-G24 -> 1446.0336 | I24: =IF(H24<=700,0,IF(H24<=1000,9%*(H24-700),9%*300+15%*(H24-1000))) -> 93.90504 | J24: =I24*15% -> 14.085756 | K24: =H24-I24-J24 -> 1338.0428 | L24: =E24*0.5% -> 8.0784 | M24: =E24+L24 -> 1623.7584
A25: EMP024 | B25: =INDEX(Master_Lista!$B$2:$B$151,MATCH(A25,Master_Lista!$A$2:$A$151,0)) -> Una Kostic | C25: Zavarivač | D25: =IFERROR(INDEX(Pozicije!$B$2:$B$19,MATCH(C25,Pozicije!$A$2:$A$19,0)),0) -> 10 | E25: =ROUND(D25*176*1.04,2) -> 1830.4 | G25: =E25*10.5% -> 192.192 | H25: =E25-G25 -> 1638.208 | I25: =IF(H25<=700,0,IF(H25<=1000,9%*(H25-700),9%*300+15%*(H25-1000))) -> 122.7312 | J25: =I25*15% -> 18.40968 | K25: =H25-I25-J25 -> 1497.0671 | L25: =E25*0.5% -> 9.152 | M25: =E25+L25 -> 1839.552
A26: EMP025 | B26: =INDEX(Master_Lista!$B$2:$B$151,MATCH(A26,Master_Lista!$A$2:$A$151,0)) -> Radoslav Vasic | C26: CNC operater | D26: =IFERROR(INDEX(Pozicije!$B$2:$B$19,MATCH(C26,Pozicije!$A$2:$A$19,0)),0) -> 12 | E26: =ROUND(D26*176*1.06,2) -> 2238.72 | G26: =E26*10.5% -> 235.0656 | H26: =E26-G26 -> 2003.6544 | I26: =IF(H26<=700,0,IF(H26<=1000,9%*(H26-700),9%*300+15%*(H26-1000))) -> 177.54816 | J26: =I26*15% -> 26.632224 | K26: =H26-I26-J26 -> 1799.474 | L26: =E26*0.5% -> 11.1936 | M26: =E26+L26 -> 2249.9136
A27: EMP026 | B27: =INDEX(Master_Lista!$B$2:$B$151,MATCH(A27,Master_Lista!$A$2:$A$151,0)) -> Ognjen Kostic | C27: Kontrola kvaliteta | D27: =IFERROR(INDEX(Pozicije!$B$2:$B$19,MATCH(C27,Pozicije!$A$2:$A$19,0)),0) -> 14 | E27: =ROUND(D27*176*0.98,2) -> 2414.72 | G27: =E27*10.5% -> 253.5456 | H27: =E27-G27 -> 2161.1744 | I27: =IF(H27<=700,0,IF(H27<=1000,9%*(H27-700),9%*300+15%*(H27-1000))) -> 201.17616 | J27: =I27*15% -> 30.176424 | K27: =H27-I27-J27 -> 1929.8218 | L27: =E27*0.5% -> 12.0736 | M27: =E27+L27 -> 2426.7936
A28: EMP027 | B28: =INDEX(Master_Lista!$B$2:$B$151,MATCH(A28,Master_Lista!$A$2:$A$151,0)) -> Branko Jankovic | C28: Mašinski inženjer | D28: =IFERROR(INDEX(Pozicije!$B$2:$B$19,MATCH(C28,Pozicije!$A$2:$A$19,0)),0) -> 20 | E28: =ROUND(D28*176*1,2) -> 3520 | G28: =E28*10.5% -> 369.6 | H28: =E28-G28 -> 3150.4 | I28: =IF(H28<=700,0,IF(H28<=1000,9%*(H28-700),9%*300+15%*(H28-1000))) -> 349.56 | J28: =I28*15% -> 52.434 | K28: =H28-I28-J28 -> 2748.406 | L28: =E28*0.5% -> 17.6 | M28: =E28+L28 -> 3537.6
A29: EMP028 | B29: =INDEX(Master_Lista!$B$2:$B$151,MATCH(A29,Master_Lista!$A$2:$A$151,0)) -> Aleksandar Cvetkovic | C29: Elektro inženjer | D29: =IFERROR(INDEX(Pozicije!$B$2:$B$19,MATCH(C29,Pozicije!$A$2:$A$19,0)),0) -> 22 | E29: =ROUND(D29*176*1.02,2) -> 3949.44 | G29: =E29*10.5% -> 414.6912 | H29: =E29-G29 -> 3534.7488 | I29: =IF(H29<=700,0,IF(H29<=1000,9%*(H29-700),9%*300+15%*(H29-1000))) -> 407.21232 | J29: =I29*15% -> 61.081848 | K29: =H29-I29-J29 -> 3066.4546 | L29: =E29*0.5% -> 19.7472 | M29: =E29+L29 -> 3969.1872
A30: EMP029 | B30: =INDEX(Master_Lista!$B$2:$B$151,MATCH(A30,Master_Lista!$A$2:$A$151,0)) -> Ognjen Jankovic | C30: Operater prese | D30: =IFERROR(INDEX(Pozicije!$B$2:$B$19,MATCH(C30,Pozicije!$A$2:$A$19,0)),0) -> 9.5 | E30: =ROUND(D30*176*1.04,2) -> 1738.88 | G30: =E30*10.5% -> 182.5824 | H30: =E30-G30 -> 1556.2976 | I30: =IF(H30<=700,0,IF(H30<=1000,9%*(H30-700),9%*300+15%*(H30-1000))) -> 110.44464 | J30: =I30*15% -> 16.566696 | K30: =H30-I30-J30 -> 1429.2863 | L30: =E30*0.5% -> 8.6944 | M30: =E30+L30 -> 1747.5744
A31: EMP030 | B31: =INDEX(Master_Lista!$B$2:$B$151,MATCH(A31,Master_Lista!$A$2:$A$151,0)) -> Uros Pavlovic | C31: Slikar | D31: =IFERROR(INDEX(Pozicije!$B$2:$B$19,MATCH(C31,Pozicije!$A$2:$A$19,0)),0) -> 8 | E31: =ROUND(D31*176*1.06,2) -> 1492.48 | G31: =E31*10.5% -> 156.7104 | H31: =E31-G31 -> 1335.7696 | I31: =IF(H31<=700,0,IF(H31<=1000,9%*(H31-700),9%*300+15%*(H31-1000))) -> 77.36544 | J31: =I31*15% -> 11.604816 | K31: =H31-I31-J31 -> 1246.7993 | L31: =E31*0.5% -> 7.4624 | M31: =E31+L31 -> 1499.9424
A32: EMP031 | B32: =INDEX(Master_Lista!$B$2:$B$151,MATCH(A32,Master_Lista!$A$2:$A$151,0)) -> Stefan Nikolic | C32: Magacioner | D32: =IFERROR(INDEX(Pozicije!$B$2:$B$19,MATCH(C32,Pozicije!$A$2:$A$19,0)),0) -> 7.5 | E32: =ROUND(D32*176*0.98,2) -> 1293.6 | G32: =E32*10.5% -> 135.828 | H32: =E32-G32 -> 1157.772 | I32: =IF(H32<=700,0,IF(H32<=1000,9%*(H32-700),9%*300+15%*(H32-1000))) -> 50.6658 | J32: =I32*15% -> 7.59987 | K32: =H32-I32-J32 -> 1099.5063 | L32: =E32*0.5% -> 6.468 | M32: =E32+L32 -> 1300.068
A33: EMP032 | B33: =INDEX(Master_Lista!$B$2:$B$151,MATCH(A33,Master_Lista!$A$2:$A$151,0)) -> Uros Obradovic | C33: Tehničar održavanja | D33: =IFERROR(INDEX(Pozicije!$B$2:$B$19,MATCH(C33,Pozicije!$A$2:$A$19,0)),0) -> 10.5 | E33: =ROUND(D33*176*1,2) -> 1848 | G33: =E33*10.5% -> 194.04 | H33: =E33-G33 -> 1653.96 | I33: =IF(H33<=700,0,IF(H33<=1000,9%*(H33-700),9%*300+15%*(H33-1000))) -> 125.094 | J33: =I33*15% -> 18.7641 | K33: =H33-I33-J33 -> 1510.1019 | L33: =E33*0.5% -> 9.24 | M33: =E33+L33 -> 1857.24
A34: EMP033 | B34: =INDEX(Master_Lista!$B$2:$B$151,MATCH(A34,Master_Lista!$A$2:$A$151,0)) -> Uros Tomic | C34: Menadžer kvaliteta | D34: =IFERROR(INDEX(Pozicije!$B$2:$B$19,MATCH(C34,Pozicije!$A$2:$A$19,0)),0) -> 25 | E34: =ROUND(D34*176*1.02,2) -> 4488 | G34: =E34*10.5% -> 471.24 | H34: =E34-G34 -> 4016.76 | I34: =IF(H34<=700,0,IF(H34<=1000,9%*(H34-700),9%*300+15%*(H34-1000))) -> 479.514 | J34: =I34*15% -> 71.9271 | K34: =H34-I34-J34 -> 3465.3189 | L34: =E34*0.5% -> 22.44 | M34: =E34+L34 -> 4510.44
A35: EMP034 | B35: =INDEX(Master_Lista!$B$2:$B$151,MATCH(A35,Master_Lista!$A$2:$A$151,0)) -> Stefan Antic | C35: Logističar | D35: =IFERROR(INDEX(Pozicije!$B$2:$B$19,MATCH(C35,Pozicije!$A$2:$A$19,0)),0) -> 15 | E35: =ROUND(D35*176*1.04,2) -> 2745.6 | G35: =E35*10.5% -> 288.288 | H35: =E35-G35 -> 2457.312 | I35: =IF(H35<=700,0,IF(H35<=1000,9%*(H35-700),9%*300+15%*(H35-1000))) -> 245.5968 | J35: =I35*15% -> 36.83952 | K35: =H35-I35-J35 -> 2174.8757 | L35: =E35*0.5% -> 13.728 | M35: =E35+L35 -> 2759.328
A36: EMP035 | B36: =INDEX(Master_Lista!$B$2:$B$151,MATCH(A36,Master_Lista!$A$2:$A$151,0)) -> Olga Markovic | C36: Administrator | D36: =IFERROR(INDEX(Pozicije!$B$2:$B$19,MATCH(C36,Pozicije!$A$2:$A$19,0)),0) -> 12.5 | E36: =ROUND(D36*176*1.06,2) -> 2332 | G36: =E36*10.5% -> 244.86 | H36: =E36-G36 -> 2087.14 | I36: =IF(H36<=700,0,IF(H36<=1000,9%*(H36-700),9%*300+15%*(H36-1000))) -> 190.071 | J36: =I36*15% -> 28.51065 | K36: =H36-I36-J36 -> 1868.5584 | L36: =E36*0.5% -> 11.66 | M36: =E36+L36 -> 2343.66
A37: EMP036 | B37: =INDEX(Master_Lista!$B$2:$B$151,MATCH(A37,Master_Lista!$A$2:$A$151,0)) -> Olga Zivkovic | C37: Finansijski analitičar | D37: =IFERROR(INDEX(Pozicije!$B$2:$B$19,MATCH(C37,Pozicije!$A$2:$A$19,0)),0) -> 16 | E37: =ROUND(D37*176*0.98,2) -> 2759.68 | G37: =E37*10.5% -> 289.7664 | H37: =E37-G37 -> 2469.9136 | I37: =IF(H37<=700,0,IF(H37<=1000,9%*(H37-700),9%*300+15%*(H37-1000))) -> 247.48704 | J37: =I37*15% -> 37.123056 | K37: =H37-I37-J37 -> 2185.3035 | L37: =E37*0.5% -> 13.7984 | M37: =E37+L37 -> 2773.4784
A38: EMP037 | B38: =INDEX(Master_Lista!$B$2:$B$151,MATCH(A38,Master_Lista!$A$2:$A$151,0)) -> Filip Tomic | C38: Elektromonter | D38: =IFERROR(INDEX(Pozicije!$B$2:$B$19,MATCH(C38,Pozicije!$A$2:$A$19,0)),0) -> 8.5 | E38: =ROUND(D38*176*1,2) -> 1496 | G38: =E38*10.5% -> 157.08 | H38: =E38-G38 -> 1338.92 | I38: =IF(H38<=700,0,IF(H38<=1000,9%*(H38-700),9%*300+15%*(H38-1000))) -> 77.838 | J38: =I38*15% -> 11.6757 | K38: =H38-I38-J38 -> 1249.4063 | L38: =E38*0.5% -> 7.48 | M38: =E38+L38 -> 1503.48
A39: EMP038 | B39: =INDEX(Master_Lista!$B$2:$B$151,MATCH(A39,Master_Lista!$A$2:$A$151,0)) -> Cedomir Simic | C39: Vodeći monter | D39: =IFERROR(INDEX(Pozicije!$B$2:$B$19,MATCH(C39,Pozicije!$A$2:$A$19,0)),0) -> 11 | E39: =ROUND(D39*176*1.02,2) -> 1974.72 | G39: =E39*10.5% -> 207.3456 | H39: =E39-G39 -> 1767.3744 | I39: =IF(H39<=700,0,IF(H39<=1000,9%*(H39-700),9%*300+15%*(H39-1000))) -> 142.10616 | J39: =I39*15% -> 21.315924 | K39: =H39-I39-J39 -> 1603.9523 | L39: =E39*0.5% -> 9.8736 | M39: =E39+L39 -> 1984.5936
A40: EMP039 | B40: =INDEX(Master_Lista!$B$2:$B$151,MATCH(A40,Master_Lista!$A$2:$A$151,0)) -> Radoslav Kostic | C40: Inženjer na gradilištu | D40: =IFERROR(INDEX(Pozicije!$B$2:$B$19,MATCH(C40,Pozicije!$A$2:$A$19,0)),0) -> 18 | E40: =ROUND(D40*176*1.04,2) -> 3294.72 | G40: =E40*10.5% -> 345.9456 | H40: =E40-G40 -> 2948.7744 | I40: =IF(H40<=700,0,IF(H40<=1000,9%*(H40-700),9%*300+15%*(H40-1000))) -> 319.31616 | J40: =I40*15% -> 47.897424 | K40: =H40-I40-J40 -> 2581.5608 | L40: =E40*0.5% -> 16.4736 | M40: =E40+L40 -> 3311.1936
...

Sheet Sheet3_Sati
A1: Employee_ID | B1: Ime Radnika | C1: Projekat | D1: Sati | E1: Datum | F1: Pozicija | G1: Satnica (€ / h) | H1: Bruto Teret | I1: Employer Contrib | J1: Finansijski Teret | K1: Status kontrole | L1: Duplikat dnevnog unosa
A2: EMP004 | B2: =IFERROR(INDEX(Master_Lista!$B$2:$B$151,MATCH(A2,Master_Lista!$A$2:$A$151,0)),"") -> Tomas Obradovic | C2: P008 | D2: 7.5 | E2: 46124 | F2: =IFERROR(INDEX(Sheet11_Zarade!$C$2:$C$151,MATCH(A2,Sheet11_Zarade!$A$2:$A$151,0)),"") -> Projekt menadžer | G2: =IFERROR(INDEX(Sheet11_Zarade!$D$2:$D$151,MATCH(A2,Sheet11_Zarade!$A$2:$A$151,0)),0) -> 28 | H2: =IFERROR(D2*G2,0) -> 210 | I2: =H2*0.5% -> 1.05 | J2: =H2+I2 -> 211.05 | K2: =IF(D2="","",IF(D2>12,"FLAG",IF(D2>8,"OVERTIME","OK"))) -> OK | L2: =IF(OR(A2="",E2="",C2=""),"",IF(COUNTIFS($A:$A,A2,$E:$E,E2,$C:$C,C2)>1,"DUPLIKAT","OK")) -> OK
A3: EMP037 | B3: =IFERROR(INDEX(Master_Lista!$B$2:$B$151,MATCH(A3,Master_Lista!$A$2:$A$151,0)),"") -> Filip Tomic | C3: P011 | D3: 6 | E3: 46059 | F3: =IFERROR(INDEX(Sheet11_Zarade!$C$2:$C$151,MATCH(A3,Sheet11_Zarade!$A$2:$A$151,0)),"") -> Elektromonter | G3: =IFERROR(INDEX(Sheet11_Zarade!$D$2:$D$151,MATCH(A3,Sheet11_Zarade!$A$2:$A$151,0)),0) -> 8.5 | H3: =IFERROR(D3*G3,0) -> 51 | I3: =H3*0.5% -> 0.255 | J3: =H3+I3 -> 51.255 | K3: =IF(D3="","",IF(D3>12,"FLAG",IF(D3>8,"OVERTIME","OK"))) -> OK | L3: =IF(OR(A3="",E3="",C3=""),"",IF(COUNTIFS($A:$A,A3,$E:$E,E3,$C:$C,C3)>1,"DUPLIKAT","OK")) -> OK
A4: EMP029 | B4: =IFERROR(INDEX(Master_Lista!$B$2:$B$151,MATCH(A4,Master_Lista!$A$2:$A$151,0)),"") -> Ognjen Jankovic | C4: P009 | D4: 8.5 | E4: 46059 | F4: =IFERROR(INDEX(Sheet11_Zarade!$C$2:$C$151,MATCH(A4,Sheet11_Zarade!$A$2:$A$151,0)),"") -> Operater prese | G4: =IFERROR(INDEX(Sheet11_Zarade!$D$2:$D$151,MATCH(A4,Sheet11_Zarade!$A$2:$A$151,0)),0) -> 9.5 | H4: =IFERROR(D4*G4,0) -> 80.75 | I4: =H4*0.5% -> 0.40375 | J4: =H4+I4 -> 81.15375 | K4: =IF(D4="","",IF(D4>12,"FLAG",IF(D4>8,"OVERTIME","OK"))) -> OVERTIME | L4: =IF(OR(A4="",E4="",C4=""),"",IF(COUNTIFS($A:$A,A4,$E:$E,E4,$C:$C,C4)>1,"DUPLIKAT","OK")) -> OK
A5: EMP038 | B5: =IFERROR(INDEX(Master_Lista!$B$2:$B$151,MATCH(A5,Master_Lista!$A$2:$A$151,0)),"") -> Cedomir Simic | C5: P012 | D5: 6 | E5: 46039 | F5: =IFERROR(INDEX(Sheet11_Zarade!$C$2:$C$151,MATCH(A5,Sheet11_Zarade!$A$2:$A$151,0)),"") -> Vodeći monter | G5: =IFERROR(INDEX(Sheet11_Zarade!$D$2:$D$151,MATCH(A5,Sheet11_Zarade!$A$2:$A$151,0)),0) -> 11 | H5: =IFERROR(D5*G5,0) -> 66 | I5: =H5*0.5% -> 0.33 | J5: =H5+I5 -> 66.33 | K5: =IF(D5="","",IF(D5>12,"FLAG",IF(D5>8,"OVERTIME","OK"))) -> OK | L5: =IF(OR(A5="",E5="",C5=""),"",IF(COUNTIFS($A:$A,A5,$E:$E,E5,$C:$C,C5)>1,"DUPLIKAT","OK")) -> OK
A6: EMP035 | B6: =IFERROR(INDEX(Master_Lista!$B$2:$B$151,MATCH(A6,Master_Lista!$A$2:$A$151,0)),"") -> Olga Markovic | C6: P004 | D6: 12 | E6: 46158 | F6: =IFERROR(INDEX(Sheet11_Zarade!$C$2:$C$151,MATCH(A6,Sheet11_Zarade!$A$2:$A$151,0)),"") -> Administrator | G6: =IFERROR(INDEX(Sheet11_Zarade!$D$2:$D$151,MATCH(A6,Sheet11_Zarade!$A$2:$A$151,0)),0) -> 12.5 | H6: =IFERROR(D6*G6,0) -> 150 | I6: =H6*0.5% -> 0.75 | J6: =H6+I6 -> 150.75 | K6: =IF(D6="","",IF(D6>12,"FLAG",IF(D6>8,"OVERTIME","OK"))) -> OVERTIME | L6: =IF(OR(A6="",E6="",C6=""),"",IF(COUNTIFS($A:$A,A6,$E:$E,E6,$C:$C,C6)>1,"DUPLIKAT","OK")) -> OK
A7: EMP106 | B7: =IFERROR(INDEX(Master_Lista!$B$2:$B$151,MATCH(A7,Master_Lista!$A$2:$A$151,0)),"") -> Ivana Jankovic | C7: P004 | D7: 7.5 | E7: 46054 | F7: =IFERROR(INDEX(Sheet11_Zarade!$C$2:$C$151,MATCH(A7,Sheet11_Zarade!$A$2:$A$151,0)),"") -> Logističar | G7: =IFERROR(INDEX(Sheet11_Zarade!$D$2:$D$151,MATCH(A7,Sheet11_Zarade!$A$2:$A$151,0)),0) -> 15 | H7: =IFERROR(D7*G7,0) -> 112.5 | I7: =H7*0.5% -> 0.5625 | J7: =H7+I7 -> 113.0625 | K7: =IF(D7="","",IF(D7>12,"FLAG",IF(D7>8,"OVERTIME","OK"))) -> OK | L7: =IF(OR(A7="",E7="",C7=""),"",IF(COUNTIFS($A:$A,A7,$E:$E,E7,$C:$C,C7)>1,"DUPLIKAT","OK")) -> OK
A8: EMP006 | B8: =IFERROR(INDEX(Master_Lista!$B$2:$B$151,MATCH(A8,Master_Lista!$A$2:$A$151,0)),"") -> Goran Zivkovic | C8: P013 | D8: 11 | E8: 46111 | F8: =IFERROR(INDEX(Sheet11_Zarade!$C$2:$C$151,MATCH(A8,Sheet11_Zarade!$A$2:$A$151,0)),"") -> Zavarivač | G8: =IFERROR(INDEX(Sheet11_Zarade!$D$2:$D$151,MATCH(A8,Sheet11_Zarade!$A$2:$A$151,0)),0) -> 10 | H8: =IFERROR(D8*G8,0) -> 110 | I8: =H8*0.5% -> 0.55 | J8: =H8+I8 -> 110.55 | K8: =IF(D8="","",IF(D8>12,"FLAG",IF(D8>8,"OVERTIME","OK"))) -> OVERTIME | L8: =IF(OR(A8="",E8="",C8=""),"",IF(COUNTIFS($A:$A,A8,$E:$E,E8,$C:$C,C8)>1,"DUPLIKAT","OK")) -> OK
A9: EMP051 | B9: =IFERROR(INDEX(Master_Lista!$B$2:$B$151,MATCH(A9,Master_Lista!$A$2:$A$151,0)),"") -> Elena Nikolic | C9: P004 | D9: 10 | E9: 46124 | F9: =IFERROR(INDEX(Sheet11_Zarade!$C$2:$C$151,MATCH(A9,Sheet11_Zarade!$A$2:$A$151,0)),"") -> Menadžer kvaliteta | G9: =IFERROR(INDEX(Sheet11_Zarade!$D$2:$D$151,MATCH(A9,Sheet11_Zarade!$A$2:$A$151,0)),0) -> 25 | H9: =IFERROR(D9*G9,0) -> 250 | I9: =H9*0.5% -> 1.25 | J9: =H9+I9 -> 251.25 | K9: =IF(D9="","",IF(D9>12,"FLAG",IF(D9>8,"OVERTIME","OK"))) -> OVERTIME | L9: =IF(OR(A9="",E9="",C9=""),"",IF(COUNTIFS($A:$A,A9,$E:$E,E9,$C:$C,C9)>1,"DUPLIKAT","OK")) -> OK
A10: EMP094 | B10: =IFERROR(INDEX(Master_Lista!$B$2:$B$151,MATCH(A10,Master_Lista!$A$2:$A$151,0)),"") -> Nikola Pavlovic | C10: P010 | D10: 8.5 | E10: 46077 | F10: =IFERROR(INDEX(Sheet11_Zarade!$C$2:$C$151,MATCH(A10,Sheet11_Zarade!$A$2:$A$151,0)),"") -> Projekt menadžer | G10: =IFERROR(INDEX(Sheet11_Zarade!$D$2:$D$151,MATCH(A10,Sheet11_Zarade!$A$2:$A$151,0)),0) -> 28 | H10: =IFERROR(D10*G10,0) -> 238 | I10: =H10*0.5% -> 1.19 | J10: =H10+I10 -> 239.19 | K10: =IF(D10="","",IF(D10>12,"FLAG",IF(D10>8,"OVERTIME","OK"))) -> OVERTIME | L10: =IF(OR(A10="",E10="",C10=""),"",IF(COUNTIFS($A:$A,A10,$E:$E,E10,$C:$C,C10)>1,"DUPLIKAT","OK")) -> OK
A11: EMP056 | B11: =IFERROR(INDEX(Master_Lista!$B$2:$B$151,MATCH(A11,Master_Lista!$A$2:$A$151,0)),"") -> Kosta Urosevic | C11: P007 | D11: 6 | E11: 46037 | F11: =IFERROR(INDEX(Sheet11_Zarade!$C$2:$C$151,MATCH(A11,Sheet11_Zarade!$A$2:$A$151,0)),"") -> Vodeći monter | G11: =IFERROR(INDEX(Sheet11_Zarade!$D$2:$D$151,MATCH(A11,Sheet11_Zarade!$A$2:$A$151,0)),0) -> 11 | H11: =IFERROR(D11*G11,0) -> 66 | I11: =H11*0.5% -> 0.33 | J11: =H11+I11 -> 66.33 | K11: =IF(D11="","",IF(D11>12,"FLAG",IF(D11>8,"OVERTIME","OK"))) -> OK | L11: =IF(OR(A11="",E11="",C11=""),"",IF(COUNTIFS($A:$A,A11,$E:$E,E11,$C:$C,C11)>1,"DUPLIKAT","OK")) -> OK
A12: EMP047 | B12: =IFERROR(INDEX(Master_Lista!$B$2:$B$151,MATCH(A12,Master_Lista!$A$2:$A$151,0)),"") -> Aleksandar Zivkovic | C12: P006 | D12: 8 | E12: 46076 | F12: =IFERROR(INDEX(Sheet11_Zarade!$C$2:$C$151,MATCH(A12,Sheet11_Zarade!$A$2:$A$151,0)),"") -> Operater prese | G12: =IFERROR(INDEX(Sheet11_Zarade!$D$2:$D$151,MATCH(A12,Sheet11_Zarade!$A$2:$A$151,0)),0) -> 9.5 | H12: =IFERROR(D12*G12,0) -> 76 | I12: =H12*0.5% -> 0.38 | J12: =H12+I12 -> 76.38 | K12: =IF(D12="","",IF(D12>12,"FLAG",IF(D12>8,"OVERTIME","OK"))) -> OK | L12: =IF(OR(A12="",E12="",C12=""),"",IF(COUNTIFS($A:$A,A12,$E:$E,E12,$C:$C,C12)>1,"DUPLIKAT","OK")) -> OK
A13: EMP038 | B13: =IFERROR(INDEX(Master_Lista!$B$2:$B$151,MATCH(A13,Master_Lista!$A$2:$A$151,0)),"") -> Cedomir Simic | C13: P014 | D13: 11 | E13: 46031 | F13: =IFERROR(INDEX(Sheet11_Zarade!$C$2:$C$151,MATCH(A13,Sheet11_Zarade!$A$2:$A$151,0)),"") -> Vodeći monter | G13: =IFERROR(INDEX(Sheet11_Zarade!$D$2:$D$151,MATCH(A13,Sheet11_Zarade!$A$2:$A$151,0)),0) -> 11 | H13: =IFERROR(D13*G13,0) -> 121 | I13: =H13*0.5% -> 0.605 | J13: =H13+I13 -> 121.605 | K13: =IF(D13="","",IF(D13>12,"FLAG",IF(D13>8,"OVERTIME","OK"))) -> OVERTIME | L13: =IF(OR(A13="",E13="",C13=""),"",IF(COUNTIFS($A:$A,A13,$E:$E,E13,$C:$C,C13)>1,"DUPLIKAT","OK")) -> OK
... A181: EMP003 | B181: =IFERROR(INDEX(Master_Lista!$B$2:$B$151,MATCH(A181,Master_Lista!$A$2:$A$151,0)),"") -> Luka Filipovic | C181: P011 | D181: 8.5 | E181: 46136 | F181: =IFERROR(INDEX(Sheet11_Zarade!$C$2:$C$151,MATCH(A181,Sheet11_Zarade!$A$2:$A$151,0)),"") -> Inženjer na gradilištu | G181: =IFERROR(INDEX(Sheet11_Zarade!$D$2:$D$151,MATCH(A181,Sheet11_Zarade!$A$2:$A$151,0)),0) -> 18 | H181: =IFERROR(D181*G181,0) -> 153 | I181: =H181*0.5% -> 0.765 | J181: =H181+I181 -> 153.765 | K181: =IF(D181="","",IF(D181>12,"FLAG",IF(D181>8,"OVERTIME","OK"))) -> OVERTIME | L181: =IF(OR(A181="",E181="",C181=""),"",IF(COUNTIFS($A:$A,A181,$E:$E,E181,$C:$C,C181)>1,"DUPLIKAT","OK")) -> OK
B182: =IFERROR(INDEX(Master_Lista!$B$2:$B$151,MATCH(A182,Master_Lista!$A$2:$A$151,0)),"") | F182: =IFERROR(INDEX(Sheet11_Zarade!$C$2:$C$151,MATCH(A182,Sheet11_Zarade!$A$2:$A$151,0)),"") | G182: =IFERROR(INDEX(Sheet11_Zarade!$D$2:$D$151,MATCH(A182,Sheet11_Zarade!$A$2:$A$151,0)),0) -> 0 | H182: =IFERROR(D182*G182,0) -> 0 | I182: =H182*0.5% -> 0 | J182: =H182+I182 -> 0 | K182: =IF(D182="","",IF(D182>12,"FLAG",IF(D182>8,"OVERTIME","OK"))) | L182: =IF(OR(A182="",E182="",C182=""),"",IF(COUNTIFS($A:$A,A182,$E:$E,E182,$C:$C,C182)>1,"DUPLIKAT","OK"))
B183: =IFERROR(INDEX(Master_Lista!$B$2:$B$151,MATCH(A183,Master_Lista!$A$2:$A$151,0)),"") | F183: =IFERROR(INDEX(Sheet11_Zarade!$C$2:$C$151,MATCH(A183,Sheet11_Zarade!$A$2:$A$151,0)),"") | G183: =IFERROR(INDEX(Sheet11_Zarade!$D$2:$D$151,MATCH(A183,Sheet11_Zarade!$A$2:$A$151,0)),0) -> 0 | H183: =IFERROR(D183*G183,0) -> 0 | I183: =H183*0.5% -> 0 | J183: =H183+I183 -> 0 | K183: =IF(D183="","",IF(D183>12,"FLAG",IF(D183>8,"OVERTIME","OK"))) | L183: =IF(OR(A183="",E183="",C183=""),"",IF(COUNTIFS($A:$A,A183,$E:$E,E183,$C:$C,C183)>1,"DUPLIKAT","OK"))
B184: =IFERROR(INDEX(Master_Lista!$B$2:$B$151,MATCH(A184,Master_Lista!$A$2:$A$151,0)),"") | F184: =IFERROR(INDEX(Sheet11_Zarade!$C$2:$C$151,MATCH(A184,Sheet11_Zarade!$A$2:$A$151,0)),"") | G184: =IFERROR(INDEX(Sheet11_Zarade!$D$2:$D$151,MATCH(A184,Sheet11_Zarade!$A$2:$A$151,0)),0) -> 0 | H184: =IFERROR(D184*G184,0) -> 0 | I184: =H184*0.5% -> 0 | J184: =H184+I184 -> 0 | K184: =IF(D184="","",IF(D184>12,"FLAG",IF(D184>8,"OVERTIME","OK"))) | L184: =IF(OR(A184="",E184="",C184=""),"",IF(COUNTIFS($A:$A,A184,$E:$E,E184,$C:$C,C184)>1,"DUPLIKAT","OK"))
B185: =IFERROR(INDEX(Master_Lista!$B$2:$B$151,MATCH(A185,Master_Lista!$A$2:$A$151,0)),"") | F185: =IFERROR(INDEX(Sheet11_Zarade!$C$2:$C$151,MATCH(A185,Sheet11_Zarade!$A$2:$A$151,0)),"") | G185: =IFERROR(INDEX(Sheet11_Zarade!$D$2:$D$151,MATCH(A185,Sheet11_Zarade!$A$2:$A$151,0)),0) -> 0 | H185: =IFERROR(D185*G185,0) -> 0 | I185: =H185*0.5% -> 0 | J185: =H185+I185 -> 0 | K185: =IF(D185="","",IF(D185>12,"FLAG",IF(D185>8,"OVERTIME","OK"))) | L185: =IF(OR(A185="",E185="",C185=""),"",IF(COUNTIFS($A:$A,A185,$E:$E,E185,$C:$C,C185)>1,"DUPLIKAT","OK"))
B186: =IFERROR(INDEX(Master_Lista!$B$2:$B$151,MATCH(A186,Master_Lista!$A$2:$A$151,0)),"") | F186: =IFERROR(INDEX(Sheet11_Zarade!$C$2:$C$151,MATCH(A186,Sheet11_Zarade!$A$2:$A$151,0)),"") | G186: =IFERROR(INDEX(Sheet11_Zarade!$D$2:$D$151,MATCH(A186,Sheet11_Zarade!$A$2:$A$151,0)),0) -> 0 | H186: =IFERROR(D186*G186,0) -> 0 | I186: =H186*0.5% -> 0 | J186: =H186+I186 -> 0 | K186: =IF(D186="","",IF(D186>12,"FLAG",IF(D186>8,"OVERTIME","OK"))) | L186: =IF(OR(A186="",E186="",C186=""),"",IF(COUNTIFS($A:$A,A186,$E:$E,E186,$C:$C,C186)>1,"DUPLIKAT","OK"))
B187: =IFERROR(INDEX(Master_Lista!$B$2:$B$151,MATCH(A187,Master_Lista!$A$2:$A$151,0)),"") | F187: =IFERROR(INDEX(Sheet11_Zarade!$C$2:$C$151,MATCH(A187,Sheet11_Zarade!$A$2:$A$151,0)),"") | G187: =IFERROR(INDEX(Sheet11_Zarade!$D$2:$D$151,MATCH(A187,Sheet11_Zarade!$A$2:$A$151,0)),0) -> 0 | H187: =IFERROR(D187*G187,0) -> 0 | I187: =H187*0.5% -> 0 | J187: =H187+I187 -> 0 | K187: =IF(D187="","",IF(D187>12,"FLAG",IF(D187>8,"OVERTIME","OK"))) | L187: =IF(OR(A187="",E187="",C187=""),"",IF(COUNTIFS($A:$A,A187,$E:$E,E187,$C:$C,C187)>1,"DUPLIKAT","OK"))
B188: =IFERROR(INDEX(Master_Lista!$B$2:$B$151,MATCH(A188,Master_Lista!$A$2:$A$151,0)),"") | F188: =IFERROR(INDEX(Sheet11_Zarade!$C$2:$C$151,MATCH(A188,Sheet11_Zarade!$A$2:$A$151,0)),"") | G188: =IFERROR(INDEX(Sheet11_Zarade!$D$2:$D$151,MATCH(A188,Sheet11_Zarade!$A$2:$A$151,0)),0) -> 0 | H188: =IFERROR(D188*G188,0) -> 0 | I188: =H188*0.5% -> 0 | J188: =H188+I188 -> 0 | K188: =IF(D188="","",IF(D188>12,"FLAG",IF(D188>8,"OVERTIME","OK"))) | L188: =IF(OR(A188="",E188="",C188=""),"",IF(COUNTIFS($A:$A,A188,$E:$E,E188,$C:$C,C188)>1,"DUPLIKAT","OK"))
B189: =IFERROR(INDEX(Master_Lista!$B$2:$B$151,MATCH(A189,Master_Lista!$A$2:$A$151,0)),"") | F189: =IFERROR(INDEX(Sheet11_Zarade!$C$2:$C$151,MATCH(A189,Sheet11_Zarade!$A$2:$A$151,0)),"") | G189: =IFERROR(INDEX(Sheet11_Zarade!$D$2:$D$151,MATCH(A189,Sheet11_Zarade!$A$2:$A$151,0)),0) -> 0 | H189: =IFERROR(D189*G189,0) -> 0 | I189: =H189*0.5% -> 0 | J189: =H189+I189 -> 0 | K189: =IF(D189="","",IF(D189>12,"FLAG",IF(D189>8,"OVERTIME","OK"))) | L189: =IF(OR(A189="",E189="",C189=""),"",IF(COUNTIFS($A:$A,A189,$E:$E,E189,$C:$C,C189)>1,"DUPLIKAT","OK"))
B190: =IFERROR(INDEX(Master_Lista!$B$2:$B$151,MATCH(A190,Master_Lista!$A$2:$A$151,0)),"") | F190: =IFERROR(INDEX(Sheet11_Zarade!$C$2:$C$151,MATCH(A190,Sheet11_Zarade!$A$2:$A$151,0)),"") | G190: =IFERROR(INDEX(Sheet11_Zarade!$D$2:$D$151,MATCH(A190,Sheet11_Zarade!$A$2:$A$151,0)),0) -> 0 | H190: =IFERROR(D190*G190,0) -> 0 | I190: =H190*0.5% -> 0 | J190: =H190+I190 -> 0 | K190: =IF(D190="","",IF(D190>12,"FLAG",IF(D190>8,"OVERTIME","OK"))) | L190: =IF(OR(A190="",E190="",C190=""),"",IF(COUNTIFS($A:$A,A190,$E:$E,E190,$C:$C,C190)>1,"DUPLIKAT","OK"))
B191: =IFERROR(INDEX(Master_Lista!$B$2:$B$151,MATCH(A191,Master_Lista!$A$2:$A$151,0)),"") | F191: =IFERROR(INDEX(Sheet11_Zarade!$C$2:$C$151,MATCH(A191,Sheet11_Zarade!$A$2:$A$151,0)),"") | G191: =IFERROR(INDEX(Sheet11_Zarade!$D$2:$D$151,MATCH(A191,Sheet11_Zarade!$A$2:$A$151,0)),0) -> 0 | H191: =IFERROR(D191*G191,0) -> 0 | I191: =H191*0.5% -> 0 | J191: =H191+I191 -> 0 | K191: =IF(D191="","",IF(D191>12,"FLAG",IF(D191>8,"OVERTIME","OK"))) | L191: =IF(OR(A191="",E191="",C191=""),"",IF(COUNTIFS($A:$A,A191,$E:$E,E191,$C:$C,C191)>1,"DUPLIKAT","OK"))
B192: =IFERROR(INDEX(Master_Lista!$B$2:$B$151,MATCH(A192,Master_Lista!$A$2:$A$151,0)),"") | F192: =IFERROR(INDEX(Sheet11_Zarade!$C$2:$C$151,MATCH(A192,Sheet11_Zarade!$A$2:$A$151,0)),"") | G192: =IFERROR(INDEX(Sheet11_Zarade!$D$2:$D$151,MATCH(A192,Sheet11_Zarade!$A$2:$A$151,0)),0) -> 0 | H192: =IFERROR(D192*G192,0) -> 0 | I192: =H192*0.5% -> 0 | J192: =H192+I192 -> 0 | K192: =IF(D192="","",IF(D192>12,"FLAG",IF(D192>8,"OVERTIME","OK"))) | L192: =IF(OR(A192="",E192="",C192=""),"",IF(COUNTIFS($A:$A,A192,$E:$E,E192,$C:$C,C192)>1,"DUPLIKAT","OK"))
B193: =IFERROR(INDEX(Master_Lista!$B$2:$B$151,MATCH(A193,Master_Lista!$A$2:$A$151,0)),"") | F193: =IFERROR(INDEX(Sheet11_Zarade!$C$2:$C$151,MATCH(A193,Sheet11_Zarade!$A$2:$A$151,0)),"") | G193: =IFERROR(INDEX(Sheet11_Zarade!$D$2:$D$151,MATCH(A193,Sheet11_Zarade!$A$2:$A$151,0)),0) -> 0 | H193: =IFERROR(D193*G193,0) -> 0 | I193: =H193*0.5% -> 0 | J193: =H193+I193 -> 0 | K193: =IF(D193="","",IF(D193>12,"FLAG",IF(D193>8,"OVERTIME","OK"))) | L193: =IF(OR(A193="",E193="",C193=""),"",IF(COUNTIFS($A:$A,A193,$E:$E,E193,$C:$C,C193)>1,"DUPLIKAT","OK"))
... B500: =IFERROR(INDEX(Master_Lista!$B$2:$B$151,MATCH(A500,Master_Lista!$A$2:$A$151,0)),"") | F500: =IFERROR(INDEX(Sheet11_Zarade!$C$2:$C$151,MATCH(A500,Sheet11_Zarade!$A$2:$A$151,0)),"") | G500: =IFERROR(INDEX(Sheet11_Zarade!$D$2:$D$151,MATCH(A500,Sheet11_Zarade!$A$2:$A$151,0)),0) -> 0 | H500: =IFERROR(D500*G500,0) -> 0 | I500: =H500*0.5% -> 0 | J500: =H500+I500 -> 0 | K500: =IF(D500="","",IF(D500>12,"FLAG",IF(D500>8,"OVERTIME","OK"))) | L500: =IF(OR(A500="",E500="",C500=""),"",IF(COUNTIFS($A:$A,A500,$E:$E,E500,$C:$C,C500)>1,"DUPLIKAT","OK"))

Sheet Sheet27_Projekti
A1: Sifra Projekta | B1: Naziv Projekta | C1: Status
A2: P001 | B2: Trafo Tank 110kV | C2: Aktivan
A3: P002 | B3: Trafo Tank 220kV | C3: Aktivan
A4: P003 | B4: Kotlovi Specijalni | C4: Aktivan
A5: P004 | B5: Metalne Konstrukcije | C5: Planirano
A6: P005 | B6: Montaža Postrojenja | C6: Aktivan
A7: P006 | B7: Trafo Tank 500kV | C7: Aktivan
A8: P007 | B8: Održavanje Transformatora | C8: Planirano
A9: P008 | B9: Proizvodnja Rashladnih Sistema | C9: Aktivan
A10: P009 | B10: Testiranje Kvaliteta | C10: Aktivan
A11: P010 | B11: Logistika Isporuka | C11: Planirano
A12: P011 | B12: Razvoj Novih Modela | C12: Aktivan
... A16: P015 | B16: Eko Projekat | C16: Planirano

Sheet Sheet31_Analitika
A1: Employee_ID | B1: Ime Radnika | C1: Ukupni Sati | D1: Ukupan Trošak | E1: Prosječan Trošak / h | F1: Broj Unosa | G1: Efikasnost | H1: Projekat | I1: Ukupni Sati | J1: Ukupan Trošak | K1: Broj Unosa | L1: Prosjek po Unosu
A2: EMP001 | B2: =INDEX(Master_Lista!$B$2:$B$151,MATCH(A2,Master_Lista!$A$2:$A$151,0)) -> Branko Vasic | C2: =SUMIFS(Sheet3_Sati!$D:$D,Sheet3_Sati!$A:$A,A2) -> 11 | D2: =SUMIFS(Sheet3_Sati!$J:$J,Sheet3_Sati!$A:$A,A2) -> 93.9675 | E2: =IFERROR(D2/C2,0) -> 8.5425 | F2: =COUNTIF(Sheet3_Sati!$A:$A,A2) -> 1 | G2: =IF(C2=0,"Nema unosa",IF(C2<160,"Niska iskorištenost",IF(C2<=220,"Optimalno","Preopterećenje"))) -> Niska iskorištenost | H2: P001 | I2: =SUMIFS(Sheet3_Sati!$D:$D,Sheet3_Sati!$C:$C,H2) -> 65.5 | J2: =SUMIFS(Sheet3_Sati!$J:$J,Sheet3_Sati!$C:$C,H2) -> 1124.3438 | K2: =COUNTIF(Sheet3_Sati!$C:$C,H2) -> 7 | L2: =IFERROR(J2/K2,0) -> 160.62054
A3: EMP002 | B3: =INDEX(Master_Lista!$B$2:$B$151,MATCH(A3,Master_Lista!$A$2:$A$151,0)) -> Filip Antic | C3: =SUMIFS(Sheet3_Sati!$D:$D,Sheet3_Sati!$A:$A,A3) -> 0 | D3: =SUMIFS(Sheet3_Sati!$J:$J,Sheet3_Sati!$A:$A,A3) -> 0 | E3: =IFERROR(D3/C3,0) -> 0 | F3: =COUNTIF(Sheet3_Sati!$A:$A,A3) -> 0 | G3: =IF(C3=0,"Nema unosa",IF(C3<160,"Niska iskorištenost",IF(C3<=220,"Optimalno","Preopterećenje"))) -> Nema unosa | H3: P002 | I3: =SUMIFS(Sheet3_Sati!$D:$D,Sheet3_Sati!$C:$C,H3) -> 99.5 | J3: =SUMIFS(Sheet3_Sati!$J:$J,Sheet3_Sati!$C:$C,H3) -> 1089.9225 | K3: =COUNTIF(Sheet3_Sati!$C:$C,H3) -> 11 | L3: =IFERROR(J3/K3,0) -> 99.083864
A4: EMP003 | B4: =INDEX(Master_Lista!$B$2:$B$151,MATCH(A4,Master_Lista!$A$2:$A$151,0)) -> Luka Filipovic | C4: =SUMIFS(Sheet3_Sati!$D:$D,Sheet3_Sati!$A:$A,A4) -> 8.5 | D4: =SUMIFS(Sheet3_Sati!$J:$J,Sheet3_Sati!$A:$A,A4) -> 153.765 | E4: =IFERROR(D4/C4,0) -> 18.09 | F4: =COUNTIF(Sheet3_Sati!$A:$A,A4) -> 1 | G4: =IF(C4=0,"Nema unosa",IF(C4<160,"Niska iskorištenost",IF(C4<=220,"Optimalno","Preopterećenje"))) -> Niska iskorištenost | H4: P003 | I4: =SUMIFS(Sheet3_Sati!$D:$D,Sheet3_Sati!$C:$C,H4) -> 85 | J4: =SUMIFS(Sheet3_Sati!$J:$J,Sheet3_Sati!$C:$C,H4) -> 1069.32 | K4: =COUNTIF(Sheet3_Sati!$C:$C,H4) -> 10 | L4: =IFERROR(J4/K4,0) -> 106.932
A5: EMP004 | B5: =INDEX(Master_Lista!$B$2:$B$151,MATCH(A5,Master_Lista!$A$2:$A$151,0)) -> Tomas Obradovic | C5: =SUMIFS(Sheet3_Sati!$D:$D,Sheet3_Sati!$A:$A,A5) -> 7.5 | D5: =SUMIFS(Sheet3_Sati!$J:$J,Sheet3_Sati!$A:$A,A5) -> 211.05 | E5: =IFERROR(D5/C5,0) -> 28.14 | F5: =COUNTIF(Sheet3_Sati!$A:$A,A5) -> 1 | G5: =IF(C5=0,"Nema unosa",IF(C5<160,"Niska iskorištenost",IF(C5<=220,"Optimalno","Preopterećenje"))) -> Niska iskorištenost | H5: P004 | I5: =SUMIFS(Sheet3_Sati!$D:$D,Sheet3_Sati!$C:$C,H5) -> 175.5 | J5: =SUMIFS(Sheet3_Sati!$J:$J,Sheet3_Sati!$C:$C,H5) -> 3170.5237 | K5: =COUNTIF(Sheet3_Sati!$C:$C,H5) -> 18 | L5: =IFERROR(J5/K5,0) -> 176.14021
A6: EMP005 | B6: =INDEX(Master_Lista!$B$2:$B$151,MATCH(A6,Master_Lista!$A$2:$A$151,0)) -> Jelena Nikolic | C6: =SUMIFS(Sheet3_Sati!$D:$D,Sheet3_Sati!$A:$A,A6) -> 7.5 | D6: =SUMIFS(Sheet3_Sati!$J:$J,Sheet3_Sati!$A:$A,A6) -> 67.8375 | E6: =IFERROR(D6/C6,0) -> 9.045 | F6: =COUNTIF(Sheet3_Sati!$A:$A,A6) -> 1 | G6: =IF(C6=0,"Nema unosa",IF(C6<160,"Niska iskorištenost",IF(C6<=220,"Optimalno","Preopterećenje"))) -> Niska iskorištenost | H6: P005 | I6: =SUMIFS(Sheet3_Sati!$D:$D,Sheet3_Sati!$C:$C,H6) -> 134.5 | J6: =SUMIFS(Sheet3_Sati!$J:$J,Sheet3_Sati!$C:$C,H6) -> 1845.6825 | K6: =COUNTIF(Sheet3_Sati!$C:$C,H6) -> 14 | L6: =IFERROR(J6/K6,0) -> 131.83446
A7: EMP006 | B7: =INDEX(Master_Lista!$B$2:$B$151,MATCH(A7,Master_Lista!$A$2:$A$151,0)) -> Goran Zivkovic | C7: =SUMIFS(Sheet3_Sati!$D:$D,Sheet3_Sati!$A:$A,A7) -> 11 | D7: =SUMIFS(Sheet3_Sati!$J:$J,Sheet3_Sati!$A:$A,A7) -> 110.55 | E7: =IFERROR(D7/C7,0) -> 10.05 | F7: =COUNTIF(Sheet3_Sati!$A:$A,A7) -> 1 | G7: =IF(C7=0,"Nema unosa",IF(C7<160,"Niska iskorištenost",IF(C7<=220,"Optimalno","Preopterećenje"))) -> Niska iskorištenost | H7: P006 | I7: =SUMIFS(Sheet3_Sati!$D:$D,Sheet3_Sati!$C:$C,H7) -> 73.5 | J7: =SUMIFS(Sheet3_Sati!$J:$J,Sheet3_Sati!$C:$C,H7) -> 1074.0938 | K7: =COUNTIF(Sheet3_Sati!$C:$C,H7) -> 8 | L7: =IFERROR(J7/K7,0) -> 134.26172
A8: EMP007 | B8: =INDEX(Master_Lista!$B$2:$B$151,MATCH(A8,Master_Lista!$A$2:$A$151,0)) -> Filip Kostic | C8: =SUMIFS(Sheet3_Sati!$D:$D,Sheet3_Sati!$A:$A,A8) -> 11 | D8: =SUMIFS(Sheet3_Sati!$J:$J,Sheet3_Sati!$A:$A,A8) -> 132.66 | E8: =IFERROR(D8/C8,0) -> 12.06 | F8: =COUNTIF(Sheet3_Sati!$A:$A,A8) -> 1 | G8: =IF(C8=0,"Nema unosa",IF(C8<160,"Niska iskorištenost",IF(C8<=220,"Optimalno","Preopterećenje"))) -> Niska iskorištenost | H8: P007 | I8: =SUMIFS(Sheet3_Sati!$D:$D,Sheet3_Sati!$C:$C,H8) -> 67.5 | J8: =SUMIFS(Sheet3_Sati!$J:$J,Sheet3_Sati!$C:$C,H8) -> 908.77125 | K8: =COUNTIF(Sheet3_Sati!$C:$C,H8) -> 8 | L8: =IFERROR(J8/K8,0) -> 113.59641
A9: EMP008 | B9: =INDEX(Master_Lista!$B$2:$B$151,MATCH(A9,Master_Lista!$A$2:$A$151,0)) -> Lidija Tomic | C9: =SUMIFS(Sheet3_Sati!$D:$D,Sheet3_Sati!$A:$A,A9) -> 0 | D9: =SUMIFS(Sheet3_Sati!$J:$J,Sheet3_Sati!$A:$A,A9) -> 0 | E9: =IFERROR(D9/C9,0) -> 0 | F9: =COUNTIF(Sheet3_Sati!$A:$A,A9) -> 0 | G9: =IF(C9=0,"Nema unosa",IF(C9<160,"Niska iskorištenost",IF(C9<=220,"Optimalno","Preopterećenje"))) -> Nema unosa | H9: P008 | I9: =SUMIFS(Sheet3_Sati!$D:$D,Sheet3_Sati!$C:$C,H9) -> 143 | J9: =SUMIFS(Sheet3_Sati!$J:$J,Sheet3_Sati!$C:$C,H9) -> 2061.7575 | K9: =COUNTIF(Sheet3_Sati!$C:$C,H9) -> 17 | L9: =IFERROR(J9/K9,0) -> 121.27985
A10: EMP009 | B10: =INDEX(Master_Lista!$B$2:$B$151,MATCH(A10,Master_Lista!$A$2:$A$151,0)) -> Petar Lazic | C10: =SUMIFS(Sheet3_Sati!$D:$D,Sheet3_Sati!$A:$A,A10) -> 8.5 | D10: =SUMIFS(Sheet3_Sati!$J:$J,Sheet3_Sati!$A:$A,A10) -> 170.85 | E10: =IFERROR(D10/C10,0) -> 20.1 | F10: =COUNTIF(Sheet3_Sati!$A:$A,A10) -> 1 | G10: =IF(C10=0,"Nema unosa",IF(C10<160,"Niska iskorištenost",IF(C10<=220,"Optimalno","Preopterećenje"))) -> Niska iskorištenost | H10: P009 | I10: =SUMIFS(Sheet3_Sati!$D:$D,Sheet3_Sati!$C:$C,H10) -> 159 | J10: =SUMIFS(Sheet3_Sati!$J:$J,Sheet3_Sati!$C:$C,H10) -> 2082.8625 | K10: =COUNTIF(Sheet3_Sati!$C:$C,H10) -> 18 | L10: =IFERROR(J10/K10,0) -> 115.71458
A11: EMP010 | B11: =INDEX(Master_Lista!$B$2:$B$151,MATCH(A11,Master_Lista!$A$2:$A$151,0)) -> Branko Babic | C11: =SUMIFS(Sheet3_Sati!$D:$D,Sheet3_Sati!$A:$A,A11) -> 28.5 | D11: =SUMIFS(Sheet3_Sati!$J:$J,Sheet3_Sati!$A:$A,A11) -> 630.135 | E11: =IFERROR(D11/C11,0) -> 22.11 | F11: =COUNTIF(Sheet3_Sati!$A:$A,A11) -> 3 | G11: =IF(C11=0,"Nema unosa",IF(C11<160,"Niska iskorištenost",IF(C11<=220,"Optimalno","Preopterećenje"))) -> Niska iskorištenost | H11: P010 | I11: =SUMIFS(Sheet3_Sati!$D:$D,Sheet3_Sati!$C:$C,H11) -> 121 | J11: =SUMIFS(Sheet3_Sati!$J:$J,Sheet3_Sati!$C:$C,H11) -> 1864.0238 | K11: =COUNTIF(Sheet3_Sati!$C:$C,H11) -> 13 | L11: =IFERROR(J11/K11,0) -> 143.38644
A12: EMP011 | B12: =INDEX(Master_Lista!$B$2:$B$151,MATCH(A12,Master_Lista!$A$2:$A$151,0)) -> Uros Djordjevic | C12: =SUMIFS(Sheet3_Sati!$D:$D,Sheet3_Sati!$A:$A,A12) -> 17.5 | D12: =SUMIFS(Sheet3_Sati!$J:$J,Sheet3_Sati!$A:$A,A12) -> 167.08125 | E12: =IFERROR(D12/C12,0) -> 9.5475 | F12: =COUNTIF(Sheet3_Sati!$A:$A,A12) -> 2 | G12: =IF(C12=0,"Nema unosa",IF(C12<160,"Niska iskorištenost",IF(C12<=220,"Optimalno","Preopterećenje"))) -> Niska iskorištenost | H12: P011 | I12: =SUMIFS(Sheet3_Sati!$D:$D,Sheet3_Sati!$C:$C,H12) -> 112 | J12: =SUMIFS(Sheet3_Sati!$J:$J,Sheet3_Sati!$C:$C,H12) -> 1590.4125 | K12: =COUNTIF(Sheet3_Sati!$C:$C,H12) -> 12 | L12: =IFERROR(J12/K12,0) -> 132.53438
A13: EMP012 | B13: =INDEX(Master_Lista!$B$2:$B$151,MATCH(A13,Master_Lista!$A$2:$A$151,0)) -> Branko Babic | C13: =SUMIFS(Sheet3_Sati!$D:$D,Sheet3_Sati!$A:$A,A13) -> 7.5 | D13: =SUMIFS(Sheet3_Sati!$J:$J,Sheet3_Sati!$A:$A,A13) -> 60.3 | E13: =IFERROR(D13/C13,0) -> 8.04 | F13: =COUNTIF(Sheet3_Sati!$A:$A,A13) -> 1 | G13: =IF(C13=0,"Nema unosa",IF(C13<160,"Niska iskorištenost",IF(C13<=220,"Optimalno","Preopterećenje"))) -> Niska iskorištenost | H13: P012 | I13: =SUMIFS(Sheet3_Sati!$D:$D,Sheet3_Sati!$C:$C,H13) -> 112.5 | J13: =SUMIFS(Sheet3_Sati!$J:$J,Sheet3_Sati!$C:$C,H13) -> 1519.56 | K13: =COUNTIF(Sheet3_Sati!$C:$C,H13) -> 13 | L13: =IFERROR(J13/K13,0) -> 116.88923
... A16: EMP015 | B16: =INDEX(Master_Lista!$B$2:$B$151,MATCH(A16,Master_Lista!$A$2:$A$151,0)) -> Petar Antic | C16: =SUMIFS(Sheet3_Sati!$D:$D,Sheet3_Sati!$A:$A,A16) -> 20 | D16: =SUMIFS(Sheet3_Sati!$J:$J,Sheet3_Sati!$A:$A,A16) -> 502.5 | E16: =IFERROR(D16/C16,0) -> 25.125 | F16: =COUNTIF(Sheet3_Sati!$A:$A,A16) -> 2 | G16: =IF(C16=0,"Nema unosa",IF(C16<160,"Niska iskorištenost",IF(C16<=220,"Optimalno","Preopterećenje"))) -> Niska iskorištenost | H16: P015 | I16: =SUMIFS(Sheet3_Sati!$D:$D,Sheet3_Sati!$C:$C,H16) -> 110.5 | J16: =SUMIFS(Sheet3_Sati!$J:$J,Sheet3_Sati!$C:$C,H16) -> 1570.815 | K16: =COUNTIF(Sheet3_Sati!$C:$C,H16) -> 11 | L16: =IFERROR(J16/K16,0) -> 142.80136
A17: EMP016 | B17: =INDEX(Master_Lista!$B$2:$B$151,MATCH(A17,Master_Lista!$A$2:$A$151,0)) -> Stefan Cvetkovic | C17: =SUMIFS(Sheet3_Sati!$D:$D,Sheet3_Sati!$A:$A,A17) -> 0 | D17: =SUMIFS(Sheet3_Sati!$J:$J,Sheet3_Sati!$A:$A,A17) -> 0 | E17: =IFERROR(D17/C17,0) -> 0 | F17: =COUNTIF(Sheet3_Sati!$A:$A,A17) -> 0 | G17: =IF(C17=0,"Nema unosa",IF(C17<160,"Niska iskorištenost",IF(C17<=220,"Optimalno","Preopterećenje"))) -> Nema unosa
A18: EMP017 | B18: =INDEX(Master_Lista!$B$2:$B$151,MATCH(A18,Master_Lista!$A$2:$A$151,0)) -> Cedomir Markovic | C18: =SUMIFS(Sheet3_Sati!$D:$D,Sheet3_Sati!$A:$A,A18) -> 11 | D18: =SUMIFS(Sheet3_Sati!$J:$J,Sheet3_Sati!$A:$A,A18) -> 138.1875 | E18: =IFERROR(D18/C18,0) -> 12.5625 | F18: =COUNTIF(Sheet3_Sati!$A:$A,A18) -> 1 | G18: =IF(C18=0,"Nema unosa",IF(C18<160,"Niska iskorištenost",IF(C18<=220,"Optimalno","Preopterećenje"))) -> Niska iskorištenost
A19: EMP018 | B19: =INDEX(Master_Lista!$B$2:$B$151,MATCH(A19,Master_Lista!$A$2:$A$151,0)) -> Sanja Grujic | C19: =SUMIFS(Sheet3_Sati!$D:$D,Sheet3_Sati!$A:$A,A19) -> 0 | D19: =SUMIFS(Sheet3_Sati!$J:$J,Sheet3_Sati!$A:$A,A19) -> 0 | E19: =IFERROR(D19/C19,0) -> 0 | F19: =COUNTIF(Sheet3_Sati!$A:$A,A19) -> 0 | G19: =IF(C19=0,"Nema unosa",IF(C19<160,"Niska iskorištenost",IF(C19<=220,"Optimalno","Preopterećenje"))) -> Nema unosa
A20: EMP019 | B20: =INDEX(Master_Lista!$B$2:$B$151,MATCH(A20,Master_Lista!$A$2:$A$151,0)) -> Jovan Tomic | C20: =SUMIFS(Sheet3_Sati!$D:$D,Sheet3_Sati!$A:$A,A20) -> 0 | D20: =SUMIFS(Sheet3_Sati!$J:$J,Sheet3_Sati!$A:$A,A20) -> 0 | E20: =IFERROR(D20/C20,0) -> 0 | F20: =COUNTIF(Sheet3_Sati!$A:$A,A20) -> 0 | G20: =IF(C20=0,"Nema unosa",IF(C20<160,"Niska iskorištenost",IF(C20<=220,"Optimalno","Preopterećenje"))) -> Nema unosa
A21: EMP020 | B21: =INDEX(Master_Lista!$B$2:$B$151,MATCH(A21,Master_Lista!$A$2:$A$151,0)) -> Luka Kostic | C21: =SUMIFS(Sheet3_Sati!$D:$D,Sheet3_Sati!$A:$A,A21) -> 8 | D21: =SUMIFS(Sheet3_Sati!$J:$J,Sheet3_Sati!$A:$A,A21) -> 88.44 | E21: =IFERROR(D21/C21,0) -> 11.055 | F21: =COUNTIF(Sheet3_Sati!$A:$A,A21) -> 1 | G21: =IF(C21=0,"Nema unosa",IF(C21<160,"Niska iskorištenost",IF(C21<=220,"Optimalno","Preopterećenje"))) -> Niska iskorištenost
A22: EMP021 | B22: =INDEX(Master_Lista!$B$2:$B$151,MATCH(A22,Master_Lista!$A$2:$A$151,0)) -> Lidija Obradovic | C22: =SUMIFS(Sheet3_Sati!$D:$D,Sheet3_Sati!$A:$A,A22) -> 7.5 | D22: =SUMIFS(Sheet3_Sati!$J:$J,Sheet3_Sati!$A:$A,A22) -> 135.675 | E22: =IFERROR(D22/C22,0) -> 18.09 | F22: =COUNTIF(Sheet3_Sati!$A:$A,A22) -> 1 | G22: =IF(C22=0,"Nema unosa",IF(C22<160,"Niska iskorištenost",IF(C22<=220,"Optimalno","Preopterećenje"))) -> Niska iskorištenost
A23: EMP022 | B23: =INDEX(Master_Lista!$B$2:$B$151,MATCH(A23,Master_Lista!$A$2:$A$151,0)) -> Aleksandar Lazic | C23: =SUMIFS(Sheet3_Sati!$D:$D,Sheet3_Sati!$A:$A,A23) -> 0 | D23: =SUMIFS(Sheet3_Sati!$J:$J,Sheet3_Sati!$A:$A,A23) -> 0 | E23: =IFERROR(D23/C23,0) -> 0 | F23: =COUNTIF(Sheet3_Sati!$A:$A,A23) -> 0 | G23: =IF(C23=0,"Nema unosa",IF(C23<160,"Niska iskorištenost",IF(C23<=220,"Optimalno","Preopterećenje"))) -> Nema unosa
A24: EMP023 | B24: =INDEX(Master_Lista!$B$2:$B$151,MATCH(A24,Master_Lista!$A$2:$A$151,0)) -> Petra Lazic | C24: =SUMIFS(Sheet3_Sati!$D:$D,Sheet3_Sati!$A:$A,A24) -> 20.5 | D24: =SUMIFS(Sheet3_Sati!$J:$J,Sheet3_Sati!$A:$A,A24) -> 185.4225 | E24: =IFERROR(D24/C24,0) -> 9.045 | F24: =COUNTIF(Sheet3_Sati!$A:$A,A24) -> 2 | G24: =IF(C24=0,"Nema unosa",IF(C24<160,"Niska iskorištenost",IF(C24<=220,"Optimalno","Preopterećenje"))) -> Niska iskorištenost
A25: EMP024 | B25: =INDEX(Master_Lista!$B$2:$B$151,MATCH(A25,Master_Lista!$A$2:$A$151,0)) -> Una Kostic | C25: =SUMIFS(Sheet3_Sati!$D:$D,Sheet3_Sati!$A:$A,A25) -> 0 | D25: =SUMIFS(Sheet3_Sati!$J:$J,Sheet3_Sati!$A:$A,A25) -> 0 | E25: =IFERROR(D25/C25,0) -> 0 | F25: =COUNTIF(Sheet3_Sati!$A:$A,A25) -> 0 | G25: =IF(C25=0,"Nema unosa",IF(C25<160,"Niska iskorištenost",IF(C25<=220,"Optimalno","Preopterećenje"))) -> Nema unosa
A26: EMP025 | B26: =INDEX(Master_Lista!$B$2:$B$151,MATCH(A26,Master_Lista!$A$2:$A$151,0)) -> Radoslav Vasic | C26: =SUMIFS(Sheet3_Sati!$D:$D,Sheet3_Sati!$A:$A,A26) -> 11 | D26: =SUMIFS(Sheet3_Sati!$J:$J,Sheet3_Sati!$A:$A,A26) -> 132.66 | E26: =IFERROR(D26/C26,0) -> 12.06 | F26: =COUNTIF(Sheet3_Sati!$A:$A,A26) -> 1 | G26: =IF(C26=0,"Nema unosa",IF(C26<160,"Niska iskorištenost",IF(C26<=220,"Optimalno","Preopterećenje"))) -> Niska iskorištenost
A27: EMP026 | B27: =INDEX(Master_Lista!$B$2:$B$151,MATCH(A27,Master_Lista!$A$2:$A$151,0)) -> Ognjen Kostic | C27: =SUMIFS(Sheet3_Sati!$D:$D,Sheet3_Sati!$A:$A,A27) -> 0 | D27: =SUMIFS(Sheet3_Sati!$J:$J,Sheet3_Sati!$A:$A,A27) -> 0 | E27: =IFERROR(D27/C27,0) -> 0 | F27: =COUNTIF(Sheet3_Sati!$A:$A,A27) -> 0 | G27: =IF(C27=0,"Nema unosa",IF(C27<160,"Niska iskorištenost",IF(C27<=220,"Optimalno","Preopterećenje"))) -> Nema unosa
A28: EMP027 | B28: =INDEX(Master_Lista!$B$2:$B$151,MATCH(A28,Master_Lista!$A$2:$A$151,0)) -> Branko Jankovic | C28: =SUMIFS(Sheet3_Sati!$D:$D,Sheet3_Sati!$A:$A,A28) -> 6 | D28: =SUMIFS(Sheet3_Sati!$J:$J,Sheet3_Sati!$A:$A,A28) -> 120.6 | E28: =IFERROR(D28/C28,0) -> 20.1 | F28: =COUNTIF(Sheet3_Sati!$A:$A,A28) -> 1 | G28: =IF(C28=0,"Nema unosa",IF(C28<160,"Niska iskorištenost",IF(C28<=220,"Optimalno","Preopterećenje"))) -> Niska iskorištenost
... A151: EMP150 | B151: =INDEX(Master_Lista!$B$2:$B$151,MATCH(A151,Master_Lista!$A$2:$A$151,0)) -> Filip Lazic | C151: =SUMIFS(Sheet3_Sati!$D:$D,Sheet3_Sati!$A:$A,A151) -> 12 | D151: =SUMIFS(Sheet3_Sati!$J:$J,Sheet3_Sati!$A:$A,A151) -> 120.6 | E151: =IFERROR(D151/C151,0) -> 10.05 | F151: =COUNTIF(Sheet3_Sati!$A:$A,A151) -> 1 | G151: =IF(C151=0,"Nema unosa",IF(C151<160,"Niska iskorištenost",IF(C151<=220,"Optimalno","Preopterećenje"))) -> Niska iskorištenost

Sheet Sheet35_Dashboard
B2: EXECUTIVE SUMMARY - EFIKASNOST 2026 (v3.1 clean)
B4: Ukupan Trošak Rada: | C4: =SUM(Sheet3_Sati!J:J) -> 23243.389 | E4: Kontrolni pragovi
B5: Ukupno Evidentiranih Sati: | C5: =SUM(Sheet3_Sati!D:D) -> 1636 | E5: Max sati / dan | F5: 16
B6: Prosječan Trošak po Satu: | C6: =IFERROR(C4/C5,0) -> 14.20745 | E6: Flag prag | F6: 12
B7: Broj Evidentiranih Unosa: | C7: =COUNTIF(Sheet3_Sati!A:A,"<>") -> 181 | E7: Valuta | F7: EUR
B8: Najskuplji Projekat: | C8: =INDEX(Sheet31_Analitika!H2:H16,MATCH(MAX(Sheet31_Analitika!J2:J16),Sheet31_Analitika!J2:J16,0)) -> P004 | E8: Period | F8: 2026
B9: Najopterećeniji Radnik (ID): | C9: =INDEX(Sheet31_Analitika!A2:A151,MATCH(MAX(Sheet31_Analitika!C2:C151),Sheet31_Analitika!C2:C151,0)) -> EMP079
B10: Sumnjivi unosi (>12h): | C10: =COUNTIF(Sheet3_Sati!D2:D500,">12") -> 0
B11: Duplikati ID+Datum+Projekat: | C11: =COUNTIF(Sheet3_Sati!L2:L500,"DUPLIKAT") -> 0

Sheet Error_Checks
A1: v3.1 CLEAN - ERROR CHECKS
A3: Check | B3: Value | C3: Target | D3: Result
A4: Ukupni sati > 0 | B4: =SUM(Sheet3_Sati!D:D) -> 1636 | C4: >0 | D4: =IF(B4>0,"PASS","REVIEW") -> PASS
A5: Ukupan trošak > 0 | B5: =SUM(Sheet3_Sati!J:J) -> 23243.389 | C5: >0 | D5: =IF(B5>0,"PASS","REVIEW") -> PASS
A6: Sumnjivi unosi (>12h) | B6: =COUNTIF(Sheet3_Sati!D2:D500,">12") -> 0 | C6: =0 -> 0 | D6: =IF(B6=0,"PASS","REVIEW") -> PASS
A7: Duplikati ID+Datum+Projekat | B7: =COUNTIF(Sheet3_Sati!L2:L500,"DUPLIKAT") -> 0 | C7: =0 -> 0 | D7: =IF(B7=0,"PASS","REVIEW") -> PASS
A8: Nevalidni ID lookup | B8: =COUNTIF(Sheet3_Sati!B2:B500,"")-COUNTBLANK(Sheet3_Sati!A2:A500) -> 0 | C8: =0 -> 0 | D8: =IF(B8=0,"PASS","REVIEW") -> PASS
