Workbook

Sheet INDEX
A1: ARS METAL INDUSTRIES DOO - FINAL HARMONIZED CFO MODEL
A2: Index | Harmonized from historical bilansi and CAPEX/OPEX model
A4: Section | B4: Sheet | C4: Purpose
A5: Core | B5: ASSUMPTIONS | C5: Master assumptions and scenario switch
A6: Historical | B6: INPUT_Bilansi | C6: Historical imported balance sheet
A7: Historical | B7: CAPEX_Historija | C7: CAPEX history by category
A8: Historical | B8: Amortizacija_Plan | C8: Depreciation schedule
A9: Projection | B9: CAPEX_Projekcija_2026_2030 | C9: Future CAPEX plan
A10: Projection | B10: OPEX_Historija | C10: Historical OPEX monthly
A11: Projection | B11: OPEX_Projekcija_2026_2030 | C11: Future OPEX plan
A12: Cash | B12: Cashflow_BurnRate | C12: Monthly burn and runway
A13: Tax | B13: PDV_Refund_Tracker | C13: VAT refund tracker
A14: FX | B14: TRY_Hedge_Calc | C14: TRY hedge calculator
A15: Integrated | B15: Full_Integrated_Model | C15: Integrated summary model
... A18: Guide | B18: Instructions | C18: Usage notes

Sheet ASSUMPTIONS
A1: ASSUMPTIONS
A2: Yellow=input | Green=calculated | Scenario selector in F4
A3: Input | B3: Value | C3: Unit | D3: Notes | E3: Scenario | F3: Selected
A4: MODEL_CCY | B4: EUR | C4: text | D4: Reporting currency | E4: Scenario | F4: Base
A5: FX_EUR_TRY | B5: 51.7 | C5: TRY/EUR | D5: Equipment import FX | E5: CAPEX_Multiplier | F5: =IF($F$4="Base",1,IF($F$4="Downside",1.15,0.90))
A6: VAT_STD | B6: 0.21 | C6: % | D6: Standard VAT rate | E6: OPEX_Multiplier | F6: =IF($F$4="Base",1,IF($F$4="Downside",1.10,0.95))
A7: VAT_CAPEX_REFUNDABLE | B7: 0.21 | C7: % | D7: Refundable CAPEX VAT | E7: Revenue_Multiplier | F7: =IF($F$4="Base",1,IF($F$4="Downside",0.85,1.10))
A8: CIT_RATE | B8: 0.15 | C8: % | D8: Corporate tax
A9: INF_CONSTRUCTION | B9: 0.035 | C9: % | D9: Construction inflation
A10: INF_OPEX | B10: 0.025 | C10: % | D10: OPEX inflation
A11: DISCOUNT_RATE | B11: 0.08 | C11: % | D11: Discount rate
A12: WACC | B12: 0.095 | C12: % | D12: WACC
A13: COD_DATE | B13: 01.07.2029 | C13: date | D13: Commercial operation date
A14: LOAN_AMOUNT | B14: 10000000 | C14: EUR | D14: Senior debt
A15: INTEREST_RATE | B15: 0.065 | C15: % | D15: Interest rate
A16: TENOR_YEARS | B16: 10 | C16: years | D16: Debt tenor
A17: GRACE_YEARS | B17: 3 | C17: years | D17: Grace period
A18: GRANT_AMOUNT | B18: 2000000 | C18: EUR | D18: Grant amount
A19: CAPEX_TOTAL_TARGET | B19: 14850000 | C19: EUR | D19: Target total CAPEX
A20: WORKING_DAYS_YR | B20: 250 | C20: days | D20: Average working days
A21: HEDGE_PCT | B21: 0.8 | C21: % | D21: TRY hedge ratio
A22: GET_ELIGIBLE_PCT | B22: 0.65 | C22: % | D22: GET eligible CAPEX
A23: MIN_CASH_DIV | B23: 100000 | C23: EUR | D23: Minimum cash for dividend
A24: DIV_START_YEAR | B24: 2032 | C24: year | D24: Dividend start year

Sheet INPUT_Bilansi
A1: INPUT_Bilansi
A2: Historical balance sheet import (2025 / 2024 / 2023)
A3: Grupa računa / račun | B3: Pozicija / Opis | C3: Redni broj | D3: Tekuća godina (2025) | E3: Prethodna (2024) | F3: Prethodna (2023)
A4: B. | B4: STALNA IMOVINA (003+008+016) | C4: 2 | D4: 740967 | E4: 602598 | F4: 399000
A5: 01 | B5: I. NEMATERIJALNA ULAGANJA (004 do 007) | C5: 3 | D5: 0 | E5: 0 | F5: 0
A6: 10 | B6: 1. Ulaganja u razvoj | C6: 4 | D6: 0 | E6: 0 | F6: 0
A7: 011 | B7: i 014 | C7: 5 | D7: 0 | E7: 0 | F7: 0
A8: 012 | B8: 3. Goodwill | C8: 6 | D8: 0 | E8: 0 | F8: 0
A9: 016 | B9: i 015 | C9: 7 | D9: 0 | E9: 0 | F9: 0
C10: 8 | D10: 740967 | E10: 602598 | F10: 399000
A11: 020 | B11: i 022 1. Zemljište i objekti | C11: 9 | D11: 419426 | E11: 399000 | F11: 399000
A12: 023 | B12: 2. Postrojenja i oprema | C12: 10 | D12: 650 | E12: 0 | F12: 0
C13: 11 | D13: 0 | E13: 0 | F13: 0
A14: 024 | B14: 3.1. Investicione nekretnine | C14: 12 | D14: 0 | E14: 0 | F14: 0
A15: 021 | B15: i 025 3.2. Biološka sredstva | C15: 13 | D15: 0 | E15: 0 | F15: 0
A16: 026 | B16: i 029 3.3. Ostala nepomenuta materijalna stalna sredstva | C16: 14 | D16: 0 | E16: 0 | F16: 0
A17: 028 | B17: i 027 | C17: 15 | D17: 320891 | E17: 203598 | F17: 0
C18: 16 | D18: 0 | E18: 0 | F18: 0
A19: 030, | B19: 039(dio) 1. Ucešca u kapitalu zavisnih pravnih lica | C19: 17 | D19: 0 | E19: 0 | F19: 0
A20: 033(dio), | B20: 039(dio) | C20: 18 | D20: 0 | E20: 0 | F20: 0
A21: 031(dio), | B21: 032(dio), 039(dio) | C21: 19 | D21: 0 | E21: 0 | F21: 0
A22: 033(dio), | B22: 039(dio) | C22: 20 | D22: 0 | E22: 0 | F22: 0
A23: 031(dio), | B23: 032(dio) | C23: 21 | D23: 0 | E23: 0 | F23: 0
C24: 22 | D24: 0 | E24: 0 | F24: 0
A25: 038, | B25: 039(dio) | C25: 23 | D25: 0 | E25: 0 | F25: 0
A26: 288 | B26: C. ODLOŽENA PORESKA SREDSTVA | C26: 24 | D26: 0 | E26: 0 | F26: 0
A27: D. | B27: OBRTNA SREDSTVA (026+031+039+043+044) | C27: 25 | D27: 127375 | E27: 62879 | F27: 39880
A28: I. | B28: ZALIHE (027 do 030) | C28: 26 | D28: 4869 | E28: 0 | F28: 0
A29: 10 | C29: 27 | D29: 0 | E29: 0 | F29: 0
A30: 11 | B30: 2. Nedovršena proizvodnja | C30: 28 | D30: 0 | E30: 0 | F30: 0
A31: 12 | B31: i 13 3. Gotovi proizvodi i roba | C31: 29 | D31: 0 | E31: 0 | F31: 0
A32: 15 | B32: 4. Dati avansi | C32: 30 | D32: 4869 | E32: 0 | F32: 0
A33: II. | B33: KRATKOROCNA POTRAŽIVANJA (032 do 035) | C33: 31 | D33: 115344 | E33: 60094 | F33: 0
A34: 202, | B34: 203, 209(dio) 1. Potraživanja od kupaca | C34: 32 | D34: 0 | E34: 0 | F34: 0
A35: 200, | B35: 209(dio) 2. Potraživanja od maticnog i zavisnih pravnih lica | C35: 33 | D35: 0 | E35: 0 | F35: 0
A36: 201, | B36: 209(dio) 3. Potraživanja od ostalih povezanih lica | C36: 34 | D36: 0 | E36: 0 | F36: 0
A37: 4. | B37: Ostala potraživanja (036-038) | C37: 35 | D37: 115344 | E37: 60094 | F37: 0
A38: 223 | B38: 4.1. Potraživanja za više placen porez na dobit | C38: 36 | D38: 0 | E38: 0 | F38: 0
A39: 27 | C39: 37 | D39: 86224 | E39: 60094 | F39: 0
A40: 21, | B40: 22 osim 223 4.3. Ostala nepomenuta potraživanja | C40: 38 | D40: 29120 | E40: 0 | F40: 0
...

Sheet CAPEX_Historija
A1: CAPEX_Historija
A2: Historical balances and additions by category
A3: Category (EN / SR) | B3: Tax Group | C3: Rate | D3: 2023 | E3: 2024 | F3: 2025 | G3: Δ24 vs 23 | H3: Δ25 vs 24 | I3: Cumulative to 2025
A4: Land & Buildings / Zemljište i objekti (RB 9) | B4: N/A / II | C4: 0.1 | D4: =INDEX(INPUT_Bilansi!$F:$F,MATCH(9,INPUT_Bilansi!$C:$C,0)) | E4: =INDEX(INPUT_Bilansi!$E:$E,MATCH(9,INPUT_Bilansi!$C:$C,0)) | F4: =INDEX(INPUT_Bilansi!$D:$D,MATCH(9,INPUT_Bilansi!$C:$C,0)) | G4: =E4-D4 | H4: =F4-E4 | I4: =SUM(D4:F4)
A5: Machinery & Equipment / Postrojenja i oprema (RB 10) | B5: III / IV | C5: 0.15 | D5: =INDEX(INPUT_Bilansi!$F:$F,MATCH(10,INPUT_Bilansi!$C:$C,0)) | E5: =INDEX(INPUT_Bilansi!$E:$E,MATCH(10,INPUT_Bilansi!$C:$C,0)) | F5: =INDEX(INPUT_Bilansi!$D:$D,MATCH(10,INPUT_Bilansi!$C:$C,0)) | G5: =E5-D5 | H5: =F5-E5 | I5: =SUM(D5:F5)
A6: Advances for PPE / Avansi za PPE (RB 15) | B6: N/A | C6: 0 | D6: =INDEX(INPUT_Bilansi!$F:$F,MATCH(15,INPUT_Bilansi!$C:$C,0)) | E6: =INDEX(INPUT_Bilansi!$E:$E,MATCH(15,INPUT_Bilansi!$C:$C,0)) | F6: =INDEX(INPUT_Bilansi!$D:$D,MATCH(15,INPUT_Bilansi!$C:$C,0)) | G6: =E6-D6 | H6: =F6-E6 | I6: =SUM(D6:F6)
A7: Intangibles / Nematerijalna ulaganja (RB 3) | B7: III | C7: 0.15 | D7: =INDEX(INPUT_Bilansi!$F:$F,MATCH(3,INPUT_Bilansi!$C:$C,0)) | E7: =INDEX(INPUT_Bilansi!$E:$E,MATCH(3,INPUT_Bilansi!$C:$C,0)) | F7: =INDEX(INPUT_Bilansi!$D:$D,MATCH(3,INPUT_Bilansi!$C:$C,0)) | G7: =E7-D7 | H7: =F7-E7 | I7: =SUM(D7:F7)
A8: Other Fixed Assets / Ostala stalna imovina | B8: Various | C8: 0.1 | D8: =INDEX(INPUT_Bilansi!$F:$F,MATCH(2,INPUT_Bilansi!$C:$C,0))-SUM(D4:D7) | E8: =INDEX(INPUT_Bilansi!$E:$E,MATCH(2,INPUT_Bilansi!$C:$C,0))-SUM(E4:E7) | F8: =INDEX(INPUT_Bilansi!$D:$D,MATCH(2,INPUT_Bilansi!$C:$C,0))-SUM(F4:F7) | G8: =E8-D8 | H8: =F8-E8 | I8: =SUM(D8:F8)
A9: TOTAL CAPEX | D9: =SUM(D4:D8) | E9: =SUM(E4:E8) | F9: =SUM(F4:F8) | G9: =E9-D9 | H9: =F9-E9 | I9: =SUM(D9:F9)

Sheet Amortizacija_Plan
A1: Amortizacija_Plan
A2: Straight-line depreciation bridge
A3: Investment Year | B3: Category | C3: Amount | D3: Rate | E3: Annual Depreciation | F3: Cum. Depreciation to 2025 | G3: Residual 2026
A4: 2023 | B4: Land & Buildings | C4: =CAPEX_Historija!D4 | D4: =CAPEX_Historija!C4 | E4: =C4*D4 | F4: =MIN(C4,E4*MAX(0,2025-A4+1)) | G4: =MAX(0,C4-F4)
A5: 2024 | B5: Land & Buildings | C5: =CAPEX_Historija!E4 | D5: =CAPEX_Historija!C4 | E5: =C5*D5 | F5: =MIN(C5,E5*MAX(0,2025-A5+1)) | G5: =MAX(0,C5-F5)
A6: 2025 | B6: Land & Buildings | C6: =CAPEX_Historija!F4 | D6: =CAPEX_Historija!C4 | E6: =C6*D6 | F6: =MIN(C6,E6*MAX(0,2025-A6+1)) | G6: =MAX(0,C6-F6)
A7: 2023 | B7: Machinery & Equipment | C7: =CAPEX_Historija!D5 | D7: =CAPEX_Historija!C5 | E7: =C7*D7 | F7: =MIN(C7,E7*MAX(0,2025-A7+1)) | G7: =MAX(0,C7-F7)
A8: 2024 | B8: Machinery & Equipment | C8: =CAPEX_Historija!E5 | D8: =CAPEX_Historija!C5 | E8: =C8*D8 | F8: =MIN(C8,E8*MAX(0,2025-A8+1)) | G8: =MAX(0,C8-F8)
A9: 2025 | B9: Machinery & Equipment | C9: =CAPEX_Historija!F5 | D9: =CAPEX_Historija!C5 | E9: =C9*D9 | F9: =MIN(C9,E9*MAX(0,2025-A9+1)) | G9: =MAX(0,C9-F9)
A10: 2023 | B10: Intangibles | C10: =CAPEX_Historija!D7 | D10: =CAPEX_Historija!C7 | E10: =C10*D10 | F10: =MIN(C10,E10*MAX(0,2025-A10+1)) | G10: =MAX(0,C10-F10)
A11: 2024 | B11: Intangibles | C11: =CAPEX_Historija!E7 | D11: =CAPEX_Historija!C7 | E11: =C11*D11 | F11: =MIN(C11,E11*MAX(0,2025-A11+1)) | G11: =MAX(0,C11-F11)
A12: 2025 | B12: Intangibles | C12: =CAPEX_Historija!F7 | D12: =CAPEX_Historija!C7 | E12: =C12*D12 | F12: =MIN(C12,E12*MAX(0,2025-A12+1)) | G12: =MAX(0,C12-F12)

Sheet CAPEX_Projekcija_2026_2030
A1: CAPEX_Projekcija_2026_2030
A2: Yellow = plan inputs for 2026-2030
A3: Category | B3: Tax Group | C3: 2026 | D3: 2027 | E3: 2028 | F3: 2029 | G3: 2030 | H3: Total Future | I3: Total Cumulative
A4: Land & Buildings | B4: II | C4: 0 | D4: 0 | E4: 0 | F4: 0 | G4: 0 | H4: =SUM(C4:G4) | I4: =CAPEX_Historija!I4+H4
A5: Machinery & Equipment | B5: III/IV | C5: 0 | D5: 0 | E5: 0 | F5: 0 | G5: 0 | H5: =SUM(C5:G5) | I5: =CAPEX_Historija!I5+H5
A6: Advances | B6: N/A | C6: 0 | D6: 0 | E6: 0 | F6: 0 | G6: 0 | H6: =SUM(C6:G6) | I6: =CAPEX_Historija!I6+H6
A7: Intangibles | B7: III | C7: 0 | D7: 0 | E7: 0 | F7: 0 | G7: 0 | H7: =SUM(C7:G7) | I7: =CAPEX_Historija!I7+H7
A8: Other Fixed Assets | B8: II | C8: 0 | D8: 0 | E8: 0 | F8: 0 | G8: 0 | H8: =SUM(C8:G8) | I8: =CAPEX_Historija!I8+H8
A9: TOTAL | C9: =SUM(C4:C8) | D9: =SUM(D4:D8) | E9: =SUM(E4:E8) | F9: =SUM(F4:F8) | G9: =SUM(G4:G8) | H9: =SUM(H4:H8) | I9: =CAPEX_Historija!I9+H9

Sheet OPEX_Historija
A1: OPEX_Historija
A2: Monthly historical OPEX inputs 2023-2025
A3: Month | B3: Salaries | C3: Energy & Utilities | D3: Rent/Services | E3: Professional Fees | F3: Travel & Misc | G3: Total OPEX | H3: Notes
A4: =DATE(2023,1,1) | B4: 0 | C4: 0 | D4: 0 | E4: 0 | F4: 0 | G4: =SUM(B4:F4)
A5: =DATE(2023,2,1) | B5: 0 | C5: 0 | D5: 0 | E5: 0 | F5: 0 | G5: =SUM(B5:F5)
A6: =DATE(2023,3,1) | B6: 0 | C6: 0 | D6: 0 | E6: 0 | F6: 0 | G6: =SUM(B6:F6)
A7: =DATE(2023,4,1) | B7: 0 | C7: 0 | D7: 0 | E7: 0 | F7: 0 | G7: =SUM(B7:F7)
A8: =DATE(2023,5,1) | B8: 0 | C8: 0 | D8: 0 | E8: 0 | F8: 0 | G8: =SUM(B8:F8)
A9: =DATE(2023,6,1) | B9: 0 | C9: 0 | D9: 0 | E9: 0 | F9: 0 | G9: =SUM(B9:F9)
A10: =DATE(2023,7,1) | B10: 0 | C10: 0 | D10: 0 | E10: 0 | F10: 0 | G10: =SUM(B10:F10)
A11: =DATE(2023,8,1) | B11: 0 | C11: 0 | D11: 0 | E11: 0 | F11: 0 | G11: =SUM(B11:F11)
A12: =DATE(2023,9,1) | B12: 0 | C12: 0 | D12: 0 | E12: 0 | F12: 0 | G12: =SUM(B12:F12)
A13: =DATE(2023,10,1) | B13: 0 | C13: 0 | D13: 0 | E13: 0 | F13: 0 | G13: =SUM(B13:F13)
A14: =DATE(2023,11,1) | B14: 0 | C14: 0 | D14: 0 | E14: 0 | F14: 0 | G14: =SUM(B14:F14)
A15: =DATE(2023,12,1) | B15: 0 | C15: 0 | D15: 0 | E15: 0 | F15: 0 | G15: =SUM(B15:F15)
A16: =DATE(2024,1,1) | B16: 0 | C16: 0 | D16: 0 | E16: 0 | F16: 0 | G16: =SUM(B16:F16)
A17: =DATE(2024,2,1) | B17: 0 | C17: 0 | D17: 0 | E17: 0 | F17: 0 | G17: =SUM(B17:F17)
A18: =DATE(2024,3,1) | B18: 0 | C18: 0 | D18: 0 | E18: 0 | F18: 0 | G18: =SUM(B18:F18)
A19: =DATE(2024,4,1) | B19: 0 | C19: 0 | D19: 0 | E19: 0 | F19: 0 | G19: =SUM(B19:F19)
A20: =DATE(2024,5,1) | B20: 0 | C20: 0 | D20: 0 | E20: 0 | F20: 0 | G20: =SUM(B20:F20)
A21: =DATE(2024,6,1) | B21: 0 | C21: 0 | D21: 0 | E21: 0 | F21: 0 | G21: =SUM(B21:F21)
A22: =DATE(2024,7,1) | B22: 0 | C22: 0 | D22: 0 | E22: 0 | F22: 0 | G22: =SUM(B22:F22)
A23: =DATE(2024,8,1) | B23: 0 | C23: 0 | D23: 0 | E23: 0 | F23: 0 | G23: =SUM(B23:F23)
A24: =DATE(2024,9,1) | B24: 0 | C24: 0 | D24: 0 | E24: 0 | F24: 0 | G24: =SUM(B24:F24)
A25: =DATE(2024,10,1) | B25: 0 | C25: 0 | D25: 0 | E25: 0 | F25: 0 | G25: =SUM(B25:F25)
A26: =DATE(2024,11,1) | B26: 0 | C26: 0 | D26: 0 | E26: 0 | F26: 0 | G26: =SUM(B26:F26)
A27: =DATE(2024,12,1) | B27: 0 | C27: 0 | D27: 0 | E27: 0 | F27: 0 | G27: =SUM(B27:F27)
A28: =DATE(2025,1,1) | B28: 0 | C28: 0 | D28: 0 | E28: 0 | F28: 0 | G28: =SUM(B28:F28)
A29: =DATE(2025,2,1) | B29: 0 | C29: 0 | D29: 0 | E29: 0 | F29: 0 | G29: =SUM(B29:F29)
A30: =DATE(2025,3,1) | B30: 0 | C30: 0 | D30: 0 | E30: 0 | F30: 0 | G30: =SUM(B30:F30)
A31: =DATE(2025,4,1) | B31: 0 | C31: 0 | D31: 0 | E31: 0 | F31: 0 | G31: =SUM(B31:F31)
A32: =DATE(2025,5,1) | B32: 0 | C32: 0 | D32: 0 | E32: 0 | F32: 0 | G32: =SUM(B32:F32)
A33: =DATE(2025,6,1) | B33: 0 | C33: 0 | D33: 0 | E33: 0 | F33: 0 | G33: =SUM(B33:F33)
A34: =DATE(2025,7,1) | B34: 0 | C34: 0 | D34: 0 | E34: 0 | F34: 0 | G34: =SUM(B34:F34)
A35: =DATE(2025,8,1) | B35: 0 | C35: 0 | D35: 0 | E35: 0 | F35: 0 | G35: =SUM(B35:F35)
A36: =DATE(2025,9,1) | B36: 0 | C36: 0 | D36: 0 | E36: 0 | F36: 0 | G36: =SUM(B36:F36)
A37: =DATE(2025,10,1) | B37: 0 | C37: 0 | D37: 0 | E37: 0 | F37: 0 | G37: =SUM(B37:F37)
A38: =DATE(2025,11,1) | B38: 0 | C38: 0 | D38: 0 | E38: 0 | F38: 0 | G38: =SUM(B38:F38)
A39: =DATE(2025,12,1) | B39: 0 | C39: 0 | D39: 0 | E39: 0 | F39: 0 | G39: =SUM(B39:F39)
A42: Yearly Summary
...

Sheet OPEX_Projekcija_2026_2030
A1: OPEX_Projekcija_2026_2030
A2: Yellow = Base 2026 inputs | linked to inflation and scenario
A3: Category | B3: Base 2026 | C3: 2027 | D3: 2028 | E3: 2029 | F3: 2030 | G3: Inflation | H3: Scenario Mult
A4: Salaries | B4: 0 | C4: =B4*(1+ASSUMPTIONS!$B$10)*ASSUMPTIONS!$F$7 | D4: =C4*(1+ASSUMPTIONS!$B$10)*ASSUMPTIONS!$F$7 | E4: =D4*(1+ASSUMPTIONS!$B$10)*ASSUMPTIONS!$F$7*1.80 | F4: =E4*(1+ASSUMPTIONS!$B$10)*1.10 | G4: =ASSUMPTIONS!$B$10 | H4: =ASSUMPTIONS!$F$7
A5: Energy & Utilities | B5: 0 | C5: =B5*(1+ASSUMPTIONS!$B$10)*ASSUMPTIONS!$F$7 | D5: =C5*(1+ASSUMPTIONS!$B$10)*ASSUMPTIONS!$F$7 | E5: =D5*(1+ASSUMPTIONS!$B$10)*ASSUMPTIONS!$F$7*1.80 | F5: =E5*(1+ASSUMPTIONS!$B$10)*1.10 | G5: =ASSUMPTIONS!$B$10 | H5: =ASSUMPTIONS!$F$7
A6: Maintenance | B6: 0 | C6: =B6*(1+ASSUMPTIONS!$B$10)*ASSUMPTIONS!$F$7 | D6: =C6*(1+ASSUMPTIONS!$B$10)*ASSUMPTIONS!$F$7 | E6: =D6*(1+ASSUMPTIONS!$B$10)*ASSUMPTIONS!$F$7*1.80 | F6: =E6*(1+ASSUMPTIONS!$B$10)*1.10 | G6: =ASSUMPTIONS!$B$10 | H6: =ASSUMPTIONS!$F$7
A7: SG&A / Admin | B7: 0 | C7: =B7*(1+ASSUMPTIONS!$B$10)*ASSUMPTIONS!$F$7 | D7: =C7*(1+ASSUMPTIONS!$B$10)*ASSUMPTIONS!$F$7 | E7: =D7*(1+ASSUMPTIONS!$B$10)*ASSUMPTIONS!$F$7*1.80 | F7: =E7*(1+ASSUMPTIONS!$B$10)*1.10 | G7: =ASSUMPTIONS!$B$10 | H7: =ASSUMPTIONS!$F$7
A8: Insurance | B8: 0 | C8: =B8*(1+ASSUMPTIONS!$B$10)*ASSUMPTIONS!$F$7 | D8: =C8*(1+ASSUMPTIONS!$B$10)*ASSUMPTIONS!$F$7 | E8: =D8*(1+ASSUMPTIONS!$B$10)*ASSUMPTIONS!$F$7*1.80 | F8: =E8*(1+ASSUMPTIONS!$B$10)*1.10 | G8: =ASSUMPTIONS!$B$10 | H8: =ASSUMPTIONS!$F$7
A9: Logistics | B9: 0 | C9: =B9*(1+ASSUMPTIONS!$B$10)*ASSUMPTIONS!$F$7 | D9: =C9*(1+ASSUMPTIONS!$B$10)*ASSUMPTIONS!$F$7 | E9: =D9*(1+ASSUMPTIONS!$B$10)*ASSUMPTIONS!$F$7*1.80 | F9: =E9*(1+ASSUMPTIONS!$B$10)*1.10 | G9: =ASSUMPTIONS!$B$10 | H9: =ASSUMPTIONS!$F$7
A10: Other OPEX | B10: 0 | C10: =B10*(1+ASSUMPTIONS!$B$10)*ASSUMPTIONS!$F$7 | D10: =C10*(1+ASSUMPTIONS!$B$10)*ASSUMPTIONS!$F$7 | E10: =D10*(1+ASSUMPTIONS!$B$10)*ASSUMPTIONS!$F$7*1.80 | F10: =E10*(1+ASSUMPTIONS!$B$10)*1.10 | G10: =ASSUMPTIONS!$B$10 | H10: =ASSUMPTIONS!$F$7
A11: TOTAL | B11: =SUM(B4:B10) | C11: =SUM(C4:C10) | D11: =SUM(D4:D10) | E11: =SUM(E4:E10) | F11: =SUM(F4:F10)

Sheet Cashflow_BurnRate
A1: Cashflow_BurnRate
A2: Monthly burn and runway 2026-2027
A3: Starting Cash (EUR) | B3: 0
A5: Month | B5: CAPEX Out | C5: OPEX Out | D5: Total Burn | E5: Funding In | F5: Net Cash Flow | G5: Opening Cash | H5: Closing Cash
A6: =DATE(2026,1,1) | B6: =CAPEX_Projekcija_2026_2030!C$9/12*ASSUMPTIONS!$F$6 | C6: =OPEX_Projekcija_2026_2030!B$11/12 | D6: =B6+C6 | E6: 0 | F6: =E6-D6 | G6: =IF(ROW()=6,$B$3,H5) | H6: =G6+F6
A7: =DATE(2026,2,1) | B7: =CAPEX_Projekcija_2026_2030!C$9/12*ASSUMPTIONS!$F$6 | C7: =OPEX_Projekcija_2026_2030!B$11/12 | D7: =B7+C7 | E7: 0 | F7: =E7-D7 | G7: =IF(ROW()=6,$B$3,H5) | H7: =G7+F7
A8: =DATE(2026,3,1) | B8: =CAPEX_Projekcija_2026_2030!C$9/12*ASSUMPTIONS!$F$6 | C8: =OPEX_Projekcija_2026_2030!B$11/12 | D8: =B8+C8 | E8: 0 | F8: =E8-D8 | G8: =IF(ROW()=6,$B$3,H5) | H8: =G8+F8
A9: =DATE(2026,4,1) | B9: =CAPEX_Projekcija_2026_2030!C$9/12*ASSUMPTIONS!$F$6 | C9: =OPEX_Projekcija_2026_2030!B$11/12 | D9: =B9+C9 | E9: 0 | F9: =E9-D9 | G9: =IF(ROW()=6,$B$3,H5) | H9: =G9+F9
A10: =DATE(2026,5,1) | B10: =CAPEX_Projekcija_2026_2030!C$9/12*ASSUMPTIONS!$F$6 | C10: =OPEX_Projekcija_2026_2030!B$11/12 | D10: =B10+C10 | E10: 0 | F10: =E10-D10 | G10: =IF(ROW()=6,$B$3,H5) | H10: =G10+F10
A11: =DATE(2026,6,1) | B11: =CAPEX_Projekcija_2026_2030!C$9/12*ASSUMPTIONS!$F$6 | C11: =OPEX_Projekcija_2026_2030!B$11/12 | D11: =B11+C11 | E11: 0 | F11: =E11-D11 | G11: =IF(ROW()=6,$B$3,H5) | H11: =G11+F11
A12: =DATE(2026,7,1) | B12: =CAPEX_Projekcija_2026_2030!C$9/12*ASSUMPTIONS!$F$6 | C12: =OPEX_Projekcija_2026_2030!B$11/12 | D12: =B12+C12 | E12: 0 | F12: =E12-D12 | G12: =IF(ROW()=6,$B$3,H5) | H12: =G12+F12
A13: =DATE(2026,8,1) | B13: =CAPEX_Projekcija_2026_2030!C$9/12*ASSUMPTIONS!$F$6 | C13: =OPEX_Projekcija_2026_2030!B$11/12 | D13: =B13+C13 | E13: 0 | F13: =E13-D13 | G13: =IF(ROW()=6,$B$3,H5) | H13: =G13+F13
A14: =DATE(2026,9,1) | B14: =CAPEX_Projekcija_2026_2030!C$9/12*ASSUMPTIONS!$F$6 | C14: =OPEX_Projekcija_2026_2030!B$11/12 | D14: =B14+C14 | E14: 0 | F14: =E14-D14 | G14: =IF(ROW()=6,$B$3,H5) | H14: =G14+F14
A15: =DATE(2026,10,1) | B15: =CAPEX_Projekcija_2026_2030!C$9/12*ASSUMPTIONS!$F$6 | C15: =OPEX_Projekcija_2026_2030!B$11/12 | D15: =B15+C15 | E15: 0 | F15: =E15-D15 | G15: =IF(ROW()=6,$B$3,H5) | H15: =G15+F15
A16: =DATE(2026,11,1) | B16: =CAPEX_Projekcija_2026_2030!C$9/12*ASSUMPTIONS!$F$6 | C16: =OPEX_Projekcija_2026_2030!B$11/12 | D16: =B16+C16 | E16: 0 | F16: =E16-D16 | G16: =IF(ROW()=6,$B$3,H5) | H16: =G16+F16
A17: =DATE(2026,12,1) | B17: =CAPEX_Projekcija_2026_2030!C$9/12*ASSUMPTIONS!$F$6 | C17: =OPEX_Projekcija_2026_2030!B$11/12 | D17: =B17+C17 | E17: 0 | F17: =E17-D17 | G17: =IF(ROW()=6,$B$3,H5) | H17: =G17+F17
A18: =DATE(2027,1,1) | B18: =CAPEX_Projekcija_2026_2030!D$9/12*ASSUMPTIONS!$F$6 | C18: =OPEX_Projekcija_2026_2030!C$11/12 | D18: =B18+C18 | E18: 0 | F18: =E18-D18 | G18: =IF(ROW()=6,$B$3,H5) | H18: =G18+F18
A19: =DATE(2027,2,1) | B19: =CAPEX_Projekcija_2026_2030!D$9/12*ASSUMPTIONS!$F$6 | C19: =OPEX_Projekcija_2026_2030!C$11/12 | D19: =B19+C19 | E19: 0 | F19: =E19-D19 | G19: =IF(ROW()=6,$B$3,H5) | H19: =G19+F19
A20: =DATE(2027,3,1) | B20: =CAPEX_Projekcija_2026_2030!D$9/12*ASSUMPTIONS!$F$6 | C20: =OPEX_Projekcija_2026_2030!C$11/12 | D20: =B20+C20 | E20: 0 | F20: =E20-D20 | G20: =IF(ROW()=6,$B$3,H5) | H20: =G20+F20
A21: =DATE(2027,4,1) | B21: =CAPEX_Projekcija_2026_2030!D$9/12*ASSUMPTIONS!$F$6 | C21: =OPEX_Projekcija_2026_2030!C$11/12 | D21: =B21+C21 | E21: 0 | F21: =E21-D21 | G21: =IF(ROW()=6,$B$3,H5) | H21: =G21+F21
A22: =DATE(2027,5,1) | B22: =CAPEX_Projekcija_2026_2030!D$9/12*ASSUMPTIONS!$F$6 | C22: =OPEX_Projekcija_2026_2030!C$11/12 | D22: =B22+C22 | E22: 0 | F22: =E22-D22 | G22: =IF(ROW()=6,$B$3,H5) | H22: =G22+F22
A23: =DATE(2027,6,1) | B23: =CAPEX_Projekcija_2026_2030!D$9/12*ASSUMPTIONS!$F$6 | C23: =OPEX_Projekcija_2026_2030!C$11/12 | D23: =B23+C23 | E23: 0 | F23: =E23-D23 | G23: =IF(ROW()=6,$B$3,H5) | H23: =G23+F23
A24: =DATE(2027,7,1) | B24: =CAPEX_Projekcija_2026_2030!D$9/12*ASSUMPTIONS!$F$6 | C24: =OPEX_Projekcija_2026_2030!C$11/12 | D24: =B24+C24 | E24: 0 | F24: =E24-D24 | G24: =IF(ROW()=6,$B$3,H5) | H24: =G24+F24
A25: =DATE(2027,8,1) | B25: =CAPEX_Projekcija_2026_2030!D$9/12*ASSUMPTIONS!$F$6 | C25: =OPEX_Projekcija_2026_2030!C$11/12 | D25: =B25+C25 | E25: 0 | F25: =E25-D25 | G25: =IF(ROW()=6,$B$3,H5) | H25: =G25+F25
A26: =DATE(2027,9,1) | B26: =CAPEX_Projekcija_2026_2030!D$9/12*ASSUMPTIONS!$F$6 | C26: =OPEX_Projekcija_2026_2030!C$11/12 | D26: =B26+C26 | E26: 0 | F26: =E26-D26 | G26: =IF(ROW()=6,$B$3,H5) | H26: =G26+F26
A27: =DATE(2027,10,1) | B27: =CAPEX_Projekcija_2026_2030!D$9/12*ASSUMPTIONS!$F$6 | C27: =OPEX_Projekcija_2026_2030!C$11/12 | D27: =B27+C27 | E27: 0 | F27: =E27-D27 | G27: =IF(ROW()=6,$B$3,H5) | H27: =G27+F27
A28: =DATE(2027,11,1) | B28: =CAPEX_Projekcija_2026_2030!D$9/12*ASSUMPTIONS!$F$6 | C28: =OPEX_Projekcija_2026_2030!C$11/12 | D28: =B28+C28 | E28: 0 | F28: =E28-D28 | G28: =IF(ROW()=6,$B$3,H5) | H28: =G28+F28
A29: =DATE(2027,12,1) | B29: =CAPEX_Projekcija_2026_2030!D$9/12*ASSUMPTIONS!$F$6 | C29: =OPEX_Projekcija_2026_2030!C$11/12 | D29: =B29+C29 | E29: 0 | F29: =E29-D29 | G29: =IF(ROW()=6,$B$3,H5) | H29: =G29+F29
G31: Avg Burn | H31: =AVERAGE(D6:D29)
G32: Closing Cash | H32: =H29
G33: Runway (months) | H33: =IF(H31>0,H32/H31,"")

Sheet PDV_Refund_Tracker
A1: PDV_Refund_Tracker
A2: Refundable input VAT on CAPEX only
A3: Year | B3: CAPEX (EUR) | C3: Input VAT Paid | D3: VAT Refund (cash-in) | E3: Cumulative Refund | F3: Refund Lag (months) | G3: Notes
A4: 2026 | B4: =CAPEX_Projekcija_2026_2030!C$9*ASSUMPTIONS!$F$6 | C4: =B4*ASSUMPTIONS!$B$7 | D4: 0 | E4: =SUM($D$4:D4) | F4: 12
A5: 2027 | B5: =CAPEX_Projekcija_2026_2030!D$9*ASSUMPTIONS!$F$6 | C5: =B5*ASSUMPTIONS!$B$7 | D5: =C4*0.8 | E5: =SUM($D$4:D5) | F5: 12
A6: 2028 | B6: =CAPEX_Projekcija_2026_2030!E$9*ASSUMPTIONS!$F$6 | C6: =B6*ASSUMPTIONS!$B$7 | D6: =C5*0.8 + C4*0.2 | E6: =SUM($D$4:D6) | F6: 12
A7: 2029 | B7: =CAPEX_Projekcija_2026_2030!F$9*ASSUMPTIONS!$F$6 | C7: =B7*ASSUMPTIONS!$B$7 | D7: =C6*0.8 + C5*0.2 | E7: =SUM($D$4:D7) | F7: 12
A8: 2030 | B8: =CAPEX_Projekcija_2026_2030!G$9*ASSUMPTIONS!$F$6 | C8: =B8*ASSUMPTIONS!$B$7 | D8: =C7*0.8 + C6*0.2 | E8: =SUM($D$4:D8) | F8: 12

Sheet TRY_Hedge_Calc
A1: TRY_Hedge_Calc
A2: TRY exposure and hedge sensitivity
A3: Item | B3: Value | C3: Unit | D3: Formula / Link | E3: Impact Notes | F3: Input?
A4: Equipment CAPEX share of total | B4: 0.8 | C4: % | E4: Assumed % of CAPEX exposed to TRY | F4: Input
A5: Hedge ratio | B5: 0.8 | C5: % | E5: % hedged via EUR pricing / forward | F5: Input
A6: FX EUR/TRY (spot) | B6: =ASSUMPTIONS!$B$5 | C6: TRY/EUR | D6: =ASSUMPTIONS!$B$5 | E6: Driver | F6: Calc
A7: Total CAPEX (plan) | B7: =ASSUMPTIONS!$B$19 | C7: EUR | D7: =ASSUMPTIONS!$B$19 | E7: Target plan | F7: Calc
A8: Equipment CAPEX (EUR) | B8: =B4*B7 | C8: EUR | D8: =B4*B7 | E8: Exposed portion | F8: Calc
A9: Unhedged portion (EUR) | B9: =B8*(1-B5) | C9: EUR | D9: =B8*(1-B5) | E9: Residual exposure | F9: Calc
A10: TRY exposure (TRY) | B10: =B9*B6 | C10: TRY | D10: =B9*B6 | E10: Converted exposure | F10: Calc
A11: Sensitivity +10% TRY dep. | B11: =B9*0.10 | C11: EUR | D11: =B9*0.10 | E11: Approx EUR cost increase | F11: Calc

Sheet Full_Integrated_Model
A1: Full_Integrated_Model
A2: Simplified P&L + CF + DSCR (2026-2030)
A3: Year | B3: Revenue | C3: OPEX | D3: EBITDA | E3: CAPEX | F3: VAT Refund | G3: CFADS | H3: Interest | I3: Debt Service | J3: Equity CF | K3: DSCR | M3: Driver | N3: Value
A4: 2026 | B4: =N4*N5*N6*ASSUMPTIONS!$F$8 | C4: =OPEX_Projekcija_2026_2030!B$11 | D4: =B4-C4 | E4: =CAPEX_Projekcija_2026_2030!C$9*ASSUMPTIONS!$F$6 | F4: =PDV_Refund_Tracker!D4 | G4: =D4-E4+F4 | H4: =ASSUMPTIONS!$B$14*ASSUMPTIONS!$B$15 | I4: =IF(A4<YEAR(DATEVALUE(ASSUMPTIONS!$B$13))+ASSUMPTIONS!$B$17,H4,H4+ASSUMPTIONS!$B$14/MAX(1,ASSUMPTIONS!$B$16-ASSUMPTIONS!$B$17)) | J4: =G4-I4 | K4: =IF(I4>0,G4/I4,"") | M4: Capacity (tpy) | N4: 75000
A5: 2027 | B5: =N4*N5*N7*ASSUMPTIONS!$F$8 | C5: =OPEX_Projekcija_2026_2030!C$11 | D5: =B5-C5 | E5: =CAPEX_Projekcija_2026_2030!D$9*ASSUMPTIONS!$F$6 | F5: =PDV_Refund_Tracker!D5 | G5: =D5-E5+F5 | H5: =ASSUMPTIONS!$B$14*ASSUMPTIONS!$B$15 | I5: =IF(A5<YEAR(DATEVALUE(ASSUMPTIONS!$B$13))+ASSUMPTIONS!$B$17,H5,H5+ASSUMPTIONS!$B$14/MAX(1,ASSUMPTIONS!$B$16-ASSUMPTIONS!$B$17)) | J5: =G5-I5 | K5: =IF(I5>0,G5/I5,"") | M5: Price €/t | N5: 1850
A6: 2028 | B6: =N4*N5*N8*ASSUMPTIONS!$F$8 | C6: =OPEX_Projekcija_2026_2030!D$11 | D6: =B6-C6 | E6: =CAPEX_Projekcija_2026_2030!E$9*ASSUMPTIONS!$F$6 | F6: =PDV_Refund_Tracker!D6 | G6: =D6-E6+F6 | H6: =ASSUMPTIONS!$B$14*ASSUMPTIONS!$B$15 | I6: =IF(A6<YEAR(DATEVALUE(ASSUMPTIONS!$B$13))+ASSUMPTIONS!$B$17,H6,H6+ASSUMPTIONS!$B$14/MAX(1,ASSUMPTIONS!$B$16-ASSUMPTIONS!$B$17)) | J6: =G6-I6 | K6: =IF(I6>0,G6/I6,"") | M6: Ramp 2026 | N6: 0
A7: 2029 | B7: =N4*N5*N9*ASSUMPTIONS!$F$8 | C7: =OPEX_Projekcija_2026_2030!E$11 | D7: =B7-C7 | E7: =CAPEX_Projekcija_2026_2030!F$9*ASSUMPTIONS!$F$6 | F7: =PDV_Refund_Tracker!D7 | G7: =D7-E7+F7 | H7: =ASSUMPTIONS!$B$14*ASSUMPTIONS!$B$15 | I7: =IF(A7<YEAR(DATEVALUE(ASSUMPTIONS!$B$13))+ASSUMPTIONS!$B$17,H7,H7+ASSUMPTIONS!$B$14/MAX(1,ASSUMPTIONS!$B$16-ASSUMPTIONS!$B$17)) | J7: =G7-I7 | K7: =IF(I7>0,G7/I7,"") | M7: Ramp 2027 | N7: 0
A8: 2030 | B8: =N4*N5*N10*ASSUMPTIONS!$F$8 | C8: =OPEX_Projekcija_2026_2030!F$11 | D8: =B8-C8 | E8: =CAPEX_Projekcija_2026_2030!G$9*ASSUMPTIONS!$F$6 | F8: =PDV_Refund_Tracker!D8 | G8: =D8-E8+F8 | H8: =ASSUMPTIONS!$B$14*ASSUMPTIONS!$B$15 | I8: =IF(A8<YEAR(DATEVALUE(ASSUMPTIONS!$B$13))+ASSUMPTIONS!$B$17,H8,H8+ASSUMPTIONS!$B$14/MAX(1,ASSUMPTIONS!$B$16-ASSUMPTIONS!$B$17)) | J8: =G8-I8 | K8: =IF(I8>0,G8/I8,"") | M8: Ramp 2028 | N8: 0
M9: Ramp 2029 | N9: 0.4
M10: Ramp 2030 | N10: 0.7

Sheet Summary_Dashboard
A1: Summary_Dashboard
A2: Management snapshot and visuals
A3: KPI | B3: Value | C3: Unit | D3: Source | F3: Year | G3: CAPEX | H3: OPEX
A4: Total historical CAPEX (to 2025) | B4: =CAPEX_Historija!I9 | C4: EUR | D4: CAPEX_Historija | F4: 2026 | G4: =CAPEX_Projekcija_2026_2030!C$9 | H4: =OPEX_Projekcija_2026_2030!B$11
A5: Cumulative fixed assets 2025 | B5: =INDEX(INPUT_Bilansi!$D:$D,MATCH(2,INPUT_Bilansi!$C:$C,0)) | C5: EUR | D5: INPUT_Bilansi | F5: 2027 | G5: =CAPEX_Projekcija_2026_2030!D$9 | H5: =OPEX_Projekcija_2026_2030!C$11
A6: % CAPEX in advances (2025) | B6: =IF(CAPEX_Historija!F9>0,CAPEX_Historija!F6/CAPEX_Historija!F9,0) | C6: % | D6: CAPEX_Historija | F6: 2028 | G6: =CAPEX_Projekcija_2026_2030!E$9 | H6: =OPEX_Projekcija_2026_2030!D$11
A7: Projected CAPEX 2026-2030 | B7: =CAPEX_Projekcija_2026_2030!H9 | C7: EUR | D7: CAPEX projection | F7: 2029 | G7: =CAPEX_Projekcija_2026_2030!F$9 | H7: =OPEX_Projekcija_2026_2030!E$11
A8: Projected OPEX 2026 | B8: =OPEX_Projekcija_2026_2030!B11 | C8: EUR | D8: OPEX projection | F8: 2030 | G8: =CAPEX_Projekcija_2026_2030!G$9 | H8: =OPEX_Projekcija_2026_2030!F$11
A9: Average monthly burn | B9: =AVERAGE(Cashflow_BurnRate!D6:D29) | C9: EUR/month | D9: Cashflow_BurnRate
A10: Runway (months) | B10: =Cashflow_BurnRate!H33 | C10: x | D10: Cashflow_BurnRate
A11: Cumulative VAT refund | B11: =PDV_Refund_Tracker!E8 | C11: EUR | D11: PDV_Refund_Tracker
A12: Min DSCR 2029-2030 | B12: =MIN(Full_Integrated_Model!K7:K8) | C12: x | D12: Integrated Model

Sheet Controls_&_Checks
A1: Controls_&_Checks
A2: All checks should be OK before sharing
A3: Check | B3: Result | C3: Status | D3: Threshold | E3: Fix Instruction | F3: Link
A4: Historical CAPEX total > 0 | B4: =CAPEX_Historija!I9 | C4: =IF(B4>0,"OK","FAIL") | D4: > 0 | E4: Populate INPUT_Bilansi correctly | F4: CAPEX_Historija
A5: Projected CAPEX vs target | B5: =CAPEX_Projekcija_2026_2030!H9-ASSUMPTIONS!$B$19 | C5: =IF(ABS(B5)<=1,"OK","FAIL") | D5: 0 +/-1 | E5: Align CAPEX plan to target | F5: CAPEX_Projekcija_2026_2030
A6: No blanks in OPEX 2026 | B6: =COUNTBLANK(OPEX_Projekcija_2026_2030!B4:B10) | C6: =IF(B6=0,"OK","FAIL") | D6: 0 | E6: Fill yellow OPEX cells | F6: OPEX_Projekcija_2026_2030
A7: VAT refundable set | B7: =ASSUMPTIONS!$B$7 | C7: =IF(AND(B7>0,B7<=0.21),"OK","FAIL") | D7: 0-21% | E7: Check VAT_CAPEX_REFUNDABLE | F7: ASSUMPTIONS
A8: Min DSCR >= 1.20 | B8: =MIN(Full_Integrated_Model!K7:K8) | C8: =IF(B8>=1.2,"OK","FAIL") | D8: >=1.20x | E8: Adjust debt / OPEX / CAPEX | F8: Full_Integrated_Model
A9: Runway > 6 months | B9: =Cashflow_BurnRate!H33 | C9: =IF(B9>6,"OK","FAIL") | D9: > 6 | E9: Increase funding or reduce burn | F9: Cashflow_BurnRate
A10: Advances share < 50% | B10: =IF(CAPEX_Historija!F9>0,CAPEX_Historija!F6/CAPEX_Historija!F9,0) | C10: =IF(B10<0.5,"OK","WARN") | D10: < 50% | E10: Convert advances post-COD | F10: CAPEX_Historija

Sheet Instructions
A1: Instructions
A2: Quick setup in 5 steps
A3: Step | B3: Instruction
A4: 1. Populate INPUT_Bilansi | B4: Paste / verify 2025 / 2024 / 2023 historical bilans rows.
A5: 2. Review CAPEX_Historija | B5: Historical CAPEX balances and changes update automatically.
A6: 3. Fill future CAPEX/OPEX | B6: Complete yellow cells in CAPEX_Projekcija and OPEX_Projekcija.
A7: 4. Update ASSUMPTIONS | B7: Set scenario, inflation, VAT, FX, grant, loan and target CAPEX.
A8: 5. Check Controls and Dashboard | B8: All checks should be OK before sharing with banks or investors.
