Workbook

Sheet 00_COVER
A2: ARS METAL INDUSTRIES – FULL V3.0 PROJECT FINANCE MODEL
B4: Model Version | C4: v3.1
B5: Prepared For | C5: Investor / Lender / IC review
B6: Project | C6: Industrial transformer tank manufacturing facility
B7: Location | C7: Tuzi, Montenegro
B8: Currency | C8: EUR
B9: Date | C9: 2026-03-23
B10: Purpose | C10: Integrated project finance model covering assumptions, scenarios, operating model, funding and debt service.
B13: Confidential

Sheet 01_INDEX_NAVIGATION
A2: INDEX / NAVIGATION
A4: No. | B4: Sheet | C4: Link | D4: Description
A5: 1 | B5: 02_ASSUMPTIONS_MASTER | C5: =HYPERLINK("#'02_ASSUMPTIONS_MASTER'!A1","Open") | D5: Central assumptions bank
A6: 2 | B6: 03_SCENARIO_CONTROL | C6: =HYPERLINK("#'03_SCENARIO_CONTROL'!A1","Open") | D6: Scenario selector and overrides
A7: 3 | B7: 10_PRODUCTION | C7: =HYPERLINK("#'10_PRODUCTION'!A1","Open") | D7: Capacity and utilization
A8: 4 | B8: 20_REVENUE | C8: =HYPERLINK("#'20_REVENUE'!A1","Open") | D8: Prices, volume, sales
A9: 5 | B9: 30_COGS | C9: =HYPERLINK("#'30_COGS'!A1","Open") | D9: Variable manufacturing costs
A10: 6 | B10: 40_OPEX | C10: =HYPERLINK("#'40_OPEX'!A1","Open") | D10: Fixed operating costs
A11: 7 | B11: 50_CAPEX | C11: =HYPERLINK("#'50_CAPEX'!A1","Open") | D11: Construction and equipment phasing
A12: 8 | B12: 60_WORKING_CAPITAL | C12: =HYPERLINK("#'60_WORKING_CAPITAL'!A1","Open") | D12: Inventory / AR / AP
A13: 9 | B13: 70_FINANCING | C13: =HYPERLINK("#'70_FINANCING'!A1","Open") | D13: Sources and debt schedule
A14: 10 | B14: 80_CASHFLOW | C14: =HYPERLINK("#'80_CASHFLOW'!A1","Open") | D14: Integrated CFADS and DSCR
A15: 11 | B15: 90_DASHBOARD_IC | C15: =HYPERLINK("#'90_DASHBOARD_IC'!A1","Open") | D15: IC dashboard
A16: 12 | B16: 99_MODEL_CHECKS | C16: =HYPERLINK("#'99_MODEL_CHECKS'!A1","Open") | D16: Audit checks and flags

Sheet 02_ASSUMPTIONS_MASTER
K1: =HYPERLINK("#'01_INDEX_NAVIGATION'!A1","Back to Index")
A2: ASSUMPTIONS MASTER
A4: Block | B4: Code | C4: Assumption Name | D4: Unit | E4: Base Case | F4: Downside | G4: Upside | H4: Active | I4: Source | J4: Impact Area | K4: Notes
A5: A | B5: A1 | C5: EU inflation | D5: % | E5: 0.025 | F5: 0.035 | G5: 0.02 | H5: =CHOOSE('03_SCENARIO_CONTROL'!$B$6,F5,E5,G5) | I5: Macro | J5: Long-term CPI
A6: A | B6: A2 | C6: Montenegro inflation | D6: % | E6: 0.03 | F6: 0.045 | G6: 0.025 | H6: =CHOOSE('03_SCENARIO_CONTROL'!$B$6,F6,E6,G6) | I6: Macro | J6: Domestic CPI
A7: A | B7: A3 | C7: Reference debt interest rate | D7: % | E7: 0.045 | F7: 0.06 | G7: 0.038 | H7: =CHOOSE('03_SCENARIO_CONTROL'!$B$6,F7,E7,G7) | I7: Financing | J7: All-in rate
A8: A | B8: A4 | C8: Industrial electricity price | D8: EUR/MWh | E8: 120 | F8: 160 | G8: 95 | H8: =CHOOSE('03_SCENARIO_CONTROL'!$B$6,F8,E8,G8) | I8: COGS/OPEX | J8: Gross tariff
A9: A | B9: A5 | C9: Steel price | D9: EUR/t | E9: 850 | F9: 1050 | G9: 760 | H9: =CHOOSE('03_SCENARIO_CONTROL'!$B$6,F9,E9,G9) | I9: COGS | J9: Raw material
A10: A | B10: A6 | C10: Corporate tax rate | D10: % | E10: 0.09 | F10: 0.12 | G10: 0.09 | H10: =CHOOSE('03_SCENARIO_CONTROL'!$B$6,F10,E10,G10) | I10: P&L | J10: Illustrative
A11: B | B11: B1 | C11: Design annual capacity | D11: units | E11: 1200 | F11: 1000 | G11: 1300 | H11: =CHOOSE('03_SCENARIO_CONTROL'!$B$6,F11,E11,G11) | I11: Production | J11: Nameplate
A12: B | B12: B2 | C12: Utilization Y1 | D12: % | E12: 0.55 | F12: 0.45 | G12: 0.65 | H12: =CHOOSE('03_SCENARIO_CONTROL'!$B$6,F12,E12,G12) | I12: Production
A13: B | B13: B3 | C13: Utilization Y2 | D13: % | E13: 0.7 | F13: 0.58 | G13: 0.78 | H13: =CHOOSE('03_SCENARIO_CONTROL'!$B$6,F13,E13,G13) | I13: Production
A14: B | B14: B4 | C14: Utilization Y3 | D14: % | E14: 0.82 | F14: 0.68 | G14: 0.9 | H14: =CHOOSE('03_SCENARIO_CONTROL'!$B$6,F14,E14,G14) | I14: Production
A15: B | B15: B5 | C15: Utilization Y4+ | D15: % | E15: 0.88 | F15: 0.75 | G15: 0.95 | H15: =CHOOSE('03_SCENARIO_CONTROL'!$B$6,F15,E15,G15) | I15: Production
A16: B | B16: B6 | C16: Energy intensity | D16: MWh/unit | E16: 0.42 | F16: 0.48 | G16: 0.38 | H16: =CHOOSE('03_SCENARIO_CONTROL'!$B$6,F16,E16,G16) | I16: COGS
A17: B | B17: B7 | C17: Direct labour hours per unit | D17: hours | E17: 18 | F17: 22 | G17: 16 | H17: =CHOOSE('03_SCENARIO_CONTROL'!$B$6,F17,E17,G17) | I17: COGS
A18: C | B18: C1 | C18: Average selling price Y1 | D18: EUR/unit | E18: 17500 | F18: 16000 | G18: 18500 | H18: =CHOOSE('03_SCENARIO_CONTROL'!$B$6,F18,E18,G18) | I18: Revenue
A19: C | B19: C2 | C19: Annual price escalation | D19: % | E19: 0.02 | F19: 0.01 | G19: 0.03 | H19: =CHOOSE('03_SCENARIO_CONTROL'!$B$6,F19,E19,G19) | I19: Revenue
A20: C | B20: C3 | C20: Service revenue share | D20: % | E20: 0.06 | F20: 0.04 | G20: 0.08 | H20: =CHOOSE('03_SCENARIO_CONTROL'!$B$6,F20,E20,G20) | I20: Revenue | J20: Aftermarket
A21: D | B21: D1 | C21: Steel consumption per unit | D21: t/unit | E21: 3.2 | F21: 3.4 | G21: 3 | H21: =CHOOSE('03_SCENARIO_CONTROL'!$B$6,F21,E21,G21) | I21: COGS
A22: D | B22: D2 | C22: Other materials per unit | D22: EUR/unit | E22: 2200 | F22: 2600 | G22: 2000 | H22: =CHOOSE('03_SCENARIO_CONTROL'!$B$6,F22,E22,G22) | I22: COGS
A23: D | B23: D3 | C23: Direct labour hourly cost | D23: EUR/hour | E23: 9.5 | F23: 11 | G23: 8.5 | H23: =CHOOSE('03_SCENARIO_CONTROL'!$B$6,F23,E23,G23) | I23: COGS
A24: D | B24: D4 | C24: Logistics cost as % of sales | D24: % | E24: 0.03 | F24: 0.045 | G24: 0.025 | H24: =CHOOSE('03_SCENARIO_CONTROL'!$B$6,F24,E24,G24) | I24: COGS
A25: D | B25: D5 | C25: Variable overhead as % of sales | D25: % | E25: 0.015 | F25: 0.022 | G25: 0.012 | H25: =CHOOSE('03_SCENARIO_CONTROL'!$B$6,F25,E25,G25) | I25: COGS
A26: E | B26: E1 | C26: Headcount Y1 | D26: FTE | E26: 95 | F26: 105 | G26: 90 | H26: =CHOOSE('03_SCENARIO_CONTROL'!$B$6,F26,E26,G26) | I26: OPEX
A27: E | B27: E2 | C27: Headcount Y4+ | D27: FTE | E27: 120 | F27: 135 | G27: 115 | H27: =CHOOSE('03_SCENARIO_CONTROL'!$B$6,F27,E27,G27) | I27: OPEX
A28: E | B28: E3 | C28: Average annual salary | D28: EUR/FTE | E28: 16800 | F28: 18200 | G28: 16000 | H28: =CHOOSE('03_SCENARIO_CONTROL'!$B$6,F28,E28,G28) | I28: OPEX
A29: E | B29: E4 | C29: Admin cost as % of sales | D29: % | E29: 0.03 | F29: 0.035 | G29: 0.025 | H29: =CHOOSE('03_SCENARIO_CONTROL'!$B$6,F29,E29,G29) | I29: OPEX
A30: E | B30: E5 | C30: Maintenance as % of gross PP&E | D30: % | E30: 0.03 | F30: 0.04 | G30: 0.025 | H30: =CHOOSE('03_SCENARIO_CONTROL'!$B$6,F30,E30,G30) | I30: OPEX
A31: E | B31: E6 | C31: Insurance as % of gross PP&E | D31: % | E31: 0.005 | F31: 0.007 | G31: 0.004 | H31: =CHOOSE('03_SCENARIO_CONTROL'!$B$6,F31,E31,G31) | I31: OPEX
A32: E | B32: E7 | C32: Other fixed OPEX | D32: EUR/year | E32: 350000 | F32: 450000 | G32: 300000 | H32: =CHOOSE('03_SCENARIO_CONTROL'!$B$6,F32,E32,G32) | I32: OPEX
... A37: F | B37: F5 | C37: Pre-operating and permits | D37: EUR | E37: 900000 | F37: 1100000 | G37: 800000 | H37: =CHOOSE('03_SCENARIO_CONTROL'!$B$6,F37,E37,G37) | I37: CAPEX
A38: F | B38: F6 | C38: Contingency | D38: % | E38: 0.1 | F38: 0.14 | G38: 0.08 | H38: =CHOOSE('03_SCENARIO_CONTROL'!$B$6,F38,E38,G38) | I38: CAPEX | J38: of base capex
A39: G | B39: G1 | C39: Inventory days | D39: days | E39: 60 | F39: 75 | G39: 50 | H39: =CHOOSE('03_SCENARIO_CONTROL'!$B$6,F39,E39,G39) | I39: Working Capital
A40: G | B40: G2 | C40: Receivables days | D40: days | E40: 45 | F40: 60 | G40: 35 | H40: =CHOOSE('03_SCENARIO_CONTROL'!$B$6,F40,E40,G40) | I40: Working Capital
A41: G | B41: G3 | C41: Payables days | D41: days | E41: 40 | F41: 30 | G41: 50 | H41: =CHOOSE('03_SCENARIO_CONTROL'!$B$6,F41,E41,G41) | I41: Working Capital
A42: H | B42: H1 | C42: Senior debt share | D42: % | E42: 0.6 | F42: 0.5 | G42: 0.65 | H42: =CHOOSE('03_SCENARIO_CONTROL'!$B$6,F42,E42,G42) | I42: Financing
A43: H | B43: H2 | C43: Equity share | D43: % | E43: 0.25 | F43: 0.35 | G43: 0.2 | H43: =CHOOSE('03_SCENARIO_CONTROL'!$B$6,F43,E43,G43) | I43: Financing
A44: H | B44: H3 | C44: Grant share | D44: % | E44: 0.15 | F44: 0.15 | G44: 0.15 | H44: =CHOOSE('03_SCENARIO_CONTROL'!$B$6,F44,E44,G44) | I44: Financing
A45: H | B45: H4 | C45: Loan tenor | D45: years | E45: 10 | F45: 8 | G45: 12 | H45: =CHOOSE('03_SCENARIO_CONTROL'!$B$6,F45,E45,G45) | I45: Financing
...

Sheet 03_SCENARIO_CONTROL
K1: =HYPERLINK("#'01_INDEX_NAVIGATION'!A1","Back to Index")
A2: SCENARIO CONTROL PANEL
A4: Parameter | B4: Value | C4: Unit | D4: Comment | E4: Logic
A5: Scenario Selector | B5: Base | C5: text | D5: Dropdown control
A6: Scenario Index | B6: =MATCH(B5,{"Downside","Base","Upside"},0) | C6: index | D6: 1=Downside 2=Base 3=Upside | E6: MATCH
A7: Stress Override | B7: 0.0% | C7: % | D7: Optional manual overlay | E7: Manual
A8: Construction Delay Override | B8: 0 | C8: months | D8: Optional manual override | E8: Manual

Sheet 10_PRODUCTION
K1: =HYPERLINK("#'01_INDEX_NAVIGATION'!A1","Back to Index")
A2: PRODUCTION MODEL
A4: Metric | B4: 2026 | C4: 2027 | D4: 2028 | E4: 2029 | F4: 2030 | G4: 2031 | H4: 2032 | I4: 2033 | J4: 2034 | K4: 2035
A5: Design capacity (units) | B5: ='02_ASSUMPTIONS_MASTER'!$H$11 | C5: ='02_ASSUMPTIONS_MASTER'!$H$11 | D5: ='02_ASSUMPTIONS_MASTER'!$H$11 | E5: ='02_ASSUMPTIONS_MASTER'!$H$11 | F5: ='02_ASSUMPTIONS_MASTER'!$H$11 | G5: ='02_ASSUMPTIONS_MASTER'!$H$11 | H5: ='02_ASSUMPTIONS_MASTER'!$H$11 | I5: ='02_ASSUMPTIONS_MASTER'!$H$11 | ... K5: ='02_ASSUMPTIONS_MASTER'!$H$11
A6: Utilization | B6: 0 | C6: ='02_ASSUMPTIONS_MASTER'!$H$12*(1+'02_ASSUMPTIONS_MASTER'!$H$48) | D6: ='02_ASSUMPTIONS_MASTER'!$H$13*(1+'02_ASSUMPTIONS_MASTER'!$H$48) | E6: ='02_ASSUMPTIONS_MASTER'!$H$14*(1+'02_ASSUMPTIONS_MASTER'!$H$48) | F6: ='02_ASSUMPTIONS_MASTER'!$H$15*(1+'02_ASSUMPTIONS_MASTER'!$H$48) | G6: ='02_ASSUMPTIONS_MASTER'!$H$15*(1+'02_ASSUMPTIONS_MASTER'!$H$48) | H6: ='02_ASSUMPTIONS_MASTER'!$H$15*(1+'02_ASSUMPTIONS_MASTER'!$H$48) | I6: ='02_ASSUMPTIONS_MASTER'!$H$15*(1+'02_ASSUMPTIONS_MASTER'!$H$48) | J6: ='02_ASSUMPTIONS_MASTER'!$H$15*(1+'02_ASSUMPTIONS_MASTER'!$H$48) | K6: ='02_ASSUMPTIONS_MASTER'!$H$15*(1+'02_ASSUMPTIONS_MASTER'!$H$48)
A7: Units produced | B7: =B5*B6 | C7: =C5*C6 | D7: =D5*D6 | E7: =E5*E6 | F7: =F5*F6 | G7: =G5*G6 | H7: =H5*H6 | I7: =I5*I6 | ... K7: =K5*K6
A8: Units sold | B8: =B7 | C8: =C7 | D8: =D7 | E8: =E7 | F8: =F7 | G8: =G7 | H8: =H7 | I8: =I7 | ... K8: =K7

Sheet 20_REVENUE
K1: =HYPERLINK("#'01_INDEX_NAVIGATION'!A1","Back to Index")
A2: REVENUE MODEL
A4: Metric | B4: 2026 | C4: 2027 | D4: 2028 | E4: 2029 | F4: 2030 | G4: 2031 | H4: 2032 | I4: 2033 | J4: 2034 | K4: 2035
A5: Units sold | B5: ='10_PRODUCTION'!B8 | C5: ='10_PRODUCTION'!C8 | D5: ='10_PRODUCTION'!D8 | E5: ='10_PRODUCTION'!E8 | F5: ='10_PRODUCTION'!F8 | G5: ='10_PRODUCTION'!G8 | H5: ='10_PRODUCTION'!H8 | I5: ='10_PRODUCTION'!I8 | ... K5: ='10_PRODUCTION'!K8
A6: Average selling price | B6: 0 | C6: ='02_ASSUMPTIONS_MASTER'!$H$18*(1+'02_ASSUMPTIONS_MASTER'!$H$49) | D6: =C6*(1+'02_ASSUMPTIONS_MASTER'!$H$19) | E6: =D6*(1+'02_ASSUMPTIONS_MASTER'!$H$19) | F6: =E6*(1+'02_ASSUMPTIONS_MASTER'!$H$19) | G6: =F6*(1+'02_ASSUMPTIONS_MASTER'!$H$19) | H6: =G6*(1+'02_ASSUMPTIONS_MASTER'!$H$19) | I6: =H6*(1+'02_ASSUMPTIONS_MASTER'!$H$19) | J6: =I6*(1+'02_ASSUMPTIONS_MASTER'!$H$19) | K6: =J6*(1+'02_ASSUMPTIONS_MASTER'!$H$19)
A7: Product revenue | B7: =B5*B6 | C7: =C5*C6 | D7: =D5*D6 | E7: =E5*E6 | F7: =F5*F6 | G7: =G5*G6 | H7: =H5*H6 | I7: =I5*I6 | ... K7: =K5*K6
A8: Service revenue | B8: =B7*'02_ASSUMPTIONS_MASTER'!$H$20 | C8: =C7*'02_ASSUMPTIONS_MASTER'!$H$20 | D8: =D7*'02_ASSUMPTIONS_MASTER'!$H$20 | E8: =E7*'02_ASSUMPTIONS_MASTER'!$H$20 | F8: =F7*'02_ASSUMPTIONS_MASTER'!$H$20 | G8: =G7*'02_ASSUMPTIONS_MASTER'!$H$20 | H8: =H7*'02_ASSUMPTIONS_MASTER'!$H$20 | I8: =I7*'02_ASSUMPTIONS_MASTER'!$H$20 | ... K8: =K7*'02_ASSUMPTIONS_MASTER'!$H$20
A9: Total revenue | B9: =B7+B8 | C9: =C7+C8 | D9: =D7+D8 | E9: =E7+E8 | F9: =F7+F8 | G9: =G7+G8 | H9: =H7+H8 | I9: =I7+I8 | ... K9: =K7+K8

Sheet 30_COGS
K1: =HYPERLINK("#'01_INDEX_NAVIGATION'!A1","Back to Index")
A2: COGS MODEL
A4: Metric | B4: 2026 | C4: 2027 | D4: 2028 | E4: 2029 | F4: 2030 | G4: 2031 | H4: 2032 | I4: 2033 | J4: 2034 | K4: 2035
A5: Units produced | B5: ='10_PRODUCTION'!B7 | C5: ='10_PRODUCTION'!C7 | D5: ='10_PRODUCTION'!D7 | E5: ='10_PRODUCTION'!E7 | F5: ='10_PRODUCTION'!F7 | G5: ='10_PRODUCTION'!G7 | H5: ='10_PRODUCTION'!H7 | I5: ='10_PRODUCTION'!I7 | ... K5: ='10_PRODUCTION'!K7
A6: Steel cost per unit | B6: ='02_ASSUMPTIONS_MASTER'!$H$21*'02_ASSUMPTIONS_MASTER'!$H$9*(1+'02_ASSUMPTIONS_MASTER'!$H$50) | C6: ='02_ASSUMPTIONS_MASTER'!$H$21*'02_ASSUMPTIONS_MASTER'!$H$9*(1+'02_ASSUMPTIONS_MASTER'!$H$50) | D6: ='02_ASSUMPTIONS_MASTER'!$H$21*'02_ASSUMPTIONS_MASTER'!$H$9*(1+'02_ASSUMPTIONS_MASTER'!$H$50) | E6: ='02_ASSUMPTIONS_MASTER'!$H$21*'02_ASSUMPTIONS_MASTER'!$H$9*(1+'02_ASSUMPTIONS_MASTER'!$H$50) | F6: ='02_ASSUMPTIONS_MASTER'!$H$21*'02_ASSUMPTIONS_MASTER'!$H$9*(1+'02_ASSUMPTIONS_MASTER'!$H$50) | G6: ='02_ASSUMPTIONS_MASTER'!$H$21*'02_ASSUMPTIONS_MASTER'!$H$9*(1+'02_ASSUMPTIONS_MASTER'!$H$50) | H6: ='02_ASSUMPTIONS_MASTER'!$H$21*'02_ASSUMPTIONS_MASTER'!$H$9*(1+'02_ASSUMPTIONS_MASTER'!$H$50) | I6: ='02_ASSUMPTIONS_MASTER'!$H$21*'02_ASSUMPTIONS_MASTER'!$H$9*(1+'02_ASSUMPTIONS_MASTER'!$H$50) | ... K6: ='02_ASSUMPTIONS_MASTER'!$H$21*'02_ASSUMPTIONS_MASTER'!$H$9*(1+'02_ASSUMPTIONS_MASTER'!$H$50)
A7: Other materials per unit | B7: ='02_ASSUMPTIONS_MASTER'!$H$22*(1+'02_ASSUMPTIONS_MASTER'!$H$50) | C7: ='02_ASSUMPTIONS_MASTER'!$H$22*(1+'02_ASSUMPTIONS_MASTER'!$H$50) | D7: ='02_ASSUMPTIONS_MASTER'!$H$22*(1+'02_ASSUMPTIONS_MASTER'!$H$50) | E7: ='02_ASSUMPTIONS_MASTER'!$H$22*(1+'02_ASSUMPTIONS_MASTER'!$H$50) | F7: ='02_ASSUMPTIONS_MASTER'!$H$22*(1+'02_ASSUMPTIONS_MASTER'!$H$50) | G7: ='02_ASSUMPTIONS_MASTER'!$H$22*(1+'02_ASSUMPTIONS_MASTER'!$H$50) | H7: ='02_ASSUMPTIONS_MASTER'!$H$22*(1+'02_ASSUMPTIONS_MASTER'!$H$50) | I7: ='02_ASSUMPTIONS_MASTER'!$H$22*(1+'02_ASSUMPTIONS_MASTER'!$H$50) | ... K7: ='02_ASSUMPTIONS_MASTER'!$H$22*(1+'02_ASSUMPTIONS_MASTER'!$H$50)
A8: Direct labour per unit | B8: ='02_ASSUMPTIONS_MASTER'!$H$17*'02_ASSUMPTIONS_MASTER'!$H$23*(1+'02_ASSUMPTIONS_MASTER'!$H$50) | C8: ='02_ASSUMPTIONS_MASTER'!$H$17*'02_ASSUMPTIONS_MASTER'!$H$23*(1+'02_ASSUMPTIONS_MASTER'!$H$50) | D8: ='02_ASSUMPTIONS_MASTER'!$H$17*'02_ASSUMPTIONS_MASTER'!$H$23*(1+'02_ASSUMPTIONS_MASTER'!$H$50) | E8: ='02_ASSUMPTIONS_MASTER'!$H$17*'02_ASSUMPTIONS_MASTER'!$H$23*(1+'02_ASSUMPTIONS_MASTER'!$H$50) | F8: ='02_ASSUMPTIONS_MASTER'!$H$17*'02_ASSUMPTIONS_MASTER'!$H$23*(1+'02_ASSUMPTIONS_MASTER'!$H$50) | G8: ='02_ASSUMPTIONS_MASTER'!$H$17*'02_ASSUMPTIONS_MASTER'!$H$23*(1+'02_ASSUMPTIONS_MASTER'!$H$50) | H8: ='02_ASSUMPTIONS_MASTER'!$H$17*'02_ASSUMPTIONS_MASTER'!$H$23*(1+'02_ASSUMPTIONS_MASTER'!$H$50) | I8: ='02_ASSUMPTIONS_MASTER'!$H$17*'02_ASSUMPTIONS_MASTER'!$H$23*(1+'02_ASSUMPTIONS_MASTER'!$H$50) | ... K8: ='02_ASSUMPTIONS_MASTER'!$H$17*'02_ASSUMPTIONS_MASTER'!$H$23*(1+'02_ASSUMPTIONS_MASTER'!$H$50)
A9: Energy cost per unit | B9: ='02_ASSUMPTIONS_MASTER'!$H$16*'02_ASSUMPTIONS_MASTER'!$H$8*(1+'02_ASSUMPTIONS_MASTER'!$H$50) | C9: ='02_ASSUMPTIONS_MASTER'!$H$16*'02_ASSUMPTIONS_MASTER'!$H$8*(1+'02_ASSUMPTIONS_MASTER'!$H$50) | D9: ='02_ASSUMPTIONS_MASTER'!$H$16*'02_ASSUMPTIONS_MASTER'!$H$8*(1+'02_ASSUMPTIONS_MASTER'!$H$50) | E9: ='02_ASSUMPTIONS_MASTER'!$H$16*'02_ASSUMPTIONS_MASTER'!$H$8*(1+'02_ASSUMPTIONS_MASTER'!$H$50) | F9: ='02_ASSUMPTIONS_MASTER'!$H$16*'02_ASSUMPTIONS_MASTER'!$H$8*(1+'02_ASSUMPTIONS_MASTER'!$H$50) | G9: ='02_ASSUMPTIONS_MASTER'!$H$16*'02_ASSUMPTIONS_MASTER'!$H$8*(1+'02_ASSUMPTIONS_MASTER'!$H$50) | H9: ='02_ASSUMPTIONS_MASTER'!$H$16*'02_ASSUMPTIONS_MASTER'!$H$8*(1+'02_ASSUMPTIONS_MASTER'!$H$50) | I9: ='02_ASSUMPTIONS_MASTER'!$H$16*'02_ASSUMPTIONS_MASTER'!$H$8*(1+'02_ASSUMPTIONS_MASTER'!$H$50) | ... K9: ='02_ASSUMPTIONS_MASTER'!$H$16*'02_ASSUMPTIONS_MASTER'!$H$8*(1+'02_ASSUMPTIONS_MASTER'!$H$50)
A10: Logistics cost | B10: ='20_REVENUE'!B9*'02_ASSUMPTIONS_MASTER'!$H$24 | C10: ='20_REVENUE'!C9*'02_ASSUMPTIONS_MASTER'!$H$24 | D10: ='20_REVENUE'!D9*'02_ASSUMPTIONS_MASTER'!$H$24 | E10: ='20_REVENUE'!E9*'02_ASSUMPTIONS_MASTER'!$H$24 | F10: ='20_REVENUE'!F9*'02_ASSUMPTIONS_MASTER'!$H$24 | G10: ='20_REVENUE'!G9*'02_ASSUMPTIONS_MASTER'!$H$24 | H10: ='20_REVENUE'!H9*'02_ASSUMPTIONS_MASTER'!$H$24 | I10: ='20_REVENUE'!I9*'02_ASSUMPTIONS_MASTER'!$H$24 | ... K10: ='20_REVENUE'!K9*'02_ASSUMPTIONS_MASTER'!$H$24
A11: Variable overhead | B11: ='20_REVENUE'!B9*'02_ASSUMPTIONS_MASTER'!$H$25 | C11: ='20_REVENUE'!C9*'02_ASSUMPTIONS_MASTER'!$H$25 | D11: ='20_REVENUE'!D9*'02_ASSUMPTIONS_MASTER'!$H$25 | E11: ='20_REVENUE'!E9*'02_ASSUMPTIONS_MASTER'!$H$25 | F11: ='20_REVENUE'!F9*'02_ASSUMPTIONS_MASTER'!$H$25 | G11: ='20_REVENUE'!G9*'02_ASSUMPTIONS_MASTER'!$H$25 | H11: ='20_REVENUE'!H9*'02_ASSUMPTIONS_MASTER'!$H$25 | I11: ='20_REVENUE'!I9*'02_ASSUMPTIONS_MASTER'!$H$25 | ... K11: ='20_REVENUE'!K9*'02_ASSUMPTIONS_MASTER'!$H$25
A12: Total COGS | B12: =(B6+B7+B8+B9)*B5+B10+B11 | C12: =(C6+C7+C8+C9)*C5+C10+C11 | D12: =(D6+D7+D8+D9)*D5+D10+D11 | E12: =(E6+E7+E8+E9)*E5+E10+E11 | F12: =(F6+F7+F8+F9)*F5+F10+F11 | G12: =(G6+G7+G8+G9)*G5+G10+G11 | H12: =(H6+H7+H8+H9)*H5+H10+H11 | I12: =(I6+I7+I8+I9)*I5+I10+I11 | ... K12: =(K6+K7+K8+K9)*K5+K10+K11
A13: COGS as % sales | B13: =IFERROR(B12/'20_REVENUE'!B9,0) | C13: =IFERROR(C12/'20_REVENUE'!C9,0) | D13: =IFERROR(D12/'20_REVENUE'!D9,0) | E13: =IFERROR(E12/'20_REVENUE'!E9,0) | F13: =IFERROR(F12/'20_REVENUE'!F9,0) | G13: =IFERROR(G12/'20_REVENUE'!G9,0) | H13: =IFERROR(H12/'20_REVENUE'!H9,0) | I13: =IFERROR(I12/'20_REVENUE'!I9,0) | ... K13: =IFERROR(K12/'20_REVENUE'!K9,0)

Sheet 40_OPEX
K1: =HYPERLINK("#'01_INDEX_NAVIGATION'!A1","Back to Index")
A2: OPEX MODEL
A4: Metric | B4: 2026 | C4: 2027 | D4: 2028 | E4: 2029 | F4: 2030 | G4: 2031 | H4: 2032 | I4: 2033 | J4: 2034 | K4: 2035
A5: Headcount | B5: 0 | C5: ='02_ASSUMPTIONS_MASTER'!$H$26*0.85 | D5: ='02_ASSUMPTIONS_MASTER'!$H$26*0.92 | E5: ='02_ASSUMPTIONS_MASTER'!$H$26*0.98 | F5: ='02_ASSUMPTIONS_MASTER'!$H$27 | G5: ='02_ASSUMPTIONS_MASTER'!$H$27 | H5: ='02_ASSUMPTIONS_MASTER'!$H$27 | I5: ='02_ASSUMPTIONS_MASTER'!$H$27 | J5: ='02_ASSUMPTIONS_MASTER'!$H$27 | K5: ='02_ASSUMPTIONS_MASTER'!$H$27
A6: Payroll | B6: =B5*'02_ASSUMPTIONS_MASTER'!$H$28*1 | C6: =C5*'02_ASSUMPTIONS_MASTER'!$H$28*(1+'02_ASSUMPTIONS_MASTER'!$H$6)^(1) | D6: =D5*'02_ASSUMPTIONS_MASTER'!$H$28*(1+'02_ASSUMPTIONS_MASTER'!$H$6)^(2) | E6: =E5*'02_ASSUMPTIONS_MASTER'!$H$28*(1+'02_ASSUMPTIONS_MASTER'!$H$6)^(3) | F6: =F5*'02_ASSUMPTIONS_MASTER'!$H$28*(1+'02_ASSUMPTIONS_MASTER'!$H$6)^(4) | G6: =G5*'02_ASSUMPTIONS_MASTER'!$H$28*(1+'02_ASSUMPTIONS_MASTER'!$H$6)^(5) | H6: =H5*'02_ASSUMPTIONS_MASTER'!$H$28*(1+'02_ASSUMPTIONS_MASTER'!$H$6)^(6) | I6: =I5*'02_ASSUMPTIONS_MASTER'!$H$28*(1+'02_ASSUMPTIONS_MASTER'!$H$6)^(7) | J6: =J5*'02_ASSUMPTIONS_MASTER'!$H$28*(1+'02_ASSUMPTIONS_MASTER'!$H$6)^(8) | K6: =K5*'02_ASSUMPTIONS_MASTER'!$H$28*(1+'02_ASSUMPTIONS_MASTER'!$H$6)^(9)
A7: Admin cost | B7: ='20_REVENUE'!B9*'02_ASSUMPTIONS_MASTER'!$H$29 | C7: ='20_REVENUE'!C9*'02_ASSUMPTIONS_MASTER'!$H$29 | D7: ='20_REVENUE'!D9*'02_ASSUMPTIONS_MASTER'!$H$29 | E7: ='20_REVENUE'!E9*'02_ASSUMPTIONS_MASTER'!$H$29 | F7: ='20_REVENUE'!F9*'02_ASSUMPTIONS_MASTER'!$H$29 | G7: ='20_REVENUE'!G9*'02_ASSUMPTIONS_MASTER'!$H$29 | H7: ='20_REVENUE'!H9*'02_ASSUMPTIONS_MASTER'!$H$29 | I7: ='20_REVENUE'!I9*'02_ASSUMPTIONS_MASTER'!$H$29 | ... K7: ='20_REVENUE'!K9*'02_ASSUMPTIONS_MASTER'!$H$29
A8: Maintenance | B8: ='50_CAPEX'!B14*'02_ASSUMPTIONS_MASTER'!$H$30 | C8: ='50_CAPEX'!C14*'02_ASSUMPTIONS_MASTER'!$H$30 | D8: ='50_CAPEX'!D14*'02_ASSUMPTIONS_MASTER'!$H$30 | E8: ='50_CAPEX'!E14*'02_ASSUMPTIONS_MASTER'!$H$30 | F8: ='50_CAPEX'!F14*'02_ASSUMPTIONS_MASTER'!$H$30 | G8: ='50_CAPEX'!G14*'02_ASSUMPTIONS_MASTER'!$H$30 | H8: ='50_CAPEX'!H14*'02_ASSUMPTIONS_MASTER'!$H$30 | I8: ='50_CAPEX'!I14*'02_ASSUMPTIONS_MASTER'!$H$30 | ... K8: ='50_CAPEX'!K14*'02_ASSUMPTIONS_MASTER'!$H$30
A9: Insurance | B9: ='50_CAPEX'!B14*'02_ASSUMPTIONS_MASTER'!$H$31 | C9: ='50_CAPEX'!C14*'02_ASSUMPTIONS_MASTER'!$H$31 | D9: ='50_CAPEX'!D14*'02_ASSUMPTIONS_MASTER'!$H$31 | E9: ='50_CAPEX'!E14*'02_ASSUMPTIONS_MASTER'!$H$31 | F9: ='50_CAPEX'!F14*'02_ASSUMPTIONS_MASTER'!$H$31 | G9: ='50_CAPEX'!G14*'02_ASSUMPTIONS_MASTER'!$H$31 | H9: ='50_CAPEX'!H14*'02_ASSUMPTIONS_MASTER'!$H$31 | I9: ='50_CAPEX'!I14*'02_ASSUMPTIONS_MASTER'!$H$31 | ... K9: ='50_CAPEX'!K14*'02_ASSUMPTIONS_MASTER'!$H$31
A10: Other fixed OPEX | B10: ='02_ASSUMPTIONS_MASTER'!$H$32*1 | C10: ='02_ASSUMPTIONS_MASTER'!$H$32*(1+'02_ASSUMPTIONS_MASTER'!$H$6)^(1) | D10: ='02_ASSUMPTIONS_MASTER'!$H$32*(1+'02_ASSUMPTIONS_MASTER'!$H$6)^(2) | E10: ='02_ASSUMPTIONS_MASTER'!$H$32*(1+'02_ASSUMPTIONS_MASTER'!$H$6)^(3) | F10: ='02_ASSUMPTIONS_MASTER'!$H$32*(1+'02_ASSUMPTIONS_MASTER'!$H$6)^(4) | G10: ='02_ASSUMPTIONS_MASTER'!$H$32*(1+'02_ASSUMPTIONS_MASTER'!$H$6)^(5) | H10: ='02_ASSUMPTIONS_MASTER'!$H$32*(1+'02_ASSUMPTIONS_MASTER'!$H$6)^(6) | I10: ='02_ASSUMPTIONS_MASTER'!$H$32*(1+'02_ASSUMPTIONS_MASTER'!$H$6)^(7) | J10: ='02_ASSUMPTIONS_MASTER'!$H$32*(1+'02_ASSUMPTIONS_MASTER'!$H$6)^(8) | K10: ='02_ASSUMPTIONS_MASTER'!$H$32*(1+'02_ASSUMPTIONS_MASTER'!$H$6)^(9)
A11: Total OPEX | B11: =SUM(B6:B10) | C11: =SUM(C6:C10) | D11: =SUM(D6:D10) | E11: =SUM(E6:E10) | F11: =SUM(F6:F10) | G11: =SUM(G6:G10) | H11: =SUM(H6:H10) | I11: =SUM(I6:I10) | ... K11: =SUM(K6:K10)

Sheet 50_CAPEX
K1: =HYPERLINK("#'01_INDEX_NAVIGATION'!A1","Back to Index")
A2: CAPEX PHASING
A4: Metric | B4: 2026 | C4: 2027 | D4: 2028 | E4: 2029 | F4: 2030 | G4: 2031 | H4: 2032 | I4: 2033 | J4: 2034 | K4: 2035
A5: Land acquisition | B5: ='02_ASSUMPTIONS_MASTER'!$H$33*1.0*(1+'02_ASSUMPTIONS_MASTER'!$H$51) | C5: ='02_ASSUMPTIONS_MASTER'!$H$33*0.0*(1+'02_ASSUMPTIONS_MASTER'!$H$51) | D5: ='02_ASSUMPTIONS_MASTER'!$H$33*0.0*(1+'02_ASSUMPTIONS_MASTER'!$H$51) | E5: ='02_ASSUMPTIONS_MASTER'!$H$33*0.0*(1+'02_ASSUMPTIONS_MASTER'!$H$51) | F5: ='02_ASSUMPTIONS_MASTER'!$H$33*0*(1+'02_ASSUMPTIONS_MASTER'!$H$51) | G5: ='02_ASSUMPTIONS_MASTER'!$H$33*0*(1+'02_ASSUMPTIONS_MASTER'!$H$51) | H5: ='02_ASSUMPTIONS_MASTER'!$H$33*0*(1+'02_ASSUMPTIONS_MASTER'!$H$51) | I5: ='02_ASSUMPTIONS_MASTER'!$H$33*0*(1+'02_ASSUMPTIONS_MASTER'!$H$51) | J5: ='02_ASSUMPTIONS_MASTER'!$H$33*0*(1+'02_ASSUMPTIONS_MASTER'!$H$51) | K5: ='02_ASSUMPTIONS_MASTER'!$H$33*0*(1+'02_ASSUMPTIONS_MASTER'!$H$51)
A6: Building & civil works | B6: ='02_ASSUMPTIONS_MASTER'!$H$34*0.15*(1+'02_ASSUMPTIONS_MASTER'!$H$51) | C6: ='02_ASSUMPTIONS_MASTER'!$H$34*0.45*(1+'02_ASSUMPTIONS_MASTER'!$H$51) | D6: ='02_ASSUMPTIONS_MASTER'!$H$34*0.3*(1+'02_ASSUMPTIONS_MASTER'!$H$51) | E6: ='02_ASSUMPTIONS_MASTER'!$H$34*0.1*(1+'02_ASSUMPTIONS_MASTER'!$H$51) | F6: ='02_ASSUMPTIONS_MASTER'!$H$34*0*(1+'02_ASSUMPTIONS_MASTER'!$H$51) | G6: ='02_ASSUMPTIONS_MASTER'!$H$34*0*(1+'02_ASSUMPTIONS_MASTER'!$H$51) | H6: ='02_ASSUMPTIONS_MASTER'!$H$34*0*(1+'02_ASSUMPTIONS_MASTER'!$H$51) | I6: ='02_ASSUMPTIONS_MASTER'!$H$34*0*(1+'02_ASSUMPTIONS_MASTER'!$H$51) | J6: ='02_ASSUMPTIONS_MASTER'!$H$34*0*(1+'02_ASSUMPTIONS_MASTER'!$H$51) | K6: ='02_ASSUMPTIONS_MASTER'!$H$34*0*(1+'02_ASSUMPTIONS_MASTER'!$H$51)
A7: Machinery and lines | B7: ='02_ASSUMPTIONS_MASTER'!$H$35*0.05*(1+'02_ASSUMPTIONS_MASTER'!$H$51) | C7: ='02_ASSUMPTIONS_MASTER'!$H$35*0.35*(1+'02_ASSUMPTIONS_MASTER'!$H$51) | D7: ='02_ASSUMPTIONS_MASTER'!$H$35*0.4*(1+'02_ASSUMPTIONS_MASTER'!$H$51) | E7: ='02_ASSUMPTIONS_MASTER'!$H$35*0.2*(1+'02_ASSUMPTIONS_MASTER'!$H$51) | F7: ='02_ASSUMPTIONS_MASTER'!$H$35*0*(1+'02_ASSUMPTIONS_MASTER'!$H$51) | G7: ='02_ASSUMPTIONS_MASTER'!$H$35*0*(1+'02_ASSUMPTIONS_MASTER'!$H$51) | H7: ='02_ASSUMPTIONS_MASTER'!$H$35*0*(1+'02_ASSUMPTIONS_MASTER'!$H$51) | I7: ='02_ASSUMPTIONS_MASTER'!$H$35*0*(1+'02_ASSUMPTIONS_MASTER'!$H$51) | J7: ='02_ASSUMPTIONS_MASTER'!$H$35*0*(1+'02_ASSUMPTIONS_MASTER'!$H$51) | K7: ='02_ASSUMPTIONS_MASTER'!$H$35*0*(1+'02_ASSUMPTIONS_MASTER'!$H$51)
A8: Solar plant | B8: ='02_ASSUMPTIONS_MASTER'!$H$36*0.0*(1+'02_ASSUMPTIONS_MASTER'!$H$51) | C8: ='02_ASSUMPTIONS_MASTER'!$H$36*0.15*(1+'02_ASSUMPTIONS_MASTER'!$H$51) | D8: ='02_ASSUMPTIONS_MASTER'!$H$36*0.45*(1+'02_ASSUMPTIONS_MASTER'!$H$51) | E8: ='02_ASSUMPTIONS_MASTER'!$H$36*0.4*(1+'02_ASSUMPTIONS_MASTER'!$H$51) | F8: ='02_ASSUMPTIONS_MASTER'!$H$36*0*(1+'02_ASSUMPTIONS_MASTER'!$H$51) | G8: ='02_ASSUMPTIONS_MASTER'!$H$36*0*(1+'02_ASSUMPTIONS_MASTER'!$H$51) | H8: ='02_ASSUMPTIONS_MASTER'!$H$36*0*(1+'02_ASSUMPTIONS_MASTER'!$H$51) | I8: ='02_ASSUMPTIONS_MASTER'!$H$36*0*(1+'02_ASSUMPTIONS_MASTER'!$H$51) | J8: ='02_ASSUMPTIONS_MASTER'!$H$36*0*(1+'02_ASSUMPTIONS_MASTER'!$H$51) | K8: ='02_ASSUMPTIONS_MASTER'!$H$36*0*(1+'02_ASSUMPTIONS_MASTER'!$H$51)
A9: Pre-op and permits | B9: ='02_ASSUMPTIONS_MASTER'!$H$37*0.4*(1+'02_ASSUMPTIONS_MASTER'!$H$51) | C9: ='02_ASSUMPTIONS_MASTER'!$H$37*0.35*(1+'02_ASSUMPTIONS_MASTER'!$H$51) | D9: ='02_ASSUMPTIONS_MASTER'!$H$37*0.2*(1+'02_ASSUMPTIONS_MASTER'!$H$51) | E9: ='02_ASSUMPTIONS_MASTER'!$H$37*0.05*(1+'02_ASSUMPTIONS_MASTER'!$H$51) | F9: ='02_ASSUMPTIONS_MASTER'!$H$37*0*(1+'02_ASSUMPTIONS_MASTER'!$H$51) | G9: ='02_ASSUMPTIONS_MASTER'!$H$37*0*(1+'02_ASSUMPTIONS_MASTER'!$H$51) | H9: ='02_ASSUMPTIONS_MASTER'!$H$37*0*(1+'02_ASSUMPTIONS_MASTER'!$H$51) | I9: ='02_ASSUMPTIONS_MASTER'!$H$37*0*(1+'02_ASSUMPTIONS_MASTER'!$H$51) | J9: ='02_ASSUMPTIONS_MASTER'!$H$37*0*(1+'02_ASSUMPTIONS_MASTER'!$H$51) | K9: ='02_ASSUMPTIONS_MASTER'!$H$37*0*(1+'02_ASSUMPTIONS_MASTER'!$H$51)
A10: Base CAPEX | B10: =SUM(B5:B9) | C10: =SUM(C5:C9) | D10: =SUM(D5:D9) | E10: =SUM(E5:E9) | F10: =SUM(F5:F9) | G10: =SUM(G5:G9) | H10: =SUM(H5:H9) | I10: =SUM(I5:I9) | ... K10: =SUM(K5:K9)
A11: Contingency | B11: =B10*'02_ASSUMPTIONS_MASTER'!$H$38 | C11: =C10*'02_ASSUMPTIONS_MASTER'!$H$38 | D11: =D10*'02_ASSUMPTIONS_MASTER'!$H$38 | E11: =E10*'02_ASSUMPTIONS_MASTER'!$H$38 | F11: =F10*'02_ASSUMPTIONS_MASTER'!$H$38 | G11: =G10*'02_ASSUMPTIONS_MASTER'!$H$38 | H11: =H10*'02_ASSUMPTIONS_MASTER'!$H$38 | I11: =I10*'02_ASSUMPTIONS_MASTER'!$H$38 | ... K11: =K10*'02_ASSUMPTIONS_MASTER'!$H$38
A12: Total CAPEX | B12: =B10+B11 | C12: =C10+C11 | D12: =D10+D11 | E12: =E10+E11 | F12: =F10+F11 | G12: =G10+G11 | H12: =H10+H11 | I12: =I10+I11 | ... K12: =K10+K11
A13: Cumulative CAPEX | B13: =B12 | C13: =B13+C12 | D13: =C13+D12 | E13: =D13+E12 | F13: =E13+F12 | G13: =F13+G12 | H13: =G13+H12 | I13: =H13+I12 | J13: =I13+J12 | K13: =J13+K12
A14: Gross PP&E closing | B14: =B12 | C14: =B14+C12 | D14: =C14+D12 | E14: =D14+E12 | F14: =E14+F12 | G14: =F14+G12 | H14: =G14+H12 | I14: =H14+I12 | J14: =I14+J12 | K14: =J14+K12

Sheet 60_WORKING_CAPITAL
K1: =HYPERLINK("#'01_INDEX_NAVIGATION'!A1","Back to Index")
A2: WORKING CAPITAL MODEL
A4: Metric | B4: 2026 | C4: 2027 | D4: 2028 | E4: 2029 | F4: 2030 | G4: 2031 | H4: 2032 | I4: 2033 | J4: 2034 | K4: 2035
A5: Revenue | B5: ='20_REVENUE'!B9 | C5: ='20_REVENUE'!C9 | D5: ='20_REVENUE'!D9 | E5: ='20_REVENUE'!E9 | F5: ='20_REVENUE'!F9 | G5: ='20_REVENUE'!G9 | H5: ='20_REVENUE'!H9 | I5: ='20_REVENUE'!I9 | ... K5: ='20_REVENUE'!K9
A6: COGS | B6: ='30_COGS'!B12 | C6: ='30_COGS'!C12 | D6: ='30_COGS'!D12 | E6: ='30_COGS'!E12 | F6: ='30_COGS'!F12 | G6: ='30_COGS'!G12 | H6: ='30_COGS'!H12 | I6: ='30_COGS'!I12 | ... K6: ='30_COGS'!K12
A7: Inventory | B7: =B6/365*'02_ASSUMPTIONS_MASTER'!$H$39 | C7: =C6/365*'02_ASSUMPTIONS_MASTER'!$H$39 | D7: =D6/365*'02_ASSUMPTIONS_MASTER'!$H$39 | E7: =E6/365*'02_ASSUMPTIONS_MASTER'!$H$39 | F7: =F6/365*'02_ASSUMPTIONS_MASTER'!$H$39 | G7: =G6/365*'02_ASSUMPTIONS_MASTER'!$H$39 | H7: =H6/365*'02_ASSUMPTIONS_MASTER'!$H$39 | I7: =I6/365*'02_ASSUMPTIONS_MASTER'!$H$39 | ... K7: =K6/365*'02_ASSUMPTIONS_MASTER'!$H$39
A8: Receivables | B8: =B5/365*'02_ASSUMPTIONS_MASTER'!$H$40 | C8: =C5/365*'02_ASSUMPTIONS_MASTER'!$H$40 | D8: =D5/365*'02_ASSUMPTIONS_MASTER'!$H$40 | E8: =E5/365*'02_ASSUMPTIONS_MASTER'!$H$40 | F8: =F5/365*'02_ASSUMPTIONS_MASTER'!$H$40 | G8: =G5/365*'02_ASSUMPTIONS_MASTER'!$H$40 | H8: =H5/365*'02_ASSUMPTIONS_MASTER'!$H$40 | I8: =I5/365*'02_ASSUMPTIONS_MASTER'!$H$40 | ... K8: =K5/365*'02_ASSUMPTIONS_MASTER'!$H$40
A9: Payables | B9: =B6/365*'02_ASSUMPTIONS_MASTER'!$H$41 | C9: =C6/365*'02_ASSUMPTIONS_MASTER'!$H$41 | D9: =D6/365*'02_ASSUMPTIONS_MASTER'!$H$41 | E9: =E6/365*'02_ASSUMPTIONS_MASTER'!$H$41 | F9: =F6/365*'02_ASSUMPTIONS_MASTER'!$H$41 | G9: =G6/365*'02_ASSUMPTIONS_MASTER'!$H$41 | H9: =H6/365*'02_ASSUMPTIONS_MASTER'!$H$41 | I9: =I6/365*'02_ASSUMPTIONS_MASTER'!$H$41 | ... K9: =K6/365*'02_ASSUMPTIONS_MASTER'!$H$41
A10: Net working capital | B10: =B7+B8-B9 | C10: =C7+C8-C9 | D10: =D7+D8-D9 | E10: =E7+E8-E9 | F10: =F7+F8-F9 | G10: =G7+G8-G9 | H10: =H7+H8-H9 | I10: =I7+I8-I9 | ... K10: =K7+K8-K9
A11: Change in NWC | B11: =B10 | C11: =C10-B10 | D11: =D10-C10 | E11: =E10-D10 | F11: =F10-E10 | G11: =G10-F10 | H11: =H10-G10 | I11: =I10-H10 | J11: =J10-I10 | K11: =K10-J10

Sheet 70_FINANCING
K1: =HYPERLINK("#'01_INDEX_NAVIGATION'!A1","Back to Index")
A2: FINANCING MODEL
A4: Metric | B4: 2026 | C4: 2027 | D4: 2028 | E4: 2029 | F4: 2030 | G4: 2031 | H4: 2032 | I4: 2033 | J4: 2034 | K4: 2035
A5: Total CAPEX | B5: ='50_CAPEX'!B12 | C5: ='50_CAPEX'!C12 | D5: ='50_CAPEX'!D12 | E5: ='50_CAPEX'!E12 | F5: ='50_CAPEX'!F12 | G5: ='50_CAPEX'!G12 | H5: ='50_CAPEX'!H12 | I5: ='50_CAPEX'!I12 | ... K5: ='50_CAPEX'!K12
A6: Debt draw | B6: =B5*'02_ASSUMPTIONS_MASTER'!$H$42 | C6: =C5*'02_ASSUMPTIONS_MASTER'!$H$42 | D6: =D5*'02_ASSUMPTIONS_MASTER'!$H$42 | E6: =E5*'02_ASSUMPTIONS_MASTER'!$H$42 | F6: 0 | G6: 0 | H6: 0 | I6: 0 | J6: 0 | K6: 0
A7: Equity injection | B7: =B5*'02_ASSUMPTIONS_MASTER'!$H$43 | C7: =C5*'02_ASSUMPTIONS_MASTER'!$H$43 | D7: =D5*'02_ASSUMPTIONS_MASTER'!$H$43 | E7: =E5*'02_ASSUMPTIONS_MASTER'!$H$43 | F7: 0 | G7: 0 | H7: 0 | I7: 0 | J7: 0 | K7: 0
A8: Grant inflow | B8: =B5*'02_ASSUMPTIONS_MASTER'!$H$44 | C8: =C5*'02_ASSUMPTIONS_MASTER'!$H$44 | D8: =D5*'02_ASSUMPTIONS_MASTER'!$H$44 | E8: =E5*'02_ASSUMPTIONS_MASTER'!$H$44 | F8: 0 | G8: 0 | H8: 0 | I8: 0 | J8: 0 | K8: 0
A9: Opening debt | B9: 0 | C9: =B12 | D9: =C12 | E9: =D12 | F9: =E12 | G9: =F12 | H9: =G12 | I9: =H12 | J9: =I12 | K9: =J12
A10: Interest expense | B10: =(B9+B6/2)*'02_ASSUMPTIONS_MASTER'!$H$7 | C10: =(C9+C6/2)*'02_ASSUMPTIONS_MASTER'!$H$7 | D10: =(D9+D6/2)*'02_ASSUMPTIONS_MASTER'!$H$7 | E10: =(E9+E6/2)*'02_ASSUMPTIONS_MASTER'!$H$7 | F10: =(F9+F6/2)*'02_ASSUMPTIONS_MASTER'!$H$7 | G10: =(G9+G6/2)*'02_ASSUMPTIONS_MASTER'!$H$7 | H10: =(H9+H6/2)*'02_ASSUMPTIONS_MASTER'!$H$7 | I10: =(I9+I6/2)*'02_ASSUMPTIONS_MASTER'!$H$7 | ... K10: =(K9+K6/2)*'02_ASSUMPTIONS_MASTER'!$H$7
A11: Principal repayment | B11: 0 | C11: 0 | D11: 0 | E11: 0 | F11: =IF(2030<=2029+'02_ASSUMPTIONS_MASTER'!$H$46,0,SUM(B6:E6)/MAX(1,('02_ASSUMPTIONS_MASTER'!$H$45-'02_ASSUMPTIONS_MASTER'!$H$46))) | G11: =IF(2031<=2029+'02_ASSUMPTIONS_MASTER'!$H$46,0,SUM(B6:E6)/MAX(1,('02_ASSUMPTIONS_MASTER'!$H$45-'02_ASSUMPTIONS_MASTER'!$H$46))) | H11: =IF(2032<=2029+'02_ASSUMPTIONS_MASTER'!$H$46,0,SUM(B6:E6)/MAX(1,('02_ASSUMPTIONS_MASTER'!$H$45-'02_ASSUMPTIONS_MASTER'!$H$46))) | I11: =IF(2033<=2029+'02_ASSUMPTIONS_MASTER'!$H$46,0,SUM(B6:E6)/MAX(1,('02_ASSUMPTIONS_MASTER'!$H$45-'02_ASSUMPTIONS_MASTER'!$H$46))) | J11: =IF(2034<=2029+'02_ASSUMPTIONS_MASTER'!$H$46,0,SUM(B6:E6)/MAX(1,('02_ASSUMPTIONS_MASTER'!$H$45-'02_ASSUMPTIONS_MASTER'!$H$46))) | K11: =IF(2035<=2029+'02_ASSUMPTIONS_MASTER'!$H$46,0,SUM(B6:E6)/MAX(1,('02_ASSUMPTIONS_MASTER'!$H$45-'02_ASSUMPTIONS_MASTER'!$H$46)))
A12: Closing debt | B12: =MAX(0,B9+B6-B11) | C12: =MAX(0,C9+C6-C11) | D12: =MAX(0,D9+D6-D11) | E12: =MAX(0,E9+E6-E11) | F12: =MAX(0,F9+F6-F11) | G12: =MAX(0,G9+G6-G11) | H12: =MAX(0,H9+H6-H11) | I12: =MAX(0,I9+I6-I11) | ... K12: =MAX(0,K9+K6-K11)

Sheet 80_CASHFLOW
K1: =HYPERLINK("#'01_INDEX_NAVIGATION'!A1","Back to Index")
A2: INTEGRATED CASH FLOW / DSCR
A4: Metric | B4: 2026 | C4: 2027 | D4: 2028 | E4: 2029 | F4: 2030 | G4: 2031 | H4: 2032 | I4: 2033 | J4: 2034 | K4: 2035
A5: Total revenue | B5: ='20_REVENUE'!B9 | C5: ='20_REVENUE'!C9 | D5: ='20_REVENUE'!D9 | E5: ='20_REVENUE'!E9 | F5: ='20_REVENUE'!F9 | G5: ='20_REVENUE'!G9 | H5: ='20_REVENUE'!H9 | I5: ='20_REVENUE'!I9 | ... K5: ='20_REVENUE'!K9
A6: Total COGS | B6: ='30_COGS'!B12 | C6: ='30_COGS'!C12 | D6: ='30_COGS'!D12 | E6: ='30_COGS'!E12 | F6: ='30_COGS'!F12 | G6: ='30_COGS'!G12 | H6: ='30_COGS'!H12 | I6: ='30_COGS'!I12 | ... K6: ='30_COGS'!K12
A7: Gross profit | B7: =B5-B6 | C7: =C5-C6 | D7: =D5-D6 | E7: =E5-E6 | F7: =F5-F6 | G7: =G5-G6 | H7: =H5-H6 | I7: =I5-I6 | ... K7: =K5-K6
A8: Total OPEX | B8: ='40_OPEX'!B11 | C8: ='40_OPEX'!C11 | D8: ='40_OPEX'!D11 | E8: ='40_OPEX'!E11 | F8: ='40_OPEX'!F11 | G8: ='40_OPEX'!G11 | H8: ='40_OPEX'!H11 | I8: ='40_OPEX'!I11 | ... K8: ='40_OPEX'!K11
A9: EBITDA | B9: =B7-B8 | C9: =C7-C8 | D9: =D7-D8 | E9: =E7-E8 | F9: =F7-F8 | G9: =G7-G8 | H9: =H7-H8 | I9: =I7-I8 | ... K9: =K7-K8
A10: Taxes | B10: =MAX(0,B9*'02_ASSUMPTIONS_MASTER'!$H$10) | C10: =MAX(0,C9*'02_ASSUMPTIONS_MASTER'!$H$10) | D10: =MAX(0,D9*'02_ASSUMPTIONS_MASTER'!$H$10) | E10: =MAX(0,E9*'02_ASSUMPTIONS_MASTER'!$H$10) | F10: =MAX(0,F9*'02_ASSUMPTIONS_MASTER'!$H$10) | G10: =MAX(0,G9*'02_ASSUMPTIONS_MASTER'!$H$10) | H10: =MAX(0,H9*'02_ASSUMPTIONS_MASTER'!$H$10) | I10: =MAX(0,I9*'02_ASSUMPTIONS_MASTER'!$H$10) | ... K10: =MAX(0,K9*'02_ASSUMPTIONS_MASTER'!$H$10)
A11: Operating cash flow pre-WC | B11: =B9-B10 | C11: =C9-C10 | D11: =D9-D10 | E11: =E9-E10 | F11: =F9-F10 | G11: =G9-G10 | H11: =H9-H10 | I11: =I9-I10 | ... K11: =K9-K10
A12: Change in NWC | B12: ='60_WORKING_CAPITAL'!B11 | C12: ='60_WORKING_CAPITAL'!C11 | D12: ='60_WORKING_CAPITAL'!D11 | E12: ='60_WORKING_CAPITAL'!E11 | F12: ='60_WORKING_CAPITAL'!F11 | G12: ='60_WORKING_CAPITAL'!G11 | H12: ='60_WORKING_CAPITAL'!H11 | I12: ='60_WORKING_CAPITAL'!I11 | ... K12: ='60_WORKING_CAPITAL'!K11
A13: Operating cash flow post-WC | B13: =B11-B12 | C13: =C11-C12 | D13: =D11-D12 | E13: =E11-E12 | F13: =F11-F12 | G13: =G11-G12 | H13: =H11-H12 | I13: =I11-I12 | ... K13: =K11-K12
A14: CAPEX | B14: ='50_CAPEX'!B12 | C14: ='50_CAPEX'!C12 | D14: ='50_CAPEX'!D12 | E14: ='50_CAPEX'!E12 | F14: ='50_CAPEX'!F12 | G14: ='50_CAPEX'!G12 | H14: ='50_CAPEX'!H12 | I14: ='50_CAPEX'!I12 | ... K14: ='50_CAPEX'!K12
A15: CFADS | B15: =B13-B14+'70_FINANCING'!B8 | C15: =C13-C14+'70_FINANCING'!C8 | D15: =D13-D14+'70_FINANCING'!D8 | E15: =E13-E14+'70_FINANCING'!E8 | F15: =F13-F14+'70_FINANCING'!F8 | G15: =G13-G14+'70_FINANCING'!G8 | H15: =H13-H14+'70_FINANCING'!H8 | I15: =I13-I14+'70_FINANCING'!I8 | ... K15: =K13-K14+'70_FINANCING'!K8
A16: Interest | B16: ='70_FINANCING'!B10 | C16: ='70_FINANCING'!C10 | D16: ='70_FINANCING'!D10 | E16: ='70_FINANCING'!E10 | F16: ='70_FINANCING'!F10 | G16: ='70_FINANCING'!G10 | H16: ='70_FINANCING'!H10 | I16: ='70_FINANCING'!I10 | ... K16: ='70_FINANCING'!K10
A17: Principal | B17: ='70_FINANCING'!B11 | C17: ='70_FINANCING'!C11 | D17: ='70_FINANCING'!D11 | E17: ='70_FINANCING'!E11 | F17: ='70_FINANCING'!F11 | G17: ='70_FINANCING'!G11 | H17: ='70_FINANCING'!H11 | I17: ='70_FINANCING'!I11 | ... K17: ='70_FINANCING'!K11
A18: Debt service | B18: =B16+B17 | C18: =C16+C17 | D18: =D16+D17 | E18: =E16+E17 | F18: =F16+F17 | G18: =G16+G17 | H18: =H16+H17 | I18: =I16+I17 | ... K18: =K16+K17
A19: DSCR | B19: =IFERROR(B15/B18,0) | C19: =IFERROR(C15/C18,0) | D19: =IFERROR(D15/D18,0) | E19: =IFERROR(E15/E18,0) | F19: =IFERROR(F15/F18,0) | G19: =IFERROR(G15/G18,0) | H19: =IFERROR(H15/H18,0) | I19: =IFERROR(I15/I18,0) | ... K19: =IFERROR(K15/K18,0)
A20: Free cash flow after debt | B20: =B15-B18+'70_FINANCING'!B7 | C20: =C15-C18+'70_FINANCING'!C7 | D20: =D15-D18+'70_FINANCING'!D7 | E20: =E15-E18+'70_FINANCING'!E7 | F20: =F15-F18+'70_FINANCING'!F7 | G20: =G15-G18+'70_FINANCING'!G7 | H20: =H15-H18+'70_FINANCING'!H7 | I20: =I15-I18+'70_FINANCING'!I7 | ... K20: =K15-K18+'70_FINANCING'!K7

Sheet 90_DASHBOARD_IC
K1: =HYPERLINK("#'01_INDEX_NAVIGATION'!A1","Back to Index")
A2: INVESTMENT COMMITTEE DASHBOARD
A4: KPI | B4: Value | C4: Threshold | D4: Status | E4: Comment | F4: Source
A5: Scenario | B5: ='03_SCENARIO_CONTROL'!B5 | D5: INFO | E5: Active case | F5: Scenario
A6: Total CAPEX | B6: =SUM('50_CAPEX'!B12:K12) | D6: INFO | E6: Total uses | F6: CAPEX
A7: Peak Revenue | B7: =MAX('20_REVENUE'!B9:K9) | D7: INFO | E7: Maximum annual sales | F7: Revenue
A8: Peak EBITDA | B8: =MAX('80_CASHFLOW'!B9:K9) | D8: INFO | E8: Maximum annual EBITDA | F8: Cash flow
A9: Minimum DSCR | B9: =MIN('80_CASHFLOW'!B19:K19) | C9: ='02_ASSUMPTIONS_MASTER'!$H$47 | D9: =IF(B9>=C9,"PASS","FAIL") | E9: Coverage floor | F9: Cash flow
A10: Ending Debt | B10: ='70_FINANCING'!K12 | D10: INFO | E10: Residual balance | F10: Financing
A11: Total Equity | B11: =SUM('70_FINANCING'!B7:K7) | D11: INFO | E11: Sponsor funds | F11: Financing
A12: Total Grants | B12: =SUM('70_FINANCING'!B8:K8) | D12: INFO | E12: Grant funds | F12: Financing

Sheet 99_MODEL_CHECKS
K1: =HYPERLINK("#'01_INDEX_NAVIGATION'!A1","Back to Index")
A2: MODEL CHECKS
A4: Check | B4: Result | C4: Tolerance | D4: Status | E4: Comment
A5: Sources less Uses | B5: =ABS(SUM('70_FINANCING'!B6:K8)-SUM('50_CAPEX'!B12:K12)) | C5: 1 | D5: =IF(B5<=C5,"PASS","FAIL") | E5: Should be near zero
A6: Ending debt residual | B6: =ABS('70_FINANCING'!K12) | C6: 1 | D6: =IF(B6<=C6,"PASS","FAIL") | E6: Should be near zero
A7: DSCR vs threshold | B7: =MIN('80_CASHFLOW'!B19:K19)-'02_ASSUMPTIONS_MASTER'!$H$47 | C7: 0 | D7: =IF(B7>=C7,"PASS","FAIL") | E7: Positive means pass
A8: No negative revenue | B8: =MIN('20_REVENUE'!B9:K9) | C8: 0 | D8: =IF(B8>=C8,"PASS","FAIL") | E8: Should be non-negative
A9: No negative gross PP&E | B9: =MIN('50_CAPEX'!B14:K14) | C9: 0 | D9: =IF(B9>=C9,"PASS","FAIL") | E9: Should be non-negative
