Workbook

Sheet SUMMARY_DASHBOARD
A1: TITAN GRID | CAPEX SUMMARY DASHBOARD
A2: Locked assumptions reflected from v4.5. Category totals update automatically once Quantity and Unit Price are entered in category sheets.
A3: Direct CAPEX | B3: =CONTROL_PANEL!B2 | C3: Contingency | D3: =CONTROL_PANEL!B3 | E3: TPC | F3: =CONTROL_PANEL!B4 | G3: IDC | H3: =CONTROL_PANEL!B5
A4: Debt % | B4: =CONTROL_PANEL!B6 | C4: Equity % | D4: =CONTROL_PANEL!B7 | E4: Min DSCR | F4: =CONTROL_PANEL!B8 | G4: Avg DSCR | H4: =CONTROL_PANEL!B9
A6: Category | B6: Base Total (EUR) | C6: Contingency (EUR) | D6: Gross Total (EUR) | E6: % of Gross Total | F6: Status
A7: LAND ACQUISITION | B7: ='LAND ACQUISITION'!G27 | C7: ='LAND ACQUISITION'!M27 | D7: ='LAND ACQUISITION'!N27 | E7: =IFERROR(D7/SUM($D$7:$D$28),0) | F7: =IF(D7=0,"Awaiting Input","Active")
A8: SITE PREPARATION & CIVIL INFRAS | B8: ='SITE PREPARATION & CIVIL INFRAS'!G30 | C8: ='SITE PREPARATION & CIVIL INFRAS'!M30 | D8: ='SITE PREPARATION & CIVIL INFRAS'!N30 | E8: =IFERROR(D8/SUM($D$7:$D$28),0) | F8: =IF(D8=0,"Awaiting Input","Active")
A9: BUILDINGS (INDUSTRIAL FACILITIE | B9: ='BUILDINGS (INDUSTRIAL FACILITIE'!G34 | C9: ='BUILDINGS (INDUSTRIAL FACILITIE'!M34 | D9: ='BUILDINGS (INDUSTRIAL FACILITIE'!N34 | E9: =IFERROR(D9/SUM($D$7:$D$28),0) | F9: =IF(D9=0,"Awaiting Input","Active")
A10: PRODUCTION EQUIPMENT (CORE PROC | B10: ='PRODUCTION EQUIPMENT (CORE PROC'!G37 | C10: ='PRODUCTION EQUIPMENT (CORE PROC'!M37 | D10: ='PRODUCTION EQUIPMENT (CORE PROC'!N37 | E10: =IFERROR(D10/SUM($D$7:$D$28),0) | F10: =IF(D10=0,"Awaiting Input","Active")
A11: DRYING INSULATION TECHNOLOGY | B11: ='DRYING INSULATION TECHNOLOGY'!G28 | C11: ='DRYING INSULATION TECHNOLOGY'!M28 | D11: ='DRYING INSULATION TECHNOLOGY'!N28 | E11: =IFERROR(D11/SUM($D$7:$D$28),0) | F11: =IF(D11=0,"Awaiting Input","Active")
A12: TANK FABRICATION METAL PROCES | B12: ='TANK FABRICATION METAL PROCES'!G37 | C12: ='TANK FABRICATION METAL PROCES'!M37 | D12: ='TANK FABRICATION METAL PROCES'!N37 | E12: =IFERROR(D12/SUM($D$7:$D$28),0) | F12: =IF(D12=0,"Awaiting Input","Active")
A13: FINAL ASSEMBLY SYSTEMS | B13: ='FINAL ASSEMBLY SYSTEMS'!G32 | C13: ='FINAL ASSEMBLY SYSTEMS'!M32 | D13: ='FINAL ASSEMBLY SYSTEMS'!N32 | E13: =IFERROR(D13/SUM($D$7:$D$28),0) | F13: =IF(D13=0,"Awaiting Input","Active")
A14: TESTING HALL EQUIPMENT | B14: ='TESTING HALL EQUIPMENT'!G37 | C14: ='TESTING HALL EQUIPMENT'!M37 | D14: ='TESTING HALL EQUIPMENT'!N37 | E14: =IFERROR(D14/SUM($D$7:$D$28),0) | F14: =IF(D14=0,"Awaiting Input","Active")
A15: INTERNAL LOGISTICS & MATERIAL | B15: ='INTERNAL LOGISTICS & MATERIAL '!G29 | C15: ='INTERNAL LOGISTICS & MATERIAL '!M29 | D15: ='INTERNAL LOGISTICS & MATERIAL '!N29 | E15: =IFERROR(D15/SUM($D$7:$D$28),0) | F15: =IF(D15=0,"Awaiting Input","Active")
A16: UTILITIES & ENERGY INFRASTRUCTU | B16: ='UTILITIES & ENERGY INFRASTRUCTU'!G44 | C16: ='UTILITIES & ENERGY INFRASTRUCTU'!M44 | D16: ='UTILITIES & ENERGY INFRASTRUCTU'!N44 | E16: =IFERROR(D16/SUM($D$7:$D$28),0) | F16: =IF(D16=0,"Awaiting Input","Active")
A17: RENEWABLES & ENERGY MANAGEMENT | B17: ='RENEWABLES & ENERGY MANAGEMENT'!G30 | C17: ='RENEWABLES & ENERGY MANAGEMENT'!M30 | D17: ='RENEWABLES & ENERGY MANAGEMENT'!N30 | E17: =IFERROR(D17/SUM($D$7:$D$28),0) | F17: =IF(D17=0,"Awaiting Input","Active")
A18: IT & DIGITAL INFRASTRUCTURE | B18: ='IT & DIGITAL INFRASTRUCTURE'!G39 | C18: ='IT & DIGITAL INFRASTRUCTURE'!M39 | D18: ='IT & DIGITAL INFRASTRUCTURE'!N39 | E18: =IFERROR(D18/SUM($D$7:$D$28),0) | F18: =IF(D18=0,"Awaiting Input","Active")
A19: QA LABORATORY & MATERIAL TESTIN | B19: ='QA LABORATORY & MATERIAL TESTIN'!G34 | C19: ='QA LABORATORY & MATERIAL TESTIN'!M34 | D19: ='QA LABORATORY & MATERIAL TESTIN'!N34 | E19: =IFERROR(D19/SUM($D$7:$D$28),0) | F19: =IF(D19=0,"Awaiting Input","Active")
A20: TRANSPORT & FLEET | B20: ='TRANSPORT & FLEET'!G29 | C20: ='TRANSPORT & FLEET'!M29 | D20: ='TRANSPORT & FLEET'!N29 | E20: =IFERROR(D20/SUM($D$7:$D$28),0) | F20: =IF(D20=0,"Awaiting Input","Active")
A21: SECURITY & SAFETY SYSTEMS | B21: ='SECURITY & SAFETY SYSTEMS'!G34 | C21: ='SECURITY & SAFETY SYSTEMS'!M34 | D21: ='SECURITY & SAFETY SYSTEMS'!N34 | E21: =IFERROR(D21/SUM($D$7:$D$28),0) | F21: =IF(D21=0,"Awaiting Input","Active")
A22: ENGINEERING & PERMITS | B22: ='ENGINEERING & PERMITS'!G36 | C22: ='ENGINEERING & PERMITS'!M36 | D22: ='ENGINEERING & PERMITS'!N36 | E22: =IFERROR(D22/SUM($D$7:$D$28),0) | F22: =IF(D22=0,"Awaiting Input","Active")
A23: PROJECT MANAGEMENT & IMPLEMENTA | B23: ='PROJECT MANAGEMENT & IMPLEMENTA'!G31 | C23: ='PROJECT MANAGEMENT & IMPLEMENTA'!M31 | D23: ='PROJECT MANAGEMENT & IMPLEMENTA'!N31 | E23: =IFERROR(D23/SUM($D$7:$D$28),0) | F23: =IF(D23=0,"Awaiting Input","Active")
A24: CONTINGENCY & COST ESCALATION | B24: ='CONTINGENCY & COST ESCALATION'!G31 | C24: ='CONTINGENCY & COST ESCALATION'!M31 | D24: ='CONTINGENCY & COST ESCALATION'!N31 | E24: =IFERROR(D24/SUM($D$7:$D$28),0) | F24: =IF(D24=0,"Awaiting Input","Active")
A25: FINANCING COSTS | B25: ='FINANCING COSTS'!G28 | C25: ='FINANCING COSTS'!M28 | D25: ='FINANCING COSTS'!N28 | E25: =IFERROR(D25/SUM($D$7:$D$28),0) | F25: =IF(D25=0,"Awaiting Input","Active")
A26: START-UP INVENTORY & SPARE PART | B26: ='START-UP INVENTORY & SPARE PART'!G29 | C26: ='START-UP INVENTORY & SPARE PART'!M29 | D26: ='START-UP INVENTORY & SPARE PART'!N29 | E26: =IFERROR(D26/SUM($D$7:$D$28),0) | F26: =IF(D26=0,"Awaiting Input","Active")
A27: TRAINING & HUMAN CAPITAL DEVELO | B27: ='TRAINING & HUMAN CAPITAL DEVELO'!G29 | C27: ='TRAINING & HUMAN CAPITAL DEVELO'!M29 | D27: ='TRAINING & HUMAN CAPITAL DEVELO'!N29 | E27: =IFERROR(D27/SUM($D$7:$D$28),0) | F27: =IF(D27=0,"Awaiting Input","Active")
A28: WORKING CAPITAL (START-UP INVEN | B28: ='WORKING CAPITAL (START-UP INVEN'!G29 | C28: ='WORKING CAPITAL (START-UP INVEN'!M29 | D28: ='WORKING CAPITAL (START-UP INVEN'!N29 | E28: =IFERROR(D28/SUM($D$7:$D$28),0) | F28: =IF(D28=0,"Awaiting Input","Active")
A30: GRAND TOTAL | B30: =SUM(B7:B28) | C30: =SUM(C7:C28) | D30: =SUM(D7:D28) | E30: 1

Sheet ASSUMPTIONS_v4_5
A1: Kategorija | B1: Parametar | C1: Vrijednost | D1: Izvor | E1: Status | F1: Napomena
A2: Land & Location | B2: Površina parcele | C2: 22.742 m² | D2: List Nepokretnosti 3301 | E2: Locked | F2: Tuške Livade, parcela 413/3
A3: Land & Location | B3: UTU ograničenje | C3: 10.000 m² BGP | D3: UTU dokument | E3: Locked | F3: Maksimalna dozvoljena građevinska površina
A4: Land & Location | B4: Vlasnik | C4: ARS METAL INDUSTRIES DOO | D4: List Nepokretnosti | E4: Locked | F4: 100% vlasništvo, bez tereta
A5: Company & Legal | B5: Crnogorska kompanija PIB | C5: 03570843 | D5: Rješenje o registraciji | E5: Locked | F5: Registrovana 19.06.2023.
A6: Company & Legal | B6: Turska matična firma PIB | C6: 03674762 | D6: Rješenje o registraciji | E6: Locked | F6: Dio stranog društva (17.07.2024.)
A7: Financial & Funding | B7: Total Project Cost (TPC) | C7: 27.796.156 € | D7: Titan Grid v4.5 | E7: Locked | F7: Ukupni troškovi projekta
A8: Financial & Funding | B8: Direct CAPEX (BoQ) | C8: 24.715.200 € | D8: Titan Grid v4.5 | E8: Locked | F8: Osnovni CAPEX
A9: Financial & Funding | B9: Contingency | C9: 2.471.520 € | D9: Titan Grid v4.5 (10%) | E9: Locked | F9: 10% od Direct CAPEX
A10: Financial & Funding | B10: Debt (gearing) | C10: 60% | D10: Titan Grid v4.5 | E10: Locked | F10: 16.677.694 €
A11: Financial & Funding | B11: Equity | C11: 40% | D11: Titan Grid v4.5 | E11: Locked | F11: 11.118.462 €
A12: Financial & Funding | B12: IDC (Interest During Construction) | C12: 1.031.579 € | D12: Titan Grid v4.5 | E12: Locked | F12: Kapitalizovani kamati
... A25: Debt & Coverage | B25: DSRA | C25: 6 mjeseci | D25: Titan Grid v4.5 | E25: Locked | F25: Debt Service Reserve Account

Sheet LAND ACQUISITION
A1: TITAN GRID CAPEX REGISTER | LAND ACQUISITION
A2: Category | B2: CAPEX item | C2: Description | D2: Quantity | E2: Unit | F2: Unit Price (EUR) | G2: Total Cost (EUR) | H2: % of Category | I2: Vendor | J2: Timeline | K2: Status | L2: Contingency % | M2: Contingency Amount | N2: Gross Total (EUR) | O2: Risk Notes
A3: Land acquisition | B3: Land purchase | C3: kupovina zemljišta | G3: =IFERROR(D3*F3,"") | H3: =IFERROR(G3/SUM($G$3:$G$25),0) | K3: Planned | L3: 0.1 | M3: =IFERROR(G3*L3,"") | N3: =IFERROR(G3+M3,"")
A4: Land acquisition | B4: Legal fees | C4: pravni troškovi | G4: =IFERROR(D4*F4,"") | H4: =IFERROR(G4/SUM($G$3:$G$25),0) | K4: Planned | L4: 0.1 | M4: =IFERROR(G4*L4,"") | N4: =IFERROR(G4+M4,"")
A5: Land acquisition | B5: Notary and registration | C5: katastar | G5: =IFERROR(D5*F5,"") | H5: =IFERROR(G5/SUM($G$3:$G$25),0) | K5: Planned | L5: 0.1 | M5: =IFERROR(G5*L5,"") | N5: =IFERROR(G5+M5,"")
A6: Land acquisition | B6: Land conversion | C6: prenamjena zemljišta | G6: =IFERROR(D6*F6,"") | H6: =IFERROR(G6/SUM($G$3:$G$25),0) | K6: Planned | L6: 0.1 | M6: =IFERROR(G6*L6,"") | N6: =IFERROR(G6+M6,"")
A7: Land acquisition | B7: Site surveys | C7: geodetski radovi | G7: =IFERROR(D7*F7,"") | H7: =IFERROR(G7/SUM($G$3:$G$25),0) | K7: Planned | L7: 0.1 | M7: =IFERROR(G7*L7,"") | N7: =IFERROR(G7+M7,"")
A8: Land acquisition | B8: Soil investigation | C8: geomehanika | G8: =IFERROR(D8*F8,"") | H8: =IFERROR(G8/SUM($G$3:$G$25),0) | K8: Planned | L8: 0.1 | M8: =IFERROR(G8*L8,"") | N8: =IFERROR(G8+M8,"")
A9: Land acquisition | B9: Environmental baseline | C9: početne studije | G9: =IFERROR(D9*F9,"") | H9: =IFERROR(G9/SUM($G$3:$G$25),0) | K9: Planned | L9: 0.1 | M9: =IFERROR(G9*L9,"") | N9: =IFERROR(G9+M9,"")
A10: Land acquisition | B10: Land clearing | C10: čišćenje zemljišta | G10: =IFERROR(D10*F10,"") | H10: =IFERROR(G10/SUM($G$3:$G$25),0) | K10: Planned | L10: 0.1 | M10: =IFERROR(G10*L10,"") | N10: =IFERROR(G10+M10,"")
A11: Land acquisition | B11: Demolition works | C11: uklanjanje postojećih objekata | G11: =IFERROR(D11*F11,"") | H11: =IFERROR(G11/SUM($G$3:$G$25),0) | K11: Planned | L11: 0.1 | M11: =IFERROR(G11*L11,"") | N11: =IFERROR(G11+M11,"")
A12: Land acquisition | B12: Land grading | C12: nivelacija terena | G12: =IFERROR(D12*F12,"") | H12: =IFERROR(G12/SUM($G$3:$G$25),0) | K12: Planned | L12: 0.1 | M12: =IFERROR(G12*L12,"") | N12: =IFERROR(G12+M12,"")
A13: Land acquisition | B13: Boundary marking | C13: obilježavanje parcele | G13: =IFERROR(D13*F13,"") | H13: =IFERROR(G13/SUM($G$3:$G$25),0) | K13: Planned | L13: 0.1 | M13: =IFERROR(G13*L13,"") | N13: =IFERROR(G13+M13,"")
A14: Land acquisition | B14: Access road preparation | C14: pristupni put | G14: =IFERROR(D14*F14,"") | H14: =IFERROR(G14/SUM($G$3:$G$25),0) | K14: Planned | L14: 0.1 | M14: =IFERROR(G14*L14,"") | N14: =IFERROR(G14+M14,"")
... A25: Land acquisition | B25: Land development planning | C25: planiranje razvoja lokacije | G25: =IFERROR(D25*F25,"") | H25: =IFERROR(G25/SUM($G$3:$G$25),0) | K25: Planned | L25: 0.1 | M25: =IFERROR(G25*L25,"") | N25: =IFERROR(G25+M25,"")
A27: === TOTAL CATEGORY === | G27: =SUM(G3:G25) | M27: =SUM(M3:M25) | N27: =SUM(N3:N25)
A29: Input logic: blue font/yellow fill = editable input | black = formula | green references in Summary | gray = locked assumptions.

Sheet SITE PREPARATION & CIVIL INFRAS
A1: TITAN GRID CAPEX REGISTER | SITE PREPARATION & CIVIL INFRAS
A2: Category | B2: CAPEX item | C2: Description | D2: Quantity | E2: Unit | F2: Unit Price (EUR) | G2: Total Cost (EUR) | H2: % of Category | I2: Vendor | J2: Timeline | K2: Status | L2: Contingency % | M2: Contingency Amount | N2: Gross Total (EUR) | O2: Risk Notes
A3: Site preparation | B3: Earthworks | C3: iskopi | G3: =IFERROR(D3*F3,"") | H3: =IFERROR(G3/SUM($G$3:$G$28),0) | K3: Planned | L3: 0.1 | M3: =IFERROR(G3*L3,"") | N3: =IFERROR(G3+M3,"")
A4: Site preparation | B4: Site leveling | C4: nivelacija | G4: =IFERROR(D4*F4,"") | H4: =IFERROR(G4/SUM($G$3:$G$28),0) | K4: Planned | L4: 0.1 | M4: =IFERROR(G4*L4,"") | N4: =IFERROR(G4+M4,"")
A5: Site preparation | B5: Soil stabilization | C5: stabilizacija tla | G5: =IFERROR(D5*F5,"") | H5: =IFERROR(G5/SUM($G$3:$G$28),0) | K5: Planned | L5: 0.1 | M5: =IFERROR(G5*L5,"") | N5: =IFERROR(G5+M5,"")
A6: Site preparation | B6: Land clearing | C6: uklanjanje vegetacije | G6: =IFERROR(D6*F6,"") | H6: =IFERROR(G6/SUM($G$3:$G$28),0) | K6: Planned | L6: 0.1 | M6: =IFERROR(G6*L6,"") | N6: =IFERROR(G6+M6,"")
A7: Site preparation | B7: Excavation and backfill | C7: iskop i nasip | G7: =IFERROR(D7*F7,"") | H7: =IFERROR(G7/SUM($G$3:$G$28),0) | K7: Planned | L7: 0.1 | M7: =IFERROR(G7*L7,"") | N7: =IFERROR(G7+M7,"")
A8: Site preparation | B8: Ground compaction | C8: zbijanje tla | G8: =IFERROR(D8*F8,"") | H8: =IFERROR(G8/SUM($G$3:$G$28),0) | K8: Planned | L8: 0.1 | M8: =IFERROR(G8*L8,"") | N8: =IFERROR(G8+M8,"")
A9: Site preparation | B9: Temporary site roads | C9: privremeni putevi | G9: =IFERROR(D9*F9,"") | H9: =IFERROR(G9/SUM($G$3:$G$28),0) | K9: Planned | L9: 0.1 | M9: =IFERROR(G9*L9,"") | N9: =IFERROR(G9+M9,"")
A10: Site preparation | B10: Construction site offices | C10: gradilišne kancelarije | G10: =IFERROR(D10*F10,"") | H10: =IFERROR(G10/SUM($G$3:$G$28),0) | K10: Planned | L10: 0.1 | M10: =IFERROR(G10*L10,"") | N10: =IFERROR(G10+M10,"")
A11: Site preparation | B11: Construction utilities | C11: privremena struja i voda | G11: =IFERROR(D11*F11,"") | H11: =IFERROR(G11/SUM($G$3:$G$28),0) | K11: Planned | L11: 0.1 | M11: =IFERROR(G11*L11,"") | N11: =IFERROR(G11+M11,"")
A12: Road infrastructure | B12: Internal roads | C12: putevi | G12: =IFERROR(D12*F12,"") | H12: =IFERROR(G12/SUM($G$3:$G$28),0) | K12: Planned | L12: 0.1 | M12: =IFERROR(G12*L12,"") | N12: =IFERROR(G12+M12,"")
A13: Road infrastructure | B13: Parking areas | C13: parking | G13: =IFERROR(D13*F13,"") | H13: =IFERROR(G13/SUM($G$3:$G$28),0) | K13: Planned | L13: 0.1 | M13: =IFERROR(G13*L13,"") | N13: =IFERROR(G13+M13,"")
A14: Road infrastructure | B14: Truck loading areas | C14: logistika | G14: =IFERROR(D14*F14,"") | H14: =IFERROR(G14/SUM($G$3:$G$28),0) | K14: Planned | L14: 0.1 | M14: =IFERROR(G14*L14,"") | N14: =IFERROR(G14+M14,"")
... A28: Security | B28: Access control infrastructure | C28: kontrola pristupa | G28: =IFERROR(D28*F28,"") | H28: =IFERROR(G28/SUM($G$3:$G$28),0) | K28: Planned | L28: 0.1 | M28: =IFERROR(G28*L28,"") | N28: =IFERROR(G28+M28,"")
A30: === TOTAL CATEGORY === | G30: =SUM(G3:G28) | M30: =SUM(M3:M28) | N30: =SUM(N3:N28)
A32: Input logic: blue font/yellow fill = editable input | black = formula | green references in Summary | gray = locked assumptions.

Sheet BUILDINGS (INDUSTRIAL FACILITIE
A1: TITAN GRID CAPEX REGISTER | BUILDINGS (INDUSTRIAL FACILITIE
A2: Category | B2: CAPEX item | C2: Description | D2: Quantity | E2: Unit | F2: Unit Price (EUR) | G2: Total Cost (EUR) | H2: % of Category | I2: Vendor | J2: Timeline | K2: Status | L2: Contingency % | M2: Contingency Amount | N2: Gross Total (EUR) | O2: Risk Notes
A3: Production building | B3: Steel structure | C3: čelična konstrukcija | G3: =IFERROR(D3*F3,"") | H3: =IFERROR(G3/SUM($G$3:$G$32),0) | K3: Planned | L3: 0.1 | M3: =IFERROR(G3*L3,"") | N3: =IFERROR(G3+M3,"")
A4: Production building | B4: Roof structure | C4: krov | G4: =IFERROR(D4*F4,"") | H4: =IFERROR(G4/SUM($G$3:$G$32),0) | K4: Planned | L4: 0.1 | M4: =IFERROR(G4*L4,"") | N4: =IFERROR(G4+M4,"")
A5: Production building | B5: Roof insulation | C5: krovna izolacija | G5: =IFERROR(D5*F5,"") | H5: =IFERROR(G5/SUM($G$3:$G$32),0) | K5: Planned | L5: 0.1 | M5: =IFERROR(G5*L5,"") | N5: =IFERROR(G5+M5,"")
A6: Production building | B6: Roof drainage | C6: odvodnja krova | G6: =IFERROR(D6*F6,"") | H6: =IFERROR(G6/SUM($G$3:$G$32),0) | K6: Planned | L6: 0.1 | M6: =IFERROR(G6*L6,"") | N6: =IFERROR(G6+M6,"")
A7: Production building | B7: Wall panels | C7: fasada | G7: =IFERROR(D7*F7,"") | H7: =IFERROR(G7/SUM($G$3:$G$32),0) | K7: Planned | L7: 0.1 | M7: =IFERROR(G7*L7,"") | N7: =IFERROR(G7+M7,"")
A8: Production building | B8: Thermal insulation | C8: termo izolacija | G8: =IFERROR(D8*F8,"") | H8: =IFERROR(G8/SUM($G$3:$G$32),0) | K8: Planned | L8: 0.1 | M8: =IFERROR(G8*L8,"") | N8: =IFERROR(G8+M8,"")
A9: Production building | B9: Industrial floors | C9: podovi | G9: =IFERROR(D9*F9,"") | H9: =IFERROR(G9/SUM($G$3:$G$32),0) | K9: Planned | L9: 0.1 | M9: =IFERROR(G9*L9,"") | N9: =IFERROR(G9+M9,"")
A10: Production building | B10: Heavy-duty reinforced floors | C10: podovi za tešku opremu | G10: =IFERROR(D10*F10,"") | H10: =IFERROR(G10/SUM($G$3:$G$32),0) | K10: Planned | L10: 0.1 | M10: =IFERROR(G10*L10,"") | N10: =IFERROR(G10+M10,"")
A11: Production building | B11: Crane rails | C11: kranske staze | G11: =IFERROR(D11*F11,"") | H11: =IFERROR(G11/SUM($G$3:$G$32),0) | K11: Planned | L11: 0.1 | M11: =IFERROR(G11*L11,"") | N11: =IFERROR(G11+M11,"")
A12: Production building | B12: Crane support columns | C12: stubovi za dizalice | G12: =IFERROR(D12*F12,"") | H12: =IFERROR(G12/SUM($G$3:$G$32),0) | K12: Planned | L12: 0.1 | M12: =IFERROR(G12*L12,"") | N12: =IFERROR(G12+M12,"")
A13: Production building | B13: Skylights | C13: krovni svjetlarnici | G13: =IFERROR(D13*F13,"") | H13: =IFERROR(G13/SUM($G$3:$G$32),0) | K13: Planned | L13: 0.1 | M13: =IFERROR(G13*L13,"") | N13: =IFERROR(G13+M13,"")
A14: Production building | B14: Industrial doors | C14: industrijska vrata | G14: =IFERROR(D14*F14,"") | H14: =IFERROR(G14/SUM($G$3:$G$32),0) | K14: Planned | L14: 0.1 | M14: =IFERROR(G14*L14,"") | N14: =IFERROR(G14+M14,"")
... A32: QA facilities | B32: Storage for test equipment | C32: skladište opreme | G32: =IFERROR(D32*F32,"") | H32: =IFERROR(G32/SUM($G$3:$G$32),0) | K32: Planned | L32: 0.1 | M32: =IFERROR(G32*L32,"") | N32: =IFERROR(G32+M32,"")
A34: === TOTAL CATEGORY === | G34: =SUM(G3:G32) | M34: =SUM(M3:M32) | N34: =SUM(N3:N32)
A36: Input logic: blue font/yellow fill = editable input | black = formula | green references in Summary | gray = locked assumptions.

Sheet PRODUCTION EQUIPMENT (CORE PROC
A1: TITAN GRID CAPEX REGISTER | PRODUCTION EQUIPMENT (CORE PROC
A2: Category | B2: CAPEX item | C2: Description | D2: Quantity | E2: Unit | F2: Unit Price (EUR) | G2: Total Cost (EUR) | H2: % of Category | I2: Vendor | J2: Timeline | K2: Status | L2: Contingency % | M2: Contingency Amount | N2: Gross Total (EUR) | O2: Risk Notes
A3: Core manufacturing | B3: Core cutting line | C3: rezanje jezgra | G3: =IFERROR(D3*F3,"") | H3: =IFERROR(G3/SUM($G$3:$G$35),0) | K3: Planned | L3: 0.1 | M3: =IFERROR(G3*L3,"") | N3: =IFERROR(G3+M3,"")
A4: Core manufacturing | B4: Slitting machine | C4: slitting | G4: =IFERROR(D4*F4,"") | H4: =IFERROR(G4/SUM($G$3:$G$35),0) | K4: Planned | L4: 0.1 | M4: =IFERROR(G4*L4,"") | N4: =IFERROR(G4+M4,"")
A5: Core manufacturing | B5: Core stacking tables | C5: slaganje | G5: =IFERROR(D5*F5,"") | H5: =IFERROR(G5/SUM($G$3:$G$35),0) | K5: Planned | L5: 0.1 | M5: =IFERROR(G5*L5,"") | N5: =IFERROR(G5+M5,"")
A6: Core manufacturing | B6: Core stacking presses | C6: presovanje jezgra | G6: =IFERROR(D6*F6,"") | H6: =IFERROR(G6/SUM($G$3:$G$35),0) | K6: Planned | L6: 0.1 | M6: =IFERROR(G6*L6,"") | N6: =IFERROR(G6+M6,"")
A7: Core manufacturing | B7: Core clamping system | C7: stezanje jezgra | G7: =IFERROR(D7*F7,"") | H7: =IFERROR(G7/SUM($G$3:$G$35),0) | K7: Planned | L7: 0.1 | M7: =IFERROR(G7*L7,"") | N7: =IFERROR(G7+M7,"")
A8: Core manufacturing | B8: Automatic core stacking line | C8: automatizovana linija | G8: =IFERROR(D8*F8,"") | H8: =IFERROR(G8/SUM($G$3:$G$35),0) | K8: Planned | L8: 0.1 | M8: =IFERROR(G8*L8,"") | N8: =IFERROR(G8+M8,"")
A9: Core manufacturing | B9: Core handling cranes | C9: manipulacija jezgra | G9: =IFERROR(D9*F9,"") | H9: =IFERROR(G9/SUM($G$3:$G$35),0) | K9: Planned | L9: 0.1 | M9: =IFERROR(G9*L9,"") | N9: =IFERROR(G9+M9,"")
A10: Core manufacturing | B10: Core tilting devices | C10: rotacija jezgra | G10: =IFERROR(D10*F10,"") | H10: =IFERROR(G10/SUM($G$3:$G$35),0) | K10: Planned | L10: 0.1 | M10: =IFERROR(G10*L10,"") | N10: =IFERROR(G10+M10,"")
A11: Core manufacturing | B11: Core annealing furnace | C11: termička obrada jezgra | G11: =IFERROR(D11*F11,"") | H11: =IFERROR(G11/SUM($G$3:$G$35),0) | K11: Planned | L11: 0.1 | M11: =IFERROR(G11*L11,"") | N11: =IFERROR(G11+M11,"")
A12: Winding | B12: CNC winding machines | C12: namotavanje | G12: =IFERROR(D12*F12,"") | H12: =IFERROR(G12/SUM($G$3:$G$35),0) | K12: Planned | L12: 0.1 | M12: =IFERROR(G12*L12,"") | N12: =IFERROR(G12+M12,"")
A13: Winding | B13: Foil winding machine | C13: foil winding | G13: =IFERROR(D13*F13,"") | H13: =IFERROR(G13/SUM($G$3:$G$35),0) | K13: Planned | L13: 0.1 | M13: =IFERROR(G13*L13,"") | N13: =IFERROR(G13+M13,"")
A14: Winding | B14: Coil pressing machines | C14: presovanje | G14: =IFERROR(D14*F14,"") | H14: =IFERROR(G14/SUM($G$3:$G$35),0) | K14: Planned | L14: 0.1 | M14: =IFERROR(G14*L14,"") | N14: =IFERROR(G14+M14,"")
... A35: Assembly | B35: Torque control systems | C35: kontrola momenta | G35: =IFERROR(D35*F35,"") | H35: =IFERROR(G35/SUM($G$3:$G$35),0) | K35: Planned | L35: 0.1 | M35: =IFERROR(G35*L35,"") | N35: =IFERROR(G35+M35,"")
A37: === TOTAL CATEGORY === | G37: =SUM(G3:G35) | M37: =SUM(M3:M35) | N37: =SUM(N3:N35)
A39: Input logic: blue font/yellow fill = editable input | black = formula | green references in Summary | gray = locked assumptions.

Sheet DRYING   INSULATION TECHNOLOGY
A1: TITAN GRID CAPEX REGISTER | DRYING INSULATION TECHNOLOGY
A2: Category | B2: CAPEX item | C2: Description | D2: Quantity | E2: Unit | F2: Unit Price (EUR) | G2: Total Cost (EUR) | H2: % of Category | I2: Vendor | J2: Timeline | K2: Status | L2: Contingency % | M2: Contingency Amount | N2: Gross Total (EUR) | O2: Risk Notes
A3: Drying systems | B3: Vacuum drying ovens | C3: vakuumske peći | G3: =IFERROR(D3*F3,"") | H3: =IFERROR(G3/SUM($G$3:$G$26),0) | K3: Planned | L3: 0.1 | M3: =IFERROR(G3*L3,"") | N3: =IFERROR(G3+M3,"")
A4: Drying systems | B4: VPD system | C4: vacuum pressure drying | G4: =IFERROR(D4*F4,"") | H4: =IFERROR(G4/SUM($G$3:$G$26),0) | K4: Planned | L4: 0.1 | M4: =IFERROR(G4*L4,"") | N4: =IFERROR(G4+M4,"")
A5: Drying systems | B5: VPI system | C5: impregnacija | G5: =IFERROR(D5*F5,"") | H5: =IFERROR(G5/SUM($G$3:$G$26),0) | K5: Planned | L5: 0.1 | M5: =IFERROR(G5*L5,"") | N5: =IFERROR(G5+M5,"")
A6: Drying systems | B6: Vacuum pumps | C6: vakuum pumpe | G6: =IFERROR(D6*F6,"") | H6: =IFERROR(G6/SUM($G$3:$G$26),0) | K6: Planned | L6: 0.1 | M6: =IFERROR(G6*L6,"") | N6: =IFERROR(G6+M6,"")
A7: Drying systems | B7: Oil vapor recovery | C7: rekuperacija | G7: =IFERROR(D7*F7,"") | H7: =IFERROR(G7/SUM($G$3:$G$26),0) | K7: Planned | L7: 0.1 | M7: =IFERROR(G7*L7,"") | N7: =IFERROR(G7+M7,"")
A8: Drying systems | B8: Vacuum chambers | C8: vakuumske komore | G8: =IFERROR(D8*F8,"") | H8: =IFERROR(G8/SUM($G$3:$G$26),0) | K8: Planned | L8: 0.1 | M8: =IFERROR(G8*L8,"") | N8: =IFERROR(G8+M8,"")
A9: Drying systems | B9: Heating systems for drying | C9: grijanje komora | G9: =IFERROR(D9*F9,"") | H9: =IFERROR(G9/SUM($G$3:$G$26),0) | K9: Planned | L9: 0.1 | M9: =IFERROR(G9*L9,"") | N9: =IFERROR(G9+M9,"")
A10: Drying systems | B10: Dry air generators | C10: generatori suhog zraka | G10: =IFERROR(D10*F10,"") | H10: =IFERROR(G10/SUM($G$3:$G$26),0) | K10: Planned | L10: 0.1 | M10: =IFERROR(G10*L10,"") | N10: =IFERROR(G10+M10,"")
A11: Drying systems | B11: Nitrogen drying system | C11: sušenje azotom | G11: =IFERROR(D11*F11,"") | H11: =IFERROR(G11/SUM($G$3:$G$26),0) | K11: Planned | L11: 0.1 | M11: =IFERROR(G11*L11,"") | N11: =IFERROR(G11+M11,"")
A12: Drying systems | B12: Oil heating systems | C12: grijanje ulja | G12: =IFERROR(D12*F12,"") | H12: =IFERROR(G12/SUM($G$3:$G$26),0) | K12: Planned | L12: 0.1 | M12: =IFERROR(G12*L12,"") | N12: =IFERROR(G12+M12,"")
A13: Drying systems | B13: Oil circulation pumps | C13: pumpe za ulje | G13: =IFERROR(D13*F13,"") | H13: =IFERROR(G13/SUM($G$3:$G$26),0) | K13: Planned | L13: 0.1 | M13: =IFERROR(G13*L13,"") | N13: =IFERROR(G13+M13,"")
A14: Drying systems | B14: Oil filtration systems | C14: filtracija ulja | G14: =IFERROR(D14*F14,"") | H14: =IFERROR(G14/SUM($G$3:$G$26),0) | K14: Planned | L14: 0.1 | M14: =IFERROR(G14*L14,"") | N14: =IFERROR(G14+M14,"")
... A26: Drying systems | B26: Process safety systems | C26: sigurnosni sistemi | G26: =IFERROR(D26*F26,"") | H26: =IFERROR(G26/SUM($G$3:$G$26),0) | K26: Planned | L26: 0.1 | M26: =IFERROR(G26*L26,"") | N26: =IFERROR(G26+M26,"")
A28: === TOTAL CATEGORY === | G28: =SUM(G3:G26) | M28: =SUM(M3:M26) | N28: =SUM(N3:N26)
A30: Input logic: blue font/yellow fill = editable input | black = formula | green references in Summary | gray = locked assumptions.

Sheet TANK FABRICATION   METAL PROCES
A1: TITAN GRID CAPEX REGISTER | TANK FABRICATION METAL PROCES
A2: Category | B2: CAPEX item | C2: Description | D2: Quantity | E2: Unit | F2: Unit Price (EUR) | G2: Total Cost (EUR) | H2: % of Category | I2: Vendor | J2: Timeline | K2: Status | L2: Contingency % | M2: Contingency Amount | N2: Gross Total (EUR) | O2: Risk Notes
A3: Metal fabrication | B3: CNC plasma cutting | C3: rezanje čelika | G3: =IFERROR(D3*F3,"") | H3: =IFERROR(G3/SUM($G$3:$G$35),0) | K3: Planned | L3: 0.1 | M3: =IFERROR(G3*L3,"") | N3: =IFERROR(G3+M3,"")
A4: Metal fabrication | B4: CNC laser cutting | C4: lasersko rezanje | G4: =IFERROR(D4*F4,"") | H4: =IFERROR(G4/SUM($G$3:$G$35),0) | K4: Planned | L4: 0.1 | M4: =IFERROR(G4*L4,"") | N4: =IFERROR(G4+M4,"")
A5: Metal fabrication | B5: Press brake | C5: savijanje | G5: =IFERROR(D5*F5,"") | H5: =IFERROR(G5/SUM($G$3:$G$35),0) | K5: Planned | L5: 0.1 | M5: =IFERROR(G5*L5,"") | N5: =IFERROR(G5+M5,"")
A6: Metal fabrication | B6: Plate rolling machine | C6: valjanje | G6: =IFERROR(D6*F6,"") | H6: =IFERROR(G6/SUM($G$3:$G$35),0) | K6: Planned | L6: 0.1 | M6: =IFERROR(G6*L6,"") | N6: =IFERROR(G6+M6,"")
A7: Metal fabrication | B7: Sheet metal bending machines | C7: savijanje limova | G7: =IFERROR(D7*F7,"") | H7: =IFERROR(G7/SUM($G$3:$G$35),0) | K7: Planned | L7: 0.1 | M7: =IFERROR(G7*L7,"") | N7: =IFERROR(G7+M7,"")
A8: Metal fabrication | B8: CNC drilling machines | C8: bušenje | G8: =IFERROR(D8*F8,"") | H8: =IFERROR(G8/SUM($G$3:$G$35),0) | K8: Planned | L8: 0.1 | M8: =IFERROR(G8*L8,"") | N8: =IFERROR(G8+M8,"")
A9: Metal fabrication | B9: Metal punching machines | C9: perforacija | G9: =IFERROR(D9*F9,"") | H9: =IFERROR(G9/SUM($G$3:$G$35),0) | K9: Planned | L9: 0.1 | M9: =IFERROR(G9*L9,"") | N9: =IFERROR(G9+M9,"")
A10: Metal fabrication | B10: Edge milling machines | C10: obrada ivica | G10: =IFERROR(D10*F10,"") | H10: =IFERROR(G10/SUM($G$3:$G$35),0) | K10: Planned | L10: 0.1 | M10: =IFERROR(G10*L10,"") | N10: =IFERROR(G10+M10,"")
A11: Metal fabrication | B11: Plate straightening machines | C11: ravnanje ploča | G11: =IFERROR(D11*F11,"") | H11: =IFERROR(G11/SUM($G$3:$G$35),0) | K11: Planned | L11: 0.1 | M11: =IFERROR(G11*L11,"") | N11: =IFERROR(G11+M11,"")
A12: Metal fabrication | B12: Metal cutting saws | C12: rezanje profila | G12: =IFERROR(D12*F12,"") | H12: =IFERROR(G12/SUM($G$3:$G$35),0) | K12: Planned | L12: 0.1 | M12: =IFERROR(G12*L12,"") | N12: =IFERROR(G12+M12,"")
A13: Welding | B13: Robotic welding systems | C13: robot zavarivanje | G13: =IFERROR(D13*F13,"") | H13: =IFERROR(G13/SUM($G$3:$G$35),0) | K13: Planned | L13: 0.1 | M13: =IFERROR(G13*L13,"") | N13: =IFERROR(G13+M13,"")
A14: Welding | B14: Manual welding stations | C14: ručno zavarivanje | G14: =IFERROR(D14*F14,"") | H14: =IFERROR(G14/SUM($G$3:$G$35),0) | K14: Planned | L14: 0.1 | M14: =IFERROR(G14*L14,"") | N14: =IFERROR(G14+M14,"")
... A35: Testing | B35: Dimensional inspection systems | C35: mjerenje dimenzija | G35: =IFERROR(D35*F35,"") | H35: =IFERROR(G35/SUM($G$3:$G$35),0) | K35: Planned | L35: 0.1 | M35: =IFERROR(G35*L35,"") | N35: =IFERROR(G35+M35,"")
A37: === TOTAL CATEGORY === | G37: =SUM(G3:G35) | M37: =SUM(M3:M35) | N37: =SUM(N3:N35)
A39: Input logic: blue font/yellow fill = editable input | black = formula | green references in Summary | gray = locked assumptions.

Sheet FINAL ASSEMBLY SYSTEMS
A1: TITAN GRID CAPEX REGISTER | FINAL ASSEMBLY SYSTEMS
A2: Category | B2: CAPEX item | C2: Description | D2: Quantity | E2: Unit | F2: Unit Price (EUR) | G2: Total Cost (EUR) | H2: % of Category | I2: Vendor | J2: Timeline | K2: Status | L2: Contingency % | M2: Contingency Amount | N2: Gross Total (EUR) | O2: Risk Notes
A3: Assembly | B3: Transformer assembly stations | C3: montaža | G3: =IFERROR(D3*F3,"") | H3: =IFERROR(G3/SUM($G$3:$G$30),0) | K3: Planned | L3: 0.1 | M3: =IFERROR(G3*L3,"") | N3: =IFERROR(G3+M3,"")
A4: Assembly | B4: Radiator installation stations | C4: radijatori | G4: =IFERROR(D4*F4,"") | H4: =IFERROR(G4/SUM($G$3:$G$30),0) | K4: Planned | L4: 0.1 | M4: =IFERROR(G4*L4,"") | N4: =IFERROR(G4+M4,"")
A5: Assembly | B5: Oil filling systems | C5: punjenje ulja | G5: =IFERROR(D5*F5,"") | H5: =IFERROR(G5/SUM($G$3:$G$30),0) | K5: Planned | L5: 0.1 | M5: =IFERROR(G5*L5,"") | N5: =IFERROR(G5+M5,"")
A6: Assembly | B6: Dry nitrogen systems | C6: inertni gas | G6: =IFERROR(D6*F6,"") | H6: =IFERROR(G6/SUM($G$3:$G$30),0) | K6: Planned | L6: 0.1 | M6: =IFERROR(G6*L6,"") | N6: =IFERROR(G6+M6,"")
A7: Assembly | B7: Transformer lifting systems | C7: dizanje transformatora | G7: =IFERROR(D7*F7,"") | H7: =IFERROR(G7/SUM($G$3:$G$30),0) | K7: Planned | L7: 0.1 | M7: =IFERROR(G7*L7,"") | N7: =IFERROR(G7+M7,"")
A8: Assembly | B8: Overhead bridge cranes | C8: mostne dizalice | G8: =IFERROR(D8*F8,"") | H8: =IFERROR(G8/SUM($G$3:$G$30),0) | K8: Planned | L8: 0.1 | M8: =IFERROR(G8*L8,"") | N8: =IFERROR(G8+M8,"")
A9: Assembly | B9: Hydraulic lifting tables | C9: hidraulične platforme | G9: =IFERROR(D9*F9,"") | H9: =IFERROR(G9/SUM($G$3:$G$30),0) | K9: Planned | L9: 0.1 | M9: =IFERROR(G9*L9,"") | N9: =IFERROR(G9+M9,"")
A10: Assembly | B10: Transformer tilting machines | C10: rotacija transformatora | G10: =IFERROR(D10*F10,"") | H10: =IFERROR(G10/SUM($G$3:$G$30),0) | K10: Planned | L10: 0.1 | M10: =IFERROR(G10*L10,"") | N10: =IFERROR(G10+M10,"")
A11: Assembly | B11: Active part insertion systems | C11: ubacivanje aktivnog dijela | G11: =IFERROR(D11*F11,"") | H11: =IFERROR(G11/SUM($G$3:$G$30),0) | K11: Planned | L11: 0.1 | M11: =IFERROR(G11*L11,"") | N11: =IFERROR(G11+M11,"")
A12: Assembly | B12: Bushing installation stations | C12: instalacija provodnika | G12: =IFERROR(D12*F12,"") | H12: =IFERROR(G12/SUM($G$3:$G$30),0) | K12: Planned | L12: 0.1 | M12: =IFERROR(G12*L12,"") | N12: =IFERROR(G12+M12,"")
A13: Assembly | B13: Tap changer installation stations | C13: instalacija regulacionih prekidača | G13: =IFERROR(D13*F13,"") | H13: =IFERROR(G13/SUM($G$3:$G$30),0) | K13: Planned | L13: 0.1 | M13: =IFERROR(G13*L13,"") | N13: =IFERROR(G13+M13,"")
A14: Assembly | B14: Cooling system installation stations | C14: instalacija sistema hlađenja | G14: =IFERROR(D14*F14,"") | H14: =IFERROR(G14/SUM($G$3:$G$30),0) | K14: Planned | L14: 0.1 | M14: =IFERROR(G14*L14,"") | N14: =IFERROR(G14+M14,"")
... A30: Assembly | B30: Lighting systems for assembly | C30: industrijska rasvjeta | G30: =IFERROR(D30*F30,"") | H30: =IFERROR(G30/SUM($G$3:$G$30),0) | K30: Planned | L30: 0.1 | M30: =IFERROR(G30*L30,"") | N30: =IFERROR(G30+M30,"")
A32: === TOTAL CATEGORY === | G32: =SUM(G3:G30) | M32: =SUM(M3:M30) | N32: =SUM(N3:N30)
A34: Input logic: blue font/yellow fill = editable input | black = formula | green references in Summary | gray = locked assumptions.

Sheet TESTING HALL EQUIPMENT
A1: TITAN GRID CAPEX REGISTER | TESTING HALL EQUIPMENT
A2: Category | B2: CAPEX item | C2: Description | D2: Quantity | E2: Unit | F2: Unit Price (EUR) | G2: Total Cost (EUR) | H2: % of Category | I2: Vendor | J2: Timeline | K2: Status | L2: Contingency % | M2: Contingency Amount | N2: Gross Total (EUR) | O2: Risk Notes
A3: Electrical testing | B3: High voltage test system | C3: HV test | G3: =IFERROR(D3*F3,"") | H3: =IFERROR(G3/SUM($G$3:$G$35),0) | K3: Planned | L3: 0.1 | M3: =IFERROR(G3*L3,"") | N3: =IFERROR(G3+M3,"")
A4: Electrical testing | B4: Impulse generator | C4: impulse test | G4: =IFERROR(D4*F4,"") | H4: =IFERROR(G4/SUM($G$3:$G$35),0) | K4: Planned | L4: 0.1 | M4: =IFERROR(G4*L4,"") | N4: =IFERROR(G4+M4,"")
A5: Electrical testing | B5: Partial discharge system | C5: PD test | G5: =IFERROR(D5*F5,"") | H5: =IFERROR(G5/SUM($G$3:$G$35),0) | K5: Planned | L5: 0.1 | M5: =IFERROR(G5*L5,"") | N5: =IFERROR(G5+M5,"")
A6: Electrical testing | B6: Load loss measurement | C6: gubici | G6: =IFERROR(D6*F6,"") | H6: =IFERROR(G6/SUM($G$3:$G$35),0) | K6: Planned | L6: 0.1 | M6: =IFERROR(G6*L6,"") | N6: =IFERROR(G6+M6,"")
A7: Electrical testing | B7: Control room systems | C7: kontrola | G7: =IFERROR(D7*F7,"") | H7: =IFERROR(G7/SUM($G$3:$G$35),0) | K7: Planned | L7: 0.1 | M7: =IFERROR(G7*L7,"") | N7: =IFERROR(G7+M7,"")
A8: Electrical testing | B8: Induced voltage test system | C8: inducirani napon | G8: =IFERROR(D8*F8,"") | H8: =IFERROR(G8/SUM($G$3:$G$35),0) | K8: Planned | L8: 0.1 | M8: =IFERROR(G8*L8,"") | N8: =IFERROR(G8+M8,"")
A9: Electrical testing | B9: Applied voltage test system | C9: primijenjeni napon | G9: =IFERROR(D9*F9,"") | H9: =IFERROR(G9/SUM($G$3:$G$35),0) | K9: Planned | L9: 0.1 | M9: =IFERROR(G9*L9,"") | N9: =IFERROR(G9+M9,"")
A10: Electrical testing | B10: Ratio test system | C10: omjer transformacije | G10: =IFERROR(D10*F10,"") | H10: =IFERROR(G10/SUM($G$3:$G$35),0) | K10: Planned | L10: 0.1 | M10: =IFERROR(G10*L10,"") | N10: =IFERROR(G10+M10,"")
A11: Electrical testing | B11: Winding resistance measurement | C11: otpor namotaja | G11: =IFERROR(D11*F11,"") | H11: =IFERROR(G11/SUM($G$3:$G$35),0) | K11: Planned | L11: 0.1 | M11: =IFERROR(G11*L11,"") | N11: =IFERROR(G11+M11,"")
A12: Electrical testing | B12: Magnetic balance test system | C12: magnetna ravnoteža | G12: =IFERROR(D12*F12,"") | H12: =IFERROR(G12/SUM($G$3:$G$35),0) | K12: Planned | L12: 0.1 | M12: =IFERROR(G12*L12,"") | N12: =IFERROR(G12+M12,"")
A13: Electrical testing | B13: No-load loss measurement | C13: gubici praznog hoda | G13: =IFERROR(D13*F13,"") | H13: =IFERROR(G13/SUM($G$3:$G$35),0) | K13: Planned | L13: 0.1 | M13: =IFERROR(G13*L13,"") | N13: =IFERROR(G13+M13,"")
A14: Electrical testing | B14: Short circuit impedance test | C14: impedansa | G14: =IFERROR(D14*F14,"") | H14: =IFERROR(G14/SUM($G$3:$G$35),0) | K14: Planned | L14: 0.1 | M14: =IFERROR(G14*L14,"") | N14: =IFERROR(G14+M14,"")
... A35: Electrical testing | B35: Environmental monitoring | C35: monitoring okoline | G35: =IFERROR(D35*F35,"") | H35: =IFERROR(G35/SUM($G$3:$G$35),0) | K35: Planned | L35: 0.1 | M35: =IFERROR(G35*L35,"") | N35: =IFERROR(G35+M35,"")
A37: === TOTAL CATEGORY === | G37: =SUM(G3:G35) | M37: =SUM(M3:M35) | N37: =SUM(N3:N35)
A39: Input logic: blue font/yellow fill = editable input | black = formula | green references in Summary | gray = locked assumptions.

Sheet INTERNAL LOGISTICS & MATERIAL 
A1: TITAN GRID CAPEX REGISTER | INTERNAL LOGISTICS & MATERIAL
A2: Category | B2: CAPEX item | C2: Description | D2: Quantity | E2: Unit | F2: Unit Price (EUR) | G2: Total Cost (EUR) | H2: % of Category | I2: Vendor | J2: Timeline | K2: Status | L2: Contingency % | M2: Contingency Amount | N2: Gross Total (EUR) | O2: Risk Notes
A3: Cranes | B3: Overhead cranes | C3: mostne dizalice | G3: =IFERROR(D3*F3,"") | H3: =IFERROR(G3/SUM($G$3:$G$27),0) | K3: Planned | L3: 0.1 | M3: =IFERROR(G3*L3,"") | N3: =IFERROR(G3+M3,"")
A4: Cranes | B4: Jib cranes | C4: kranovi | G4: =IFERROR(D4*F4,"") | H4: =IFERROR(G4/SUM($G$3:$G$27),0) | K4: Planned | L4: 0.1 | M4: =IFERROR(G4*L4,"") | N4: =IFERROR(G4+M4,"")
A5: Cranes | B5: Gantry cranes | C5: portalne dizalice | G5: =IFERROR(D5*F5,"") | H5: =IFERROR(G5/SUM($G$3:$G$27),0) | K5: Planned | L5: 0.1 | M5: =IFERROR(G5*L5,"") | N5: =IFERROR(G5+M5,"")
A6: Cranes | B6: Crane hoists | C6: vitla | G6: =IFERROR(D6*F6,"") | H6: =IFERROR(G6/SUM($G$3:$G$27),0) | K6: Planned | L6: 0.1 | M6: =IFERROR(G6*L6,"") | N6: =IFERROR(G6+M6,"")
A7: Cranes | B7: Crane control systems | C7: upravljanje dizalicama | G7: =IFERROR(D7*F7,"") | H7: =IFERROR(G7/SUM($G$3:$G$27),0) | K7: Planned | L7: 0.1 | M7: =IFERROR(G7*L7,"") | N7: =IFERROR(G7+M7,"")
A8: Cranes | B8: Crane safety systems | C8: sigurnosni sistemi | G8: =IFERROR(D8*F8,"") | H8: =IFERROR(G8/SUM($G$3:$G$27),0) | K8: Planned | L8: 0.1 | M8: =IFERROR(G8*L8,"") | N8: =IFERROR(G8+M8,"")
A9: Transport | B9: Forklifts | C9: viljuškari | G9: =IFERROR(D9*F9,"") | H9: =IFERROR(G9/SUM($G$3:$G$27),0) | K9: Planned | L9: 0.1 | M9: =IFERROR(G9*L9,"") | N9: =IFERROR(G9+M9,"")
A10: Transport | B10: Heavy transport trolleys | C10: transport | G10: =IFERROR(D10*F10,"") | H10: =IFERROR(G10/SUM($G$3:$G$27),0) | K10: Planned | L10: 0.1 | M10: =IFERROR(G10*L10,"") | N10: =IFERROR(G10+M10,"")
A11: Transport | B11: Electric pallet trucks | C11: električni paletari | G11: =IFERROR(D11*F11,"") | H11: =IFERROR(G11/SUM($G$3:$G$27),0) | K11: Planned | L11: 0.1 | M11: =IFERROR(G11*L11,"") | N11: =IFERROR(G11+M11,"")
A12: Transport | B12: Industrial tractors | C12: industrijski tegljači | G12: =IFERROR(D12*F12,"") | H12: =IFERROR(G12/SUM($G$3:$G$27),0) | K12: Planned | L12: 0.1 | M12: =IFERROR(G12*L12,"") | N12: =IFERROR(G12+M12,"")
A13: Transport | B13: Rail transport carts | C13: šinski transport | G13: =IFERROR(D13*F13,"") | H13: =IFERROR(G13/SUM($G$3:$G$27),0) | K13: Planned | L13: 0.1 | M13: =IFERROR(G13*L13,"") | N13: =IFERROR(G13+M13,"")
A14: Transport | B14: Motorized transport platforms | C14: transportne platforme | G14: =IFERROR(D14*F14,"") | H14: =IFERROR(G14/SUM($G$3:$G$27),0) | K14: Planned | L14: 0.1 | M14: =IFERROR(G14*L14,"") | N14: =IFERROR(G14+M14,"")
... A27: Automation | B27: Smart factory integration | C27: integracija industrija 4.0 | G27: =IFERROR(D27*F27,"") | H27: =IFERROR(G27/SUM($G$3:$G$27),0) | K27: Planned | L27: 0.1 | M27: =IFERROR(G27*L27,"") | N27: =IFERROR(G27+M27,"")
A29: === TOTAL CATEGORY === | G29: =SUM(G3:G27) | M29: =SUM(M3:M27) | N29: =SUM(N3:N27)
A31: Input logic: blue font/yellow fill = editable input | black = formula | green references in Summary | gray = locked assumptions.

Sheet UTILITIES & ENERGY INFRASTRUCTU
A1: TITAN GRID CAPEX REGISTER | UTILITIES & ENERGY INFRASTRUCTU
A2: Category | B2: CAPEX item | C2: Description | D2: Quantity | E2: Unit | F2: Unit Price (EUR) | G2: Total Cost (EUR) | H2: % of Category | I2: Vendor | J2: Timeline | K2: Status | L2: Contingency % | M2: Contingency Amount | N2: Gross Total (EUR) | O2: Risk Notes
A3: Power | B3: Substation | C3: trafostanica | G3: =IFERROR(D3*F3,"") | H3: =IFERROR(G3/SUM($G$3:$G$42),0) | K3: Planned | L3: 0.1 | M3: =IFERROR(G3*L3,"") | N3: =IFERROR(G3+M3,"")
A4: Power | B4: Power distribution | C4: razvod | G4: =IFERROR(D4*F4,"") | H4: =IFERROR(G4/SUM($G$3:$G$42),0) | K4: Planned | L4: 0.1 | M4: =IFERROR(G4*L4,"") | N4: =IFERROR(G4+M4,"")
A5: Power | B5: Medium voltage switchgear | C5: srednjenaponski razvod | G5: =IFERROR(D5*F5,"") | H5: =IFERROR(G5/SUM($G$3:$G$42),0) | K5: Planned | L5: 0.1 | M5: =IFERROR(G5*L5,"") | N5: =IFERROR(G5+M5,"")
A6: Power | B6: Low voltage switchgear | C6: niskonaponski razvod | G6: =IFERROR(D6*F6,"") | H6: =IFERROR(G6/SUM($G$3:$G$42),0) | K6: Planned | L6: 0.1 | M6: =IFERROR(G6*L6,"") | N6: =IFERROR(G6+M6,"")
A7: Power | B7: Backup generators | C7: rezervni generatori | G7: =IFERROR(D7*F7,"") | H7: =IFERROR(G7/SUM($G$3:$G$42),0) | K7: Planned | L7: 0.1 | M7: =IFERROR(G7*L7,"") | N7: =IFERROR(G7+M7,"")
A8: Power | B8: UPS systems | C8: besprekidno napajanje | G8: =IFERROR(D8*F8,"") | H8: =IFERROR(G8/SUM($G$3:$G$42),0) | K8: Planned | L8: 0.1 | M8: =IFERROR(G8*L8,"") | N8: =IFERROR(G8+M8,"")
A9: Power | B9: Power factor correction | C9: kompenzacija jalove energije | G9: =IFERROR(D9*F9,"") | H9: =IFERROR(G9/SUM($G$3:$G$42),0) | K9: Planned | L9: 0.1 | M9: =IFERROR(G9*L9,"") | N9: =IFERROR(G9+M9,"")
A10: Power | B10: Cable trays | C10: kablovske trase | G10: =IFERROR(D10*F10,"") | H10: =IFERROR(G10/SUM($G$3:$G$42),0) | K10: Planned | L10: 0.1 | M10: =IFERROR(G10*L10,"") | N10: =IFERROR(G10+M10,"")
A11: Power | B11: Industrial lighting systems | C11: industrijska rasvjeta | G11: =IFERROR(D11*F11,"") | H11: =IFERROR(G11/SUM($G$3:$G$42),0) | K11: Planned | L11: 0.1 | M11: =IFERROR(G11*L11,"") | N11: =IFERROR(G11+M11,"")
A12: Power | B12: Emergency lighting | C12: sigurnosna rasvjeta | G12: =IFERROR(D12*F12,"") | H12: =IFERROR(G12/SUM($G$3:$G$42),0) | K12: Planned | L12: 0.1 | M12: =IFERROR(G12*L12,"") | N12: =IFERROR(G12+M12,"")
A13: Air | B13: Compressors | C13: kompresori | G13: =IFERROR(D13*F13,"") | H13: =IFERROR(G13/SUM($G$3:$G$42),0) | K13: Planned | L13: 0.1 | M13: =IFERROR(G13*L13,"") | N13: =IFERROR(G13+M13,"")
A14: Air | B14: Air dryers | C14: sušači | G14: =IFERROR(D14*F14,"") | H14: =IFERROR(G14/SUM($G$3:$G$42),0) | K14: Planned | L14: 0.1 | M14: =IFERROR(G14*L14,"") | N14: =IFERROR(G14+M14,"")
... A42: Monitoring | B42: Process monitoring sensors | C42: senzori | G42: =IFERROR(D42*F42,"") | H42: =IFERROR(G42/SUM($G$3:$G$42),0) | K42: Planned | L42: 0.1 | M42: =IFERROR(G42*L42,"") | N42: =IFERROR(G42+M42,"")
A44: === TOTAL CATEGORY === | G44: =SUM(G3:G42) | M44: =SUM(M3:M42) | N44: =SUM(N3:N42)
A46: Input logic: blue font/yellow fill = editable input | black = formula | green references in Summary | gray = locked assumptions.

Sheet RENEWABLES & ENERGY MANAGEMENT
A1: TITAN GRID CAPEX REGISTER | RENEWABLES & ENERGY MANAGEMENT
A2: Category | B2: CAPEX item | C2: Description | D2: Quantity | E2: Unit | F2: Unit Price (EUR) | G2: Total Cost (EUR) | H2: % of Category | I2: Vendor | J2: Timeline | K2: Status | L2: Contingency % | M2: Contingency Amount | N2: Gross Total (EUR) | O2: Risk Notes
A3: Renewables | B3: Solar PV system | C3: solarna elektrana | G3: =IFERROR(D3*F3,"") | H3: =IFERROR(G3/SUM($G$3:$G$28),0) | K3: Planned | L3: 0.1 | M3: =IFERROR(G3*L3,"") | N3: =IFERROR(G3+M3,"")
A4: Renewables | B4: Inverters | C4: inverteri | G4: =IFERROR(D4*F4,"") | H4: =IFERROR(G4/SUM($G$3:$G$28),0) | K4: Planned | L4: 0.1 | M4: =IFERROR(G4*L4,"") | N4: =IFERROR(G4+M4,"")
A5: Energy | B5: Battery storage | C5: baterije | G5: =IFERROR(D5*F5,"") | H5: =IFERROR(G5/SUM($G$3:$G$28),0) | K5: Planned | L5: 0.1 | M5: =IFERROR(G5*L5,"") | N5: =IFERROR(G5+M5,"")
A6: Energy | B6: Energy management system | C6: EMS | G6: =IFERROR(D6*F6,"") | H6: =IFERROR(G6/SUM($G$3:$G$28),0) | K6: Planned | L6: 0.1 | M6: =IFERROR(G6*L6,"") | N6: =IFERROR(G6+M6,"")
A7: Renewables | B7: PV mounting structures | C7: nosači panela | G7: =IFERROR(D7*F7,"") | H7: =IFERROR(G7/SUM($G$3:$G$28),0) | K7: Planned | L7: 0.1 | M7: =IFERROR(G7*L7,"") | N7: =IFERROR(G7+M7,"")
A8: Renewables | B8: Solar panels | C8: solarni moduli | G8: =IFERROR(D8*F8,"") | H8: =IFERROR(G8/SUM($G$3:$G$28),0) | K8: Planned | L8: 0.1 | M8: =IFERROR(G8*L8,"") | N8: =IFERROR(G8+M8,"")
A9: Renewables | B9: DC combiner boxes | C9: DC razvod | G9: =IFERROR(D9*F9,"") | H9: =IFERROR(G9/SUM($G$3:$G$28),0) | K9: Planned | L9: 0.1 | M9: =IFERROR(G9*L9,"") | N9: =IFERROR(G9+M9,"")
A10: Renewables | B10: AC distribution panels | C10: AC razvod | G10: =IFERROR(D10*F10,"") | H10: =IFERROR(G10/SUM($G$3:$G$28),0) | K10: Planned | L10: 0.1 | M10: =IFERROR(G10*L10,"") | N10: =IFERROR(G10+M10,"")
A11: Renewables | B11: PV monitoring systems | C11: monitoring sistema | G11: =IFERROR(D11*F11,"") | H11: =IFERROR(G11/SUM($G$3:$G$28),0) | K11: Planned | L11: 0.1 | M11: =IFERROR(G11*L11,"") | N11: =IFERROR(G11+M11,"")
A12: Renewables | B12: Weather monitoring station | C12: meteorološka stanica | G12: =IFERROR(D12*F12,"") | H12: =IFERROR(G12/SUM($G$3:$G$28),0) | K12: Planned | L12: 0.1 | M12: =IFERROR(G12*L12,"") | N12: =IFERROR(G12+M12,"")
A13: Renewables | B13: PV cabling systems | C13: solarni kablovi | G13: =IFERROR(D13*F13,"") | H13: =IFERROR(G13/SUM($G$3:$G$28),0) | K13: Planned | L13: 0.1 | M13: =IFERROR(G13*L13,"") | N13: =IFERROR(G13+M13,"")
A14: Renewables | B14: Grid connection equipment | C14: priključak na mrežu | G14: =IFERROR(D14*F14,"") | H14: =IFERROR(G14/SUM($G$3:$G$28),0) | K14: Planned | L14: 0.1 | M14: =IFERROR(G14*L14,"") | N14: =IFERROR(G14+M14,"")
... A28: Energy | B28: ESG reporting software | C28: ESG izvještavanje | G28: =IFERROR(D28*F28,"") | H28: =IFERROR(G28/SUM($G$3:$G$28),0) | K28: Planned | L28: 0.1 | M28: =IFERROR(G28*L28,"") | N28: =IFERROR(G28+M28,"")
A30: === TOTAL CATEGORY === | G30: =SUM(G3:G28) | M30: =SUM(M3:M28) | N30: =SUM(N3:N28)
A32: Input logic: blue font/yellow fill = editable input | black = formula | green references in Summary | gray = locked assumptions.

Sheet IT & DIGITAL INFRASTRUCTURE
A1: TITAN GRID CAPEX REGISTER | IT & DIGITAL INFRASTRUCTURE
A2: Category | B2: CAPEX item | C2: Description | D2: Quantity | E2: Unit | F2: Unit Price (EUR) | G2: Total Cost (EUR) | H2: % of Category | I2: Vendor | J2: Timeline | K2: Status | L2: Contingency % | M2: Contingency Amount | N2: Gross Total (EUR) | O2: Risk Notes
A3: IT | B3: Servers | C3: serveri | G3: =IFERROR(D3*F3,"") | H3: =IFERROR(G3/SUM($G$3:$G$37),0) | K3: Planned | L3: 0.1 | M3: =IFERROR(G3*L3,"") | N3: =IFERROR(G3+M3,"")
A4: IT | B4: Network infrastructure | C4: mreža | G4: =IFERROR(D4*F4,"") | H4: =IFERROR(G4/SUM($G$3:$G$37),0) | K4: Planned | L4: 0.1 | M4: =IFERROR(G4*L4,"") | N4: =IFERROR(G4+M4,"")
A5: Software | B5: ERP system | C5: ERP | G5: =IFERROR(D5*F5,"") | H5: =IFERROR(G5/SUM($G$3:$G$37),0) | K5: Planned | L5: 0.1 | M5: =IFERROR(G5*L5,"") | N5: =IFERROR(G5+M5,"")
A6: Software | B6: MES system | C6: proizvodnja | G6: =IFERROR(D6*F6,"") | H6: =IFERROR(G6/SUM($G$3:$G$37),0) | K6: Planned | L6: 0.1 | M6: =IFERROR(G6*L6,"") | N6: =IFERROR(G6+M6,"")
A7: Software | B7: Engineering software | C7: CAD | G7: =IFERROR(D7*F7,"") | H7: =IFERROR(G7/SUM($G$3:$G$37),0) | K7: Planned | L7: 0.1 | M7: =IFERROR(G7*L7,"") | N7: =IFERROR(G7+M7,"")
A8: IT | B8: Data center racks | C8: server ormari | G8: =IFERROR(D8*F8,"") | H8: =IFERROR(G8/SUM($G$3:$G$37),0) | K8: Planned | L8: 0.1 | M8: =IFERROR(G8*L8,"") | N8: =IFERROR(G8+M8,"")
A9: IT | B9: Backup storage systems | C9: backup sistemi | G9: =IFERROR(D9*F9,"") | H9: =IFERROR(G9/SUM($G$3:$G$37),0) | K9: Planned | L9: 0.1 | M9: =IFERROR(G9*L9,"") | N9: =IFERROR(G9+M9,"")
A10: IT | B10: Network switches | C10: mrežni switch | G10: =IFERROR(D10*F10,"") | H10: =IFERROR(G10/SUM($G$3:$G$37),0) | K10: Planned | L10: 0.1 | M10: =IFERROR(G10*L10,"") | N10: =IFERROR(G10+M10,"")
A11: IT | B11: Industrial routers | C11: industrijski ruteri | G11: =IFERROR(D11*F11,"") | H11: =IFERROR(G11/SUM($G$3:$G$37),0) | K11: Planned | L11: 0.1 | M11: =IFERROR(G11*L11,"") | N11: =IFERROR(G11+M11,"")
A12: IT | B12: Fiber optic network | C12: optička mreža | G12: =IFERROR(D12*F12,"") | H12: =IFERROR(G12/SUM($G$3:$G$37),0) | K12: Planned | L12: 0.1 | M12: =IFERROR(G12*L12,"") | N12: =IFERROR(G12+M12,"")
A13: IT | B13: Wireless access points | C13: WiFi pristup | G13: =IFERROR(D13*F13,"") | H13: =IFERROR(G13/SUM($G$3:$G$37),0) | K13: Planned | L13: 0.1 | M13: =IFERROR(G13*L13,"") | N13: =IFERROR(G13+M13,"")
A14: IT | B14: Firewall security systems | C14: sigurnosni firewall | G14: =IFERROR(D14*F14,"") | H14: =IFERROR(G14/SUM($G$3:$G$37),0) | K14: Planned | L14: 0.1 | M14: =IFERROR(G14*L14,"") | N14: =IFERROR(G14+M14,"")
... A37: IT | B37: RFID systems | C37: RFID | G37: =IFERROR(D37*F37,"") | H37: =IFERROR(G37/SUM($G$3:$G$37),0) | K37: Planned | L37: 0.1 | M37: =IFERROR(G37*L37,"") | N37: =IFERROR(G37+M37,"")
A39: === TOTAL CATEGORY === | G39: =SUM(G3:G37) | M39: =SUM(M3:M37) | N39: =SUM(N3:N37)
A41: Input logic: blue font/yellow fill = editable input | black = formula | green references in Summary | gray = locked assumptions.

Sheet QA LABORATORY & MATERIAL TESTIN
A1: TITAN GRID CAPEX REGISTER | QA LABORATORY & MATERIAL TESTIN
A2: Category | B2: CAPEX item | C2: Description | D2: Quantity | E2: Unit | F2: Unit Price (EUR) | G2: Total Cost (EUR) | H2: % of Category | I2: Vendor | J2: Timeline | K2: Status | L2: Contingency % | M2: Contingency Amount | N2: Gross Total (EUR) | O2: Risk Notes
A3: Testing | B3: Oil analysis lab | C3: ulje | G3: =IFERROR(D3*F3,"") | H3: =IFERROR(G3/SUM($G$3:$G$32),0) | K3: Planned | L3: 0.1 | M3: =IFERROR(G3*L3,"") | N3: =IFERROR(G3+M3,"")
A4: Testing | B4: Insulation lab | C4: izolacija | G4: =IFERROR(D4*F4,"") | H4: =IFERROR(G4/SUM($G$3:$G$32),0) | K4: Planned | L4: 0.1 | M4: =IFERROR(G4*L4,"") | N4: =IFERROR(G4+M4,"")
A5: Testing | B5: Material testing | C5: materijali | G5: =IFERROR(D5*F5,"") | H5: =IFERROR(G5/SUM($G$3:$G$32),0) | K5: Planned | L5: 0.1 | M5: =IFERROR(G5*L5,"") | N5: =IFERROR(G5+M5,"")
A6: Testing | B6: CMM machine | C6: mjerenja | G6: =IFERROR(D6*F6,"") | H6: =IFERROR(G6/SUM($G$3:$G$32),0) | K6: Planned | L6: 0.1 | M6: =IFERROR(G6*L6,"") | N6: =IFERROR(G6+M6,"")
A7: Testing | B7: Oil dielectric strength tester | C7: test dielektrične čvrstoće ulja | G7: =IFERROR(D7*F7,"") | H7: =IFERROR(G7/SUM($G$3:$G$32),0) | K7: Planned | L7: 0.1 | M7: =IFERROR(G7*L7,"") | N7: =IFERROR(G7+M7,"")
A8: Testing | B8: Dissolved gas analysis system | C8: DGA analiza ulja | G8: =IFERROR(D8*F8,"") | H8: =IFERROR(G8/SUM($G$3:$G$32),0) | K8: Planned | L8: 0.1 | M8: =IFERROR(G8*L8,"") | N8: =IFERROR(G8+M8,"")
A9: Testing | B9: Moisture analysis system | C9: vlaga u ulju | G9: =IFERROR(D9*F9,"") | H9: =IFERROR(G9/SUM($G$3:$G$32),0) | K9: Planned | L9: 0.1 | M9: =IFERROR(G9*L9,"") | N9: =IFERROR(G9+M9,"")
A10: Testing | B10: Oil acidity testing | C10: kiselost ulja | G10: =IFERROR(D10*F10,"") | H10: =IFERROR(G10/SUM($G$3:$G$32),0) | K10: Planned | L10: 0.1 | M10: =IFERROR(G10*L10,"") | N10: =IFERROR(G10+M10,"")
A11: Testing | B11: Oil particle counter | C11: kontaminacija ulja | G11: =IFERROR(D11*F11,"") | H11: =IFERROR(G11/SUM($G$3:$G$32),0) | K11: Planned | L11: 0.1 | M11: =IFERROR(G11*L11,"") | N11: =IFERROR(G11+M11,"")
A12: Testing | B12: Oil viscosity tester | C12: viskoznost ulja | G12: =IFERROR(D12*F12,"") | H12: =IFERROR(G12/SUM($G$3:$G$32),0) | K12: Planned | L12: 0.1 | M12: =IFERROR(G12*L12,"") | N12: =IFERROR(G12+M12,"")
A13: Testing | B13: Insulation resistance tester | C13: otpor izolacije | G13: =IFERROR(D13*F13,"") | H13: =IFERROR(G13/SUM($G$3:$G$32),0) | K13: Planned | L13: 0.1 | M13: =IFERROR(G13*L13,"") | N13: =IFERROR(G13+M13,"")
A14: Testing | B14: Insulation aging ovens | C14: starenje izolacije | G14: =IFERROR(D14*F14,"") | H14: =IFERROR(G14/SUM($G$3:$G$32),0) | K14: Planned | L14: 0.1 | M14: =IFERROR(G14*L14,"") | N14: =IFERROR(G14+M14,"")
... A32: Testing | B32: Laboratory safety systems | C32: sigurnost | G32: =IFERROR(D32*F32,"") | H32: =IFERROR(G32/SUM($G$3:$G$32),0) | K32: Planned | L32: 0.1 | M32: =IFERROR(G32*L32,"") | N32: =IFERROR(G32+M32,"")
A34: === TOTAL CATEGORY === | G34: =SUM(G3:G32) | M34: =SUM(M3:M32) | N34: =SUM(N3:N32)
A36: Input logic: blue font/yellow fill = editable input | black = formula | green references in Summary | gray = locked assumptions.

Sheet TRANSPORT & FLEET
A1: TITAN GRID CAPEX REGISTER | TRANSPORT & FLEET
A2: Category | B2: CAPEX item | C2: Description | D2: Quantity | E2: Unit | F2: Unit Price (EUR) | G2: Total Cost (EUR) | H2: % of Category | I2: Vendor | J2: Timeline | K2: Status | L2: Contingency % | M2: Contingency Amount | N2: Gross Total (EUR) | O2: Risk Notes
A3: Transport | B3: Heavy trucks | C3: kamioni | G3: =IFERROR(D3*F3,"") | H3: =IFERROR(G3/SUM($G$3:$G$27),0) | K3: Planned | L3: 0.1 | M3: =IFERROR(G3*L3,"") | N3: =IFERROR(G3+M3,"")
A4: Transport | B4: Vans | C4: kombiji | G4: =IFERROR(D4*F4,"") | H4: =IFERROR(G4/SUM($G$3:$G$27),0) | K4: Planned | L4: 0.1 | M4: =IFERROR(G4*L4,"") | N4: =IFERROR(G4+M4,"")
A5: Transport | B5: Forklifts | C5: viljuškari | G5: =IFERROR(D5*F5,"") | H5: =IFERROR(G5/SUM($G$3:$G$27),0) | K5: Planned | L5: 0.1 | M5: =IFERROR(G5*L5,"") | N5: =IFERROR(G5+M5,"")
A6: Transport | B6: Service vehicles | C6: službena | G6: =IFERROR(D6*F6,"") | H6: =IFERROR(G6/SUM($G$3:$G$27),0) | K6: Planned | L6: 0.1 | M6: =IFERROR(G6*L6,"") | N6: =IFERROR(G6+M6,"")
A7: Transport | B7: Heavy-duty tractor units | C7: tegljači | G7: =IFERROR(D7*F7,"") | H7: =IFERROR(G7/SUM($G$3:$G$27),0) | K7: Planned | L7: 0.1 | M7: =IFERROR(G7*L7,"") | N7: =IFERROR(G7+M7,"")
A8: Transport | B8: Low-bed trailers | C8: niskopodni prikolice | G8: =IFERROR(D8*F8,"") | H8: =IFERROR(G8/SUM($G$3:$G$27),0) | K8: Planned | L8: 0.1 | M8: =IFERROR(G8*L8,"") | N8: =IFERROR(G8+M8,"")
A9: Transport | B9: Transformer transport trailers | C9: specijalne prikolice | G9: =IFERROR(D9*F9,"") | H9: =IFERROR(G9/SUM($G$3:$G$27),0) | K9: Planned | L9: 0.1 | M9: =IFERROR(G9*L9,"") | N9: =IFERROR(G9+M9,"")
A10: Transport | B10: Container trucks | C10: kontejnerski kamioni | G10: =IFERROR(D10*F10,"") | H10: =IFERROR(G10/SUM($G$3:$G$27),0) | K10: Planned | L10: 0.1 | M10: =IFERROR(G10*L10,"") | N10: =IFERROR(G10+M10,"")
A11: Transport | B11: Flatbed trucks | C11: kamioni platforme | G11: =IFERROR(D11*F11,"") | H11: =IFERROR(G11/SUM($G$3:$G$27),0) | K11: Planned | L11: 0.1 | M11: =IFERROR(G11*L11,"") | N11: =IFERROR(G11+M11,"")
A12: Transport | B12: Box trucks | C12: zatvoreni kamioni | G12: =IFERROR(D12*F12,"") | H12: =IFERROR(G12/SUM($G$3:$G$27),0) | K12: Planned | L12: 0.1 | M12: =IFERROR(G12*L12,"") | N12: =IFERROR(G12+M12,"")
A13: Transport | B13: Pickup trucks | C13: pickup vozila | G13: =IFERROR(D13*F13,"") | H13: =IFERROR(G13/SUM($G$3:$G$27),0) | K13: Planned | L13: 0.1 | M13: =IFERROR(G13*L13,"") | N13: =IFERROR(G13+M13,"")
A14: Transport | B14: Electric forklifts | C14: električni viljuškari | G14: =IFERROR(D14*F14,"") | H14: =IFERROR(G14/SUM($G$3:$G$27),0) | K14: Planned | L14: 0.1 | M14: =IFERROR(G14*L14,"") | N14: =IFERROR(G14+M14,"")
... A27: Transport | B27: Spare parts storage | C27: rezervni dijelovi | G27: =IFERROR(D27*F27,"") | H27: =IFERROR(G27/SUM($G$3:$G$27),0) | K27: Planned | L27: 0.1 | M27: =IFERROR(G27*L27,"") | N27: =IFERROR(G27+M27,"")
A29: === TOTAL CATEGORY === | G29: =SUM(G3:G27) | M29: =SUM(M3:M27) | N29: =SUM(N3:N27)
A31: Input logic: blue font/yellow fill = editable input | black = formula | green references in Summary | gray = locked assumptions.

Sheet SECURITY & SAFETY SYSTEMS
A1: TITAN GRID CAPEX REGISTER | SECURITY & SAFETY SYSTEMS
A2: Category | B2: CAPEX item | C2: Description | D2: Quantity | E2: Unit | F2: Unit Price (EUR) | G2: Total Cost (EUR) | H2: % of Category | I2: Vendor | J2: Timeline | K2: Status | L2: Contingency % | M2: Contingency Amount | N2: Gross Total (EUR) | O2: Risk Notes
A3: Security | B3: CCTV system | C3: kamere | G3: =IFERROR(D3*F3,"") | H3: =IFERROR(G3/SUM($G$3:$G$32),0) | K3: Planned | L3: 0.1 | M3: =IFERROR(G3*L3,"") | N3: =IFERROR(G3+M3,"")
A4: Security | B4: Access control | C4: kontrola | G4: =IFERROR(D4*F4,"") | H4: =IFERROR(G4/SUM($G$3:$G$32),0) | K4: Planned | L4: 0.1 | M4: =IFERROR(G4*L4,"") | N4: =IFERROR(G4+M4,"")
A5: Security | B5: Alarm systems | C5: alarm | G5: =IFERROR(D5*F5,"") | H5: =IFERROR(G5/SUM($G$3:$G$32),0) | K5: Planned | L5: 0.1 | M5: =IFERROR(G5*L5,"") | N5: =IFERROR(G5+M5,"")
A6: Security | B6: Fire detection | C6: detekcija | G6: =IFERROR(D6*F6,"") | H6: =IFERROR(G6/SUM($G$3:$G$32),0) | K6: Planned | L6: 0.1 | M6: =IFERROR(G6*L6,"") | N6: =IFERROR(G6+M6,"")
A7: Security | B7: Perimeter surveillance cameras | C7: perimetarske kamere | G7: =IFERROR(D7*F7,"") | H7: =IFERROR(G7/SUM($G$3:$G$32),0) | K7: Planned | L7: 0.1 | M7: =IFERROR(G7*L7,"") | N7: =IFERROR(G7+M7,"")
A8: Security | B8: PTZ cameras | C8: rotirajuće kamere | G8: =IFERROR(D8*F8,"") | H8: =IFERROR(G8/SUM($G$3:$G$32),0) | K8: Planned | L8: 0.1 | M8: =IFERROR(G8*L8,"") | N8: =IFERROR(G8+M8,"")
A9: Security | B9: Video recording servers | C9: snimanje | G9: =IFERROR(D9*F9,"") | H9: =IFERROR(G9/SUM($G$3:$G$32),0) | K9: Planned | L9: 0.1 | M9: =IFERROR(G9*L9,"") | N9: =IFERROR(G9+M9,"")
A10: Security | B10: Video management software | C10: upravljanje video sistemom | G10: =IFERROR(D10*F10,"") | H10: =IFERROR(G10/SUM($G$3:$G$32),0) | K10: Planned | L10: 0.1 | M10: =IFERROR(G10*L10,"") | N10: =IFERROR(G10+M10,"")
A11: Security | B11: Motion detection systems | C11: detekcija pokreta | G11: =IFERROR(D11*F11,"") | H11: =IFERROR(G11/SUM($G$3:$G$32),0) | K11: Planned | L11: 0.1 | M11: =IFERROR(G11*L11,"") | N11: =IFERROR(G11+M11,"")
A12: Security | B12: Thermal cameras | C12: termalne kamere | G12: =IFERROR(D12*F12,"") | H12: =IFERROR(G12/SUM($G$3:$G$32),0) | K12: Planned | L12: 0.1 | M12: =IFERROR(G12*L12,"") | N12: =IFERROR(G12+M12,"")
A13: Security | B13: License plate recognition | C13: prepoznavanje tablica | G13: =IFERROR(D13*F13,"") | H13: =IFERROR(G13/SUM($G$3:$G$32),0) | K13: Planned | L13: 0.1 | M13: =IFERROR(G13*L13,"") | N13: =IFERROR(G13+M13,"")
A14: Security | B14: Biometric access control | C14: biometrija | G14: =IFERROR(D14*F14,"") | H14: =IFERROR(G14/SUM($G$3:$G$32),0) | K14: Planned | L14: 0.1 | M14: =IFERROR(G14*L14,"") | N14: =IFERROR(G14+M14,"")
... A32: Security | B32: Integrated safety monitoring | C32: centralni monitoring | G32: =IFERROR(D32*F32,"") | H32: =IFERROR(G32/SUM($G$3:$G$32),0) | K32: Planned | L32: 0.1 | M32: =IFERROR(G32*L32,"") | N32: =IFERROR(G32+M32,"")
A34: === TOTAL CATEGORY === | G34: =SUM(G3:G32) | M34: =SUM(M3:M32) | N34: =SUM(N3:N32)
A36: Input logic: blue font/yellow fill = editable input | black = formula | green references in Summary | gray = locked assumptions.

Sheet ENGINEERING & PERMITS
A1: TITAN GRID CAPEX REGISTER | ENGINEERING & PERMITS
A2: Category | B2: CAPEX item | C2: Description | D2: Quantity | E2: Unit | F2: Unit Price (EUR) | G2: Total Cost (EUR) | H2: % of Category | I2: Vendor | J2: Timeline | K2: Status | L2: Contingency % | M2: Contingency Amount | N2: Gross Total (EUR) | O2: Risk Notes
A3: Engineering | B3: Feasibility studies | C3: studije | G3: =IFERROR(D3*F3,"") | H3: =IFERROR(G3/SUM($G$3:$G$34),0) | K3: Planned | L3: 0.1 | M3: =IFERROR(G3*L3,"") | N3: =IFERROR(G3+M3,"")
A4: Engineering | B4: Detailed engineering | C4: projekti | G4: =IFERROR(D4*F4,"") | H4: =IFERROR(G4/SUM($G$3:$G$34),0) | K4: Planned | L4: 0.1 | M4: =IFERROR(G4*L4,"") | N4: =IFERROR(G4+M4,"")
A5: Engineering | B5: Environmental permits | C5: dozvole | G5: =IFERROR(D5*F5,"") | H5: =IFERROR(G5/SUM($G$3:$G$34),0) | K5: Planned | L5: 0.1 | M5: =IFERROR(G5*L5,"") | N5: =IFERROR(G5+M5,"")
A6: Engineering | B6: Construction permits | C6: građevinska | G6: =IFERROR(D6*F6,"") | H6: =IFERROR(G6/SUM($G$3:$G$34),0) | K6: Planned | L6: 0.1 | M6: =IFERROR(G6*L6,"") | N6: =IFERROR(G6+M6,"")
A7: Engineering | B7: Concept design | C7: idejni projekat | G7: =IFERROR(D7*F7,"") | H7: =IFERROR(G7/SUM($G$3:$G$34),0) | K7: Planned | L7: 0.1 | M7: =IFERROR(G7*L7,"") | N7: =IFERROR(G7+M7,"")
A8: Engineering | B8: Basic engineering design | C8: osnovni projekat | G8: =IFERROR(D8*F8,"") | H8: =IFERROR(G8/SUM($G$3:$G$34),0) | K8: Planned | L8: 0.1 | M8: =IFERROR(G8*L8,"") | N8: =IFERROR(G8+M8,"")
A9: Engineering | B9: Front-end engineering design (FEED) | C9: FEED projekat | G9: =IFERROR(D9*F9,"") | H9: =IFERROR(G9/SUM($G$3:$G$34),0) | K9: Planned | L9: 0.1 | M9: =IFERROR(G9*L9,"") | N9: =IFERROR(G9+M9,"")
A10: Engineering | B10: Process engineering | C10: procesni dizajn | G10: =IFERROR(D10*F10,"") | H10: =IFERROR(G10/SUM($G$3:$G$34),0) | K10: Planned | L10: 0.1 | M10: =IFERROR(G10*L10,"") | N10: =IFERROR(G10+M10,"")
A11: Engineering | B11: Plant layout design | C11: layout fabrike | G11: =IFERROR(D11*F11,"") | H11: =IFERROR(G11/SUM($G$3:$G$34),0) | K11: Planned | L11: 0.1 | M11: =IFERROR(G11*L11,"") | N11: =IFERROR(G11+M11,"")
A12: Engineering | B12: Architectural design | C12: arhitektonski projekat | G12: =IFERROR(D12*F12,"") | H12: =IFERROR(G12/SUM($G$3:$G$34),0) | K12: Planned | L12: 0.1 | M12: =IFERROR(G12*L12,"") | N12: =IFERROR(G12+M12,"")
A13: Engineering | B13: Structural engineering | C13: konstrukcija | G13: =IFERROR(D13*F13,"") | H13: =IFERROR(G13/SUM($G$3:$G$34),0) | K13: Planned | L13: 0.1 | M13: =IFERROR(G13*L13,"") | N13: =IFERROR(G13+M13,"")
A14: Engineering | B14: Electrical engineering | C14: elektro projekat | G14: =IFERROR(D14*F14,"") | H14: =IFERROR(G14/SUM($G$3:$G$34),0) | K14: Planned | L14: 0.1 | M14: =IFERROR(G14*L14,"") | N14: =IFERROR(G14+M14,"")
