Workbook

Sheet Inputs_Control
A1: v3.2 CLEAN INVESTOR / AUDIT MODEL - CONTROL INPUTS
A3: Parameter | B3: Value | C3: Unit | D3: Comment
A4: Standard monthly hours | B4: 160 | C4: hours | D4: Payroll monthly gross base
A5: Employee contribution rate | B5: 0.105 | C5: % | D5: User input / assumed
A6: PIT threshold | B6: 700 | C6: € | D6: User input / assumed
A7: PIT rate - lower band | B7: 0.09 | C7: % | D7: User input / assumed
A8: PIT rate - upper band | B8: 0.15 | C8: % | D8: User input / assumed
A9: Surtax rate | B9: 0.15 | C9: % | D9: User input / assumed
A10: Employer contribution rate | B10: 0.005 | C10: % | D10: User input / assumed
A11: Overtime review threshold | B11: 8 | C11: hours | D11: Rows above threshold flagged
A12: Suspicious hours threshold | B12: 12 | C12: hours | D12: Rows above threshold flagged red
A14: Working days / month | B14: 22 | C14: days | D14: Board planning assumption
A15: Shifts / day | B15: 2 | C15: count | D15: Factory shift plan
A16: Hours / shift | B16: 8 | C16: hours | D16: Standard shift length
... A25: Target EBITDA margin | B25: 0.14 | C25: % | D25: Board target
A26: Effective annual capacity hours | B26: =B15*B16*B17*B18 -> 3400 | C26: hours | D26: Theoretical annual productive hours
A27: Loaded labor cost / hour | B27: =SUM(Sheet11_Zarade!$N$4:$N$15)/SUM(Sheet11_Zarade!$E$4:$E$15) -> 11.8925 | C27: €/h | D27: Payroll fully loaded hourly cost
A28: Annual payroll base | B28: =SUM(Sheet11_Zarade!$N$4:$N$15)*12 -> 274003.2 | C28: € | D28: Loaded payroll annualized

Sheet Master_Lista
A1: Master employee list
A3: Employee_ID | B3: Ime Radnika | C3: Pozicija | D3: Department | E3: Status
A4: EMP001 | B4: Branko Vasic | C4: Elektromonter | D4: Assembly | E4: Active
A5: EMP002 | B5: Filip Antic | C5: Winding Specialist | D5: Winding | E5: Active
A6: EMP003 | B6: Luka Filipovic | C6: Bravar | D6: Tank | E6: Active
A7: EMP004 | B7: Tomas Obradovic | C7: Zavarivač | D7: Tank | E7: Active
A8: EMP005 | B8: Jelena Nikolic | C8: Kontrola kvaliteta | D8: QA | E8: Active
A9: EMP006 | B9: Goran Zivkovic | C9: CNC operater | D9: Core | E9: Active
A10: EMP007 | B10: Filip Kostic | C10: Oil Filling Operator | D10: Testing | E10: Active
A11: EMP008 | B11: Lidija Tomic | C11: Administrator | D11: Admin | E11: Active
A12: EMP009 | B12: Petar Lazic | C12: Magacioner | D12: Warehouse | E12: Active
A13: EMP010 | B13: Branko Babic | C13: Tehničar održavanja | D13: Maintenance | E13: Active
A14: EMP011 | B14: Uros Djordjevic | C14: Elektro inženjer | D14: Engineering | E14: Active
A15: EMP012 | B15: Sanja Grujic | C15: Finansijski analitičar | D15: Finance | E15: Active

Sheet Pozicije
A1: Position rate card
A3: Pozicija | B3: Satnica (€ / h) | C3: Source note
A4: Elektromonter | B4: 8.5 | C4: Internal test rate card
A5: Vodeći monter | B5: 11 | C5: Internal test rate card
A6: Inženjer na gradilištu | B6: 18 | C6: Internal test rate card
A7: Projekt menadžer | B7: 28 | C7: Internal test rate card
A8: Bravar | B8: 9 | C8: Internal test rate card
A9: Zavarivač | B9: 10 | C9: Internal test rate card
A10: CNC operater | B10: 12 | C10: Internal test rate card
A11: Kontrola kvaliteta | B11: 14 | C11: Internal test rate card
A12: Mašinski inženjer | B12: 20 | C12: Internal test rate card
A13: Elektro inženjer | B13: 22 | C13: Internal test rate card
A14: Operater prese | B14: 9.5 | C14: Internal test rate card
A15: Slikar | B15: 8 | C15: Internal test rate card
... A23: Winding Specialist | B23: 10.5 | C23: Internal test rate card

Sheet Sheet27_Projekti
A1: Project master
A3: Sifra Projekta | B3: Naziv Projekta | C3: Status | D3: In Dropdown
A4: P001 | B4: Oil Trafo 5MVA Assembly | C4: Aktivan | D4: YES
A5: P002 | B5: Winding Production | C5: Aktivan | D5: YES
A6: P003 | B6: Core Stacking | C6: Planirano | D6: NO
A7: P004 | B7: Tank Fabrication | C7: Aktivan | D7: YES
A8: P005 | B8: Oil Filling & Testing | C8: Aktivan | D8: YES

Sheet Lists
A1: Employee_IDs | B1: Active_Projects
A2: EMP001 | B2: P001
A3: EMP002 | B3: P002
A4: EMP003 | B4: P004
A5: EMP004 | B5: P005
A6: EMP005
A7: EMP006
A8: EMP007
A9: EMP008
A10: EMP009
A11: EMP010
A12: EMP011
A13: EMP012

Sheet Sheet11_Zarade
A1: Monthly payroll model
A3: Employee_ID | B3: Ime Radnika | C3: Pozicija | D3: Satnica (€ / h) | E3: Norm Hours | F3: Bruto Plata (€ / mj.) | G3: Napomena | H3: Employee Contrib | I3: Taxable | J3: PIT | K3: Surtax | L3: Neto Plata | M3: Employer Contrib | N3: Total Cost
A4: EMP001 | B4: =IFERROR(VLOOKUP(A4,Master_Lista!$A$4:$E$15,2,FALSE()),"INVALID_ID") -> Branko Vasic | C4: =IFERROR(VLOOKUP(A4,Master_Lista!$A$4:$E$15,3,FALSE()),"INVALID_ID") -> Elektromonter | D4: =IFERROR(VLOOKUP(C4,Pozicije!$A$4:$B$23,2,FALSE()),0) -> 8.5 | E4: =Inputs_Control!$B$4 -> 160 | F4: =D4*E4 -> 1360 | H4: =F4*Inputs_Control!$B$5 -> 142.8 | I4: =F4-H4 -> 1217.2 | J4: =IF(I4<Inputs_Control!$B$6,I4*Inputs_Control!$B$7,I4*Inputs_Control!$B$8) -> 182.58 | K4: =J4*Inputs_Control!$B$9 -> 27.387 | L4: =I4-J4-K4 -> 1007.233 | M4: =F4*Inputs_Control!$B$10 -> 6.8 | N4: =F4+M4 -> 1366.8
A5: EMP002 | B5: =IFERROR(VLOOKUP(A5,Master_Lista!$A$4:$E$15,2,FALSE()),"INVALID_ID") -> Filip Antic | C5: =IFERROR(VLOOKUP(A5,Master_Lista!$A$4:$E$15,3,FALSE()),"INVALID_ID") -> Winding Specialist | D5: =IFERROR(VLOOKUP(C5,Pozicije!$A$4:$B$23,2,FALSE()),0) -> 10.5 | E5: =Inputs_Control!$B$4 -> 160 | F5: =D5*E5 -> 1680 | H5: =F5*Inputs_Control!$B$5 -> 176.4 | I5: =F5-H5 -> 1503.6 | J5: =IF(I5<Inputs_Control!$B$6,I5*Inputs_Control!$B$7,I5*Inputs_Control!$B$8) -> 225.54 | K5: =J5*Inputs_Control!$B$9 -> 33.831 | L5: =I5-J5-K5 -> 1244.229 | M5: =F5*Inputs_Control!$B$10 -> 8.4 | N5: =F5+M5 -> 1688.4
A6: EMP003 | B6: =IFERROR(VLOOKUP(A6,Master_Lista!$A$4:$E$15,2,FALSE()),"INVALID_ID") -> Luka Filipovic | C6: =IFERROR(VLOOKUP(A6,Master_Lista!$A$4:$E$15,3,FALSE()),"INVALID_ID") -> Bravar | D6: =IFERROR(VLOOKUP(C6,Pozicije!$A$4:$B$23,2,FALSE()),0) -> 9 | E6: =Inputs_Control!$B$4 -> 160 | F6: =D6*E6 -> 1440 | H6: =F6*Inputs_Control!$B$5 -> 151.2 | I6: =F6-H6 -> 1288.8 | J6: =IF(I6<Inputs_Control!$B$6,I6*Inputs_Control!$B$7,I6*Inputs_Control!$B$8) -> 193.32 | K6: =J6*Inputs_Control!$B$9 -> 28.998 | L6: =I6-J6-K6 -> 1066.482 | M6: =F6*Inputs_Control!$B$10 -> 7.2 | N6: =F6+M6 -> 1447.2
A7: EMP004 | B7: =IFERROR(VLOOKUP(A7,Master_Lista!$A$4:$E$15,2,FALSE()),"INVALID_ID") -> Tomas Obradovic | C7: =IFERROR(VLOOKUP(A7,Master_Lista!$A$4:$E$15,3,FALSE()),"INVALID_ID") -> Zavarivač | D7: =IFERROR(VLOOKUP(C7,Pozicije!$A$4:$B$23,2,FALSE()),0) -> 10 | E7: =Inputs_Control!$B$4 -> 160 | F7: =D7*E7 -> 1600 | H7: =F7*Inputs_Control!$B$5 -> 168 | I7: =F7-H7 -> 1432 | J7: =IF(I7<Inputs_Control!$B$6,I7*Inputs_Control!$B$7,I7*Inputs_Control!$B$8) -> 214.8 | K7: =J7*Inputs_Control!$B$9 -> 32.22 | L7: =I7-J7-K7 -> 1184.98 | M7: =F7*Inputs_Control!$B$10 -> 8 | N7: =F7+M7 -> 1608
A8: EMP005 | B8: =IFERROR(VLOOKUP(A8,Master_Lista!$A$4:$E$15,2,FALSE()),"INVALID_ID") -> Jelena Nikolic | C8: =IFERROR(VLOOKUP(A8,Master_Lista!$A$4:$E$15,3,FALSE()),"INVALID_ID") -> Kontrola kvaliteta | D8: =IFERROR(VLOOKUP(C8,Pozicije!$A$4:$B$23,2,FALSE()),0) -> 14 | E8: =Inputs_Control!$B$4 -> 160 | F8: =D8*E8 -> 2240 | H8: =F8*Inputs_Control!$B$5 -> 235.2 | I8: =F8-H8 -> 2004.8 | J8: =IF(I8<Inputs_Control!$B$6,I8*Inputs_Control!$B$7,I8*Inputs_Control!$B$8) -> 300.72 | K8: =J8*Inputs_Control!$B$9 -> 45.108 | L8: =I8-J8-K8 -> 1658.972 | M8: =F8*Inputs_Control!$B$10 -> 11.2 | N8: =F8+M8 -> 2251.2
A9: EMP006 | B9: =IFERROR(VLOOKUP(A9,Master_Lista!$A$4:$E$15,2,FALSE()),"INVALID_ID") -> Goran Zivkovic | C9: =IFERROR(VLOOKUP(A9,Master_Lista!$A$4:$E$15,3,FALSE()),"INVALID_ID") -> CNC operater | D9: =IFERROR(VLOOKUP(C9,Pozicije!$A$4:$B$23,2,FALSE()),0) -> 12 | E9: =Inputs_Control!$B$4 -> 160 | F9: =D9*E9 -> 1920 | H9: =F9*Inputs_Control!$B$5 -> 201.6 | I9: =F9-H9 -> 1718.4 | J9: =IF(I9<Inputs_Control!$B$6,I9*Inputs_Control!$B$7,I9*Inputs_Control!$B$8) -> 257.76 | K9: =J9*Inputs_Control!$B$9 -> 38.664 | L9: =I9-J9-K9 -> 1421.976 | M9: =F9*Inputs_Control!$B$10 -> 9.6 | N9: =F9+M9 -> 1929.6
A10: EMP007 | B10: =IFERROR(VLOOKUP(A10,Master_Lista!$A$4:$E$15,2,FALSE()),"INVALID_ID") -> Filip Kostic | C10: =IFERROR(VLOOKUP(A10,Master_Lista!$A$4:$E$15,3,FALSE()),"INVALID_ID") -> Oil Filling Operator | D10: =IFERROR(VLOOKUP(C10,Pozicije!$A$4:$B$23,2,FALSE()),0) -> 9.5 | E10: =Inputs_Control!$B$4 -> 160 | F10: =D10*E10 -> 1520 | H10: =F10*Inputs_Control!$B$5 -> 159.6 | I10: =F10-H10 -> 1360.4 | J10: =IF(I10<Inputs_Control!$B$6,I10*Inputs_Control!$B$7,I10*Inputs_Control!$B$8) -> 204.06 | K10: =J10*Inputs_Control!$B$9 -> 30.609 | L10: =I10-J10-K10 -> 1125.731 | M10: =F10*Inputs_Control!$B$10 -> 7.6 | N10: =F10+M10 -> 1527.6
A11: EMP008 | B11: =IFERROR(VLOOKUP(A11,Master_Lista!$A$4:$E$15,2,FALSE()),"INVALID_ID") -> Lidija Tomic | C11: =IFERROR(VLOOKUP(A11,Master_Lista!$A$4:$E$15,3,FALSE()),"INVALID_ID") -> Administrator | D11: =IFERROR(VLOOKUP(C11,Pozicije!$A$4:$B$23,2,FALSE()),0) -> 12.5 | E11: =Inputs_Control!$B$4 -> 160 | F11: =D11*E11 -> 2000 | H11: =F11*Inputs_Control!$B$5 -> 210 | I11: =F11-H11 -> 1790 | J11: =IF(I11<Inputs_Control!$B$6,I11*Inputs_Control!$B$7,I11*Inputs_Control!$B$8) -> 268.5 | K11: =J11*Inputs_Control!$B$9 -> 40.275 | L11: =I11-J11-K11 -> 1481.225 | M11: =F11*Inputs_Control!$B$10 -> 10 | N11: =F11+M11 -> 2010
A12: EMP009 | B12: =IFERROR(VLOOKUP(A12,Master_Lista!$A$4:$E$15,2,FALSE()),"INVALID_ID") -> Petar Lazic | C12: =IFERROR(VLOOKUP(A12,Master_Lista!$A$4:$E$15,3,FALSE()),"INVALID_ID") -> Magacioner | D12: =IFERROR(VLOOKUP(C12,Pozicije!$A$4:$B$23,2,FALSE()),0) -> 7.5 | E12: =Inputs_Control!$B$4 -> 160 | F12: =D12*E12 -> 1200 | H12: =F12*Inputs_Control!$B$5 -> 126 | I12: =F12-H12 -> 1074 | J12: =IF(I12<Inputs_Control!$B$6,I12*Inputs_Control!$B$7,I12*Inputs_Control!$B$8) -> 161.1 | K12: =J12*Inputs_Control!$B$9 -> 24.165 | L12: =I12-J12-K12 -> 888.735 | M12: =F12*Inputs_Control!$B$10 -> 6 | N12: =F12+M12 -> 1206
A13: EMP010 | B13: =IFERROR(VLOOKUP(A13,Master_Lista!$A$4:$E$15,2,FALSE()),"INVALID_ID") -> Branko Babic | C13: =IFERROR(VLOOKUP(A13,Master_Lista!$A$4:$E$15,3,FALSE()),"INVALID_ID") -> Tehničar održavanja | D13: =IFERROR(VLOOKUP(C13,Pozicije!$A$4:$B$23,2,FALSE()),0) -> 10.5 | E13: =Inputs_Control!$B$4 -> 160 | F13: =D13*E13 -> 1680 | H13: =F13*Inputs_Control!$B$5 -> 176.4 | I13: =F13-H13 -> 1503.6 | J13: =IF(I13<Inputs_Control!$B$6,I13*Inputs_Control!$B$7,I13*Inputs_Control!$B$8) -> 225.54 | K13: =J13*Inputs_Control!$B$9 -> 33.831 | L13: =I13-J13-K13 -> 1244.229 | M13: =F13*Inputs_Control!$B$10 -> 8.4 | N13: =F13+M13 -> 1688.4
A14: EMP011 | B14: =IFERROR(VLOOKUP(A14,Master_Lista!$A$4:$E$15,2,FALSE()),"INVALID_ID") -> Uros Djordjevic | C14: =IFERROR(VLOOKUP(A14,Master_Lista!$A$4:$E$15,3,FALSE()),"INVALID_ID") -> Elektro inženjer | D14: =IFERROR(VLOOKUP(C14,Pozicije!$A$4:$B$23,2,FALSE()),0) -> 22 | E14: =Inputs_Control!$B$4 -> 160 | F14: =D14*E14 -> 3520 | H14: =F14*Inputs_Control!$B$5 -> 369.6 | I14: =F14-H14 -> 3150.4 | J14: =IF(I14<Inputs_Control!$B$6,I14*Inputs_Control!$B$7,I14*Inputs_Control!$B$8) -> 472.56 | K14: =J14*Inputs_Control!$B$9 -> 70.884 | L14: =I14-J14-K14 -> 2606.956 | M14: =F14*Inputs_Control!$B$10 -> 17.6 | N14: =F14+M14 -> 3537.6
A15: EMP012 | B15: =IFERROR(VLOOKUP(A15,Master_Lista!$A$4:$E$15,2,FALSE()),"INVALID_ID") -> Sanja Grujic | C15: =IFERROR(VLOOKUP(A15,Master_Lista!$A$4:$E$15,3,FALSE()),"INVALID_ID") -> Finansijski analitičar | D15: =IFERROR(VLOOKUP(C15,Pozicije!$A$4:$B$23,2,FALSE()),0) -> 16 | E15: =Inputs_Control!$B$4 -> 160 | F15: =D15*E15 -> 2560 | H15: =F15*Inputs_Control!$B$5 -> 268.8 | I15: =F15-H15 -> 2291.2 | J15: =IF(I15<Inputs_Control!$B$6,I15*Inputs_Control!$B$7,I15*Inputs_Control!$B$8) -> 343.68 | K15: =J15*Inputs_Control!$B$9 -> 51.552 | L15: =I15-J15-K15 -> 1895.968 | M15: =F15*Inputs_Control!$B$10 -> 12.8 | N15: =F15+M15 -> 2572.8
A17: TOTAL | E17: =SUM(E4:E15) -> 1920 | F17: =SUM(F4:F15) -> 22720 | H17: =SUM(H4:H15) -> 2385.6 | I17: =SUM(I4:I15) -> 20334.4 | J17: =SUM(J4:J15) -> 3050.16 | K17: =SUM(K4:K15) -> 457.524 | L17: =SUM(L4:L15) -> 16826.716 | M17: =SUM(M4:M15) -> 113.6 | N17: =SUM(N4:N15) -> 22833.6

Sheet Sheet3_Sati
A1: Daily labor booking sheet
A3: Employee_ID | B3: Ime Radnika | C3: Projekat | D3: Datum | E3: Sati | F3: Pozicija | G3: Satnica (€ / h) | H3: Bruto Teret | I3: Employer Contrib | J3: Finansijski Teret | K3: Lookup Status | L3: Project Status | M3: Status kontrole | N3: Duplikat dnevnog unosa
A4: EMP001 | B4: =IF(A4="","",IFERROR(VLOOKUP(A4,Master_Lista!$A$4:$E$15,2,FALSE()),"INVALID_ID")) -> Branko Vasic | C4: P001 | D4: 46027 | E4: 8 | F4: =IF(A4="","",IFERROR(VLOOKUP(A4,Master_Lista!$A$4:$E$15,3,FALSE()),"INVALID_ID")) -> Elektromonter | G4: =IF(F4="","",IFERROR(VLOOKUP(F4,Pozicije!$A$4:$B$23,2,FALSE()),0)) -> 8.5 | H4: =IF(OR(E4="",G4=""),"",E4*G4) -> 68 | I4: =IF(H4="","",H4*Inputs_Control!$B$10) -> 0.34 | J4: =IF(H4="","",H4+I4) -> 68.34 | K4: =IF(OR(A4="",B4=""),"",IF(B4="INVALID_ID","INVALID_ID","OK")) -> OK | L4: =IF(C4="","",IF(COUNTIF(Lists!$B$2:$B$5,C4)=0,"INVALID_OR_INACTIVE","OK")) -> OK | M4: =IF(E4="","",IF(E4>Inputs_Control!$B$12,"SUSPICIOUS",IF(E4>Inputs_Control!$B$11,"OVERTIME","OK"))) -> OK | N4: =IF(OR(A4="",C4="",D4=""),"",IF(COUNTIFS($A:$A,A4,$C:$C,C4,$D:$D,D4)>1,"DUPLICATE","OK")) -> OK
A5: EMP002 | B5: =IF(A5="","",IFERROR(VLOOKUP(A5,Master_Lista!$A$4:$E$15,2,FALSE()),"INVALID_ID")) -> Filip Antic | C5: P002 | D5: 46027 | E5: 8 | F5: =IF(A5="","",IFERROR(VLOOKUP(A5,Master_Lista!$A$4:$E$15,3,FALSE()),"INVALID_ID")) -> Winding Specialist | G5: =IF(F5="","",IFERROR(VLOOKUP(F5,Pozicije!$A$4:$B$23,2,FALSE()),0)) -> 10.5 | H5: =IF(OR(E5="",G5=""),"",E5*G5) -> 84 | I5: =IF(H5="","",H5*Inputs_Control!$B$10) -> 0.42 | J5: =IF(H5="","",H5+I5) -> 84.42 | K5: =IF(OR(A5="",B5=""),"",IF(B5="INVALID_ID","INVALID_ID","OK")) -> OK | L5: =IF(C5="","",IF(COUNTIF(Lists!$B$2:$B$5,C5)=0,"INVALID_OR_INACTIVE","OK")) -> OK | M5: =IF(E5="","",IF(E5>Inputs_Control!$B$12,"SUSPICIOUS",IF(E5>Inputs_Control!$B$11,"OVERTIME","OK"))) -> OK | N5: =IF(OR(A5="",C5="",D5=""),"",IF(COUNTIFS($A:$A,A5,$C:$C,C5,$D:$D,D5)>1,"DUPLICATE","OK")) -> OK
A6: EMP003 | B6: =IF(A6="","",IFERROR(VLOOKUP(A6,Master_Lista!$A$4:$E$15,2,FALSE()),"INVALID_ID")) -> Luka Filipovic | C6: P004 | D6: 46027 | E6: 8 | F6: =IF(A6="","",IFERROR(VLOOKUP(A6,Master_Lista!$A$4:$E$15,3,FALSE()),"INVALID_ID")) -> Bravar | G6: =IF(F6="","",IFERROR(VLOOKUP(F6,Pozicije!$A$4:$B$23,2,FALSE()),0)) -> 9 | H6: =IF(OR(E6="",G6=""),"",E6*G6) -> 72 | I6: =IF(H6="","",H6*Inputs_Control!$B$10) -> 0.36 | J6: =IF(H6="","",H6+I6) -> 72.36 | K6: =IF(OR(A6="",B6=""),"",IF(B6="INVALID_ID","INVALID_ID","OK")) -> OK | L6: =IF(C6="","",IF(COUNTIF(Lists!$B$2:$B$5,C6)=0,"INVALID_OR_INACTIVE","OK")) -> OK | M6: =IF(E6="","",IF(E6>Inputs_Control!$B$12,"SUSPICIOUS",IF(E6>Inputs_Control!$B$11,"OVERTIME","OK"))) -> OK | N6: =IF(OR(A6="",C6="",D6=""),"",IF(COUNTIFS($A:$A,A6,$C:$C,C6,$D:$D,D6)>1,"DUPLICATE","OK")) -> OK
A7: EMP004 | B7: =IF(A7="","",IFERROR(VLOOKUP(A7,Master_Lista!$A$4:$E$15,2,FALSE()),"INVALID_ID")) -> Tomas Obradovic | C7: P004 | D7: 46027 | E7: 8 | F7: =IF(A7="","",IFERROR(VLOOKUP(A7,Master_Lista!$A$4:$E$15,3,FALSE()),"INVALID_ID")) -> Zavarivač | G7: =IF(F7="","",IFERROR(VLOOKUP(F7,Pozicije!$A$4:$B$23,2,FALSE()),0)) -> 10 | H7: =IF(OR(E7="",G7=""),"",E7*G7) -> 80 | I7: =IF(H7="","",H7*Inputs_Control!$B$10) -> 0.4 | J7: =IF(H7="","",H7+I7) -> 80.4 | K7: =IF(OR(A7="",B7=""),"",IF(B7="INVALID_ID","INVALID_ID","OK")) -> OK | L7: =IF(C7="","",IF(COUNTIF(Lists!$B$2:$B$5,C7)=0,"INVALID_OR_INACTIVE","OK")) -> OK | M7: =IF(E7="","",IF(E7>Inputs_Control!$B$12,"SUSPICIOUS",IF(E7>Inputs_Control!$B$11,"OVERTIME","OK"))) -> OK | N7: =IF(OR(A7="",C7="",D7=""),"",IF(COUNTIFS($A:$A,A7,$C:$C,C7,$D:$D,D7)>1,"DUPLICATE","OK")) -> OK
A8: EMP005 | B8: =IF(A8="","",IFERROR(VLOOKUP(A8,Master_Lista!$A$4:$E$15,2,FALSE()),"INVALID_ID")) -> Jelena Nikolic | C8: P005 | D8: 46027 | E8: 8 | F8: =IF(A8="","",IFERROR(VLOOKUP(A8,Master_Lista!$A$4:$E$15,3,FALSE()),"INVALID_ID")) -> Kontrola kvaliteta | G8: =IF(F8="","",IFERROR(VLOOKUP(F8,Pozicije!$A$4:$B$23,2,FALSE()),0)) -> 14 | H8: =IF(OR(E8="",G8=""),"",E8*G8) -> 112 | I8: =IF(H8="","",H8*Inputs_Control!$B$10) -> 0.56 | J8: =IF(H8="","",H8+I8) -> 112.56 | K8: =IF(OR(A8="",B8=""),"",IF(B8="INVALID_ID","INVALID_ID","OK")) -> OK | L8: =IF(C8="","",IF(COUNTIF(Lists!$B$2:$B$5,C8)=0,"INVALID_OR_INACTIVE","OK")) -> OK | M8: =IF(E8="","",IF(E8>Inputs_Control!$B$12,"SUSPICIOUS",IF(E8>Inputs_Control!$B$11,"OVERTIME","OK"))) -> OK | N8: =IF(OR(A8="",C8="",D8=""),"",IF(COUNTIFS($A:$A,A8,$C:$C,C8,$D:$D,D8)>1,"DUPLICATE","OK")) -> OK
A9: EMP006 | B9: =IF(A9="","",IFERROR(VLOOKUP(A9,Master_Lista!$A$4:$E$15,2,FALSE()),"INVALID_ID")) -> Goran Zivkovic | C9: P002 | D9: 46027 | E9: 8 | F9: =IF(A9="","",IFERROR(VLOOKUP(A9,Master_Lista!$A$4:$E$15,3,FALSE()),"INVALID_ID")) -> CNC operater | G9: =IF(F9="","",IFERROR(VLOOKUP(F9,Pozicije!$A$4:$B$23,2,FALSE()),0)) -> 12 | H9: =IF(OR(E9="",G9=""),"",E9*G9) -> 96 | I9: =IF(H9="","",H9*Inputs_Control!$B$10) -> 0.48 | J9: =IF(H9="","",H9+I9) -> 96.48 | K9: =IF(OR(A9="",B9=""),"",IF(B9="INVALID_ID","INVALID_ID","OK")) -> OK | L9: =IF(C9="","",IF(COUNTIF(Lists!$B$2:$B$5,C9)=0,"INVALID_OR_INACTIVE","OK")) -> OK | M9: =IF(E9="","",IF(E9>Inputs_Control!$B$12,"SUSPICIOUS",IF(E9>Inputs_Control!$B$11,"OVERTIME","OK"))) -> OK | N9: =IF(OR(A9="",C9="",D9=""),"",IF(COUNTIFS($A:$A,A9,$C:$C,C9,$D:$D,D9)>1,"DUPLICATE","OK")) -> OK
A10: EMP007 | B10: =IF(A10="","",IFERROR(VLOOKUP(A10,Master_Lista!$A$4:$E$15,2,FALSE()),"INVALID_ID")) -> Filip Kostic | C10: P005 | D10: 46028 | E10: 8 | F10: =IF(A10="","",IFERROR(VLOOKUP(A10,Master_Lista!$A$4:$E$15,3,FALSE()),"INVALID_ID")) -> Oil Filling Operator | G10: =IF(F10="","",IFERROR(VLOOKUP(F10,Pozicije!$A$4:$B$23,2,FALSE()),0)) -> 9.5 | H10: =IF(OR(E10="",G10=""),"",E10*G10) -> 76 | I10: =IF(H10="","",H10*Inputs_Control!$B$10) -> 0.38 | J10: =IF(H10="","",H10+I10) -> 76.38 | K10: =IF(OR(A10="",B10=""),"",IF(B10="INVALID_ID","INVALID_ID","OK")) -> OK | L10: =IF(C10="","",IF(COUNTIF(Lists!$B$2:$B$5,C10)=0,"INVALID_OR_INACTIVE","OK")) -> OK | M10: =IF(E10="","",IF(E10>Inputs_Control!$B$12,"SUSPICIOUS",IF(E10>Inputs_Control!$B$11,"OVERTIME","OK"))) -> OK | N10: =IF(OR(A10="",C10="",D10=""),"",IF(COUNTIFS($A:$A,A10,$C:$C,C10,$D:$D,D10)>1,"DUPLICATE","OK")) -> OK
A11: EMP009 | B11: =IF(A11="","",IFERROR(VLOOKUP(A11,Master_Lista!$A$4:$E$15,2,FALSE()),"INVALID_ID")) -> Petar Lazic | C11: P001 | D11: 46028 | E11: 8 | F11: =IF(A11="","",IFERROR(VLOOKUP(A11,Master_Lista!$A$4:$E$15,3,FALSE()),"INVALID_ID")) -> Magacioner | G11: =IF(F11="","",IFERROR(VLOOKUP(F11,Pozicije!$A$4:$B$23,2,FALSE()),0)) -> 7.5 | H11: =IF(OR(E11="",G11=""),"",E11*G11) -> 60 | I11: =IF(H11="","",H11*Inputs_Control!$B$10) -> 0.3 | J11: =IF(H11="","",H11+I11) -> 60.3 | K11: =IF(OR(A11="",B11=""),"",IF(B11="INVALID_ID","INVALID_ID","OK")) -> OK | L11: =IF(C11="","",IF(COUNTIF(Lists!$B$2:$B$5,C11)=0,"INVALID_OR_INACTIVE","OK")) -> OK | M11: =IF(E11="","",IF(E11>Inputs_Control!$B$12,"SUSPICIOUS",IF(E11>Inputs_Control!$B$11,"OVERTIME","OK"))) -> OK | N11: =IF(OR(A11="",C11="",D11=""),"",IF(COUNTIFS($A:$A,A11,$C:$C,C11,$D:$D,D11)>1,"DUPLICATE","OK")) -> OK
A12: EMP010 | B12: =IF(A12="","",IFERROR(VLOOKUP(A12,Master_Lista!$A$4:$E$15,2,FALSE()),"INVALID_ID")) -> Branko Babic | C12: P004 | D12: 46028 | E12: 8 | F12: =IF(A12="","",IFERROR(VLOOKUP(A12,Master_Lista!$A$4:$E$15,3,FALSE()),"INVALID_ID")) -> Tehničar održavanja | G12: =IF(F12="","",IFERROR(VLOOKUP(F12,Pozicije!$A$4:$B$23,2,FALSE()),0)) -> 10.5 | H12: =IF(OR(E12="",G12=""),"",E12*G12) -> 84 | I12: =IF(H12="","",H12*Inputs_Control!$B$10) -> 0.42 | J12: =IF(H12="","",H12+I12) -> 84.42 | K12: =IF(OR(A12="",B12=""),"",IF(B12="INVALID_ID","INVALID_ID","OK")) -> OK | L12: =IF(C12="","",IF(COUNTIF(Lists!$B$2:$B$5,C12)=0,"INVALID_OR_INACTIVE","OK")) -> OK | M12: =IF(E12="","",IF(E12>Inputs_Control!$B$12,"SUSPICIOUS",IF(E12>Inputs_Control!$B$11,"OVERTIME","OK"))) -> OK | N12: =IF(OR(A12="",C12="",D12=""),"",IF(COUNTIFS($A:$A,A12,$C:$C,C12,$D:$D,D12)>1,"DUPLICATE","OK")) -> OK
A13: EMP011 | B13: =IF(A13="","",IFERROR(VLOOKUP(A13,Master_Lista!$A$4:$E$15,2,FALSE()),"INVALID_ID")) -> Uros Djordjevic | C13: P001 | D13: 46028 | E13: 8 | F13: =IF(A13="","",IFERROR(VLOOKUP(A13,Master_Lista!$A$4:$E$15,3,FALSE()),"INVALID_ID")) -> Elektro inženjer | G13: =IF(F13="","",IFERROR(VLOOKUP(F13,Pozicije!$A$4:$B$23,2,FALSE()),0)) -> 22 | H13: =IF(OR(E13="",G13=""),"",E13*G13) -> 176 | I13: =IF(H13="","",H13*Inputs_Control!$B$10) -> 0.88 | J13: =IF(H13="","",H13+I13) -> 176.88 | K13: =IF(OR(A13="",B13=""),"",IF(B13="INVALID_ID","INVALID_ID","OK")) -> OK | L13: =IF(C13="","",IF(COUNTIF(Lists!$B$2:$B$5,C13)=0,"INVALID_OR_INACTIVE","OK")) -> OK | M13: =IF(E13="","",IF(E13>Inputs_Control!$B$12,"SUSPICIOUS",IF(E13>Inputs_Control!$B$11,"OVERTIME","OK"))) -> OK | N13: =IF(OR(A13="",C13="",D13=""),"",IF(COUNTIFS($A:$A,A13,$C:$C,C13,$D:$D,D13)>1,"DUPLICATE","OK")) -> OK
A14: EMP001 | B14: =IF(A14="","",IFERROR(VLOOKUP(A14,Master_Lista!$A$4:$E$15,2,FALSE()),"INVALID_ID")) -> Branko Vasic | C14: P001 | D14: 46029 | E14: 9.5 | F14: =IF(A14="","",IFERROR(VLOOKUP(A14,Master_Lista!$A$4:$E$15,3,FALSE()),"INVALID_ID")) -> Elektromonter | G14: =IF(F14="","",IFERROR(VLOOKUP(F14,Pozicije!$A$4:$B$23,2,FALSE()),0)) -> 8.5 | H14: =IF(OR(E14="",G14=""),"",E14*G14) -> 80.75 | I14: =IF(H14="","",H14*Inputs_Control!$B$10) -> 0.40375 | J14: =IF(H14="","",H14+I14) -> 81.15375 | K14: =IF(OR(A14="",B14=""),"",IF(B14="INVALID_ID","INVALID_ID","OK")) -> OK | L14: =IF(C14="","",IF(COUNTIF(Lists!$B$2:$B$5,C14)=0,"INVALID_OR_INACTIVE","OK")) -> OK | M14: =IF(E14="","",IF(E14>Inputs_Control!$B$12,"SUSPICIOUS",IF(E14>Inputs_Control!$B$11,"OVERTIME","OK"))) -> OVERTIME | N14: =IF(OR(A14="",C14="",D14=""),"",IF(COUNTIFS($A:$A,A14,$C:$C,C14,$D:$D,D14)>1,"DUPLICATE","OK")) -> OK
A15: EMP002 | B15: =IF(A15="","",IFERROR(VLOOKUP(A15,Master_Lista!$A$4:$E$15,2,FALSE()),"INVALID_ID")) -> Filip Antic | C15: P002 | D15: 46029 | E15: 9 | F15: =IF(A15="","",IFERROR(VLOOKUP(A15,Master_Lista!$A$4:$E$15,3,FALSE()),"INVALID_ID")) -> Winding Specialist | G15: =IF(F15="","",IFERROR(VLOOKUP(F15,Pozicije!$A$4:$B$23,2,FALSE()),0)) -> 10.5 | H15: =IF(OR(E15="",G15=""),"",E15*G15) -> 94.5 | I15: =IF(H15="","",H15*Inputs_Control!$B$10) -> 0.4725 | J15: =IF(H15="","",H15+I15) -> 94.9725 | K15: =IF(OR(A15="",B15=""),"",IF(B15="INVALID_ID","INVALID_ID","OK")) -> OK | L15: =IF(C15="","",IF(COUNTIF(Lists!$B$2:$B$5,C15)=0,"INVALID_OR_INACTIVE","OK")) -> OK | M15: =IF(E15="","",IF(E15>Inputs_Control!$B$12,"SUSPICIOUS",IF(E15>Inputs_Control!$B$11,"OVERTIME","OK"))) -> OVERTIME | N15: =IF(OR(A15="",C15="",D15=""),"",IF(COUNTIFS($A:$A,A15,$C:$C,C15,$D:$D,D15)>1,"DUPLICATE","OK")) -> OK
... A33: EMP011 | B33: =IF(A33="","",IFERROR(VLOOKUP(A33,Master_Lista!$A$4:$E$15,2,FALSE()),"INVALID_ID")) -> Uros Djordjevic | C33: P001 | D33: 46034 | E33: 8 | F33: =IF(A33="","",IFERROR(VLOOKUP(A33,Master_Lista!$A$4:$E$15,3,FALSE()),"INVALID_ID")) -> Elektro inženjer | G33: =IF(F33="","",IFERROR(VLOOKUP(F33,Pozicije!$A$4:$B$23,2,FALSE()),0)) -> 22 | H33: =IF(OR(E33="",G33=""),"",E33*G33) -> 176 | I33: =IF(H33="","",H33*Inputs_Control!$B$10) -> 0.88 | J33: =IF(H33="","",H33+I33) -> 176.88 | K33: =IF(OR(A33="",B33=""),"",IF(B33="INVALID_ID","INVALID_ID","OK")) -> OK | L33: =IF(C33="","",IF(COUNTIF(Lists!$B$2:$B$5,C33)=0,"INVALID_OR_INACTIVE","OK")) -> OK | M33: =IF(E33="","",IF(E33>Inputs_Control!$B$12,"SUSPICIOUS",IF(E33>Inputs_Control!$B$11,"OVERTIME","OK"))) -> OK | N33: =IF(OR(A33="",C33="",D33=""),"",IF(COUNTIFS($A:$A,A33,$C:$C,C33,$D:$D,D33)>1,"DUPLICATE","OK")) -> OK
B34: =IF(A34="","",IFERROR(VLOOKUP(A34,Master_Lista!$A$4:$E$15,2,FALSE()),"INVALID_ID")) | F34: =IF(A34="","",IFERROR(VLOOKUP(A34,Master_Lista!$A$4:$E$15,3,FALSE()),"INVALID_ID")) | G34: =IF(F34="","",IFERROR(VLOOKUP(F34,Pozicije!$A$4:$B$23,2,FALSE()),0)) | H34: =IF(OR(E34="",G34=""),"",E34*G34) | I34: =IF(H34="","",H34*Inputs_Control!$B$10) | J34: =IF(H34="","",H34+I34) | K34: =IF(OR(A34="",B34=""),"",IF(B34="INVALID_ID","INVALID_ID","OK")) | L34: =IF(C34="","",IF(COUNTIF(Lists!$B$2:$B$5,C34)=0,"INVALID_OR_INACTIVE","OK")) | M34: =IF(E34="","",IF(E34>Inputs_Control!$B$12,"SUSPICIOUS",IF(E34>Inputs_Control!$B$11,"OVERTIME","OK"))) | N34: =IF(OR(A34="",C34="",D34=""),"",IF(COUNTIFS($A:$A,A34,$C:$C,C34,$D:$D,D34)>1,"DUPLICATE","OK"))
B35: =IF(A35="","",IFERROR(VLOOKUP(A35,Master_Lista!$A$4:$E$15,2,FALSE()),"INVALID_ID")) | F35: =IF(A35="","",IFERROR(VLOOKUP(A35,Master_Lista!$A$4:$E$15,3,FALSE()),"INVALID_ID")) | G35: =IF(F35="","",IFERROR(VLOOKUP(F35,Pozicije!$A$4:$B$23,2,FALSE()),0)) | H35: =IF(OR(E35="",G35=""),"",E35*G35) | I35: =IF(H35="","",H35*Inputs_Control!$B$10) | J35: =IF(H35="","",H35+I35) | K35: =IF(OR(A35="",B35=""),"",IF(B35="INVALID_ID","INVALID_ID","OK")) | L35: =IF(C35="","",IF(COUNTIF(Lists!$B$2:$B$5,C35)=0,"INVALID_OR_INACTIVE","OK")) | M35: =IF(E35="","",IF(E35>Inputs_Control!$B$12,"SUSPICIOUS",IF(E35>Inputs_Control!$B$11,"OVERTIME","OK"))) | N35: =IF(OR(A35="",C35="",D35=""),"",IF(COUNTIFS($A:$A,A35,$C:$C,C35,$D:$D,D35)>1,"DUPLICATE","OK"))
B36: =IF(A36="","",IFERROR(VLOOKUP(A36,Master_Lista!$A$4:$E$15,2,FALSE()),"INVALID_ID")) | F36: =IF(A36="","",IFERROR(VLOOKUP(A36,Master_Lista!$A$4:$E$15,3,FALSE()),"INVALID_ID")) | G36: =IF(F36="","",IFERROR(VLOOKUP(F36,Pozicije!$A$4:$B$23,2,FALSE()),0)) | H36: =IF(OR(E36="",G36=""),"",E36*G36) | I36: =IF(H36="","",H36*Inputs_Control!$B$10) | J36: =IF(H36="","",H36+I36) | K36: =IF(OR(A36="",B36=""),"",IF(B36="INVALID_ID","INVALID_ID","OK")) | L36: =IF(C36="","",IF(COUNTIF(Lists!$B$2:$B$5,C36)=0,"INVALID_OR_INACTIVE","OK")) | M36: =IF(E36="","",IF(E36>Inputs_Control!$B$12,"SUSPICIOUS",IF(E36>Inputs_Control!$B$11,"OVERTIME","OK"))) | N36: =IF(OR(A36="",C36="",D36=""),"",IF(COUNTIFS($A:$A,A36,$C:$C,C36,$D:$D,D36)>1,"DUPLICATE","OK"))
B37: =IF(A37="","",IFERROR(VLOOKUP(A37,Master_Lista!$A$4:$E$15,2,FALSE()),"INVALID_ID")) | F37: =IF(A37="","",IFERROR(VLOOKUP(A37,Master_Lista!$A$4:$E$15,3,FALSE()),"INVALID_ID")) | G37: =IF(F37="","",IFERROR(VLOOKUP(F37,Pozicije!$A$4:$B$23,2,FALSE()),0)) | H37: =IF(OR(E37="",G37=""),"",E37*G37) | I37: =IF(H37="","",H37*Inputs_Control!$B$10) | J37: =IF(H37="","",H37+I37) | K37: =IF(OR(A37="",B37=""),"",IF(B37="INVALID_ID","INVALID_ID","OK")) | L37: =IF(C37="","",IF(COUNTIF(Lists!$B$2:$B$5,C37)=0,"INVALID_OR_INACTIVE","OK")) | M37: =IF(E37="","",IF(E37>Inputs_Control!$B$12,"SUSPICIOUS",IF(E37>Inputs_Control!$B$11,"OVERTIME","OK"))) | N37: =IF(OR(A37="",C37="",D37=""),"",IF(COUNTIFS($A:$A,A37,$C:$C,C37,$D:$D,D37)>1,"DUPLICATE","OK"))
B38: =IF(A38="","",IFERROR(VLOOKUP(A38,Master_Lista!$A$4:$E$15,2,FALSE()),"INVALID_ID")) | F38: =IF(A38="","",IFERROR(VLOOKUP(A38,Master_Lista!$A$4:$E$15,3,FALSE()),"INVALID_ID")) | G38: =IF(F38="","",IFERROR(VLOOKUP(F38,Pozicije!$A$4:$B$23,2,FALSE()),0)) | H38: =IF(OR(E38="",G38=""),"",E38*G38) | I38: =IF(H38="","",H38*Inputs_Control!$B$10) | J38: =IF(H38="","",H38+I38) | K38: =IF(OR(A38="",B38=""),"",IF(B38="INVALID_ID","INVALID_ID","OK")) | L38: =IF(C38="","",IF(COUNTIF(Lists!$B$2:$B$5,C38)=0,"INVALID_OR_INACTIVE","OK")) | M38: =IF(E38="","",IF(E38>Inputs_Control!$B$12,"SUSPICIOUS",IF(E38>Inputs_Control!$B$11,"OVERTIME","OK"))) | N38: =IF(OR(A38="",C38="",D38=""),"",IF(COUNTIFS($A:$A,A38,$C:$C,C38,$D:$D,D38)>1,"DUPLICATE","OK"))
B39: =IF(A39="","",IFERROR(VLOOKUP(A39,Master_Lista!$A$4:$E$15,2,FALSE()),"INVALID_ID")) | F39: =IF(A39="","",IFERROR(VLOOKUP(A39,Master_Lista!$A$4:$E$15,3,FALSE()),"INVALID_ID")) | G39: =IF(F39="","",IFERROR(VLOOKUP(F39,Pozicije!$A$4:$B$23,2,FALSE()),0)) | H39: =IF(OR(E39="",G39=""),"",E39*G39) | I39: =IF(H39="","",H39*Inputs_Control!$B$10) | J39: =IF(H39="","",H39+I39) | K39: =IF(OR(A39="",B39=""),"",IF(B39="INVALID_ID","INVALID_ID","OK")) | L39: =IF(C39="","",IF(COUNTIF(Lists!$B$2:$B$5,C39)=0,"INVALID_OR_INACTIVE","OK")) | M39: =IF(E39="","",IF(E39>Inputs_Control!$B$12,"SUSPICIOUS",IF(E39>Inputs_Control!$B$11,"OVERTIME","OK"))) | N39: =IF(OR(A39="",C39="",D39=""),"",IF(COUNTIFS($A:$A,A39,$C:$C,C39,$D:$D,D39)>1,"DUPLICATE","OK"))
B40: =IF(A40="","",IFERROR(VLOOKUP(A40,Master_Lista!$A$4:$E$15,2,FALSE()),"INVALID_ID")) | F40: =IF(A40="","",IFERROR(VLOOKUP(A40,Master_Lista!$A$4:$E$15,3,FALSE()),"INVALID_ID")) | G40: =IF(F40="","",IFERROR(VLOOKUP(F40,Pozicije!$A$4:$B$23,2,FALSE()),0)) | H40: =IF(OR(E40="",G40=""),"",E40*G40) | I40: =IF(H40="","",H40*Inputs_Control!$B$10) | J40: =IF(H40="","",H40+I40) | K40: =IF(OR(A40="",B40=""),"",IF(B40="INVALID_ID","INVALID_ID","OK")) | L40: =IF(C40="","",IF(COUNTIF(Lists!$B$2:$B$5,C40)=0,"INVALID_OR_INACTIVE","OK")) | M40: =IF(E40="","",IF(E40>Inputs_Control!$B$12,"SUSPICIOUS",IF(E40>Inputs_Control!$B$11,"OVERTIME","OK"))) | N40: =IF(OR(A40="",C40="",D40=""),"",IF(COUNTIFS($A:$A,A40,$C:$C,C40,$D:$D,D40)>1,"DUPLICATE","OK"))
B41: =IF(A41="","",IFERROR(VLOOKUP(A41,Master_Lista!$A$4:$E$15,2,FALSE()),"INVALID_ID")) | F41: =IF(A41="","",IFERROR(VLOOKUP(A41,Master_Lista!$A$4:$E$15,3,FALSE()),"INVALID_ID")) | G41: =IF(F41="","",IFERROR(VLOOKUP(F41,Pozicije!$A$4:$B$23,2,FALSE()),0)) | H41: =IF(OR(E41="",G41=""),"",E41*G41) | I41: =IF(H41="","",H41*Inputs_Control!$B$10) | J41: =IF(H41="","",H41+I41) | K41: =IF(OR(A41="",B41=""),"",IF(B41="INVALID_ID","INVALID_ID","OK")) | L41: =IF(C41="","",IF(COUNTIF(Lists!$B$2:$B$5,C41)=0,"INVALID_OR_INACTIVE","OK")) | M41: =IF(E41="","",IF(E41>Inputs_Control!$B$12,"SUSPICIOUS",IF(E41>Inputs_Control!$B$11,"OVERTIME","OK"))) | N41: =IF(OR(A41="",C41="",D41=""),"",IF(COUNTIFS($A:$A,A41,$C:$C,C41,$D:$D,D41)>1,"DUPLICATE","OK"))
B42: =IF(A42="","",IFERROR(VLOOKUP(A42,Master_Lista!$A$4:$E$15,2,FALSE()),"INVALID_ID")) | F42: =IF(A42="","",IFERROR(VLOOKUP(A42,Master_Lista!$A$4:$E$15,3,FALSE()),"INVALID_ID")) | G42: =IF(F42="","",IFERROR(VLOOKUP(F42,Pozicije!$A$4:$B$23,2,FALSE()),0)) | H42: =IF(OR(E42="",G42=""),"",E42*G42) | I42: =IF(H42="","",H42*Inputs_Control!$B$10) | J42: =IF(H42="","",H42+I42) | K42: =IF(OR(A42="",B42=""),"",IF(B42="INVALID_ID","INVALID_ID","OK")) | L42: =IF(C42="","",IF(COUNTIF(Lists!$B$2:$B$5,C42)=0,"INVALID_OR_INACTIVE","OK")) | M42: =IF(E42="","",IF(E42>Inputs_Control!$B$12,"SUSPICIOUS",IF(E42>Inputs_Control!$B$11,"OVERTIME","OK"))) | N42: =IF(OR(A42="",C42="",D42=""),"",IF(COUNTIFS($A:$A,A42,$C:$C,C42,$D:$D,D42)>1,"DUPLICATE","OK"))
B43: =IF(A43="","",IFERROR(VLOOKUP(A43,Master_Lista!$A$4:$E$15,2,FALSE()),"INVALID_ID")) | F43: =IF(A43="","",IFERROR(VLOOKUP(A43,Master_Lista!$A$4:$E$15,3,FALSE()),"INVALID_ID")) | G43: =IF(F43="","",IFERROR(VLOOKUP(F43,Pozicije!$A$4:$B$23,2,FALSE()),0)) | H43: =IF(OR(E43="",G43=""),"",E43*G43) | I43: =IF(H43="","",H43*Inputs_Control!$B$10) | J43: =IF(H43="","",H43+I43) | K43: =IF(OR(A43="",B43=""),"",IF(B43="INVALID_ID","INVALID_ID","OK")) | L43: =IF(C43="","",IF(COUNTIF(Lists!$B$2:$B$5,C43)=0,"INVALID_OR_INACTIVE","OK")) | M43: =IF(E43="","",IF(E43>Inputs_Control!$B$12,"SUSPICIOUS",IF(E43>Inputs_Control!$B$11,"OVERTIME","OK"))) | N43: =IF(OR(A43="",C43="",D43=""),"",IF(COUNTIFS($A:$A,A43,$C:$C,C43,$D:$D,D43)>1,"DUPLICATE","OK"))
B44: =IF(A44="","",IFERROR(VLOOKUP(A44,Master_Lista!$A$4:$E$15,2,FALSE()),"INVALID_ID")) | F44: =IF(A44="","",IFERROR(VLOOKUP(A44,Master_Lista!$A$4:$E$15,3,FALSE()),"INVALID_ID")) | G44: =IF(F44="","",IFERROR(VLOOKUP(F44,Pozicije!$A$4:$B$23,2,FALSE()),0)) | H44: =IF(OR(E44="",G44=""),"",E44*G44) | I44: =IF(H44="","",H44*Inputs_Control!$B$10) | J44: =IF(H44="","",H44+I44) | K44: =IF(OR(A44="",B44=""),"",IF(B44="INVALID_ID","INVALID_ID","OK")) | L44: =IF(C44="","",IF(COUNTIF(Lists!$B$2:$B$5,C44)=0,"INVALID_OR_INACTIVE","OK")) | M44: =IF(E44="","",IF(E44>Inputs_Control!$B$12,"SUSPICIOUS",IF(E44>Inputs_Control!$B$11,"OVERTIME","OK"))) | N44: =IF(OR(A44="",C44="",D44=""),"",IF(COUNTIFS($A:$A,A44,$C:$C,C44,$D:$D,D44)>1,"DUPLICATE","OK"))
B45: =IF(A45="","",IFERROR(VLOOKUP(A45,Master_Lista!$A$4:$E$15,2,FALSE()),"INVALID_ID")) | F45: =IF(A45="","",IFERROR(VLOOKUP(A45,Master_Lista!$A$4:$E$15,3,FALSE()),"INVALID_ID")) | G45: =IF(F45="","",IFERROR(VLOOKUP(F45,Pozicije!$A$4:$B$23,2,FALSE()),0)) | H45: =IF(OR(E45="",G45=""),"",E45*G45) | I45: =IF(H45="","",H45*Inputs_Control!$B$10) | J45: =IF(H45="","",H45+I45) | K45: =IF(OR(A45="",B45=""),"",IF(B45="INVALID_ID","INVALID_ID","OK")) | L45: =IF(C45="","",IF(COUNTIF(Lists!$B$2:$B$5,C45)=0,"INVALID_OR_INACTIVE","OK")) | M45: =IF(E45="","",IF(E45>Inputs_Control!$B$12,"SUSPICIOUS",IF(E45>Inputs_Control!$B$11,"OVERTIME","OK"))) | N45: =IF(OR(A45="",C45="",D45=""),"",IF(COUNTIFS($A:$A,A45,$C:$C,C45,$D:$D,D45)>1,"DUPLICATE","OK"))
... B63: =IF(A63="","",IFERROR(VLOOKUP(A63,Master_Lista!$A$4:$E$15,2,FALSE()),"INVALID_ID")) | F63: =IF(A63="","",IFERROR(VLOOKUP(A63,Master_Lista!$A$4:$E$15,3,FALSE()),"INVALID_ID")) | G63: =IF(F63="","",IFERROR(VLOOKUP(F63,Pozicije!$A$4:$B$23,2,FALSE()),0)) | H63: =IF(OR(E63="",G63=""),"",E63*G63) | I63: =IF(H63="","",H63*Inputs_Control!$B$10) | J63: =IF(H63="","",H63+I63) | K63: =IF(OR(A63="",B63=""),"",IF(B63="INVALID_ID","INVALID_ID","OK")) | L63: =IF(C63="","",IF(COUNTIF(Lists!$B$2:$B$5,C63)=0,"INVALID_OR_INACTIVE","OK")) | M63: =IF(E63="","",IF(E63>Inputs_Control!$B$12,"SUSPICIOUS",IF(E63>Inputs_Control!$B$11,"OVERTIME","OK"))) | N63: =IF(OR(A63="",C63="",D63=""),"",IF(COUNTIFS($A:$A,A63,$C:$C,C63,$D:$D,D63)>1,"DUPLICATE","OK"))

Sheet Sheet31_Analitika
A1: Analytics and aggregation
A3: Employee_ID | B3: Ime Radnika | C3: Ukupni Sati | D3: Ukupan Trošak | E3: Prosječan Trošak / h | F3: Broj Unosa | G3: Efikasnost | J3: Projekat | K3: Naziv | L3: Ukupni Sati | M3: Ukupan Trošak | N3: Broj Unosa | O3: Prosjek po Unosu
A4: EMP001 | B4: Branko Vasic | C4: =SUMIF(Sheet3_Sati!$A$4:$A$63,A4,Sheet3_Sati!$E$4:$E$63) -> 25.5 | D4: =SUMIF(Sheet3_Sati!$A$4:$A$63,A4,Sheet3_Sati!$J$4:$J$63) -> 217.83375 | E4: =IF(C4=0,0,D4/C4) -> 8.5425 | F4: =COUNTIF(Sheet3_Sati!$A$4:$A$63,A4) -> 3 | G4: =IF(F4=0,"No entries",IF(C4<16,"Low utilization","OK")) -> OK | J4: P001 | K4: Oil Trafo 5MVA Assembly | L4: =SUMIF(Sheet3_Sati!$C$4:$C$63,J4,Sheet3_Sati!$E$4:$E$63) -> 73.5 | M4: =SUMIF(Sheet3_Sati!$C$4:$C$63,J4,Sheet3_Sati!$J$4:$J$63) -> 929.37375 | N4: =COUNTIF(Sheet3_Sati!$C$4:$C$63,J4) -> 9 | O4: =IF(N4=0,0,M4/N4) -> 103.26375
A5: EMP002 | B5: Filip Antic | C5: =SUMIF(Sheet3_Sati!$A$4:$A$63,A5,Sheet3_Sati!$E$4:$E$63) -> 25 | D5: =SUMIF(Sheet3_Sati!$A$4:$A$63,A5,Sheet3_Sati!$J$4:$J$63) -> 263.8125 | E5: =IF(C5=0,0,D5/C5) -> 10.5525 | F5: =COUNTIF(Sheet3_Sati!$A$4:$A$63,A5) -> 3 | G5: =IF(F5=0,"No entries",IF(C5<16,"Low utilization","OK")) -> OK | J5: P002 | K5: Winding Production | L5: =SUMIF(Sheet3_Sati!$C$4:$C$63,J5,Sheet3_Sati!$E$4:$E$63) -> 49 | M5: =SUMIF(Sheet3_Sati!$C$4:$C$63,J5,Sheet3_Sati!$J$4:$J$63) -> 553.2525 | N5: =COUNTIF(Sheet3_Sati!$C$4:$C$63,J5) -> 6 | O5: =IF(N5=0,0,M5/N5) -> 92.20875
A6: EMP003 | B6: Luka Filipovic | C6: =SUMIF(Sheet3_Sati!$A$4:$A$63,A6,Sheet3_Sati!$E$4:$E$63) -> 24.5 | D6: =SUMIF(Sheet3_Sati!$A$4:$A$63,A6,Sheet3_Sati!$J$4:$J$63) -> 221.6025 | E6: =IF(C6=0,0,D6/C6) -> 9.045 | F6: =COUNTIF(Sheet3_Sati!$A$4:$A$63,A6) -> 3 | G6: =IF(F6=0,"No entries",IF(C6<16,"Low utilization","OK")) -> OK | J6: P003 | K6: Core Stacking | L6: =SUMIF(Sheet3_Sati!$C$4:$C$63,J6,Sheet3_Sati!$E$4:$E$63) -> 0 | M6: =SUMIF(Sheet3_Sati!$C$4:$C$63,J6,Sheet3_Sati!$J$4:$J$63) -> 0 | N6: =COUNTIF(Sheet3_Sati!$C$4:$C$63,J6) -> 0 | O6: =IF(N6=0,0,M6/N6) -> 0
A7: EMP004 | B7: Tomas Obradovic | C7: =SUMIF(Sheet3_Sati!$A$4:$A$63,A7,Sheet3_Sati!$E$4:$E$63) -> 24 | D7: =SUMIF(Sheet3_Sati!$A$4:$A$63,A7,Sheet3_Sati!$J$4:$J$63) -> 241.2 | E7: =IF(C7=0,0,D7/C7) -> 10.05 | F7: =COUNTIF(Sheet3_Sati!$A$4:$A$63,A7) -> 3 | G7: =IF(F7=0,"No entries",IF(C7<16,"Low utilization","OK")) -> OK | J7: P004 | K7: Tank Fabrication | L7: =SUMIF(Sheet3_Sati!$C$4:$C$63,J7,Sheet3_Sati!$E$4:$E$63) -> 72.5 | M7: =SUMIF(Sheet3_Sati!$C$4:$C$63,J7,Sheet3_Sati!$J$4:$J$63) -> 716.0625 | N7: =COUNTIF(Sheet3_Sati!$C$4:$C$63,J7) -> 9 | O7: =IF(N7=0,0,M7/N7) -> 79.5625
A8: EMP005 | B8: Jelena Nikolic | C8: =SUMIF(Sheet3_Sati!$A$4:$A$63,A8,Sheet3_Sati!$E$4:$E$63) -> 24 | D8: =SUMIF(Sheet3_Sati!$A$4:$A$63,A8,Sheet3_Sati!$J$4:$J$63) -> 337.68 | E8: =IF(C8=0,0,D8/C8) -> 14.07 | F8: =COUNTIF(Sheet3_Sati!$A$4:$A$63,A8) -> 3 | G8: =IF(F8=0,"No entries",IF(C8<16,"Low utilization","OK")) -> OK | J8: P005 | K8: Oil Filling & Testing | L8: =SUMIF(Sheet3_Sati!$C$4:$C$63,J8,Sheet3_Sati!$E$4:$E$63) -> 48 | M8: =SUMIF(Sheet3_Sati!$C$4:$C$63,J8,Sheet3_Sati!$J$4:$J$63) -> 566.82 | N8: =COUNTIF(Sheet3_Sati!$C$4:$C$63,J8) -> 6 | O8: =IF(N8=0,0,M8/N8) -> 94.47
A9: EMP006 | B9: Goran Zivkovic | C9: =SUMIF(Sheet3_Sati!$A$4:$A$63,A9,Sheet3_Sati!$E$4:$E$63) -> 24 | D9: =SUMIF(Sheet3_Sati!$A$4:$A$63,A9,Sheet3_Sati!$J$4:$J$63) -> 289.44 | E9: =IF(C9=0,0,D9/C9) -> 12.06 | F9: =COUNTIF(Sheet3_Sati!$A$4:$A$63,A9) -> 3 | G9: =IF(F9=0,"No entries",IF(C9<16,"Low utilization","OK")) -> OK
A10: EMP007 | B10: Filip Kostic | C10: =SUMIF(Sheet3_Sati!$A$4:$A$63,A10,Sheet3_Sati!$E$4:$E$63) -> 24 | D10: =SUMIF(Sheet3_Sati!$A$4:$A$63,A10,Sheet3_Sati!$J$4:$J$63) -> 229.14 | E10: =IF(C10=0,0,D10/C10) -> 9.5475 | F10: =COUNTIF(Sheet3_Sati!$A$4:$A$63,A10) -> 3 | G10: =IF(F10=0,"No entries",IF(C10<16,"Low utilization","OK")) -> OK
A11: EMP008 | B11: Lidija Tomic | C11: =SUMIF(Sheet3_Sati!$A$4:$A$63,A11,Sheet3_Sati!$E$4:$E$63) -> 0 | D11: =SUMIF(Sheet3_Sati!$A$4:$A$63,A11,Sheet3_Sati!$J$4:$J$63) -> 0 | E11: =IF(C11=0,0,D11/C11) -> 0 | F11: =COUNTIF(Sheet3_Sati!$A$4:$A$63,A11) -> 0 | G11: =IF(F11=0,"No entries",IF(C11<16,"Low utilization","OK")) -> No entries
A12: EMP009 | B12: Petar Lazic | C12: =SUMIF(Sheet3_Sati!$A$4:$A$63,A12,Sheet3_Sati!$E$4:$E$63) -> 24 | D12: =SUMIF(Sheet3_Sati!$A$4:$A$63,A12,Sheet3_Sati!$J$4:$J$63) -> 180.9 | E12: =IF(C12=0,0,D12/C12) -> 7.5375 | F12: =COUNTIF(Sheet3_Sati!$A$4:$A$63,A12) -> 3 | G12: =IF(F12=0,"No entries",IF(C12<16,"Low utilization","OK")) -> OK
A13: EMP010 | B13: Branko Babic | C13: =SUMIF(Sheet3_Sati!$A$4:$A$63,A13,Sheet3_Sati!$E$4:$E$63) -> 24 | D13: =SUMIF(Sheet3_Sati!$A$4:$A$63,A13,Sheet3_Sati!$J$4:$J$63) -> 253.26 | E13: =IF(C13=0,0,D13/C13) -> 10.5525 | F13: =COUNTIF(Sheet3_Sati!$A$4:$A$63,A13) -> 3 | G13: =IF(F13=0,"No entries",IF(C13<16,"Low utilization","OK")) -> OK
A14: EMP011 | B14: Uros Djordjevic | C14: =SUMIF(Sheet3_Sati!$A$4:$A$63,A14,Sheet3_Sati!$E$4:$E$63) -> 24 | D14: =SUMIF(Sheet3_Sati!$A$4:$A$63,A14,Sheet3_Sati!$J$4:$J$63) -> 530.64 | E14: =IF(C14=0,0,D14/C14) -> 22.11 | F14: =COUNTIF(Sheet3_Sati!$A$4:$A$63,A14) -> 3 | G14: =IF(F14=0,"No entries",IF(C14<16,"Low utilization","OK")) -> OK
A15: EMP012 | B15: Sanja Grujic | C15: =SUMIF(Sheet3_Sati!$A$4:$A$63,A15,Sheet3_Sati!$E$4:$E$63) -> 0 | D15: =SUMIF(Sheet3_Sati!$A$4:$A$63,A15,Sheet3_Sati!$J$4:$J$63) -> 0 | E15: =IF(C15=0,0,D15/C15) -> 0 | F15: =COUNTIF(Sheet3_Sati!$A$4:$A$63,A15) -> 0 | G15: =IF(F15=0,"No entries",IF(C15<16,"Low utilization","OK")) -> No entries
C16: =SUM(C4:C15) -> 243 | D16: =SUM(D4:D15) -> 2765.5087 | F16: =SUM(F4:F15) -> 30

Sheet Sheet35_Dashboard
A1: EXECUTIVE SUMMARY - EFIKASNOST 2026 (v3.2 clean investor/audit)
B3: Ukupan Trošak Rada | F3: Ukupno Evidentiranih Sati | J3: Prosječan Trošak po Satu | N3: Broj Evidentiranih Unosa
B4: =SUM(Sheet3_Sati!$J$4:$J$63) -> 2765.5087 | F4: =SUM(Sheet3_Sati!$E$4:$E$63) -> 243 | J4: =IF(F4=0,0,B4/F4) -> 11.380694 | N4: =COUNTA(Sheet3_Sati!$A$4:$A$63) -> 30
B8: Najskuplji Projekat | F8: Najopterećeniji Radnik (ID) | J8: Overtime Unosi | N8: Sumnjivi Unosi (>12h)
B9: =INDEX(Sheet31_Analitika!$J$4:$J$8,MATCH(MAX(Sheet31_Analitika!$M$4:$M$8),Sheet31_Analitika!$M$4:$M$8,0)) -> P001 | F9: =INDEX(Sheet31_Analitika!$A$4:$A$15,MATCH(MAX(Sheet31_Analitika!$D$4:$D$15),Sheet31_Analitika!$D$4:$D$15,0)) -> EMP011 | J9: =COUNTIF(Sheet3_Sati!$M$4:$M$63,"OVERTIME") -> 3 | N9: =COUNTIF(Sheet3_Sati!$M$4:$M$63,"SUSPICIOUS") -> 0
B13: Duplikat Redovi | F13: Invalid Employee Lookup | J13: Invalid / Inactive Project | N13: Payroll Total Cost
B14: =COUNTIF(Sheet3_Sati!$N$4:$N$63,"DUPLICATE") -> 0 | F14: =COUNTIF(Sheet3_Sati!$K$4:$K$63,"INVALID_ID") -> 0 | J14: =COUNTIF(Sheet3_Sati!$L$4:$L$63,"INVALID_OR_INACTIVE") -> 0 | N14: =SUM(Sheet11_Zarade!$N$4:$N$15) -> 22833.6
A19: Control item | B19: Value
B20: Payroll employees | C20: =COUNTA(Sheet11_Zarade!$A$4:$A$15) -> 12 | N20: Board-ready view
B21: Active projects in dropdown | C21: =COUNTA(Lists!$B$2:$B$5) -> 4 | N21: Open Board_Dashboard
B22: Rows prepared in timesheet | C22: 60
B23: Model status | C23: =IF(COUNTIF(Error_Checks!$D$4:$D$15,"FAIL")=0,"CLEAN","REVIEW") -> REVIEW

Sheet Error_Checks
A1: Audit control checks (formula-driven)
A3: Check | B3: Value | C3: Target | D3: Result
A4: Ukupni sati > 0 | B4: =SUM(Sheet3_Sati!$E$4:$E$63) -> 243 | C4: >0 | D4: =IF(B4>0,"PASS","FAIL") -> PASS
A5: Ukupan trošak > 0 | B5: =SUM(Sheet3_Sati!$J$4:$J$63) -> 2765.5087 | C5: >0 | D5: =IF(B5>0,"PASS","FAIL") -> PASS
A6: Sumnjivi unosi (>12h) | B6: =COUNTIF(Sheet3_Sati!$M$4:$M$63,"SUSPICIOUS") -> 0 | C6: 0 | D6: =IF(B6=0,"PASS","FAIL") -> PASS
A7: Duplikati ID+Datum+Projekat | B7: =COUNTIF(Sheet3_Sati!$N$4:$N$63,"DUPLICATE") -> 0 | C7: 0 | D7: =IF(B7=0,"PASS","FAIL") -> PASS
A8: Nevalidni Employee_ID lookup | B8: =COUNTIF(Sheet3_Sati!$K$4:$K$63,"INVALID_ID") -> 0 | C8: 0 | D8: =IF(B8=0,"PASS","FAIL") -> PASS
A9: Nevalidan ili neaktivan projekat | B9: =COUNTIF(Sheet3_Sati!$L$4:$L$63,"INVALID_OR_INACTIVE") -> 0 | C9: 0 | D9: =IF(B9=0,"PASS","FAIL") -> PASS
A10: Payroll employee count = master count | B10: =COUNTA(Sheet11_Zarade!$A$4:$A$15)-COUNTA(Master_Lista!$A$4:$A$15) -> 0 | C10: 0 | D10: =IF(B10=0,"PASS","FAIL") -> PASS
A11: Board revenue > 0 | B11: =Project_Profitability!G9 -> 19524000 | C11: >0 | D11: =IF(B11>0,"PASS","FAIL") -> PASS
A12: Gross margin >= target | B12: =Project_Profitability!L9 -> 0.37830024 | C12: =Inputs_Control!$B$24 -> 0.26 | D12: =IF(B12>=Inputs_Control!$B$24,"PASS","FAIL") -> PASS
A13: EBITDA margin >= target | B13: =IF(Project_Profitability!G9=0,0,(Project_Profitability!K9-OPEX_Plan!O8)/Project_Profitability!G9) -> 0.16655888 | C13: =Inputs_Control!$B$25 -> 0.14 | D13: =IF(B13>=Inputs_Control!$B$25,"PASS","FAIL") -> PASS
A14: CAPEX base case <= limit | B14: =CAPEX_Plan!C10 -> 10910000 | C14: <=9000000 | D14: =IF(B14<=9000000,"PASS","FAIL") -> FAIL
A15: Capacity base MVA > 0 | B15: =Capacity_Planning!I4 -> 4.25 | C15: >0 | D15: =IF(B15>0,"PASS","FAIL") -> PASS

Sheet Project_Profitability
A1: v3.3 BOARD-READY - PROJECT / PRODUCT PROFITABILITY
A3: Project Code | B3: Project Name | C3: Transformer Type | D3: Units / Year | E3: MVA / Unit | F3: Revenue / Unit | G3: Annual Revenue | H3: Material Ratio | I3: Material Cost | J3: Direct Labor Cost | K3: Gross Profit | L3: Gross Margin
A4: P001 | B4: Oil Trafo 5MVA Assembly | C4: 5 MVA Oil Transformer | D4: 24 | E4: 5 | F4: 210000 | G4: =D4*F4 -> 5040000 | H4: =Inputs_Control!$B$20 -> 0.62 | I4: =G4*H4 -> 3124800 | J4: =Sheet31_Analitika!$M$4*12 -> 11152.485 | K4: =G4-I4-J4 -> 1904047.5 | L4: =IF(G4=0,0,K4/G4) -> 0.37778721
A5: P002 | B5: Winding Production | C5: 2.5 MVA Transformer | D5: 36 | E5: 2.5 | F5: 145000 | G5: =D5*F5 -> 5220000 | H5: =Inputs_Control!$B$20 -> 0.62 | I5: =G5*H5 -> 3236400 | J5: =Sheet31_Analitika!$M$5*12 -> 6639.03 | K5: =G5-I5-J5 -> 1976961 | L5: =IF(G5=0,0,K5/G5) -> 0.37872816
A6: P004 | B6: Tank Fabrication | C6: 1.6 MVA Tank Package | D6: 48 | E6: 1.6 | F6: 98000 | G6: =D6*F6 -> 4704000 | H6: =Inputs_Control!$B$20 -> 0.62 | I6: =G6*H6 -> 2916480 | J6: =Sheet31_Analitika!$M$7*12 -> 8592.75 | K6: =G6-I6-J6 -> 1778927.2 | L6: =IF(G6=0,0,K6/G6) -> 0.37817331
A7: P005 | B7: Oil Filling & Testing | C7: 1.0 MVA Final Test Unit | D7: 60 | E7: 1 | F7: 76000 | G7: =D7*F7 -> 4560000 | H7: =Inputs_Control!$B$20 -> 0.62 | I7: =G7*H7 -> 2827200 | J7: =Sheet31_Analitika!$M$8*12 -> 6801.84 | K7: =G7-I7-J7 -> 1725998.2 | L7: =IF(G7=0,0,K7/G7) -> 0.37850837
A9: TOTAL | D9: =SUM(D4:D7) -> 168 | E9: =SUM(E4:E7) -> 10.1 | F9: =SUM(F4:F7) -> 529000 | G9: =SUM(G4:G7) -> 19524000 | H9: =SUM(H4:H7) -> 2.48 | I9: =SUM(I4:I7) -> 12104880 | J9: =SUM(J4:J7) -> 33186.105 | K9: =SUM(K4:K7) -> 7385933.9 | L9: =IF(G9=0,0,K9/G9) -> 0.37830024

Sheet OPEX_Plan
A1: v3.3 BOARD-READY - OPEX PLAN
A3: Category | B3: Driver | C3: Jan | D3: Feb | E3: Mar | F3: Apr | G3: May | H3: Jun | I3: Jul | J3: Aug | K3: Sep | L3: Oct | M3: Nov | N3: Dec | O3: Annual
A4: Loaded payroll | B4: =Inputs_Control!$B$28 -> 274003.2 | C4: =$B4 -> 274003.2 | D4: =$B4 -> 274003.2 | E4: =$B4 -> 274003.2 | F4: =$B4 -> 274003.2 | G4: =$B4 -> 274003.2 | H4: =$B4 -> 274003.2 | I4: =$B4 -> 274003.2 | J4: =$B4 -> 274003.2 | ... N4: =$B4 -> 274003.2 | O4: =SUM(C4:N4) -> 3288038.4
A5: Factory overhead | B5: =Inputs_Control!$B$21 -> 45000 | C5: =$B5 -> 45000 | D5: =$B5 -> 45000 | E5: =$B5 -> 45000 | F5: =$B5 -> 45000 | G5: =$B5 -> 45000 | H5: =$B5 -> 45000 | I5: =$B5 -> 45000 | J5: =$B5 -> 45000 | ... N5: =$B5 -> 45000 | O5: =SUM(C5:N5) -> 540000
A6: Sales & admin | B6: =Inputs_Control!$B$22 -> 18000 | C6: =$B6 -> 18000 | D6: =$B6 -> 18000 | E6: =$B6 -> 18000 | F6: =$B6 -> 18000 | G6: =$B6 -> 18000 | H6: =$B6 -> 18000 | I6: =$B6 -> 18000 | J6: =$B6 -> 18000 | ... N6: =$B6 -> 18000 | O6: =SUM(C6:N6) -> 216000
A7: Maintenance reserve | B7: =Inputs_Control!$B$23 -> 7500 | C7: =$B7 -> 7500 | D7: =$B7 -> 7500 | E7: =$B7 -> 7500 | F7: =$B7 -> 7500 | G7: =$B7 -> 7500 | H7: =$B7 -> 7500 | I7: =$B7 -> 7500 | J7: =$B7 -> 7500 | ... N7: =$B7 -> 7500 | O7: =SUM(C7:N7) -> 90000
A8: TOTAL OPEX | B8: =SUM(B4:B7) -> 344503.2 | C8: =SUM(C4:C7) -> 344503.2 | D8: =SUM(D4:D7) -> 344503.2 | E8: =SUM(E4:E7) -> 344503.2 | F8: =SUM(F4:F7) -> 344503.2 | G8: =SUM(G4:G7) -> 344503.2 | H8: =SUM(H4:H7) -> 344503.2 | I8: =SUM(I4:I7) -> 344503.2 | ... O8: =SUM(O4:O7) -> 4134038.4

Sheet CAPEX_Plan
A1: v3.3 BOARD-READY - CAPEX PLAN
A3: CAPEX Category | B3: Low Case | C3: Base Case | D3: High Case | E3: 2026 | F3: 2027 | G3: 2028 | H3: 2029 | I3: Status | J3: Comment
A4: Land & site development | B4: 450000 | C4: 550000 | D4: 650000 | E4: 200000 | F4: 200000 | G4: 150000 | H4: 0 | I4: Planned | J4: Site prep and utilities
A5: Building & civil works | B5: 4200000 | C5: 5100000 | D5: 6200000 | E5: 800000 | F5: 1800000 | G5: 2000000 | H5: 500000 | I5: Planned | J5: Main hall and offices
A6: Process machinery | B6: 2600000 | C6: 3400000 | D6: 4200000 | E6: 400000 | F6: 1200000 | G6: 1400000 | H6: 400000 | I6: Planned | J6: Winding, core, tank, testing
A7: Utilities & infrastructure | B7: 550000 | C7: 700000 | D7: 850000 | E7: 100000 | F7: 250000 | G7: 250000 | H7: 100000 | I7: Planned | J7: Compressed air, cranes, power
A8: IT / MES / QA systems | B8: 180000 | C8: 260000 | D8: 340000 | E8: 50000 | F8: 90000 | G8: 90000 | H8: 30000 | I8: Planned | J8: MES, traceability, QA
A9: Contingency | B9: 650000 | C9: 900000 | D9: 1200000 | E9: 150000 | F9: 250000 | G9: 350000 | H9: 150000 | I9: Planned | J9: Board contingency
A10: TOTAL CAPEX | B10: =SUM(B4:B9) -> 8630000 | C10: =SUM(C4:C9) -> 10910000 | D10: =SUM(D4:D9) -> 13440000 | E10: =SUM(E4:E9) -> 1700000 | F10: =SUM(F4:F9) -> 3790000 | G10: =SUM(G4:G9) -> 4240000 | H10: =SUM(H4:H9) -> 1180000

Sheet Capacity_Planning
A1: v3.3 BOARD-READY - CAPACITY PLANNING
A3: Scenario | B3: Shifts / Day | C3: Hours / Shift | D3: Operating Days | E3: Utilization | F3: Annual Productive Hours | G3: Equivalent Units | H3: Average MVA / Unit | I3: Annual MVA Output | J3: Implied Revenue | K3: Comment
A4: Base | B4: =Inputs_Control!$B$15 -> 2 | C4: =Inputs_Control!$B$16 -> 8 | D4: =Inputs_Control!$B$18 -> 250 | E4: =Inputs_Control!$B$17 -> 0.85 | F4: =B4*C4*D4*E4 -> 3400 | G4: =F4/(Inputs_Control!$B$4*12) -> 1.7708333 | H4: =2.4 -> 2.4 | I4: =G4*H4 -> 4.25 | J4: =G4*Inputs_Control!$B$19 -> 212500 | K4: Board plan
A5: Upside | B5: 3 | C5: 8 | D5: 270 | E5: 0.9 | F5: =B5*C5*D5*E5 -> 5832 | G5: =F5/(Inputs_Control!$B$4*12) -> 3.0375 | H5: =2.8 -> 2.8 | I5: =G5*H5 -> 8.505 | J5: =G5*Inputs_Control!$B$19 -> 364500 | K5: 3-shift run
A6: Downside | B6: 2 | C6: 8 | D6: 220 | E6: 0.7 | F6: =B6*C6*D6*E6 -> 2464 | G6: =F6/(Inputs_Control!$B$4*12) -> 1.2833333 | H6: =2 -> 2 | I6: =G6*H6 -> 2.5666667 | J6: =G6*Inputs_Control!$B$19 -> 154000 | K6: Lower utilization

Sheet Board_Dashboard
A1: v3.3 BOARD DASHBOARD
B3: Total Revenue | F3: Gross Profit | J3: Gross Margin | N3: Annual OPEX
B4: =Project_Profitability!G9 -> 19524000 | F4: =Project_Profitability!K9 -> 7385933.9 | J4: =Project_Profitability!L9 -> 0.37830024 | N4: =OPEX_Plan!O8 -> 4134038.4
B8: EBITDA | F8: EBITDA Margin | J8: Base Capacity MVA | N8: Base Units
B9: =B4-N4 -> 15389962 | F9: =IF(B4=0,0,B9/B4) -> 0.78825864 | J9: =Capacity_Planning!I4 -> 4.25 | N9: =Capacity_Planning!G4 -> 1.7708333
B14: Board Summary
B15: Metric | C15: Value | D15: Target | E15: Status | H15: Navigation | I15: Linked Sheet | J15: Purpose
B16: Gross Margin | C16: =Project_Profitability!L9 -> 0.37830024 | D16: =Inputs_Control!$B$24 -> 0.26 | E16: =IF(C16>=D16,"ON TARGET","BELOW TARGET") -> ON TARGET | H16: Open profitability | I16: Project_Profitability | J16: Revenue / gross profit by transformer type
B17: EBITDA Margin | C17: =IF(B4=0,0,B9/B4) -> 0.78825864 | D17: =Inputs_Control!$B$25 -> 0.14 | E17: =IF(C17>=D17,"ON TARGET","BELOW TARGET") -> ON TARGET | H17: Open OPEX plan | I17: OPEX_Plan | J17: Monthly and annual operating expenditure
B18: Base Capacity Utilization | C18: =Capacity_Planning!E4 -> 0.85 | D18: 0.85 | E18: =IF(C18>=D18,"ON TARGET","REVIEW") -> ON TARGET | H18: Open CAPEX plan | I18: CAPEX_Plan | J18: Base / low / high capex envelope
B19: CAPEX Base Case | C19: =CAPEX_Plan!C10 -> 10910000 | D19: 9000000 | E19: =IF(C19<=D19,"WITHIN LIMIT","ABOVE LIMIT") -> ABOVE LIMIT | H19: Open capacity plan | I19: Capacity_Planning | J19: Shift-based unit and MVA planning
B20: Suspicious labor entries | C20: =COUNTIF(Sheet3_Sati!$M$4:$M$63,"SUSPICIOUS") -> 0 | D20: 0 | E20: =IF(C20=D20,"CLEAN","REVIEW") -> CLEAN

Sheet Finance_Document_Assumptions
A1: v4.3 FINANCE DOCUMENT LOGIC ENGINE - ASSUMPTIONS
A3: Assumption | B3: Value | C3: Unit | D3: Comment
A4: Debt Ratio | B4: 0.6 | C4: x | D4: Senior debt as % of base CAPEX
A5: Interest Rate | B5: 0.06 | C5: % | D5: Base case annual interest
A6: Lender Case Interest Rate | B6: 0.075 | C6: % | D6: Credit case annual interest
A7: Tenor (years) | B7: 8 | C7: years | D7: Straight-line principal assumption
A8: CFADS Conversion | B8: 0.9 | C8: % | D8: EBITDA to CFADS after tax/WC drag
A9: DSRA Months Required | B9: 6 | C9: months | D9: Target DSRA coverage
A10: DSCR Lock-up Threshold | B10: 1.2 | C10: x | D10: Restricted payment trigger
A11: DSCR Default Threshold | B11: 1 | C11: x | D11: Event of default threshold
A12: LLCR Threshold | B12: 1.3 | C12: x | D12: Loan life cover threshold
A13: PLCR Threshold | B13: 1.4 | C13: x | D13: Project life cover threshold
A14: Cash Sweep Trigger | B14: 1.35 | C14: x | D14: Minimum DSCR to permit sweep
A15: Cash Sweep Percentage | B15: 0.5 | C15: % | D15: Applied to post-debt excess cash
... A19: Max Equity Cure Uses | B19: 2 | C19: count | D19: Indicative cure count limit
A20: Base Revenue 2029 | B20: =Board_Dashboard!B4 -> 19524000 | C20: EUR | D20: Linked from Board Dashboard
A21: Base EBITDA Margin | B21: =Board_Dashboard!F9 -> 0.78825864 | C21: % | D21: Linked from Board Dashboard
A22: Base CAPEX | B22: =CAPEX_Plan!C10 -> 10910000 | C22: EUR | D22: Linked from CAPEX plan
A23: Debt Amount | B23: =B22*B4 -> 6546000 | C23: EUR | D23: Debt ratio x base capex
A24: Ramp 2026 | B24: 0.35 | C24: % | D24: Construction/ramp assumption
A25: Ramp 2027 | B25: 0.55 | C25: % | D25: Ramp assumption
A26: Ramp 2028 | B26: 0.8 | C26: % | D26: Ramp assumption
A27: Ramp 2029 | B27: 1 | C27: % | D27: Steady state assumption

Sheet Base_Case_Finance
A1: v4.3 BASE CASE FINANCE LOGIC
A3: Metric | B3: Formula / Driver | C3: 2026 | D3: 2027 | E3: 2028 | F3: 2029
A4: Revenue | B4: Board revenue x ramp | C4: =Finance_Document_Assumptions!$B$20*Finance_Document_Assumptions!$B$24 -> 6833400 | D4: =Finance_Document_Assumptions!$B$20*Finance_Document_Assumptions!$B$25 -> 10738200 | E4: =Finance_Document_Assumptions!$B$20*Finance_Document_Assumptions!$B$26 -> 15619200 | F4: =Finance_Document_Assumptions!$B$20*Finance_Document_Assumptions!$B$27 -> 19524000
A5: EBITDA Margin | B5: Board EBITDA margin | C5: =Finance_Document_Assumptions!$B$21 -> 0.78825864 | D5: =Finance_Document_Assumptions!$B$21 -> 0.78825864 | E5: =Finance_Document_Assumptions!$B$21 -> 0.78825864 | F5: =Finance_Document_Assumptions!$B$21 -> 0.78825864
A6: EBITDA | B6: Revenue x EBITDA margin | C6: =C4*C5 -> 5386486.6 | D6: =D4*D5 -> 8464478.9 | E6: =E4*E5 -> 12311969 | F6: =F4*F5 -> 15389962
A7: CFADS Conversion | B7: Assumption | C7: =Finance_Document_Assumptions!$B$8 -> 0.9 | D7: =Finance_Document_Assumptions!$B$8 -> 0.9 | E7: =Finance_Document_Assumptions!$B$8 -> 0.9 | F7: =Finance_Document_Assumptions!$B$8 -> 0.9
A8: CFADS | B8: EBITDA x conversion | C8: =C6*C7 -> 4847837.9 | D8: =D6*D7 -> 7618031 | E8: =E6*E7 -> 11080772 | F8: =F6*F7 -> 13850965
A9: CAPEX | B9: Phasing from CAPEX_Plan | C9: =CAPEX_Plan!E10 -> 1700000 | D9: =CAPEX_Plan!F10 -> 3790000 | E9: =CAPEX_Plan!G10 -> 4240000 | F9: =CAPEX_Plan!H10 -> 1180000
A10: Debt Drawdown | B10: CAPEX x debt ratio | C10: =C9*Finance_Document_Assumptions!$B$4 -> 1020000 | D10: =D9*Finance_Document_Assumptions!$B$4 -> 2274000 | E10: =E9*Finance_Document_Assumptions!$B$4 -> 2544000 | F10: =F9*Finance_Document_Assumptions!$B$4 -> 708000
A11: Opening Debt | B11: Roll-forward | C11: =0 -> 0 | D11: =C16 -> 1020000 | E11: =D16 -> 3294000 | F11: =E16 -> 5019750
A12: Interest | B12: Opening debt x rate | C12: =C11*Finance_Document_Assumptions!$B$5 -> 0 | D12: =D11*Finance_Document_Assumptions!$B$5 -> 61200 | E12: =E11*Finance_Document_Assumptions!$B$5 -> 197640 | F12: =F11*Finance_Document_Assumptions!$B$5 -> 301185
A13: Principal | B13: Straight-line from 2028 | C13: =0 -> 0 | D13: =0 -> 0 | E13: =Finance_Document_Assumptions!$B$23/Finance_Document_Assumptions!$B$7 -> 818250 | F13: =Finance_Document_Assumptions!$B$23/Finance_Document_Assumptions!$B$7 -> 818250
A14: Debt Service | B14: Interest + principal | C14: =C12+C13 -> 0 | D14: =D12+D13 -> 61200 | E14: =E12+E13 -> 1015890 | F14: =F12+F13 -> 1119435
A15: DSCR | B15: CFADS / Debt Service | C15: =IF(C14=0,"",IFERROR(C8/C14,"")) | D15: =IF(D14=0,"",IFERROR(D8/D14,"")) -> 124.47763 | E15: =IF(E14=0,"",IFERROR(E8/E14,"")) -> 10.907453 | F15: =IF(F14=0,"",IFERROR(F8/F14,"")) -> 12.373175
A16: Closing Debt | B16: Opening + draw - principal | C16: =C11+C10-C13 -> 1020000 | D16: =D11+D10-D13 -> 3294000 | E16: =E11+E10-E13 -> 5019750 | F16: =F11+F10-F13 -> 4909500
A17: LLCR | B17: Remaining CFADS / Opening Debt | C17: =IF(C11=0,"",SUM(C8:$F8)/C11) | D17: =IF(D11=0,"",SUM(D8:$F8)/D11) -> 31.911538 | E17: =IF(E11=0,"",SUM(E8:$F8)/E11) -> 7.5688336 | F17: =IF(F11=0,"",SUM(F8:$F8)/F11) -> 2.7592939
A18: PLCR | B18: Remaining EBITDA / Opening Debt | C18: =IF(C11=0,"",SUM(C6:$F6)/C11) | D18: =IF(D11=0,"",SUM(D6:$F6)/D11) -> 35.457264 | E18: =IF(E11=0,"",SUM(E6:$F6)/E11) -> 8.4098151 | F18: =IF(F11=0,"",SUM(F6:$F6)/F11) -> 3.0658821
A19: DSRA Required | B19: Debt service x months/12 | C19: =C14*(Finance_Document_Assumptions!$B$9/12) -> 0 | D19: =D14*(Finance_Document_Assumptions!$B$9/12) -> 30600 | E19: =E14*(Finance_Document_Assumptions!$B$9/12) -> 507945 | F19: =F14*(Finance_Document_Assumptions!$B$9/12) -> 559717.5
A20: DSRA Balance | B20: Assumed funded to requirement | C20: =C19 -> 0 | D20: =D19 -> 30600 | E20: =E19 -> 507945 | F20: =F19 -> 559717.5
A21: DSRA Adequacy | B21: DSRA / required | C21: =IF(C19=0,"",IFERROR(C20/C19,"")) | D21: =IF(D19=0,"",IFERROR(D20/D19,"")) -> 1 | E21: =IF(E19=0,"",IFERROR(E20/E19,"")) -> 1 | F21: =IF(F19=0,"",IFERROR(F20/F19,"")) -> 1
A22: Cash Balance Pre Sweep | B22: CFADS - debt service | C22: =C8-C14 -> 4847837.9 | D22: =D8-D14 -> 7556831 | E22: =E8-E14 -> 10064882 | F22: =F8-F14 -> 12731530
A23: Cash Sweep | B23: If DSCR >= trigger | C23: =IF(AND(C15<>"",C15>=Finance_Document_Assumptions!$B$14,C22>0),C22*Finance_Document_Assumptions!$B$15,0) -> 0 | D23: =IF(AND(D15<>"",D15>=Finance_Document_Assumptions!$B$14,D22>0),D22*Finance_Document_Assumptions!$B$15,0) -> 3778415.5 | E23: =IF(AND(E15<>"",E15>=Finance_Document_Assumptions!$B$14,E22>0),E22*Finance_Document_Assumptions!$B$15,0) -> 5032441.2 | F23: =IF(AND(F15<>"",F15>=Finance_Document_Assumptions!$B$14,F22>0),F22*Finance_Document_Assumptions!$B$15,0) -> 6365765.2
A24: Cash Balance Post Sweep | B24: Pre sweep - sweep | C24: =C22-C23 -> 4847837.9 | D24: =D22-D23 -> 3778415.5 | E24: =E22-E23 -> 5032441.2 | F24: =F22-F23 -> 6365765.2
A25: Distribution | B25: If allowed, 30% of post-sweep cash | C25: =IF(AND(C15<>"",C15>=Finance_Document_Assumptions!$B$10,C21>=1),C24*0.3,0) -> 0 | D25: =IF(AND(D15<>"",D15>=Finance_Document_Assumptions!$B$10,D21>=1),D24*0.3,0) -> 1133524.6 | E25: =IF(AND(E15<>"",E15>=Finance_Document_Assumptions!$B$10,E21>=1),E24*0.3,0) -> 1509732.4 | F25: =IF(AND(F15<>"",F15>=Finance_Document_Assumptions!$B$10,F21>=1),F24*0.3,0) -> 1909729.6
A26: Distribution Allowed? | B26: DSCR + DSRA gate | C26: =IF(AND(C15<>"",C15>=Finance_Document_Assumptions!$B$10,C21>=1),"YES","NO") -> NO | D26: =IF(AND(D15<>"",D15>=Finance_Document_Assumptions!$B$10,D21>=1),"YES","NO") -> YES | E26: =IF(AND(E15<>"",E15>=Finance_Document_Assumptions!$B$10,E21>=1),"YES","NO") -> YES | F26: =IF(AND(F15<>"",F15>=Finance_Document_Assumptions!$B$10,F21>=1),"YES","NO") -> YES
A27: Equity Cure Needed? | B27: If DSCR below lock-up | C27: =IF(AND(C15<>"",C15<Finance_Document_Assumptions!$B$10),"YES","NO") -> NO | D27: =IF(AND(D15<>"",D15<Finance_Document_Assumptions!$B$10),"YES","NO") -> NO | E27: =IF(AND(E15<>"",E15<Finance_Document_Assumptions!$B$10),"YES","NO") -> NO | F27: =IF(AND(F15<>"",F15<Finance_Document_Assumptions!$B$10),"YES","NO") -> NO
A28: Waiver Required? | B28: If default / lock-up | C28: =IF(AND(C15<>"",C15<Finance_Document_Assumptions!$B$10),"YES","NO") -> NO | D28: =IF(AND(D15<>"",D15<Finance_Document_Assumptions!$B$10),"YES","NO") -> NO | E28: =IF(AND(E15<>"",E15<Finance_Document_Assumptions!$B$10),"YES","NO") -> NO | F28: =IF(AND(F15<>"",F15<Finance_Document_Assumptions!$B$10),"YES","NO") -> NO

Sheet Lender_Case_Finance
A1: v4.3 LENDER CASE FINANCE LOGIC
A3: Metric | B3: Formula / Driver | C3: 2026 | D3: 2027 | E3: 2028 | F3: 2029
A4: Revenue | B4: Board revenue x ramp | C4: =Finance_Document_Assumptions!$B$20*Finance_Document_Assumptions!$B$24*(1-Finance_Document_Assumptions!$B$16) -> 5808390 | D4: =Finance_Document_Assumptions!$B$20*Finance_Document_Assumptions!$B$25*(1-Finance_Document_Assumptions!$B$16) -> 9127470 | E4: =Finance_Document_Assumptions!$B$20*Finance_Document_Assumptions!$B$26*(1-Finance_Document_Assumptions!$B$16) -> 13276320 | F4: =Finance_Document_Assumptions!$B$20*Finance_Document_Assumptions!$B$27*(1-Finance_Document_Assumptions!$B$16) -> 16595400
A5: EBITDA Margin | B5: Board EBITDA margin | C5: =Finance_Document_Assumptions!$B$21*(1-Finance_Document_Assumptions!$B$17) -> 0.63060691 | D5: =Finance_Document_Assumptions!$B$21*(1-Finance_Document_Assumptions!$B$17) -> 0.63060691 | E5: =Finance_Document_Assumptions!$B$21*(1-Finance_Document_Assumptions!$B$17) -> 0.63060691 | F5: =Finance_Document_Assumptions!$B$21*(1-Finance_Document_Assumptions!$B$17) -> 0.63060691
A6: EBITDA | B6: Revenue x EBITDA margin | C6: =C4*C5 -> 3662810.9 | D6: =D4*D5 -> 5755845.6 | E6: =E4*E5 -> 8372139.1 | F6: =F4*F5 -> 10465174
A7: CFADS Conversion | B7: Assumption | C7: =Finance_Document_Assumptions!$B$8 -> 0.9 | D7: =Finance_Document_Assumptions!$B$8 -> 0.9 | E7: =Finance_Document_Assumptions!$B$8 -> 0.9 | F7: =Finance_Document_Assumptions!$B$8 -> 0.9
A8: CFADS | B8: EBITDA x conversion | C8: =C6*C7 -> 3296529.8 | D8: =D6*D7 -> 5180261.1 | E8: =E6*E7 -> 7534925.2 | F8: =F6*F7 -> 9418656.5
A9: CAPEX | B9: Phasing from CAPEX_Plan | C9: =CAPEX_Plan!E10 -> 1700000 | D9: =CAPEX_Plan!F10 -> 3790000 | E9: =CAPEX_Plan!G10 -> 4240000 | F9: =CAPEX_Plan!H10 -> 1180000
